distributed.nanny - INFO -         Start Nanny at: 'tcp://172.21.7.52:35076'
distributed.nanny - INFO -         Start Nanny at: 'tcp://172.21.9.113:34920'
distributed.nanny - INFO -         Start Nanny at: 'tcp://172.21.7.100:34465'
distributed.nanny - INFO -         Start Nanny at: 'tcp://172.21.7.169:35353'
distributed.nanny - INFO -         Start Nanny at: 'tcp://172.21.9.76:43697'
distributed.nanny - INFO -         Start Nanny at: 'tcp://172.21.9.93:40188'
distributed.nanny - INFO -         Start Nanny at: 'tcp://172.21.9.92:36006'
distributed.nanny - INFO -         Start Nanny at: 'tcp://172.21.7.176:33357'
distributed.nanny - INFO -         Start Nanny at: 'tcp://172.21.7.100:36396'
distributed.nanny - INFO -         Start Nanny at: 'tcp://172.21.9.92:37434'
distributed.nanny - INFO -         Start Nanny at: 'tcp://172.21.7.176:36629'
distributed.nanny - INFO -         Start Nanny at: 'tcp://172.21.9.113:38850'
distributed.nanny - INFO -         Start Nanny at: 'tcp://172.21.7.169:36894'
distributed.nanny - INFO -         Start Nanny at: 'tcp://172.21.9.76:36969'
distributed.nanny - INFO -         Start Nanny at: 'tcp://172.21.7.52:45054'
distributed.nanny - INFO -         Start Nanny at: 'tcp://172.21.9.93:42232'
distributed.worker - INFO -       Start worker at:    tcp://172.21.9.76:43128
distributed.worker - INFO -          Listening to:    tcp://172.21.9.76:43128
distributed.worker - INFO -          dashboard at:          172.21.9.76:43653
distributed.worker - INFO - Waiting to connect to:    tcp://172.21.0.191:8786
distributed.worker - INFO - -------------------------------------------------
distributed.worker - INFO -               Threads:                         24
distributed.worker - INFO -                Memory:                 172.73 GiB
distributed.worker - INFO -       Local Directory: /tmp/dask-worker-space/worker-kc9kb20d
distributed.worker - INFO -       Start worker at:    tcp://172.21.9.76:33504
distributed.worker - INFO - -------------------------------------------------
distributed.worker - INFO -       Start worker at:   tcp://172.21.9.113:38885
distributed.worker - INFO -          Listening to:   tcp://172.21.9.113:38885
distributed.worker - INFO -          Listening to:    tcp://172.21.9.76:33504
distributed.worker - INFO -          dashboard at:          172.21.9.76:45190
distributed.worker - INFO - Waiting to connect to:    tcp://172.21.0.191:8786
distributed.worker - INFO -       Start worker at:    tcp://172.21.9.93:33187
distributed.worker - INFO -          Listening to:    tcp://172.21.9.93:33187
distributed.worker - INFO -       Start worker at:   tcp://172.21.7.169:41830
distributed.worker - INFO -          Listening to:   tcp://172.21.7.169:41830
distributed.worker - INFO -          dashboard at:         172.21.7.169:40806
distributed.worker - INFO - -------------------------------------------------
distributed.worker - INFO -               Threads:                         24
distributed.worker - INFO -       Start worker at:    tcp://172.21.9.92:42945
distributed.worker - INFO -       Start worker at:   tcp://172.21.7.100:42140
distributed.worker - INFO -          Listening to:   tcp://172.21.7.100:42140
distributed.worker - INFO -       Start worker at:    tcp://172.21.7.52:38431
distributed.worker - INFO -          Listening to:    tcp://172.21.7.52:38431
distributed.worker - INFO -                Memory:                 172.73 GiB
distributed.worker - INFO -       Local Directory: /tmp/dask-worker-space/worker-2q263n48
distributed.worker - INFO - -------------------------------------------------
distributed.worker - INFO -       Start worker at:   tcp://172.21.7.176:45049
distributed.worker - INFO -          dashboard at:         172.21.9.113:44546
distributed.worker - INFO - Waiting to connect to:    tcp://172.21.0.191:8786
distributed.worker - INFO - -------------------------------------------------
distributed.worker - INFO -          dashboard at:          172.21.9.93:37349
distributed.worker - INFO -               Threads:                         24
distributed.worker - INFO - Waiting to connect to:    tcp://172.21.0.191:8786
distributed.worker - INFO - Waiting to connect to:    tcp://172.21.0.191:8786
distributed.worker - INFO -                Memory:                 172.73 GiB
distributed.worker - INFO - -------------------------------------------------
distributed.worker - INFO - -------------------------------------------------
distributed.worker - INFO -       Local Directory: /tmp/dask-worker-space/worker-gn51bmvx
distributed.worker - INFO -               Threads:                         24
distributed.worker - INFO -               Threads:                         24
distributed.worker - INFO -          Listening to:    tcp://172.21.9.92:42945
distributed.worker - INFO - -------------------------------------------------
distributed.worker - INFO -                Memory:                 172.73 GiB
distributed.worker - INFO -                Memory:                 172.73 GiB
distributed.worker - INFO -          dashboard at:          172.21.9.92:35365
distributed.worker - INFO -       Start worker at:   tcp://172.21.9.113:40497
distributed.worker - INFO -       Local Directory: /tmp/dask-worker-space/worker-2d68o97b
distributed.worker - INFO -       Start worker at:    tcp://172.21.9.93:41946
distributed.worker - INFO - Waiting to connect to:    tcp://172.21.0.191:8786
distributed.worker - INFO -          Listening to:   tcp://172.21.7.176:45049
distributed.worker - INFO -          Listening to:   tcp://172.21.9.113:40497
distributed.worker - INFO -          dashboard at:         172.21.7.100:37591
distributed.worker - INFO -       Start worker at:   tcp://172.21.7.169:32848
distributed.worker - INFO -       Local Directory: /tmp/dask-worker-space/worker-ciu2i33k
distributed.worker - INFO - -------------------------------------------------
distributed.worker - INFO -          dashboard at:         172.21.7.176:46047
distributed.worker - INFO -          dashboard at:         172.21.9.113:35034
distributed.worker - INFO - Waiting to connect to:    tcp://172.21.0.191:8786
distributed.worker - INFO - -------------------------------------------------
distributed.worker - INFO -          Listening to:    tcp://172.21.9.93:41946
distributed.worker - INFO -               Threads:                         24
distributed.worker - INFO - Waiting to connect to:    tcp://172.21.0.191:8786
distributed.worker - INFO - Waiting to connect to:    tcp://172.21.0.191:8786
distributed.worker - INFO - -------------------------------------------------
distributed.worker - INFO -          Listening to:   tcp://172.21.7.169:32848
distributed.worker - INFO - -------------------------------------------------
distributed.worker - INFO -                Memory:                 172.73 GiB
distributed.worker - INFO - -------------------------------------------------
distributed.worker - INFO - -------------------------------------------------
distributed.worker - INFO -               Threads:                         24
distributed.worker - INFO -          dashboard at:         172.21.7.169:39122
distributed.worker - INFO -          dashboard at:          172.21.9.93:39775
distributed.worker - INFO -       Local Directory: /tmp/dask-worker-space/worker-6y_j9sov
distributed.worker - INFO -               Threads:                         24
distributed.worker - INFO -               Threads:                         24
distributed.worker - INFO -                Memory:                 172.73 GiB
distributed.worker - INFO - Waiting to connect to:    tcp://172.21.0.191:8786
distributed.worker - INFO - Waiting to connect to:    tcp://172.21.0.191:8786
distributed.worker - INFO -       Start worker at:    tcp://172.21.9.92:37136
distributed.worker - INFO -                Memory:                 172.73 GiB
distributed.worker - INFO -                Memory:                 172.73 GiB
distributed.worker - INFO -       Local Directory: /tmp/dask-worker-space/worker-t7vovu59
distributed.worker - INFO -          dashboard at:          172.21.7.52:35715
distributed.worker - INFO - -------------------------------------------------
distributed.worker - INFO - -------------------------------------------------
distributed.worker - INFO - -------------------------------------------------
distributed.worker - INFO -       Local Directory: /tmp/dask-worker-space/worker-pwu588u7
distributed.worker - INFO -       Local Directory: /tmp/dask-worker-space/worker-ndlvdage
distributed.worker - INFO -       Start worker at:   tcp://172.21.7.100:38272
distributed.worker - INFO - Waiting to connect to:    tcp://172.21.0.191:8786
distributed.worker - INFO - -------------------------------------------------
distributed.worker - INFO -               Threads:                         24
distributed.worker - INFO -               Threads:                         24
distributed.worker - INFO -          Listening to:    tcp://172.21.9.92:37136
distributed.worker - INFO - -------------------------------------------------
distributed.worker - INFO - -------------------------------------------------
distributed.worker - INFO - -------------------------------------------------
distributed.worker - INFO -               Threads:                         24
distributed.worker - INFO -                Memory:                 172.73 GiB
distributed.worker - INFO -                Memory:                 172.73 GiB
distributed.worker - INFO -          dashboard at:          172.21.9.92:32925
distributed.worker - INFO -       Start worker at:   tcp://172.21.7.176:37112
distributed.worker - INFO -          Listening to:   tcp://172.21.7.100:38272
distributed.worker - INFO -                Memory:                 172.73 GiB
distributed.worker - INFO -       Local Directory: /tmp/dask-worker-space/worker-12qw0e3w
distributed.worker - INFO -       Local Directory: /tmp/dask-worker-space/worker-fmg4841i
distributed.worker - INFO - Waiting to connect to:    tcp://172.21.0.191:8786
distributed.worker - INFO -          Listening to:   tcp://172.21.7.176:37112
distributed.worker - INFO -          dashboard at:         172.21.7.100:45415
distributed.worker - INFO -       Local Directory: /tmp/dask-worker-space/worker-ud9vjuum
distributed.worker - INFO - -------------------------------------------------
distributed.worker - INFO - -------------------------------------------------
distributed.worker - INFO - -------------------------------------------------
distributed.worker - INFO -          dashboard at:         172.21.7.176:45806
distributed.worker - INFO - Waiting to connect to:    tcp://172.21.0.191:8786
distributed.worker - INFO - -------------------------------------------------
distributed.worker - INFO -               Threads:                         24
distributed.worker - INFO - Waiting to connect to:    tcp://172.21.0.191:8786
distributed.worker - INFO - -------------------------------------------------
distributed.worker - INFO -       Start worker at:    tcp://172.21.7.52:37647
distributed.worker - INFO -                Memory:                 172.73 GiB
distributed.worker - INFO - -------------------------------------------------
distributed.worker - INFO -               Threads:                         24
distributed.worker - INFO -          Listening to:    tcp://172.21.7.52:37647
distributed.worker - INFO -       Local Directory: /tmp/dask-worker-space/worker-no9xbzj_
distributed.worker - INFO -               Threads:                         24
distributed.worker - INFO -                Memory:                 172.73 GiB
distributed.worker - INFO -          dashboard at:          172.21.7.52:38980
distributed.worker - INFO - -------------------------------------------------
distributed.worker - INFO -                Memory:                 172.73 GiB
distributed.worker - INFO -       Local Directory: /tmp/dask-worker-space/worker-w192ox3z
distributed.worker - INFO - Waiting to connect to:    tcp://172.21.0.191:8786
distributed.worker - INFO -       Local Directory: /tmp/dask-worker-space/worker-bj20n5aw
distributed.worker - INFO - -------------------------------------------------
distributed.worker - INFO - -------------------------------------------------
distributed.worker - INFO - -------------------------------------------------
distributed.worker - INFO -               Threads:                         24
distributed.worker - INFO -                Memory:                 172.73 GiB
distributed.worker - INFO -       Local Directory: /tmp/dask-worker-space/worker-gokjzotk
distributed.worker - INFO - -------------------------------------------------
distributed.worker - INFO -         Registered to:    tcp://172.21.0.191:8786
distributed.worker - INFO - -------------------------------------------------
distributed.core - INFO - Starting established connection
distributed.worker - INFO -         Registered to:    tcp://172.21.0.191:8786
distributed.worker - INFO - -------------------------------------------------
distributed.core - INFO - Starting established connection
distributed.worker - INFO -         Registered to:    tcp://172.21.0.191:8786
distributed.worker - INFO - -------------------------------------------------
distributed.core - INFO - Starting established connection
distributed.worker - INFO -         Registered to:    tcp://172.21.0.191:8786
distributed.worker - INFO - -------------------------------------------------
distributed.core - INFO - Starting established connection
distributed.worker - INFO -         Registered to:    tcp://172.21.0.191:8786
distributed.worker - INFO - -------------------------------------------------
distributed.core - INFO - Starting established connection
distributed.worker - INFO -         Registered to:    tcp://172.21.0.191:8786
distributed.worker - INFO - -------------------------------------------------
distributed.core - INFO - Starting established connection
distributed.worker - INFO -         Registered to:    tcp://172.21.0.191:8786
distributed.worker - INFO - -------------------------------------------------
distributed.core - INFO - Starting established connection
distributed.worker - INFO -         Registered to:    tcp://172.21.0.191:8786
distributed.worker - INFO - -------------------------------------------------
distributed.core - INFO - Starting established connection
distributed.worker - INFO -         Registered to:    tcp://172.21.0.191:8786
distributed.worker - INFO - -------------------------------------------------
distributed.core - INFO - Starting established connection
distributed.worker - INFO -         Registered to:    tcp://172.21.0.191:8786
distributed.worker - INFO - -------------------------------------------------
distributed.core - INFO - Starting established connection
distributed.worker - INFO -         Registered to:    tcp://172.21.0.191:8786
distributed.worker - INFO - -------------------------------------------------
distributed.core - INFO - Starting established connection
distributed.worker - INFO -         Registered to:    tcp://172.21.0.191:8786
distributed.worker - INFO - -------------------------------------------------
distributed.core - INFO - Starting established connection
distributed.worker - INFO -         Registered to:    tcp://172.21.0.191:8786
distributed.worker - INFO - -------------------------------------------------
distributed.core - INFO - Starting established connection
distributed.worker - INFO -         Registered to:    tcp://172.21.0.191:8786
distributed.worker - INFO - -------------------------------------------------
distributed.core - INFO - Starting established connection
distributed.worker - INFO -         Registered to:    tcp://172.21.0.191:8786
distributed.worker - INFO - -------------------------------------------------
distributed.core - INFO - Starting established connection
distributed.worker - INFO -         Registered to:    tcp://172.21.0.191:8786
distributed.worker - INFO - -------------------------------------------------
distributed.core - INFO - Starting established connection
distributed.core - INFO - Event loop was unresponsive in Worker for 4.31s.  This is often caused by long-running GIL-holding functions or moving large chunks of data. This can cause timeouts and instability.
distributed.core - INFO - Event loop was unresponsive in Worker for 11.90s.  This is often caused by long-running GIL-holding functions or moving large chunks of data. This can cause timeouts and instability.
distributed.core - INFO - Event loop was unresponsive in Worker for 7.62s.  This is often caused by long-running GIL-holding functions or moving large chunks of data. This can cause timeouts and instability.
distributed.core - INFO - Event loop was unresponsive in Worker for 3.53s.  This is often caused by long-running GIL-holding functions or moving large chunks of data. This can cause timeouts and instability.
distributed.core - INFO - Event loop was unresponsive in Worker for 12.48s.  This is often caused by long-running GIL-holding functions or moving large chunks of data. This can cause timeouts and instability.
distributed.core - INFO - Event loop was unresponsive in Worker for 10.88s.  This is often caused by long-running GIL-holding functions or moving large chunks of data. This can cause timeouts and instability.
distributed.core - INFO - Event loop was unresponsive in Worker for 9.38s.  This is often caused by long-running GIL-holding functions or moving large chunks of data. This can cause timeouts and instability.
distributed.core - INFO - Event loop was unresponsive in Worker for 9.38s.  This is often caused by long-running GIL-holding functions or moving large chunks of data. This can cause timeouts and instability.
distributed.core - INFO - Event loop was unresponsive in Worker for 9.38s.  This is often caused by long-running GIL-holding functions or moving large chunks of data. This can cause timeouts and instability.
distributed.core - INFO - Event loop was unresponsive in Worker for 9.38s.  This is often caused by long-running GIL-holding functions or moving large chunks of data. This can cause timeouts and instability.
distributed.core - INFO - Event loop was unresponsive in Worker for 9.38s.  This is often caused by long-running GIL-holding functions or moving large chunks of data. This can cause timeouts and instability.
distributed.core - INFO - Event loop was unresponsive in Worker for 9.44s.  This is often caused by long-running GIL-holding functions or moving large chunks of data. This can cause timeouts and instability.
distributed.core - INFO - Event loop was unresponsive in Worker for 9.45s.  This is often caused by long-running GIL-holding functions or moving large chunks of data. This can cause timeouts and instability.
distributed.core - INFO - Event loop was unresponsive in Worker for 9.45s.  This is often caused by long-running GIL-holding functions or moving large chunks of data. This can cause timeouts and instability.
distributed.worker - ERROR - Worker stream died during communication: tcp://172.21.9.113:40497
Traceback (most recent call last):
  File "/ccc/work/cont003/gen2224/gen2224/spack/var/spack/environments/gysela-deisa-irene-skl-draft/.spack-env/view/lib/python3.9/site-packages/distributed/comm/tcp.py", line 205, in read
    frames_nbytes = await stream.read_bytes(fmt_size)
asyncio.exceptions.CancelledError

During handling of the above exception, another exception occurred:

Traceback (most recent call last):
  File "/ccc/work/cont003/gen2224/gen2224/spack/var/spack/environments/gysela-deisa-irene-skl-draft/.spack-env/._view/whcr3wyhzgorszy3rfxsphyebtvfpqzk/lib/python3.9/asyncio/tasks.py", line 490, in wait_for
    return fut.result()
asyncio.exceptions.CancelledError

The above exception was the direct cause of the following exception:

Traceback (most recent call last):
  File "/ccc/work/cont003/gen2224/gen2224/spack/var/spack/environments/gysela-deisa-irene-skl-draft/.spack-env/view/lib/python3.9/site-packages/distributed/comm/core.py", line 319, in connect
    handshake = await asyncio.wait_for(comm.read(), time_left())
  File "/ccc/work/cont003/gen2224/gen2224/spack/var/spack/environments/gysela-deisa-irene-skl-draft/.spack-env/._view/whcr3wyhzgorszy3rfxsphyebtvfpqzk/lib/python3.9/asyncio/tasks.py", line 492, in wait_for
    raise exceptions.TimeoutError() from exc
asyncio.exceptions.TimeoutError

The above exception was the direct cause of the following exception:

Traceback (most recent call last):
  File "/ccc/work/cont003/gen2224/gen2224/spack/var/spack/environments/gysela-deisa-irene-skl-draft/.spack-env/view/lib/python3.9/site-packages/distributed/worker.py", line 2878, in gather_dep
    response = await get_data_from_worker(
  File "/ccc/work/cont003/gen2224/gen2224/spack/var/spack/environments/gysela-deisa-irene-skl-draft/.spack-env/view/lib/python3.9/site-packages/distributed/worker.py", line 4143, in get_data_from_worker
    return await retry_operation(_get_data, operation="get_data_from_worker")
  File "/ccc/work/cont003/gen2224/gen2224/spack/var/spack/environments/gysela-deisa-irene-skl-draft/.spack-env/view/lib/python3.9/site-packages/distributed/utils_comm.py", line 366, in retry_operation
    return await retry(
  File "/ccc/work/cont003/gen2224/gen2224/spack/var/spack/environments/gysela-deisa-irene-skl-draft/.spack-env/view/lib/python3.9/site-packages/distributed/utils_comm.py", line 351, in retry
    return await coro()
  File "/ccc/work/cont003/gen2224/gen2224/spack/var/spack/environments/gysela-deisa-irene-skl-draft/.spack-env/view/lib/python3.9/site-packages/distributed/worker.py", line 4120, in _get_data
    comm = await rpc.connect(worker)
  File "/ccc/work/cont003/gen2224/gen2224/spack/var/spack/environments/gysela-deisa-irene-skl-draft/.spack-env/view/lib/python3.9/site-packages/distributed/core.py", line 1081, in connect
    raise exc
  File "/ccc/work/cont003/gen2224/gen2224/spack/var/spack/environments/gysela-deisa-irene-skl-draft/.spack-env/view/lib/python3.9/site-packages/distributed/core.py", line 1065, in connect
    comm = await fut
  File "/ccc/work/cont003/gen2224/gen2224/spack/var/spack/environments/gysela-deisa-irene-skl-draft/.spack-env/view/lib/python3.9/site-packages/distributed/comm/core.py", line 324, in connect
    raise OSError(
OSError: Timed out during handshake while connecting to tcp://172.21.9.113:40497 after 30 s
distributed.core - INFO - Event loop was unresponsive in Worker for 3.10s.  This is often caused by long-running GIL-holding functions or moving large chunks of data. This can cause timeouts and instability.
distributed.worker - ERROR - Worker stream died during communication: tcp://172.21.9.113:40497
Traceback (most recent call last):
  File "/ccc/work/cont003/gen2224/gen2224/spack/var/spack/environments/gysela-deisa-irene-skl-draft/.spack-env/view/lib/python3.9/site-packages/distributed/comm/tcp.py", line 205, in read
    frames_nbytes = await stream.read_bytes(fmt_size)
asyncio.exceptions.CancelledError

During handling of the above exception, another exception occurred:

Traceback (most recent call last):
  File "/ccc/work/cont003/gen2224/gen2224/spack/var/spack/environments/gysela-deisa-irene-skl-draft/.spack-env/._view/whcr3wyhzgorszy3rfxsphyebtvfpqzk/lib/python3.9/asyncio/tasks.py", line 490, in wait_for
    return fut.result()
asyncio.exceptions.CancelledError

The above exception was the direct cause of the following exception:

Traceback (most recent call last):
  File "/ccc/work/cont003/gen2224/gen2224/spack/var/spack/environments/gysela-deisa-irene-skl-draft/.spack-env/view/lib/python3.9/site-packages/distributed/comm/core.py", line 319, in connect
    handshake = await asyncio.wait_for(comm.read(), time_left())
  File "/ccc/work/cont003/gen2224/gen2224/spack/var/spack/environments/gysela-deisa-irene-skl-draft/.spack-env/._view/whcr3wyhzgorszy3rfxsphyebtvfpqzk/lib/python3.9/asyncio/tasks.py", line 492, in wait_for
    raise exceptions.TimeoutError() from exc
asyncio.exceptions.TimeoutError

The above exception was the direct cause of the following exception:

Traceback (most recent call last):
  File "/ccc/work/cont003/gen2224/gen2224/spack/var/spack/environments/gysela-deisa-irene-skl-draft/.spack-env/view/lib/python3.9/site-packages/distributed/worker.py", line 2878, in gather_dep
    response = await get_data_from_worker(
  File "/ccc/work/cont003/gen2224/gen2224/spack/var/spack/environments/gysela-deisa-irene-skl-draft/.spack-env/view/lib/python3.9/site-packages/distributed/worker.py", line 4143, in get_data_from_worker
    return await retry_operation(_get_data, operation="get_data_from_worker")
  File "/ccc/work/cont003/gen2224/gen2224/spack/var/spack/environments/gysela-deisa-irene-skl-draft/.spack-env/view/lib/python3.9/site-packages/distributed/utils_comm.py", line 366, in retry_operation
    return await retry(
  File "/ccc/work/cont003/gen2224/gen2224/spack/var/spack/environments/gysela-deisa-irene-skl-draft/.spack-env/view/lib/python3.9/site-packages/distributed/utils_comm.py", line 351, in retry
    return await coro()
  File "/ccc/work/cont003/gen2224/gen2224/spack/var/spack/environments/gysela-deisa-irene-skl-draft/.spack-env/view/lib/python3.9/site-packages/distributed/worker.py", line 4120, in _get_data
    comm = await rpc.connect(worker)
  File "/ccc/work/cont003/gen2224/gen2224/spack/var/spack/environments/gysela-deisa-irene-skl-draft/.spack-env/view/lib/python3.9/site-packages/distributed/core.py", line 1081, in connect
    raise exc
  File "/ccc/work/cont003/gen2224/gen2224/spack/var/spack/environments/gysela-deisa-irene-skl-draft/.spack-env/view/lib/python3.9/site-packages/distributed/core.py", line 1065, in connect
    comm = await fut
  File "/ccc/work/cont003/gen2224/gen2224/spack/var/spack/environments/gysela-deisa-irene-skl-draft/.spack-env/view/lib/python3.9/site-packages/distributed/comm/core.py", line 324, in connect
    raise OSError(
OSError: Timed out during handshake while connecting to tcp://172.21.9.113:40497 after 30 s
distributed.core - INFO - Event loop was unresponsive in Worker for 3.11s.  This is often caused by long-running GIL-holding functions or moving large chunks of data. This can cause timeouts and instability.
distributed.worker - ERROR - Worker stream died during communication: tcp://172.21.9.113:40497
Traceback (most recent call last):
  File "/ccc/work/cont003/gen2224/gen2224/spack/var/spack/environments/gysela-deisa-irene-skl-draft/.spack-env/view/lib/python3.9/site-packages/distributed/comm/tcp.py", line 205, in read
    frames_nbytes = await stream.read_bytes(fmt_size)
asyncio.exceptions.CancelledError

During handling of the above exception, another exception occurred:

Traceback (most recent call last):
  File "/ccc/work/cont003/gen2224/gen2224/spack/var/spack/environments/gysela-deisa-irene-skl-draft/.spack-env/._view/whcr3wyhzgorszy3rfxsphyebtvfpqzk/lib/python3.9/asyncio/tasks.py", line 490, in wait_for
    return fut.result()
asyncio.exceptions.CancelledError

The above exception was the direct cause of the following exception:

Traceback (most recent call last):
distributed.worker - ERROR - Worker stream died during communication: tcp://172.21.9.113:40497
Traceback (most recent call last):
  File "/ccc/work/cont003/gen2224/gen2224/spack/var/spack/environments/gysela-deisa-irene-skl-draft/.spack-env/view/lib/python3.9/site-packages/distributed/comm/tcp.py", line 205, in read
    frames_nbytes = await stream.read_bytes(fmt_size)
asyncio.exceptions.CancelledError

During handling of the above exception, another exception occurred:

Traceback (most recent call last):
  File "/ccc/work/cont003/gen2224/gen2224/spack/var/spack/environments/gysela-deisa-irene-skl-draft/.spack-env/._view/whcr3wyhzgorszy3rfxsphyebtvfpqzk/lib/python3.9/asyncio/tasks.py", line 490, in wait_for
    return fut.result()
asyncio.exceptions.CancelledError

The above exception was the direct cause of the following exception:

Traceback (most recent call last):
  File "/ccc/work/cont003/gen2224/gen2224/spack/var/spack/environments/gysela-deisa-irene-skl-draft/.spack-env/view/lib/python3.9/site-packages/distributed/comm/core.py", line 319, in connect
    handshake = await asyncio.wait_for(comm.read(), time_left())
  File "/ccc/work/cont003/gen2224/gen2224/spack/var/spack/environments/gysela-deisa-irene-skl-draft/.spack-env/._view/whcr3wyhzgorszy3rfxsphyebtvfpqzk/lib/python3.9/asyncio/tasks.py", line 492, in wait_for
    raise exceptions.TimeoutError() from exc
asyncio.exceptions.TimeoutError

The above exception was the direct cause of the following exception:

Traceback (most recent call last):
  File "/ccc/work/cont003/gen2224/gen2224/spack/var/spack/environments/gysela-deisa-irene-skl-draft/.spack-env/view/lib/python3.9/site-packages/distributed/worker.py", line 2878, in gather_dep
    response = await get_data_from_worker(
  File "/ccc/work/cont003/gen2224/gen2224/spack/var/spack/environments/gysela-deisa-irene-skl-draft/.spack-env/view/lib/python3.9/site-packages/distributed/comm/core.py", line 319, in connect
    handshake = await asyncio.wait_for(comm.read(), time_left())
  File "/ccc/work/cont003/gen2224/gen2224/spack/var/spack/environments/gysela-deisa-irene-skl-draft/.spack-env/._view/whcr3wyhzgorszy3rfxsphyebtvfpqzk/lib/python3.9/asyncio/tasks.py", line 492, in wait_for
    raise exceptions.TimeoutError() from exc
asyncio.exceptions.TimeoutError

The above exception was the direct cause of the following exception:

Traceback (most recent call last):
  File "/ccc/work/cont003/gen2224/gen2224/spack/var/spack/environments/gysela-deisa-irene-skl-draft/.spack-env/view/lib/python3.9/site-packages/distributed/worker.py", line 2878, in gather_dep
    response = await get_data_from_worker(
  File "/ccc/work/cont003/gen2224/gen2224/spack/var/spack/environments/gysela-deisa-irene-skl-draft/.spack-env/view/lib/python3.9/site-packages/distributed/worker.py", line 4143, in get_data_from_worker
    return await retry_operation(_get_data, operation="get_data_from_worker")
  File "/ccc/work/cont003/gen2224/gen2224/spack/var/spack/environments/gysela-deisa-irene-skl-draft/.spack-env/view/lib/python3.9/site-packages/distributed/utils_comm.py", line 366, in retry_operation
    return await retry(
  File "/ccc/work/cont003/gen2224/gen2224/spack/var/spack/environments/gysela-deisa-irene-skl-draft/.spack-env/view/lib/python3.9/site-packages/distributed/utils_comm.py", line 351, in retry
    return await coro()
  File "/ccc/work/cont003/gen2224/gen2224/spack/var/spack/environments/gysela-deisa-irene-skl-draft/.spack-env/view/lib/python3.9/site-packages/distributed/worker.py", line 4120, in _get_data
    comm = await rpc.connect(worker)
  File "/ccc/work/cont003/gen2224/gen2224/spack/var/spack/environments/gysela-deisa-irene-skl-draft/.spack-env/view/lib/python3.9/site-packages/distributed/worker.py", line 4143, in get_data_from_worker
    return await retry_operation(_get_data, operation="get_data_from_worker")
  File "/ccc/work/cont003/gen2224/gen2224/spack/var/spack/environments/gysela-deisa-irene-skl-draft/.spack-env/view/lib/python3.9/site-packages/distributed/utils_comm.py", line 366, in retry_operation
    return await retry(
  File "/ccc/work/cont003/gen2224/gen2224/spack/var/spack/environments/gysela-deisa-irene-skl-draft/.spack-env/view/lib/python3.9/site-packages/distributed/utils_comm.py", line 351, in retry
    return await coro()
  File "/ccc/work/cont003/gen2224/gen2224/spack/var/spack/environments/gysela-deisa-irene-skl-draft/.spack-env/view/lib/python3.9/site-packages/distributed/worker.py", line 4120, in _get_data
    comm = await rpc.connect(worker)
  File "/ccc/work/cont003/gen2224/gen2224/spack/var/spack/environments/gysela-deisa-irene-skl-draft/.spack-env/view/lib/python3.9/site-packages/distributed/core.py", line 1081, in connect
    raise exc
  File "/ccc/work/cont003/gen2224/gen2224/spack/var/spack/environments/gysela-deisa-irene-skl-draft/.spack-env/view/lib/python3.9/site-packages/distributed/core.py", line 1065, in connect
    comm = await fut
  File "/ccc/work/cont003/gen2224/gen2224/spack/var/spack/environments/gysela-deisa-irene-skl-draft/.spack-env/view/lib/python3.9/site-packages/distributed/comm/core.py", line 324, in connect
    raise OSError(
OSError: Timed out during handshake while connecting to tcp://172.21.9.113:40497 after 30 s
  File "/ccc/work/cont003/gen2224/gen2224/spack/var/spack/environments/gysela-deisa-irene-skl-draft/.spack-env/view/lib/python3.9/site-packages/distributed/core.py", line 1081, in connect
    raise exc
  File "/ccc/work/cont003/gen2224/gen2224/spack/var/spack/environments/gysela-deisa-irene-skl-draft/.spack-env/view/lib/python3.9/site-packages/distributed/core.py", line 1065, in connect
    comm = await fut
  File "/ccc/work/cont003/gen2224/gen2224/spack/var/spack/environments/gysela-deisa-irene-skl-draft/.spack-env/view/lib/python3.9/site-packages/distributed/comm/core.py", line 324, in connect
    raise OSError(
OSError: Timed out during handshake while connecting to tcp://172.21.9.113:40497 after 30 s
distributed.worker - ERROR - Worker stream died during communication: tcp://172.21.9.113:40497
Traceback (most recent call last):
  File "/ccc/work/cont003/gen2224/gen2224/spack/var/spack/environments/gysela-deisa-irene-skl-draft/.spack-env/view/lib/python3.9/site-packages/distributed/comm/tcp.py", line 205, in read
    frames_nbytes = await stream.read_bytes(fmt_size)
asyncio.exceptions.CancelledError

During handling of the above exception, another exception occurred:

Traceback (most recent call last):
  File "/ccc/work/cont003/gen2224/gen2224/spack/var/spack/environments/gysela-deisa-irene-skl-draft/.spack-env/._view/whcr3wyhzgorszy3rfxsphyebtvfpqzk/lib/python3.9/asyncio/tasks.py", line 490, in wait_for
    return fut.result()
asyncio.exceptions.CancelledError

The above exception was the direct cause of the following exception:

Traceback (most recent call last):
distributed.worker - ERROR - Worker stream died during communication: tcp://172.21.9.113:40497
Traceback (most recent call last):
  File "/ccc/work/cont003/gen2224/gen2224/spack/var/spack/environments/gysela-deisa-irene-skl-draft/.spack-env/view/lib/python3.9/site-packages/distributed/comm/tcp.py", line 205, in read
    frames_nbytes = await stream.read_bytes(fmt_size)
asyncio.exceptions.CancelledError

During handling of the above exception, another exception occurred:

Traceback (most recent call last):
  File "/ccc/work/cont003/gen2224/gen2224/spack/var/spack/environments/gysela-deisa-irene-skl-draft/.spack-env/._view/whcr3wyhzgorszy3rfxsphyebtvfpqzk/lib/python3.9/asyncio/tasks.py", line 490, in wait_for
    return fut.result()
asyncio.exceptions.CancelledError

The above exception was the direct cause of the following exception:

Traceback (most recent call last):
  File "/ccc/work/cont003/gen2224/gen2224/spack/var/spack/environments/gysela-deisa-irene-skl-draft/.spack-env/view/lib/python3.9/site-packages/distributed/comm/core.py", line 319, in connect
    handshake = await asyncio.wait_for(comm.read(), time_left())
  File "/ccc/work/cont003/gen2224/gen2224/spack/var/spack/environments/gysela-deisa-irene-skl-draft/.spack-env/._view/whcr3wyhzgorszy3rfxsphyebtvfpqzk/lib/python3.9/asyncio/tasks.py", line 492, in wait_for
    raise exceptions.TimeoutError() from exc
asyncio.exceptions.TimeoutError

The above exception was the direct cause of the following exception:

Traceback (most recent call last):
  File "/ccc/work/cont003/gen2224/gen2224/spack/var/spack/environments/gysela-deisa-irene-skl-draft/.spack-env/view/lib/python3.9/site-packages/distributed/worker.py", line 2878, in gather_dep
    response = await get_data_from_worker(
  File "/ccc/work/cont003/gen2224/gen2224/spack/var/spack/environments/gysela-deisa-irene-skl-draft/.spack-env/view/lib/python3.9/site-packages/distributed/comm/core.py", line 319, in connect
    handshake = await asyncio.wait_for(comm.read(), time_left())
  File "/ccc/work/cont003/gen2224/gen2224/spack/var/spack/environments/gysela-deisa-irene-skl-draft/.spack-env/._view/whcr3wyhzgorszy3rfxsphyebtvfpqzk/lib/python3.9/asyncio/tasks.py", line 492, in wait_for
    raise exceptions.TimeoutError() from exc
asyncio.exceptions.TimeoutError

The above exception was the direct cause of the following exception:

Traceback (most recent call last):
  File "/ccc/work/cont003/gen2224/gen2224/spack/var/spack/environments/gysela-deisa-irene-skl-draft/.spack-env/view/lib/python3.9/site-packages/distributed/worker.py", line 2878, in gather_dep
    response = await get_data_from_worker(
  File "/ccc/work/cont003/gen2224/gen2224/spack/var/spack/environments/gysela-deisa-irene-skl-draft/.spack-env/view/lib/python3.9/site-packages/distributed/worker.py", line 4143, in get_data_from_worker
    return await retry_operation(_get_data, operation="get_data_from_worker")
  File "/ccc/work/cont003/gen2224/gen2224/spack/var/spack/environments/gysela-deisa-irene-skl-draft/.spack-env/view/lib/python3.9/site-packages/distributed/utils_comm.py", line 366, in retry_operation
    return await retry(
  File "/ccc/work/cont003/gen2224/gen2224/spack/var/spack/environments/gysela-deisa-irene-skl-draft/.spack-env/view/lib/python3.9/site-packages/distributed/utils_comm.py", line 351, in retry
    return await coro()
  File "/ccc/work/cont003/gen2224/gen2224/spack/var/spack/environments/gysela-deisa-irene-skl-draft/.spack-env/view/lib/python3.9/site-packages/distributed/worker.py", line 4120, in _get_data
    comm = await rpc.connect(worker)
  File "/ccc/work/cont003/gen2224/gen2224/spack/var/spack/environments/gysela-deisa-irene-skl-draft/.spack-env/view/lib/python3.9/site-packages/distributed/worker.py", line 4143, in get_data_from_worker
    return await retry_operation(_get_data, operation="get_data_from_worker")
  File "/ccc/work/cont003/gen2224/gen2224/spack/var/spack/environments/gysela-deisa-irene-skl-draft/.spack-env/view/lib/python3.9/site-packages/distributed/utils_comm.py", line 366, in retry_operation
    return await retry(
  File "/ccc/work/cont003/gen2224/gen2224/spack/var/spack/environments/gysela-deisa-irene-skl-draft/.spack-env/view/lib/python3.9/site-packages/distributed/utils_comm.py", line 351, in retry
    return await coro()
  File "/ccc/work/cont003/gen2224/gen2224/spack/var/spack/environments/gysela-deisa-irene-skl-draft/.spack-env/view/lib/python3.9/site-packages/distributed/worker.py", line 4120, in _get_data
    comm = await rpc.connect(worker)
  File "/ccc/work/cont003/gen2224/gen2224/spack/var/spack/environments/gysela-deisa-irene-skl-draft/.spack-env/view/lib/python3.9/site-packages/distributed/core.py", line 1081, in connect
    raise exc
  File "/ccc/work/cont003/gen2224/gen2224/spack/var/spack/environments/gysela-deisa-irene-skl-draft/.spack-env/view/lib/python3.9/site-packages/distributed/core.py", line 1065, in connect
    comm = await fut
  File "/ccc/work/cont003/gen2224/gen2224/spack/var/spack/environments/gysela-deisa-irene-skl-draft/.spack-env/view/lib/python3.9/site-packages/distributed/comm/core.py", line 324, in connect
    raise OSError(
OSError: Timed out during handshake while connecting to tcp://172.21.9.113:40497 after 30 s
  File "/ccc/work/cont003/gen2224/gen2224/spack/var/spack/environments/gysela-deisa-irene-skl-draft/.spack-env/view/lib/python3.9/site-packages/distributed/core.py", line 1081, in connect
    raise exc
  File "/ccc/work/cont003/gen2224/gen2224/spack/var/spack/environments/gysela-deisa-irene-skl-draft/.spack-env/view/lib/python3.9/site-packages/distributed/core.py", line 1065, in connect
    comm = await fut
  File "/ccc/work/cont003/gen2224/gen2224/spack/var/spack/environments/gysela-deisa-irene-skl-draft/.spack-env/view/lib/python3.9/site-packages/distributed/comm/core.py", line 324, in connect
    raise OSError(
OSError: Timed out during handshake while connecting to tcp://172.21.9.113:40497 after 30 s
distributed.worker - ERROR - Worker stream died during communication: tcp://172.21.9.113:40497
Traceback (most recent call last):
  File "/ccc/work/cont003/gen2224/gen2224/spack/var/spack/environments/gysela-deisa-irene-skl-draft/.spack-env/view/lib/python3.9/site-packages/distributed/comm/tcp.py", line 205, in read
    frames_nbytes = await stream.read_bytes(fmt_size)
asyncio.exceptions.CancelledError

During handling of the above exception, another exception occurred:

Traceback (most recent call last):
  File "/ccc/work/cont003/gen2224/gen2224/spack/var/spack/environments/gysela-deisa-irene-skl-draft/.spack-env/._view/whcr3wyhzgorszy3rfxsphyebtvfpqzk/lib/python3.9/asyncio/tasks.py", line 490, in wait_for
    return fut.result()
asyncio.exceptions.CancelledError

The above exception was the direct cause of the following exception:

Traceback (most recent call last):
  File "/ccc/work/cont003/gen2224/gen2224/spack/var/spack/environments/gysela-deisa-irene-skl-draft/.spack-env/view/lib/python3.9/site-packages/distributed/comm/core.py", line 319, in connect
    handshake = await asyncio.wait_for(comm.read(), time_left())
  File "/ccc/work/cont003/gen2224/gen2224/spack/var/spack/environments/gysela-deisa-irene-skl-draft/.spack-env/._view/whcr3wyhzgorszy3rfxsphyebtvfpqzk/lib/python3.9/asyncio/tasks.py", line 492, in wait_for
    raise exceptions.TimeoutError() from exc
asyncio.exceptions.TimeoutError

The above exception was the direct cause of the following exception:

Traceback (most recent call last):
  File "/ccc/work/cont003/gen2224/gen2224/spack/var/spack/environments/gysela-deisa-irene-skl-draft/.spack-env/view/lib/python3.9/site-packages/distributed/worker.py", line 2878, in gather_dep
    response = await get_data_from_worker(
  File "/ccc/work/cont003/gen2224/gen2224/spack/var/spack/environments/gysela-deisa-irene-skl-draft/.spack-env/view/lib/python3.9/site-packages/distributed/worker.py", line 4143, in get_data_from_worker
    return await retry_operation(_get_data, operation="get_data_from_worker")
  File "/ccc/work/cont003/gen2224/gen2224/spack/var/spack/environments/gysela-deisa-irene-skl-draft/.spack-env/view/lib/python3.9/site-packages/distributed/utils_comm.py", line 366, in retry_operation
    return await retry(
  File "/ccc/work/cont003/gen2224/gen2224/spack/var/spack/environments/gysela-deisa-irene-skl-draft/.spack-env/view/lib/python3.9/site-packages/distributed/utils_comm.py", line 351, in retry
    return await coro()
  File "/ccc/work/cont003/gen2224/gen2224/spack/var/spack/environments/gysela-deisa-irene-skl-draft/.spack-env/view/lib/python3.9/site-packages/distributed/worker.py", line 4120, in _get_data
    comm = await rpc.connect(worker)
  File "/ccc/work/cont003/gen2224/gen2224/spack/var/spack/environments/gysela-deisa-irene-skl-draft/.spack-env/view/lib/python3.9/site-packages/distributed/core.py", line 1081, in connect
    raise exc
  File "/ccc/work/cont003/gen2224/gen2224/spack/var/spack/environments/gysela-deisa-irene-skl-draft/.spack-env/view/lib/python3.9/site-packages/distributed/core.py", line 1065, in connect
    comm = await fut
  File "/ccc/work/cont003/gen2224/gen2224/spack/var/spack/environments/gysela-deisa-irene-skl-draft/.spack-env/view/lib/python3.9/site-packages/distributed/comm/core.py", line 324, in connect
    raise OSError(
OSError: Timed out during handshake while connecting to tcp://172.21.9.113:40497 after 30 s
distributed.worker - ERROR - Worker stream died during communication: tcp://172.21.9.113:40497
Traceback (most recent call last):
  File "/ccc/work/cont003/gen2224/gen2224/spack/var/spack/environments/gysela-deisa-irene-skl-draft/.spack-env/view/lib/python3.9/site-packages/distributed/comm/tcp.py", line 205, in read
    frames_nbytes = await stream.read_bytes(fmt_size)
asyncio.exceptions.CancelledError

During handling of the above exception, another exception occurred:

Traceback (most recent call last):
  File "/ccc/work/cont003/gen2224/gen2224/spack/var/spack/environments/gysela-deisa-irene-skl-draft/.spack-env/._view/whcr3wyhzgorszy3rfxsphyebtvfpqzk/lib/python3.9/asyncio/tasks.py", line 490, in wait_for
    return fut.result()
asyncio.exceptions.CancelledError

The above exception was the direct cause of the following exception:

Traceback (most recent call last):
  File "/ccc/work/cont003/gen2224/gen2224/spack/var/spack/environments/gysela-deisa-irene-skl-draft/.spack-env/view/lib/python3.9/site-packages/distributed/comm/core.py", line 319, in connect
    handshake = await asyncio.wait_for(comm.read(), time_left())
  File "/ccc/work/cont003/gen2224/gen2224/spack/var/spack/environments/gysela-deisa-irene-skl-draft/.spack-env/._view/whcr3wyhzgorszy3rfxsphyebtvfpqzk/lib/python3.9/asyncio/tasks.py", line 492, in wait_for
    raise exceptions.TimeoutError() from exc
asyncio.exceptions.TimeoutError

The above exception was the direct cause of the following exception:

Traceback (most recent call last):
  File "/ccc/work/cont003/gen2224/gen2224/spack/var/spack/environments/gysela-deisa-irene-skl-draft/.spack-env/view/lib/python3.9/site-packages/distributed/worker.py", line 2878, in gather_dep
    response = await get_data_from_worker(
  File "/ccc/work/cont003/gen2224/gen2224/spack/var/spack/environments/gysela-deisa-irene-skl-draft/.spack-env/view/lib/python3.9/site-packages/distributed/worker.py", line 4143, in get_data_from_worker
    return await retry_operation(_get_data, operation="get_data_from_worker")
  File "/ccc/work/cont003/gen2224/gen2224/spack/var/spack/environments/gysela-deisa-irene-skl-draft/.spack-env/view/lib/python3.9/site-packages/distributed/utils_comm.py", line 366, in retry_operation
    return await retry(
  File "/ccc/work/cont003/gen2224/gen2224/spack/var/spack/environments/gysela-deisa-irene-skl-draft/.spack-env/view/lib/python3.9/site-packages/distributed/utils_comm.py", line 351, in retry
    return await coro()
  File "/ccc/work/cont003/gen2224/gen2224/spack/var/spack/environments/gysela-deisa-irene-skl-draft/.spack-env/view/lib/python3.9/site-packages/distributed/worker.py", line 4120, in _get_data
    comm = await rpc.connect(worker)
  File "/ccc/work/cont003/gen2224/gen2224/spack/var/spack/environments/gysela-deisa-irene-skl-draft/.spack-env/view/lib/python3.9/site-packages/distributed/core.py", line 1081, in connect
    raise exc
  File "/ccc/work/cont003/gen2224/gen2224/spack/var/spack/environments/gysela-deisa-irene-skl-draft/.spack-env/view/lib/python3.9/site-packages/distributed/core.py", line 1065, in connect
    comm = await fut
  File "/ccc/work/cont003/gen2224/gen2224/spack/var/spack/environments/gysela-deisa-irene-skl-draft/.spack-env/view/lib/python3.9/site-packages/distributed/comm/core.py", line 324, in connect
    raise OSError(
OSError: Timed out during handshake while connecting to tcp://172.21.9.113:40497 after 30 s
distributed.worker - ERROR - Worker stream died during communication: tcp://172.21.9.113:40497
Traceback (most recent call last):
  File "/ccc/work/cont003/gen2224/gen2224/spack/var/spack/environments/gysela-deisa-irene-skl-draft/.spack-env/view/lib/python3.9/site-packages/distributed/comm/tcp.py", line 205, in read
    frames_nbytes = await stream.read_bytes(fmt_size)
asyncio.exceptions.CancelledError

During handling of the above exception, another exception occurred:

Traceback (most recent call last):
  File "/ccc/work/cont003/gen2224/gen2224/spack/var/spack/environments/gysela-deisa-irene-skl-draft/.spack-env/._view/whcr3wyhzgorszy3rfxsphyebtvfpqzk/lib/python3.9/asyncio/tasks.py", line 490, in wait_for
    return fut.result()
asyncio.exceptions.CancelledError

The above exception was the direct cause of the following exception:

Traceback (most recent call last):
  File "/ccc/work/cont003/gen2224/gen2224/spack/var/spack/environments/gysela-deisa-irene-skl-draft/.spack-env/view/lib/python3.9/site-packages/distributed/comm/core.py", line 319, in connect
    handshake = await asyncio.wait_for(comm.read(), time_left())
  File "/ccc/work/cont003/gen2224/gen2224/spack/var/spack/environments/gysela-deisa-irene-skl-draft/.spack-env/._view/whcr3wyhzgorszy3rfxsphyebtvfpqzk/lib/python3.9/asyncio/tasks.py", line 492, in wait_for
    raise exceptions.TimeoutError() from exc
asyncio.exceptions.TimeoutError

The above exception was the direct cause of the following exception:

Traceback (most recent call last):
  File "/ccc/work/cont003/gen2224/gen2224/spack/var/spack/environments/gysela-deisa-irene-skl-draft/.spack-env/view/lib/python3.9/site-packages/distributed/worker.py", line 2878, in gather_dep
    response = await get_data_from_worker(
  File "/ccc/work/cont003/gen2224/gen2224/spack/var/spack/environments/gysela-deisa-irene-skl-draft/.spack-env/view/lib/python3.9/site-packages/distributed/worker.py", line 4143, in get_data_from_worker
    return await retry_operation(_get_data, operation="get_data_from_worker")
  File "/ccc/work/cont003/gen2224/gen2224/spack/var/spack/environments/gysela-deisa-irene-skl-draft/.spack-env/view/lib/python3.9/site-packages/distributed/utils_comm.py", line 366, in retry_operation
    return await retry(
  File "/ccc/work/cont003/gen2224/gen2224/spack/var/spack/environments/gysela-deisa-irene-skl-draft/.spack-env/view/lib/python3.9/site-packages/distributed/utils_comm.py", line 351, in retry
    return await coro()
  File "/ccc/work/cont003/gen2224/gen2224/spack/var/spack/environments/gysela-deisa-irene-skl-draft/.spack-env/view/lib/python3.9/site-packages/distributed/worker.py", line 4120, in _get_data
    comm = await rpc.connect(worker)
  File "/ccc/work/cont003/gen2224/gen2224/spack/var/spack/environments/gysela-deisa-irene-skl-draft/.spack-env/view/lib/python3.9/site-packages/distributed/core.py", line 1081, in connect
    raise exc
  File "/ccc/work/cont003/gen2224/gen2224/spack/var/spack/environments/gysela-deisa-irene-skl-draft/.spack-env/view/lib/python3.9/site-packages/distributed/core.py", line 1065, in connect
    comm = await fut
  File "/ccc/work/cont003/gen2224/gen2224/spack/var/spack/environments/gysela-deisa-irene-skl-draft/.spack-env/view/lib/python3.9/site-packages/distributed/comm/core.py", line 324, in connect
    raise OSError(
OSError: Timed out during handshake while connecting to tcp://172.21.9.113:40497 after 30 s
distributed.core - INFO - Event loop was unresponsive in Worker for 6.40s.  This is often caused by long-running GIL-holding functions or moving large chunks of data. This can cause timeouts and instability.
distributed.worker - ERROR - Worker stream died during communication: tcp://172.21.9.113:40497
Traceback (most recent call last):
  File "/ccc/work/cont003/gen2224/gen2224/spack/var/spack/environments/gysela-deisa-irene-skl-draft/.spack-env/view/lib/python3.9/site-packages/distributed/comm/tcp.py", line 205, in read
    frames_nbytes = await stream.read_bytes(fmt_size)
asyncio.exceptions.CancelledError

During handling of the above exception, another exception occurred:

Traceback (most recent call last):
  File "/ccc/work/cont003/gen2224/gen2224/spack/var/spack/environments/gysela-deisa-irene-skl-draft/.spack-env/._view/whcr3wyhzgorszy3rfxsphyebtvfpqzk/lib/python3.9/asyncio/tasks.py", line 490, in wait_for
    return fut.result()
asyncio.exceptions.CancelledError

The above exception was the direct cause of the following exception:

Traceback (most recent call last):
  File "/ccc/work/cont003/gen2224/gen2224/spack/var/spack/environments/gysela-deisa-irene-skl-draft/.spack-env/view/lib/python3.9/site-packages/distributed/comm/core.py", line 319, in connect
    handshake = await asyncio.wait_for(comm.read(), time_left())
  File "/ccc/work/cont003/gen2224/gen2224/spack/var/spack/environments/gysela-deisa-irene-skl-draft/.spack-env/._view/whcr3wyhzgorszy3rfxsphyebtvfpqzk/lib/python3.9/asyncio/tasks.py", line 492, in wait_for
    raise exceptions.TimeoutError() from exc
asyncio.exceptions.TimeoutError

The above exception was the direct cause of the following exception:

Traceback (most recent call last):
  File "/ccc/work/cont003/gen2224/gen2224/spack/var/spack/environments/gysela-deisa-irene-skl-draft/.spack-env/view/lib/python3.9/site-packages/distributed/worker.py", line 2878, in gather_dep
    response = await get_data_from_worker(
  File "/ccc/work/cont003/gen2224/gen2224/spack/var/spack/environments/gysela-deisa-irene-skl-draft/.spack-env/view/lib/python3.9/site-packages/distributed/worker.py", line 4143, in get_data_from_worker
    return await retry_operation(_get_data, operation="get_data_from_worker")
  File "/ccc/work/cont003/gen2224/gen2224/spack/var/spack/environments/gysela-deisa-irene-skl-draft/.spack-env/view/lib/python3.9/site-packages/distributed/utils_comm.py", line 366, in retry_operation
    return await retry(
  File "/ccc/work/cont003/gen2224/gen2224/spack/var/spack/environments/gysela-deisa-irene-skl-draft/.spack-env/view/lib/python3.9/site-packages/distributed/utils_comm.py", line 351, in retry
    return await coro()
  File "/ccc/work/cont003/gen2224/gen2224/spack/var/spack/environments/gysela-deisa-irene-skl-draft/.spack-env/view/lib/python3.9/site-packages/distributed/worker.py", line 4120, in _get_data
    comm = await rpc.connect(worker)
  File "/ccc/work/cont003/gen2224/gen2224/spack/var/spack/environments/gysela-deisa-irene-skl-draft/.spack-env/view/lib/python3.9/site-packages/distributed/core.py", line 1081, in connect
    raise exc
  File "/ccc/work/cont003/gen2224/gen2224/spack/var/spack/environments/gysela-deisa-irene-skl-draft/.spack-env/view/lib/python3.9/site-packages/distributed/core.py", line 1065, in connect
    comm = await fut
  File "/ccc/work/cont003/gen2224/gen2224/spack/var/spack/environments/gysela-deisa-irene-skl-draft/.spack-env/view/lib/python3.9/site-packages/distributed/comm/core.py", line 324, in connect
    raise OSError(
OSError: Timed out during handshake while connecting to tcp://172.21.9.113:40497 after 30 s
distributed.worker - ERROR - Worker stream died during communication: tcp://172.21.9.92:37136
Traceback (most recent call last):
  File "/ccc/work/cont003/gen2224/gen2224/spack/var/spack/environments/gysela-deisa-irene-skl-draft/.spack-env/view/lib/python3.9/site-packages/distributed/comm/tcp.py", line 205, in read
    frames_nbytes = await stream.read_bytes(fmt_size)
asyncio.exceptions.CancelledError

During handling of the above exception, another exception occurred:

Traceback (most recent call last):
  File "/ccc/work/cont003/gen2224/gen2224/spack/var/spack/environments/gysela-deisa-irene-skl-draft/.spack-env/._view/whcr3wyhzgorszy3rfxsphyebtvfpqzk/lib/python3.9/asyncio/tasks.py", line 490, in wait_for
    return fut.result()
asyncio.exceptions.CancelledError

The above exception was the direct cause of the following exception:

Traceback (most recent call last):
distributed.worker - ERROR - Worker stream died during communication: tcp://172.21.9.92:37136
Traceback (most recent call last):
  File "/ccc/work/cont003/gen2224/gen2224/spack/var/spack/environments/gysela-deisa-irene-skl-draft/.spack-env/view/lib/python3.9/site-packages/distributed/comm/tcp.py", line 205, in read
    frames_nbytes = await stream.read_bytes(fmt_size)
asyncio.exceptions.CancelledError

During handling of the above exception, another exception occurred:

Traceback (most recent call last):
  File "/ccc/work/cont003/gen2224/gen2224/spack/var/spack/environments/gysela-deisa-irene-skl-draft/.spack-env/._view/whcr3wyhzgorszy3rfxsphyebtvfpqzk/lib/python3.9/asyncio/tasks.py", line 490, in wait_for
    return fut.result()
asyncio.exceptions.CancelledError

The above exception was the direct cause of the following exception:

Traceback (most recent call last):
  File "/ccc/work/cont003/gen2224/gen2224/spack/var/spack/environments/gysela-deisa-irene-skl-draft/.spack-env/view/lib/python3.9/site-packages/distributed/comm/core.py", line 319, in connect
    handshake = await asyncio.wait_for(comm.read(), time_left())
  File "/ccc/work/cont003/gen2224/gen2224/spack/var/spack/environments/gysela-deisa-irene-skl-draft/.spack-env/._view/whcr3wyhzgorszy3rfxsphyebtvfpqzk/lib/python3.9/asyncio/tasks.py", line 492, in wait_for
    raise exceptions.TimeoutError() from exc
asyncio.exceptions.TimeoutError

The above exception was the direct cause of the following exception:

Traceback (most recent call last):
  File "/ccc/work/cont003/gen2224/gen2224/spack/var/spack/environments/gysela-deisa-irene-skl-draft/.spack-env/view/lib/python3.9/site-packages/distributed/worker.py", line 2878, in gather_dep
    response = await get_data_from_worker(
  File "/ccc/work/cont003/gen2224/gen2224/spack/var/spack/environments/gysela-deisa-irene-skl-draft/.spack-env/view/lib/python3.9/site-packages/distributed/comm/core.py", line 319, in connect
    handshake = await asyncio.wait_for(comm.read(), time_left())
  File "/ccc/work/cont003/gen2224/gen2224/spack/var/spack/environments/gysela-deisa-irene-skl-draft/.spack-env/._view/whcr3wyhzgorszy3rfxsphyebtvfpqzk/lib/python3.9/asyncio/tasks.py", line 492, in wait_for
    raise exceptions.TimeoutError() from exc
asyncio.exceptions.TimeoutError

The above exception was the direct cause of the following exception:

Traceback (most recent call last):
  File "/ccc/work/cont003/gen2224/gen2224/spack/var/spack/environments/gysela-deisa-irene-skl-draft/.spack-env/view/lib/python3.9/site-packages/distributed/worker.py", line 2878, in gather_dep
    response = await get_data_from_worker(
  File "/ccc/work/cont003/gen2224/gen2224/spack/var/spack/environments/gysela-deisa-irene-skl-draft/.spack-env/view/lib/python3.9/site-packages/distributed/worker.py", line 4143, in get_data_from_worker
    return await retry_operation(_get_data, operation="get_data_from_worker")
  File "/ccc/work/cont003/gen2224/gen2224/spack/var/spack/environments/gysela-deisa-irene-skl-draft/.spack-env/view/lib/python3.9/site-packages/distributed/utils_comm.py", line 366, in retry_operation
    return await retry(
  File "/ccc/work/cont003/gen2224/gen2224/spack/var/spack/environments/gysela-deisa-irene-skl-draft/.spack-env/view/lib/python3.9/site-packages/distributed/utils_comm.py", line 351, in retry
    return await coro()
  File "/ccc/work/cont003/gen2224/gen2224/spack/var/spack/environments/gysela-deisa-irene-skl-draft/.spack-env/view/lib/python3.9/site-packages/distributed/worker.py", line 4120, in _get_data
    comm = await rpc.connect(worker)
  File "/ccc/work/cont003/gen2224/gen2224/spack/var/spack/environments/gysela-deisa-irene-skl-draft/.spack-env/view/lib/python3.9/site-packages/distributed/worker.py", line 4143, in get_data_from_worker
    return await retry_operation(_get_data, operation="get_data_from_worker")
  File "/ccc/work/cont003/gen2224/gen2224/spack/var/spack/environments/gysela-deisa-irene-skl-draft/.spack-env/view/lib/python3.9/site-packages/distributed/utils_comm.py", line 366, in retry_operation
    return await retry(
  File "/ccc/work/cont003/gen2224/gen2224/spack/var/spack/environments/gysela-deisa-irene-skl-draft/.spack-env/view/lib/python3.9/site-packages/distributed/utils_comm.py", line 351, in retry
    return await coro()
  File "/ccc/work/cont003/gen2224/gen2224/spack/var/spack/environments/gysela-deisa-irene-skl-draft/.spack-env/view/lib/python3.9/site-packages/distributed/worker.py", line 4120, in _get_data
    comm = await rpc.connect(worker)
  File "/ccc/work/cont003/gen2224/gen2224/spack/var/spack/environments/gysela-deisa-irene-skl-draft/.spack-env/view/lib/python3.9/site-packages/distributed/core.py", line 1081, in connect
    raise exc
  File "/ccc/work/cont003/gen2224/gen2224/spack/var/spack/environments/gysela-deisa-irene-skl-draft/.spack-env/view/lib/python3.9/site-packages/distributed/core.py", line 1065, in connect
    comm = await fut
  File "/ccc/work/cont003/gen2224/gen2224/spack/var/spack/environments/gysela-deisa-irene-skl-draft/.spack-env/view/lib/python3.9/site-packages/distributed/comm/core.py", line 324, in connect
    raise OSError(
OSError: Timed out during handshake while connecting to tcp://172.21.9.92:37136 after 30 s
  File "/ccc/work/cont003/gen2224/gen2224/spack/var/spack/environments/gysela-deisa-irene-skl-draft/.spack-env/view/lib/python3.9/site-packages/distributed/core.py", line 1081, in connect
    raise exc
  File "/ccc/work/cont003/gen2224/gen2224/spack/var/spack/environments/gysela-deisa-irene-skl-draft/.spack-env/view/lib/python3.9/site-packages/distributed/core.py", line 1065, in connect
    comm = await fut
  File "/ccc/work/cont003/gen2224/gen2224/spack/var/spack/environments/gysela-deisa-irene-skl-draft/.spack-env/view/lib/python3.9/site-packages/distributed/comm/core.py", line 324, in connect
    raise OSError(
OSError: Timed out during handshake while connecting to tcp://172.21.9.92:37136 after 30 s
distributed.worker - ERROR - Worker stream died during communication: tcp://172.21.9.92:37136
Traceback (most recent call last):
  File "/ccc/work/cont003/gen2224/gen2224/spack/var/spack/environments/gysela-deisa-irene-skl-draft/.spack-env/view/lib/python3.9/site-packages/distributed/comm/tcp.py", line 205, in read
    frames_nbytes = await stream.read_bytes(fmt_size)
asyncio.exceptions.CancelledError

During handling of the above exception, another exception occurred:

Traceback (most recent call last):
  File "/ccc/work/cont003/gen2224/gen2224/spack/var/spack/environments/gysela-deisa-irene-skl-draft/.spack-env/._view/whcr3wyhzgorszy3rfxsphyebtvfpqzk/lib/python3.9/asyncio/tasks.py", line 490, in wait_for
    return fut.result()
asyncio.exceptions.CancelledError

The above exception was the direct cause of the following exception:

Traceback (most recent call last):
  File "/ccc/work/cont003/gen2224/gen2224/spack/var/spack/environments/gysela-deisa-irene-skl-draft/.spack-env/view/lib/python3.9/site-packages/distributed/comm/core.py", line 319, in connect
    handshake = await asyncio.wait_for(comm.read(), time_left())
  File "/ccc/work/cont003/gen2224/gen2224/spack/var/spack/environments/gysela-deisa-irene-skl-draft/.spack-env/._view/whcr3wyhzgorszy3rfxsphyebtvfpqzk/lib/python3.9/asyncio/tasks.py", line 492, in wait_for
    raise exceptions.TimeoutError() from exc
asyncio.exceptions.TimeoutError

The above exception was the direct cause of the following exception:

Traceback (most recent call last):
  File "/ccc/work/cont003/gen2224/gen2224/spack/var/spack/environments/gysela-deisa-irene-skl-draft/.spack-env/view/lib/python3.9/site-packages/distributed/worker.py", line 2878, in gather_dep
    response = await get_data_from_worker(
  File "/ccc/work/cont003/gen2224/gen2224/spack/var/spack/environments/gysela-deisa-irene-skl-draft/.spack-env/view/lib/python3.9/site-packages/distributed/worker.py", line 4143, in get_data_from_worker
    return await retry_operation(_get_data, operation="get_data_from_worker")
  File "/ccc/work/cont003/gen2224/gen2224/spack/var/spack/environments/gysela-deisa-irene-skl-draft/.spack-env/view/lib/python3.9/site-packages/distributed/utils_comm.py", line 366, in retry_operation
    return await retry(
  File "/ccc/work/cont003/gen2224/gen2224/spack/var/spack/environments/gysela-deisa-irene-skl-draft/.spack-env/view/lib/python3.9/site-packages/distributed/utils_comm.py", line 351, in retry
    return await coro()
  File "/ccc/work/cont003/gen2224/gen2224/spack/var/spack/environments/gysela-deisa-irene-skl-draft/.spack-env/view/lib/python3.9/site-packages/distributed/worker.py", line 4120, in _get_data
    comm = await rpc.connect(worker)
distributed.worker - ERROR - Worker stream died during communication: tcp://172.21.9.92:37136
Traceback (most recent call last):
  File "/ccc/work/cont003/gen2224/gen2224/spack/var/spack/environments/gysela-deisa-irene-skl-draft/.spack-env/view/lib/python3.9/site-packages/distributed/comm/tcp.py", line 205, in read
    frames_nbytes = await stream.read_bytes(fmt_size)
asyncio.exceptions.CancelledError

During handling of the above exception, another exception occurred:

Traceback (most recent call last):
  File "/ccc/work/cont003/gen2224/gen2224/spack/var/spack/environments/gysela-deisa-irene-skl-draft/.spack-env/._view/whcr3wyhzgorszy3rfxsphyebtvfpqzk/lib/python3.9/asyncio/tasks.py", line 490, in wait_for
    return fut.result()
asyncio.exceptions.CancelledError

The above exception was the direct cause of the following exception:

Traceback (most recent call last):
  File "/ccc/work/cont003/gen2224/gen2224/spack/var/spack/environments/gysela-deisa-irene-skl-draft/.spack-env/view/lib/python3.9/site-packages/distributed/core.py", line 1081, in connect
    raise exc
  File "/ccc/work/cont003/gen2224/gen2224/spack/var/spack/environments/gysela-deisa-irene-skl-draft/.spack-env/view/lib/python3.9/site-packages/distributed/core.py", line 1065, in connect
    comm = await fut
  File "/ccc/work/cont003/gen2224/gen2224/spack/var/spack/environments/gysela-deisa-irene-skl-draft/.spack-env/view/lib/python3.9/site-packages/distributed/comm/core.py", line 324, in connect
    raise OSError(
OSError: Timed out during handshake while connecting to tcp://172.21.9.92:37136 after 30 s
  File "/ccc/work/cont003/gen2224/gen2224/spack/var/spack/environments/gysela-deisa-irene-skl-draft/.spack-env/view/lib/python3.9/site-packages/distributed/comm/core.py", line 319, in connect
    handshake = await asyncio.wait_for(comm.read(), time_left())
  File "/ccc/work/cont003/gen2224/gen2224/spack/var/spack/environments/gysela-deisa-irene-skl-draft/.spack-env/._view/whcr3wyhzgorszy3rfxsphyebtvfpqzk/lib/python3.9/asyncio/tasks.py", line 492, in wait_for
    raise exceptions.TimeoutError() from exc
asyncio.exceptions.TimeoutError

The above exception was the direct cause of the following exception:

Traceback (most recent call last):
  File "/ccc/work/cont003/gen2224/gen2224/spack/var/spack/environments/gysela-deisa-irene-skl-draft/.spack-env/view/lib/python3.9/site-packages/distributed/worker.py", line 2878, in gather_dep
    response = await get_data_from_worker(
  File "/ccc/work/cont003/gen2224/gen2224/spack/var/spack/environments/gysela-deisa-irene-skl-draft/.spack-env/view/lib/python3.9/site-packages/distributed/worker.py", line 4143, in get_data_from_worker
    return await retry_operation(_get_data, operation="get_data_from_worker")
  File "/ccc/work/cont003/gen2224/gen2224/spack/var/spack/environments/gysela-deisa-irene-skl-draft/.spack-env/view/lib/python3.9/site-packages/distributed/utils_comm.py", line 366, in retry_operation
    return await retry(
  File "/ccc/work/cont003/gen2224/gen2224/spack/var/spack/environments/gysela-deisa-irene-skl-draft/.spack-env/view/lib/python3.9/site-packages/distributed/utils_comm.py", line 351, in retry
    return await coro()
  File "/ccc/work/cont003/gen2224/gen2224/spack/var/spack/environments/gysela-deisa-irene-skl-draft/.spack-env/view/lib/python3.9/site-packages/distributed/worker.py", line 4120, in _get_data
    comm = await rpc.connect(worker)
  File "/ccc/work/cont003/gen2224/gen2224/spack/var/spack/environments/gysela-deisa-irene-skl-draft/.spack-env/view/lib/python3.9/site-packages/distributed/core.py", line 1081, in connect
    raise exc
  File "/ccc/work/cont003/gen2224/gen2224/spack/var/spack/environments/gysela-deisa-irene-skl-draft/.spack-env/view/lib/python3.9/site-packages/distributed/core.py", line 1065, in connect
    comm = await fut
  File "/ccc/work/cont003/gen2224/gen2224/spack/var/spack/environments/gysela-deisa-irene-skl-draft/.spack-env/view/lib/python3.9/site-packages/distributed/comm/core.py", line 324, in connect
    raise OSError(
OSError: Timed out during handshake while connecting to tcp://172.21.9.92:37136 after 30 s
distributed.worker - ERROR - Worker stream died during communication: tcp://172.21.9.92:37136
Traceback (most recent call last):
  File "/ccc/work/cont003/gen2224/gen2224/spack/var/spack/environments/gysela-deisa-irene-skl-draft/.spack-env/view/lib/python3.9/site-packages/distributed/comm/tcp.py", line 205, in read
    frames_nbytes = await stream.read_bytes(fmt_size)
asyncio.exceptions.CancelledError

During handling of the above exception, another exception occurred:

Traceback (most recent call last):
  File "/ccc/work/cont003/gen2224/gen2224/spack/var/spack/environments/gysela-deisa-irene-skl-draft/.spack-env/._view/whcr3wyhzgorszy3rfxsphyebtvfpqzk/lib/python3.9/asyncio/tasks.py", line 490, in wait_for
    return fut.result()
asyncio.exceptions.CancelledError

The above exception was the direct cause of the following exception:

Traceback (most recent call last):
  File "/ccc/work/cont003/gen2224/gen2224/spack/var/spack/environments/gysela-deisa-irene-skl-draft/.spack-env/view/lib/python3.9/site-packages/distributed/comm/core.py", line 319, in connect
    handshake = await asyncio.wait_for(comm.read(), time_left())
  File "/ccc/work/cont003/gen2224/gen2224/spack/var/spack/environments/gysela-deisa-irene-skl-draft/.spack-env/._view/whcr3wyhzgorszy3rfxsphyebtvfpqzk/lib/python3.9/asyncio/tasks.py", line 492, in wait_for
    raise exceptions.TimeoutError() from exc
asyncio.exceptions.TimeoutError

The above exception was the direct cause of the following exception:

Traceback (most recent call last):
  File "/ccc/work/cont003/gen2224/gen2224/spack/var/spack/environments/gysela-deisa-irene-skl-draft/.spack-env/view/lib/python3.9/site-packages/distributed/worker.py", line 2878, in gather_dep
    response = await get_data_from_worker(
  File "/ccc/work/cont003/gen2224/gen2224/spack/var/spack/environments/gysela-deisa-irene-skl-draft/.spack-env/view/lib/python3.9/site-packages/distributed/worker.py", line 4143, in get_data_from_worker
    return await retry_operation(_get_data, operation="get_data_from_worker")
  File "/ccc/work/cont003/gen2224/gen2224/spack/var/spack/environments/gysela-deisa-irene-skl-draft/.spack-env/view/lib/python3.9/site-packages/distributed/utils_comm.py", line 366, in retry_operation
    return await retry(
  File "/ccc/work/cont003/gen2224/gen2224/spack/var/spack/environments/gysela-deisa-irene-skl-draft/.spack-env/view/lib/python3.9/site-packages/distributed/utils_comm.py", line 351, in retry
    return await coro()
  File "/ccc/work/cont003/gen2224/gen2224/spack/var/spack/environments/gysela-deisa-irene-skl-draft/.spack-env/view/lib/python3.9/site-packages/distributed/worker.py", line 4120, in _get_data
    comm = await rpc.connect(worker)
  File "/ccc/work/cont003/gen2224/gen2224/spack/var/spack/environments/gysela-deisa-irene-skl-draft/.spack-env/view/lib/python3.9/site-packages/distributed/core.py", line 1081, in connect
    raise exc
  File "/ccc/work/cont003/gen2224/gen2224/spack/var/spack/environments/gysela-deisa-irene-skl-draft/.spack-env/view/lib/python3.9/site-packages/distributed/core.py", line 1065, in connect
    comm = await fut
  File "/ccc/work/cont003/gen2224/gen2224/spack/var/spack/environments/gysela-deisa-irene-skl-draft/.spack-env/view/lib/python3.9/site-packages/distributed/comm/core.py", line 324, in connect
    raise OSError(
OSError: Timed out during handshake while connecting to tcp://172.21.9.92:37136 after 30 s
distributed.worker - ERROR - Worker stream died during communication: tcp://172.21.9.92:37136
Traceback (most recent call last):
  File "/ccc/work/cont003/gen2224/gen2224/spack/var/spack/environments/gysela-deisa-irene-skl-draft/.spack-env/view/lib/python3.9/site-packages/distributed/comm/tcp.py", line 205, in read
    frames_nbytes = await stream.read_bytes(fmt_size)
asyncio.exceptions.CancelledError

During handling of the above exception, another exception occurred:

Traceback (most recent call last):
  File "/ccc/work/cont003/gen2224/gen2224/spack/var/spack/environments/gysela-deisa-irene-skl-draft/.spack-env/._view/whcr3wyhzgorszy3rfxsphyebtvfpqzk/lib/python3.9/asyncio/tasks.py", line 490, in wait_for
    return fut.result()
asyncio.exceptions.CancelledError

The above exception was the direct cause of the following exception:

Traceback (most recent call last):
  File "/ccc/work/cont003/gen2224/gen2224/spack/var/spack/environments/gysela-deisa-irene-skl-draft/.spack-env/view/lib/python3.9/site-packages/distributed/comm/core.py", line 319, in connect
    handshake = await asyncio.wait_for(comm.read(), time_left())
  File "/ccc/work/cont003/gen2224/gen2224/spack/var/spack/environments/gysela-deisa-irene-skl-draft/.spack-env/._view/whcr3wyhzgorszy3rfxsphyebtvfpqzk/lib/python3.9/asyncio/tasks.py", line 492, in wait_for
    raise exceptions.TimeoutError() from exc
asyncio.exceptions.TimeoutError

The above exception was the direct cause of the following exception:

Traceback (most recent call last):
  File "/ccc/work/cont003/gen2224/gen2224/spack/var/spack/environments/gysela-deisa-irene-skl-draft/.spack-env/view/lib/python3.9/site-packages/distributed/worker.py", line 2878, in gather_dep
    response = await get_data_from_worker(
  File "/ccc/work/cont003/gen2224/gen2224/spack/var/spack/environments/gysela-deisa-irene-skl-draft/.spack-env/view/lib/python3.9/site-packages/distributed/worker.py", line 4143, in get_data_from_worker
    return await retry_operation(_get_data, operation="get_data_from_worker")
  File "/ccc/work/cont003/gen2224/gen2224/spack/var/spack/environments/gysela-deisa-irene-skl-draft/.spack-env/view/lib/python3.9/site-packages/distributed/utils_comm.py", line 366, in retry_operation
    return await retry(
  File "/ccc/work/cont003/gen2224/gen2224/spack/var/spack/environments/gysela-deisa-irene-skl-draft/.spack-env/view/lib/python3.9/site-packages/distributed/utils_comm.py", line 351, in retry
    return await coro()
  File "/ccc/work/cont003/gen2224/gen2224/spack/var/spack/environments/gysela-deisa-irene-skl-draft/.spack-env/view/lib/python3.9/site-packages/distributed/worker.py", line 4120, in _get_data
    comm = await rpc.connect(worker)
  File "/ccc/work/cont003/gen2224/gen2224/spack/var/spack/environments/gysela-deisa-irene-skl-draft/.spack-env/view/lib/python3.9/site-packages/distributed/core.py", line 1081, in connect
    raise exc
  File "/ccc/work/cont003/gen2224/gen2224/spack/var/spack/environments/gysela-deisa-irene-skl-draft/.spack-env/view/lib/python3.9/site-packages/distributed/core.py", line 1065, in connect
    comm = await fut
  File "/ccc/work/cont003/gen2224/gen2224/spack/var/spack/environments/gysela-deisa-irene-skl-draft/.spack-env/view/lib/python3.9/site-packages/distributed/comm/core.py", line 324, in connect
    raise OSError(
OSError: Timed out during handshake while connecting to tcp://172.21.9.92:37136 after 30 s
distributed.worker - ERROR - Worker stream died during communication: tcp://172.21.9.92:37136
Traceback (most recent call last):
  File "/ccc/work/cont003/gen2224/gen2224/spack/var/spack/environments/gysela-deisa-irene-skl-draft/.spack-env/view/lib/python3.9/site-packages/distributed/comm/tcp.py", line 205, in read
    frames_nbytes = await stream.read_bytes(fmt_size)
asyncio.exceptions.CancelledError

During handling of the above exception, another exception occurred:

Traceback (most recent call last):
  File "/ccc/work/cont003/gen2224/gen2224/spack/var/spack/environments/gysela-deisa-irene-skl-draft/.spack-env/._view/whcr3wyhzgorszy3rfxsphyebtvfpqzk/lib/python3.9/asyncio/tasks.py", line 490, in wait_for
    return fut.result()
asyncio.exceptions.CancelledError

The above exception was the direct cause of the following exception:

Traceback (most recent call last):
  File "/ccc/work/cont003/gen2224/gen2224/spack/var/spack/environments/gysela-deisa-irene-skl-draft/.spack-env/view/lib/python3.9/site-packages/distributed/comm/core.py", line 319, in connect
    handshake = await asyncio.wait_for(comm.read(), time_left())
  File "/ccc/work/cont003/gen2224/gen2224/spack/var/spack/environments/gysela-deisa-irene-skl-draft/.spack-env/._view/whcr3wyhzgorszy3rfxsphyebtvfpqzk/lib/python3.9/asyncio/tasks.py", line 492, in wait_for
    raise exceptions.TimeoutError() from exc
asyncio.exceptions.TimeoutError

The above exception was the direct cause of the following exception:

Traceback (most recent call last):
  File "/ccc/work/cont003/gen2224/gen2224/spack/var/spack/environments/gysela-deisa-irene-skl-draft/.spack-env/view/lib/python3.9/site-packages/distributed/worker.py", line 2878, in gather_dep
    response = await get_data_from_worker(
  File "/ccc/work/cont003/gen2224/gen2224/spack/var/spack/environments/gysela-deisa-irene-skl-draft/.spack-env/view/lib/python3.9/site-packages/distributed/worker.py", line 4143, in get_data_from_worker
    return await retry_operation(_get_data, operation="get_data_from_worker")
  File "/ccc/work/cont003/gen2224/gen2224/spack/var/spack/environments/gysela-deisa-irene-skl-draft/.spack-env/view/lib/python3.9/site-packages/distributed/utils_comm.py", line 366, in retry_operation
    return await retry(
  File "/ccc/work/cont003/gen2224/gen2224/spack/var/spack/environments/gysela-deisa-irene-skl-draft/.spack-env/view/lib/python3.9/site-packages/distributed/utils_comm.py", line 351, in retry
    return await coro()
  File "/ccc/work/cont003/gen2224/gen2224/spack/var/spack/environments/gysela-deisa-irene-skl-draft/.spack-env/view/lib/python3.9/site-packages/distributed/worker.py", line 4120, in _get_data
    comm = await rpc.connect(worker)
  File "/ccc/work/cont003/gen2224/gen2224/spack/var/spack/environments/gysela-deisa-irene-skl-draft/.spack-env/view/lib/python3.9/site-packages/distributed/core.py", line 1081, in connect
    raise exc
  File "/ccc/work/cont003/gen2224/gen2224/spack/var/spack/environments/gysela-deisa-irene-skl-draft/.spack-env/view/lib/python3.9/site-packages/distributed/core.py", line 1065, in connect
    comm = await fut
  File "/ccc/work/cont003/gen2224/gen2224/spack/var/spack/environments/gysela-deisa-irene-skl-draft/.spack-env/view/lib/python3.9/site-packages/distributed/comm/core.py", line 324, in connect
    raise OSError(
OSError: Timed out during handshake while connecting to tcp://172.21.9.92:37136 after 30 s
distributed.utils - ERROR - 'array-original-b28294aa84e0af22f5c0bf428197c430'
Traceback (most recent call last):
  File "/ccc/work/cont003/gen2224/gen2224/spack/var/spack/environments/gysela-deisa-irene-skl-draft/.spack-env/view/lib/python3.9/site-packages/distributed/utils.py", line 684, in log_errors
    yield
  File "/ccc/work/cont003/gen2224/gen2224/spack/var/spack/environments/gysela-deisa-irene-skl-draft/.spack-env/view/lib/python3.9/site-packages/distributed/worker.py", line 2929, in gather_dep
    ts = self.tasks[d]
KeyError: 'array-original-b28294aa84e0af22f5c0bf428197c430'
tornado.application - ERROR - Exception in callback functools.partial(<bound method IOLoop._discard_future_result of <tornado.platform.asyncio.AsyncIOLoop object at 0x2b35d9e7f7f0>>, <Task finished name='Task-3625' coro=<Worker.gather_dep() done, defined at /ccc/work/cont003/gen2224/gen2224/spack/var/spack/environments/gysela-deisa-irene-skl-draft/.spack-env/view/lib/python3.9/site-packages/distributed/worker.py:2823> exception=KeyError('array-original-b28294aa84e0af22f5c0bf428197c430')>)
Traceback (most recent call last):
  File "/ccc/work/cont003/gen2224/gen2224/spack/var/spack/environments/gysela-deisa-irene-skl-draft/.spack-env/view/lib/python3.9/site-packages/tornado/ioloop.py", line 741, in _run_callback
    ret = callback()
  File "/ccc/work/cont003/gen2224/gen2224/spack/var/spack/environments/gysela-deisa-irene-skl-draft/.spack-env/view/lib/python3.9/site-packages/tornado/ioloop.py", line 765, in _discard_future_result
    future.result()
  File "/ccc/work/cont003/gen2224/gen2224/spack/var/spack/environments/gysela-deisa-irene-skl-draft/.spack-env/view/lib/python3.9/site-packages/distributed/worker.py", line 2929, in gather_dep
    ts = self.tasks[d]
KeyError: 'array-original-b28294aa84e0af22f5c0bf428197c430'
distributed.worker - ERROR - Worker stream died during communication: tcp://172.21.9.92:37136
Traceback (most recent call last):
  File "/ccc/work/cont003/gen2224/gen2224/spack/var/spack/environments/gysela-deisa-irene-skl-draft/.spack-env/view/lib/python3.9/site-packages/distributed/comm/tcp.py", line 205, in read
    frames_nbytes = await stream.read_bytes(fmt_size)
asyncio.exceptions.CancelledError

During handling of the above exception, another exception occurred:

Traceback (most recent call last):
  File "/ccc/work/cont003/gen2224/gen2224/spack/var/spack/environments/gysela-deisa-irene-skl-draft/.spack-env/._view/whcr3wyhzgorszy3rfxsphyebtvfpqzk/lib/python3.9/asyncio/tasks.py", line 490, in wait_for
    return fut.result()
asyncio.exceptions.CancelledError

The above exception was the direct cause of the following exception:

Traceback (most recent call last):
  File "/ccc/work/cont003/gen2224/gen2224/spack/var/spack/environments/gysela-deisa-irene-skl-draft/.spack-env/view/lib/python3.9/site-packages/distributed/comm/core.py", line 319, in connect
    handshake = await asyncio.wait_for(comm.read(), time_left())
  File "/ccc/work/cont003/gen2224/gen2224/spack/var/spack/environments/gysela-deisa-irene-skl-draft/.spack-env/._view/whcr3wyhzgorszy3rfxsphyebtvfpqzk/lib/python3.9/asyncio/tasks.py", line 492, in wait_for
    raise exceptions.TimeoutError() from exc
asyncio.exceptions.TimeoutError

The above exception was the direct cause of the following exception:

Traceback (most recent call last):
  File "/ccc/work/cont003/gen2224/gen2224/spack/var/spack/environments/gysela-deisa-irene-skl-draft/.spack-env/view/lib/python3.9/site-packages/distributed/worker.py", line 2878, in gather_dep
    response = await get_data_from_worker(
  File "/ccc/work/cont003/gen2224/gen2224/spack/var/spack/environments/gysela-deisa-irene-skl-draft/.spack-env/view/lib/python3.9/site-packages/distributed/worker.py", line 4143, in get_data_from_worker
    return await retry_operation(_get_data, operation="get_data_from_worker")
  File "/ccc/work/cont003/gen2224/gen2224/spack/var/spack/environments/gysela-deisa-irene-skl-draft/.spack-env/view/lib/python3.9/site-packages/distributed/utils_comm.py", line 366, in retry_operation
    return await retry(
  File "/ccc/work/cont003/gen2224/gen2224/spack/var/spack/environments/gysela-deisa-irene-skl-draft/.spack-env/view/lib/python3.9/site-packages/distributed/utils_comm.py", line 351, in retry
    return await coro()
  File "/ccc/work/cont003/gen2224/gen2224/spack/var/spack/environments/gysela-deisa-irene-skl-draft/.spack-env/view/lib/python3.9/site-packages/distributed/worker.py", line 4120, in _get_data
    comm = await rpc.connect(worker)
  File "/ccc/work/cont003/gen2224/gen2224/spack/var/spack/environments/gysela-deisa-irene-skl-draft/.spack-env/view/lib/python3.9/site-packages/distributed/core.py", line 1081, in connect
    raise exc
  File "/ccc/work/cont003/gen2224/gen2224/spack/var/spack/environments/gysela-deisa-irene-skl-draft/.spack-env/view/lib/python3.9/site-packages/distributed/core.py", line 1065, in connect
    comm = await fut
  File "/ccc/work/cont003/gen2224/gen2224/spack/var/spack/environments/gysela-deisa-irene-skl-draft/.spack-env/view/lib/python3.9/site-packages/distributed/comm/core.py", line 324, in connect
    raise OSError(
OSError: Timed out during handshake while connecting to tcp://172.21.9.92:37136 after 30 s
distributed.utils - ERROR - 'array-original-b28294aa84e0af22f5c0bf428197c430'
Traceback (most recent call last):
  File "/ccc/work/cont003/gen2224/gen2224/spack/var/spack/environments/gysela-deisa-irene-skl-draft/.spack-env/view/lib/python3.9/site-packages/distributed/utils.py", line 684, in log_errors
    yield
  File "/ccc/work/cont003/gen2224/gen2224/spack/var/spack/environments/gysela-deisa-irene-skl-draft/.spack-env/view/lib/python3.9/site-packages/distributed/worker.py", line 2929, in gather_dep
    ts = self.tasks[d]
KeyError: 'array-original-b28294aa84e0af22f5c0bf428197c430'
tornado.application - ERROR - Exception in callback functools.partial(<bound method IOLoop._discard_future_result of <tornado.platform.asyncio.AsyncIOLoop object at 0x2b2b429d87f0>>, <Task finished name='Task-3669' coro=<Worker.gather_dep() done, defined at /ccc/work/cont003/gen2224/gen2224/spack/var/spack/environments/gysela-deisa-irene-skl-draft/.spack-env/view/lib/python3.9/site-packages/distributed/worker.py:2823> exception=KeyError('array-original-b28294aa84e0af22f5c0bf428197c430')>)
Traceback (most recent call last):
  File "/ccc/work/cont003/gen2224/gen2224/spack/var/spack/environments/gysela-deisa-irene-skl-draft/.spack-env/view/lib/python3.9/site-packages/tornado/ioloop.py", line 741, in _run_callback
    ret = callback()
  File "/ccc/work/cont003/gen2224/gen2224/spack/var/spack/environments/gysela-deisa-irene-skl-draft/.spack-env/view/lib/python3.9/site-packages/tornado/ioloop.py", line 765, in _discard_future_result
    future.result()
  File "/ccc/work/cont003/gen2224/gen2224/spack/var/spack/environments/gysela-deisa-irene-skl-draft/.spack-env/view/lib/python3.9/site-packages/distributed/worker.py", line 2929, in gather_dep
    ts = self.tasks[d]
KeyError: 'array-original-b28294aa84e0af22f5c0bf428197c430'
distributed.worker - ERROR - 'array-original-b28294aa84e0af22f5c0bf428197c430'
Traceback (most recent call last):
  File "/ccc/work/cont003/gen2224/gen2224/spack/var/spack/environments/gysela-deisa-irene-skl-draft/.spack-env/view/lib/python3.9/site-packages/distributed/worker.py", line 2885, in gather_dep
    self._update_metrics_received_data(
  File "/ccc/work/cont003/gen2224/gen2224/spack/var/spack/environments/gysela-deisa-irene-skl-draft/.spack-env/view/lib/python3.9/site-packages/distributed/worker.py", line 2782, in _update_metrics_received_data
    total_bytes = sum(self.tasks[key].get_nbytes() for key in data)
  File "/ccc/work/cont003/gen2224/gen2224/spack/var/spack/environments/gysela-deisa-irene-skl-draft/.spack-env/view/lib/python3.9/site-packages/distributed/worker.py", line 2782, in <genexpr>
    total_bytes = sum(self.tasks[key].get_nbytes() for key in data)
KeyError: 'array-original-b28294aa84e0af22f5c0bf428197c430'
distributed.core - INFO - Event loop was unresponsive in Worker for 111.78s.  This is often caused by long-running GIL-holding functions or moving large chunks of data. This can cause timeouts and instability.
distributed.utils - ERROR - 'array-original-b28294aa84e0af22f5c0bf428197c430'
Traceback (most recent call last):
  File "/ccc/work/cont003/gen2224/gen2224/spack/var/spack/environments/gysela-deisa-irene-skl-draft/.spack-env/view/lib/python3.9/site-packages/distributed/worker.py", line 2885, in gather_dep
    self._update_metrics_received_data(
  File "/ccc/work/cont003/gen2224/gen2224/spack/var/spack/environments/gysela-deisa-irene-skl-draft/.spack-env/view/lib/python3.9/site-packages/distributed/worker.py", line 2782, in _update_metrics_received_data
    total_bytes = sum(self.tasks[key].get_nbytes() for key in data)
  File "/ccc/work/cont003/gen2224/gen2224/spack/var/spack/environments/gysela-deisa-irene-skl-draft/.spack-env/view/lib/python3.9/site-packages/distributed/worker.py", line 2782, in <genexpr>
    total_bytes = sum(self.tasks[key].get_nbytes() for key in data)
KeyError: 'array-original-b28294aa84e0af22f5c0bf428197c430'

During handling of the above exception, another exception occurred:

Traceback (most recent call last):
  File "/ccc/work/cont003/gen2224/gen2224/spack/var/spack/environments/gysela-deisa-irene-skl-draft/.spack-env/view/lib/python3.9/site-packages/distributed/worker.py", line 2915, in gather_dep
    ts = self.tasks[k]
KeyError: 'array-original-b28294aa84e0af22f5c0bf428197c430'

During handling of the above exception, another exception occurred:

Traceback (most recent call last):
  File "/ccc/work/cont003/gen2224/gen2224/spack/var/spack/environments/gysela-deisa-irene-skl-draft/.spack-env/view/lib/python3.9/site-packages/distributed/utils.py", line 684, in log_errors
    yield
  File "/ccc/work/cont003/gen2224/gen2224/spack/var/spack/environments/gysela-deisa-irene-skl-draft/.spack-env/view/lib/python3.9/site-packages/distributed/worker.py", line 2929, in gather_dep
    ts = self.tasks[d]
KeyError: 'array-original-b28294aa84e0af22f5c0bf428197c430'
tornado.application - ERROR - Exception in callback functools.partial(<bound method IOLoop._discard_future_result of <tornado.platform.asyncio.AsyncIOLoop object at 0x2b1104f6f820>>, <Task finished name='Task-3655' coro=<Worker.gather_dep() done, defined at /ccc/work/cont003/gen2224/gen2224/spack/var/spack/environments/gysela-deisa-irene-skl-draft/.spack-env/view/lib/python3.9/site-packages/distributed/worker.py:2823> exception=KeyError('array-original-b28294aa84e0af22f5c0bf428197c430')>)
Traceback (most recent call last):
  File "/ccc/work/cont003/gen2224/gen2224/spack/var/spack/environments/gysela-deisa-irene-skl-draft/.spack-env/view/lib/python3.9/site-packages/distributed/worker.py", line 2885, in gather_dep
    self._update_metrics_received_data(
  File "/ccc/work/cont003/gen2224/gen2224/spack/var/spack/environments/gysela-deisa-irene-skl-draft/.spack-env/view/lib/python3.9/site-packages/distributed/worker.py", line 2782, in _update_metrics_received_data
    total_bytes = sum(self.tasks[key].get_nbytes() for key in data)
  File "/ccc/work/cont003/gen2224/gen2224/spack/var/spack/environments/gysela-deisa-irene-skl-draft/.spack-env/view/lib/python3.9/site-packages/distributed/worker.py", line 2782, in <genexpr>
    total_bytes = sum(self.tasks[key].get_nbytes() for key in data)
KeyError: 'array-original-b28294aa84e0af22f5c0bf428197c430'

During handling of the above exception, another exception occurred:

Traceback (most recent call last):
  File "/ccc/work/cont003/gen2224/gen2224/spack/var/spack/environments/gysela-deisa-irene-skl-draft/.spack-env/view/lib/python3.9/site-packages/distributed/worker.py", line 2915, in gather_dep
    ts = self.tasks[k]
KeyError: 'array-original-b28294aa84e0af22f5c0bf428197c430'

During handling of the above exception, another exception occurred:

Traceback (most recent call last):
  File "/ccc/work/cont003/gen2224/gen2224/spack/var/spack/environments/gysela-deisa-irene-skl-draft/.spack-env/view/lib/python3.9/site-packages/tornado/ioloop.py", line 741, in _run_callback
    ret = callback()
  File "/ccc/work/cont003/gen2224/gen2224/spack/var/spack/environments/gysela-deisa-irene-skl-draft/.spack-env/view/lib/python3.9/site-packages/tornado/ioloop.py", line 765, in _discard_future_result
    future.result()
  File "/ccc/work/cont003/gen2224/gen2224/spack/var/spack/environments/gysela-deisa-irene-skl-draft/.spack-env/view/lib/python3.9/site-packages/distributed/worker.py", line 2929, in gather_dep
    ts = self.tasks[d]
KeyError: 'array-original-b28294aa84e0af22f5c0bf428197c430'
distributed.comm.tcp - INFO - Connection from tcp://172.21.7.100:36308 closed before handshake completed
distributed.comm.tcp - INFO - Connection from tcp://172.21.9.92:52774 closed before handshake completed
distributed.comm.tcp - INFO - Connection from tcp://172.21.9.93:38616 closed before handshake completed
distributed.comm.tcp - INFO - Connection from tcp://172.21.9.93:38618 closed before handshake completed
distributed.comm.tcp - INFO - Connection from tcp://172.21.9.76:42746 closed before handshake completed
distributed.comm.tcp - INFO - Connection from tcp://172.21.9.76:42748 closed before handshake completed
distributed.comm.tcp - INFO - Connection from tcp://172.21.7.169:54044 closed before handshake completed
distributed.comm.tcp - INFO - Connection from tcp://172.21.7.169:54046 closed before handshake completed
distributed.comm.tcp - INFO - Connection from tcp://172.21.7.52:34310 closed before handshake completed
distributed.comm.tcp - INFO - Connection from tcp://172.21.7.52:34312 closed before handshake completed
distributed.core - INFO - Event loop was unresponsive in Worker for 84.64s.  This is often caused by long-running GIL-holding functions or moving large chunks of data. This can cause timeouts and instability.
distributed.comm.tcp - INFO - Connection from tcp://172.21.9.93:36968 closed before handshake completed
distributed.comm.tcp - INFO - Connection from tcp://172.21.9.76:33334 closed before handshake completed
distributed.comm.tcp - INFO - Connection from tcp://172.21.9.93:36970 closed before handshake completed
distributed.comm.tcp - INFO - Connection from tcp://172.21.9.76:33336 closed before handshake completed
distributed.comm.tcp - INFO - Connection from tcp://172.21.7.169:41828 closed before handshake completed
distributed.comm.tcp - INFO - Connection from tcp://172.21.7.169:41831 closed before handshake completed
distributed.comm.tcp - INFO - Connection from tcp://172.21.7.52:43238 closed before handshake completed
distributed.comm.tcp - INFO - Connection from tcp://172.21.7.52:43240 closed before handshake completed
distributed.worker - ERROR - Worker stream died during communication: tcp://172.21.7.176:37112
Traceback (most recent call last):
  File "/ccc/work/cont003/gen2224/gen2224/spack/var/spack/environments/gysela-deisa-irene-skl-draft/.spack-env/view/lib/python3.9/site-packages/distributed/comm/tcp.py", line 205, in read
    frames_nbytes = await stream.read_bytes(fmt_size)
asyncio.exceptions.CancelledError

During handling of the above exception, another exception occurred:

Traceback (most recent call last):
  File "/ccc/work/cont003/gen2224/gen2224/spack/var/spack/environments/gysela-deisa-irene-skl-draft/.spack-env/._view/whcr3wyhzgorszy3rfxsphyebtvfpqzk/lib/python3.9/asyncio/tasks.py", line 490, in wait_for
    return fut.result()
asyncio.exceptions.CancelledError

The above exception was the direct cause of the following exception:

Traceback (most recent call last):
distributed.worker - ERROR - Worker stream died during communication: tcp://172.21.7.176:37112
Traceback (most recent call last):
  File "/ccc/work/cont003/gen2224/gen2224/spack/var/spack/environments/gysela-deisa-irene-skl-draft/.spack-env/view/lib/python3.9/site-packages/distributed/comm/tcp.py", line 205, in read
    frames_nbytes = await stream.read_bytes(fmt_size)
asyncio.exceptions.CancelledError

During handling of the above exception, another exception occurred:

Traceback (most recent call last):
  File "/ccc/work/cont003/gen2224/gen2224/spack/var/spack/environments/gysela-deisa-irene-skl-draft/.spack-env/._view/whcr3wyhzgorszy3rfxsphyebtvfpqzk/lib/python3.9/asyncio/tasks.py", line 490, in wait_for
    return fut.result()
asyncio.exceptions.CancelledError

The above exception was the direct cause of the following exception:

Traceback (most recent call last):
  File "/ccc/work/cont003/gen2224/gen2224/spack/var/spack/environments/gysela-deisa-irene-skl-draft/.spack-env/view/lib/python3.9/site-packages/distributed/comm/core.py", line 319, in connect
    handshake = await asyncio.wait_for(comm.read(), time_left())
  File "/ccc/work/cont003/gen2224/gen2224/spack/var/spack/environments/gysela-deisa-irene-skl-draft/.spack-env/._view/whcr3wyhzgorszy3rfxsphyebtvfpqzk/lib/python3.9/asyncio/tasks.py", line 492, in wait_for
    raise exceptions.TimeoutError() from exc
asyncio.exceptions.TimeoutError

The above exception was the direct cause of the following exception:

Traceback (most recent call last):
  File "/ccc/work/cont003/gen2224/gen2224/spack/var/spack/environments/gysela-deisa-irene-skl-draft/.spack-env/view/lib/python3.9/site-packages/distributed/worker.py", line 2878, in gather_dep
    response = await get_data_from_worker(
  File "/ccc/work/cont003/gen2224/gen2224/spack/var/spack/environments/gysela-deisa-irene-skl-draft/.spack-env/view/lib/python3.9/site-packages/distributed/worker.py", line 4143, in get_data_from_worker
    return await retry_operation(_get_data, operation="get_data_from_worker")
  File "/ccc/work/cont003/gen2224/gen2224/spack/var/spack/environments/gysela-deisa-irene-skl-draft/.spack-env/view/lib/python3.9/site-packages/distributed/utils_comm.py", line 366, in retry_operation
    return await retry(
  File "/ccc/work/cont003/gen2224/gen2224/spack/var/spack/environments/gysela-deisa-irene-skl-draft/.spack-env/view/lib/python3.9/site-packages/distributed/utils_comm.py", line 351, in retry
    return await coro()
  File "/ccc/work/cont003/gen2224/gen2224/spack/var/spack/environments/gysela-deisa-irene-skl-draft/.spack-env/view/lib/python3.9/site-packages/distributed/worker.py", line 4120, in _get_data
    comm = await rpc.connect(worker)
  File "/ccc/work/cont003/gen2224/gen2224/spack/var/spack/environments/gysela-deisa-irene-skl-draft/.spack-env/view/lib/python3.9/site-packages/distributed/comm/core.py", line 319, in connect
    handshake = await asyncio.wait_for(comm.read(), time_left())
  File "/ccc/work/cont003/gen2224/gen2224/spack/var/spack/environments/gysela-deisa-irene-skl-draft/.spack-env/._view/whcr3wyhzgorszy3rfxsphyebtvfpqzk/lib/python3.9/asyncio/tasks.py", line 492, in wait_for
    raise exceptions.TimeoutError() from exc
asyncio.exceptions.TimeoutError

The above exception was the direct cause of the following exception:

Traceback (most recent call last):
  File "/ccc/work/cont003/gen2224/gen2224/spack/var/spack/environments/gysela-deisa-irene-skl-draft/.spack-env/view/lib/python3.9/site-packages/distributed/worker.py", line 2878, in gather_dep
    response = await get_data_from_worker(
  File "/ccc/work/cont003/gen2224/gen2224/spack/var/spack/environments/gysela-deisa-irene-skl-draft/.spack-env/view/lib/python3.9/site-packages/distributed/core.py", line 1081, in connect
    raise exc
  File "/ccc/work/cont003/gen2224/gen2224/spack/var/spack/environments/gysela-deisa-irene-skl-draft/.spack-env/view/lib/python3.9/site-packages/distributed/core.py", line 1065, in connect
    comm = await fut
  File "/ccc/work/cont003/gen2224/gen2224/spack/var/spack/environments/gysela-deisa-irene-skl-draft/.spack-env/view/lib/python3.9/site-packages/distributed/comm/core.py", line 324, in connect
    raise OSError(
OSError: Timed out during handshake while connecting to tcp://172.21.7.176:37112 after 30 s
  File "/ccc/work/cont003/gen2224/gen2224/spack/var/spack/environments/gysela-deisa-irene-skl-draft/.spack-env/view/lib/python3.9/site-packages/distributed/worker.py", line 4143, in get_data_from_worker
    return await retry_operation(_get_data, operation="get_data_from_worker")
  File "/ccc/work/cont003/gen2224/gen2224/spack/var/spack/environments/gysela-deisa-irene-skl-draft/.spack-env/view/lib/python3.9/site-packages/distributed/utils_comm.py", line 366, in retry_operation
    return await retry(
  File "/ccc/work/cont003/gen2224/gen2224/spack/var/spack/environments/gysela-deisa-irene-skl-draft/.spack-env/view/lib/python3.9/site-packages/distributed/utils_comm.py", line 351, in retry
    return await coro()
  File "/ccc/work/cont003/gen2224/gen2224/spack/var/spack/environments/gysela-deisa-irene-skl-draft/.spack-env/view/lib/python3.9/site-packages/distributed/worker.py", line 4120, in _get_data
    comm = await rpc.connect(worker)
  File "/ccc/work/cont003/gen2224/gen2224/spack/var/spack/environments/gysela-deisa-irene-skl-draft/.spack-env/view/lib/python3.9/site-packages/distributed/core.py", line 1081, in connect
    raise exc
  File "/ccc/work/cont003/gen2224/gen2224/spack/var/spack/environments/gysela-deisa-irene-skl-draft/.spack-env/view/lib/python3.9/site-packages/distributed/core.py", line 1065, in connect
    comm = await fut
  File "/ccc/work/cont003/gen2224/gen2224/spack/var/spack/environments/gysela-deisa-irene-skl-draft/.spack-env/view/lib/python3.9/site-packages/distributed/comm/core.py", line 324, in connect
    raise OSError(
OSError: Timed out during handshake while connecting to tcp://172.21.7.176:37112 after 30 s
distributed.worker - ERROR - Worker stream died during communication: tcp://172.21.7.176:37112
Traceback (most recent call last):
  File "/ccc/work/cont003/gen2224/gen2224/spack/var/spack/environments/gysela-deisa-irene-skl-draft/.spack-env/view/lib/python3.9/site-packages/distributed/comm/tcp.py", line 205, in read
    frames_nbytes = await stream.read_bytes(fmt_size)
asyncio.exceptions.CancelledError

During handling of the above exception, another exception occurred:

Traceback (most recent call last):
  File "/ccc/work/cont003/gen2224/gen2224/spack/var/spack/environments/gysela-deisa-irene-skl-draft/.spack-env/._view/whcr3wyhzgorszy3rfxsphyebtvfpqzk/lib/python3.9/asyncio/tasks.py", line 490, in wait_for
    return fut.result()
asyncio.exceptions.CancelledError

The above exception was the direct cause of the following exception:

Traceback (most recent call last):
  File "/ccc/work/cont003/gen2224/gen2224/spack/var/spack/environments/gysela-deisa-irene-skl-draft/.spack-env/view/lib/python3.9/site-packages/distributed/comm/core.py", line 319, in connect
    handshake = await asyncio.wait_for(comm.read(), time_left())
  File "/ccc/work/cont003/gen2224/gen2224/spack/var/spack/environments/gysela-deisa-irene-skl-draft/.spack-env/._view/whcr3wyhzgorszy3rfxsphyebtvfpqzk/lib/python3.9/asyncio/tasks.py", line 492, in wait_for
    raise exceptions.TimeoutError() from exc
asyncio.exceptions.TimeoutError

The above exception was the direct cause of the following exception:

Traceback (most recent call last):
  File "/ccc/work/cont003/gen2224/gen2224/spack/var/spack/environments/gysela-deisa-irene-skl-draft/.spack-env/view/lib/python3.9/site-packages/distributed/worker.py", line 2878, in gather_dep
    response = await get_data_from_worker(
  File "/ccc/work/cont003/gen2224/gen2224/spack/var/spack/environments/gysela-deisa-irene-skl-draft/.spack-env/view/lib/python3.9/site-packages/distributed/worker.py", line 4143, in get_data_from_worker
    return await retry_operation(_get_data, operation="get_data_from_worker")
  File "/ccc/work/cont003/gen2224/gen2224/spack/var/spack/environments/gysela-deisa-irene-skl-draft/.spack-env/view/lib/python3.9/site-packages/distributed/utils_comm.py", line 366, in retry_operation
    return await retry(
  File "/ccc/work/cont003/gen2224/gen2224/spack/var/spack/environments/gysela-deisa-irene-skl-draft/.spack-env/view/lib/python3.9/site-packages/distributed/utils_comm.py", line 351, in retry
    return await coro()
  File "/ccc/work/cont003/gen2224/gen2224/spack/var/spack/environments/gysela-deisa-irene-skl-draft/.spack-env/view/lib/python3.9/site-packages/distributed/worker.py", line 4120, in _get_data
    comm = await rpc.connect(worker)
  File "/ccc/work/cont003/gen2224/gen2224/spack/var/spack/environments/gysela-deisa-irene-skl-draft/.spack-env/view/lib/python3.9/site-packages/distributed/core.py", line 1081, in connect
    raise exc
  File "/ccc/work/cont003/gen2224/gen2224/spack/var/spack/environments/gysela-deisa-irene-skl-draft/.spack-env/view/lib/python3.9/site-packages/distributed/core.py", line 1065, in connect
    comm = await fut
  File "/ccc/work/cont003/gen2224/gen2224/spack/var/spack/environments/gysela-deisa-irene-skl-draft/.spack-env/view/lib/python3.9/site-packages/distributed/comm/core.py", line 324, in connect
    raise OSError(
OSError: Timed out during handshake while connecting to tcp://172.21.7.176:37112 after 30 s
distributed.worker - ERROR - Worker stream died during communication: tcp://172.21.7.176:37112
Traceback (most recent call last):
  File "/ccc/work/cont003/gen2224/gen2224/spack/var/spack/environments/gysela-deisa-irene-skl-draft/.spack-env/view/lib/python3.9/site-packages/distributed/comm/tcp.py", line 205, in read
    frames_nbytes = await stream.read_bytes(fmt_size)
asyncio.exceptions.CancelledError

During handling of the above exception, another exception occurred:

Traceback (most recent call last):
  File "/ccc/work/cont003/gen2224/gen2224/spack/var/spack/environments/gysela-deisa-irene-skl-draft/.spack-env/._view/whcr3wyhzgorszy3rfxsphyebtvfpqzk/lib/python3.9/asyncio/tasks.py", line 490, in wait_for
    return fut.result()
asyncio.exceptions.CancelledError

The above exception was the direct cause of the following exception:

Traceback (most recent call last):
  File "/ccc/work/cont003/gen2224/gen2224/spack/var/spack/environments/gysela-deisa-irene-skl-draft/.spack-env/view/lib/python3.9/site-packages/distributed/comm/core.py", line 319, in connect
    handshake = await asyncio.wait_for(comm.read(), time_left())
  File "/ccc/work/cont003/gen2224/gen2224/spack/var/spack/environments/gysela-deisa-irene-skl-draft/.spack-env/._view/whcr3wyhzgorszy3rfxsphyebtvfpqzk/lib/python3.9/asyncio/tasks.py", line 492, in wait_for
    raise exceptions.TimeoutError() from exc
asyncio.exceptions.TimeoutError

The above exception was the direct cause of the following exception:

Traceback (most recent call last):
  File "/ccc/work/cont003/gen2224/gen2224/spack/var/spack/environments/gysela-deisa-irene-skl-draft/.spack-env/view/lib/python3.9/site-packages/distributed/worker.py", line 2878, in gather_dep
    response = await get_data_from_worker(
distributed.worker - ERROR - Worker stream died during communication: tcp://172.21.7.176:37112
Traceback (most recent call last):
  File "/ccc/work/cont003/gen2224/gen2224/spack/var/spack/environments/gysela-deisa-irene-skl-draft/.spack-env/view/lib/python3.9/site-packages/distributed/comm/tcp.py", line 205, in read
    frames_nbytes = await stream.read_bytes(fmt_size)
asyncio.exceptions.CancelledError

During handling of the above exception, another exception occurred:

Traceback (most recent call last):
  File "/ccc/work/cont003/gen2224/gen2224/spack/var/spack/environments/gysela-deisa-irene-skl-draft/.spack-env/._view/whcr3wyhzgorszy3rfxsphyebtvfpqzk/lib/python3.9/asyncio/tasks.py", line 490, in wait_for
    return fut.result()
asyncio.exceptions.CancelledError

The above exception was the direct cause of the following exception:

Traceback (most recent call last):
  File "/ccc/work/cont003/gen2224/gen2224/spack/var/spack/environments/gysela-deisa-irene-skl-draft/.spack-env/view/lib/python3.9/site-packages/distributed/worker.py", line 4143, in get_data_from_worker
    return await retry_operation(_get_data, operation="get_data_from_worker")
  File "/ccc/work/cont003/gen2224/gen2224/spack/var/spack/environments/gysela-deisa-irene-skl-draft/.spack-env/view/lib/python3.9/site-packages/distributed/utils_comm.py", line 366, in retry_operation
    return await retry(
  File "/ccc/work/cont003/gen2224/gen2224/spack/var/spack/environments/gysela-deisa-irene-skl-draft/.spack-env/view/lib/python3.9/site-packages/distributed/utils_comm.py", line 351, in retry
    return await coro()
  File "/ccc/work/cont003/gen2224/gen2224/spack/var/spack/environments/gysela-deisa-irene-skl-draft/.spack-env/view/lib/python3.9/site-packages/distributed/worker.py", line 4120, in _get_data
    comm = await rpc.connect(worker)
  File "/ccc/work/cont003/gen2224/gen2224/spack/var/spack/environments/gysela-deisa-irene-skl-draft/.spack-env/view/lib/python3.9/site-packages/distributed/core.py", line 1081, in connect
    raise exc
  File "/ccc/work/cont003/gen2224/gen2224/spack/var/spack/environments/gysela-deisa-irene-skl-draft/.spack-env/view/lib/python3.9/site-packages/distributed/core.py", line 1065, in connect
    comm = await fut
  File "/ccc/work/cont003/gen2224/gen2224/spack/var/spack/environments/gysela-deisa-irene-skl-draft/.spack-env/view/lib/python3.9/site-packages/distributed/comm/core.py", line 324, in connect
    raise OSError(
OSError: Timed out during handshake while connecting to tcp://172.21.7.176:37112 after 30 s
  File "/ccc/work/cont003/gen2224/gen2224/spack/var/spack/environments/gysela-deisa-irene-skl-draft/.spack-env/view/lib/python3.9/site-packages/distributed/comm/core.py", line 319, in connect
    handshake = await asyncio.wait_for(comm.read(), time_left())
  File "/ccc/work/cont003/gen2224/gen2224/spack/var/spack/environments/gysela-deisa-irene-skl-draft/.spack-env/._view/whcr3wyhzgorszy3rfxsphyebtvfpqzk/lib/python3.9/asyncio/tasks.py", line 492, in wait_for
    raise exceptions.TimeoutError() from exc
asyncio.exceptions.TimeoutError

The above exception was the direct cause of the following exception:

Traceback (most recent call last):
  File "/ccc/work/cont003/gen2224/gen2224/spack/var/spack/environments/gysela-deisa-irene-skl-draft/.spack-env/view/lib/python3.9/site-packages/distributed/worker.py", line 2878, in gather_dep
    response = await get_data_from_worker(
distributed.worker - ERROR - Worker stream died during communication: tcp://172.21.7.176:37112
Traceback (most recent call last):
  File "/ccc/work/cont003/gen2224/gen2224/spack/var/spack/environments/gysela-deisa-irene-skl-draft/.spack-env/view/lib/python3.9/site-packages/distributed/comm/tcp.py", line 205, in read
    frames_nbytes = await stream.read_bytes(fmt_size)
asyncio.exceptions.CancelledError

During handling of the above exception, another exception occurred:

Traceback (most recent call last):
  File "/ccc/work/cont003/gen2224/gen2224/spack/var/spack/environments/gysela-deisa-irene-skl-draft/.spack-env/._view/whcr3wyhzgorszy3rfxsphyebtvfpqzk/lib/python3.9/asyncio/tasks.py", line 490, in wait_for
    return fut.result()
asyncio.exceptions.CancelledError

The above exception was the direct cause of the following exception:

Traceback (most recent call last):
distributed.worker - ERROR - Worker stream died during communication: tcp://172.21.7.176:37112
Traceback (most recent call last):
  File "/ccc/work/cont003/gen2224/gen2224/spack/var/spack/environments/gysela-deisa-irene-skl-draft/.spack-env/view/lib/python3.9/site-packages/distributed/comm/tcp.py", line 205, in read
    frames_nbytes = await stream.read_bytes(fmt_size)
asyncio.exceptions.CancelledError

During handling of the above exception, another exception occurred:

Traceback (most recent call last):
  File "/ccc/work/cont003/gen2224/gen2224/spack/var/spack/environments/gysela-deisa-irene-skl-draft/.spack-env/._view/whcr3wyhzgorszy3rfxsphyebtvfpqzk/lib/python3.9/asyncio/tasks.py", line 490, in wait_for
    return fut.result()
asyncio.exceptions.CancelledError

The above exception was the direct cause of the following exception:

Traceback (most recent call last):
  File "/ccc/work/cont003/gen2224/gen2224/spack/var/spack/environments/gysela-deisa-irene-skl-draft/.spack-env/view/lib/python3.9/site-packages/distributed/worker.py", line 4143, in get_data_from_worker
    return await retry_operation(_get_data, operation="get_data_from_worker")
  File "/ccc/work/cont003/gen2224/gen2224/spack/var/spack/environments/gysela-deisa-irene-skl-draft/.spack-env/view/lib/python3.9/site-packages/distributed/utils_comm.py", line 366, in retry_operation
    return await retry(
  File "/ccc/work/cont003/gen2224/gen2224/spack/var/spack/environments/gysela-deisa-irene-skl-draft/.spack-env/view/lib/python3.9/site-packages/distributed/utils_comm.py", line 351, in retry
    return await coro()
  File "/ccc/work/cont003/gen2224/gen2224/spack/var/spack/environments/gysela-deisa-irene-skl-draft/.spack-env/view/lib/python3.9/site-packages/distributed/worker.py", line 4120, in _get_data
    comm = await rpc.connect(worker)
  File "/ccc/work/cont003/gen2224/gen2224/spack/var/spack/environments/gysela-deisa-irene-skl-draft/.spack-env/view/lib/python3.9/site-packages/distributed/comm/core.py", line 319, in connect
    handshake = await asyncio.wait_for(comm.read(), time_left())
  File "/ccc/work/cont003/gen2224/gen2224/spack/var/spack/environments/gysela-deisa-irene-skl-draft/.spack-env/._view/whcr3wyhzgorszy3rfxsphyebtvfpqzk/lib/python3.9/asyncio/tasks.py", line 492, in wait_for
    raise exceptions.TimeoutError() from exc
asyncio.exceptions.TimeoutError

The above exception was the direct cause of the following exception:

Traceback (most recent call last):
  File "/ccc/work/cont003/gen2224/gen2224/spack/var/spack/environments/gysela-deisa-irene-skl-draft/.spack-env/view/lib/python3.9/site-packages/distributed/worker.py", line 2878, in gather_dep
    response = await get_data_from_worker(
  File "/ccc/work/cont003/gen2224/gen2224/spack/var/spack/environments/gysela-deisa-irene-skl-draft/.spack-env/view/lib/python3.9/site-packages/distributed/core.py", line 1081, in connect
    raise exc
  File "/ccc/work/cont003/gen2224/gen2224/spack/var/spack/environments/gysela-deisa-irene-skl-draft/.spack-env/view/lib/python3.9/site-packages/distributed/core.py", line 1065, in connect
    comm = await fut
  File "/ccc/work/cont003/gen2224/gen2224/spack/var/spack/environments/gysela-deisa-irene-skl-draft/.spack-env/view/lib/python3.9/site-packages/distributed/comm/core.py", line 324, in connect
    raise OSError(
OSError: Timed out during handshake while connecting to tcp://172.21.7.176:37112 after 30 s
  File "/ccc/work/cont003/gen2224/gen2224/spack/var/spack/environments/gysela-deisa-irene-skl-draft/.spack-env/view/lib/python3.9/site-packages/distributed/worker.py", line 4143, in get_data_from_worker
    return await retry_operation(_get_data, operation="get_data_from_worker")
  File "/ccc/work/cont003/gen2224/gen2224/spack/var/spack/environments/gysela-deisa-irene-skl-draft/.spack-env/view/lib/python3.9/site-packages/distributed/utils_comm.py", line 366, in retry_operation
    return await retry(
  File "/ccc/work/cont003/gen2224/gen2224/spack/var/spack/environments/gysela-deisa-irene-skl-draft/.spack-env/view/lib/python3.9/site-packages/distributed/utils_comm.py", line 351, in retry
    return await coro()
  File "/ccc/work/cont003/gen2224/gen2224/spack/var/spack/environments/gysela-deisa-irene-skl-draft/.spack-env/view/lib/python3.9/site-packages/distributed/worker.py", line 4120, in _get_data
    comm = await rpc.connect(worker)
  File "/ccc/work/cont003/gen2224/gen2224/spack/var/spack/environments/gysela-deisa-irene-skl-draft/.spack-env/view/lib/python3.9/site-packages/distributed/comm/core.py", line 319, in connect
    handshake = await asyncio.wait_for(comm.read(), time_left())
  File "/ccc/work/cont003/gen2224/gen2224/spack/var/spack/environments/gysela-deisa-irene-skl-draft/.spack-env/._view/whcr3wyhzgorszy3rfxsphyebtvfpqzk/lib/python3.9/asyncio/tasks.py", line 492, in wait_for
    raise exceptions.TimeoutError() from exc
asyncio.exceptions.TimeoutError

The above exception was the direct cause of the following exception:

Traceback (most recent call last):
  File "/ccc/work/cont003/gen2224/gen2224/spack/var/spack/environments/gysela-deisa-irene-skl-draft/.spack-env/view/lib/python3.9/site-packages/distributed/worker.py", line 2878, in gather_dep
    response = await get_data_from_worker(
distributed.worker - ERROR - Worker stream died during communication: tcp://172.21.7.176:37112
Traceback (most recent call last):
  File "/ccc/work/cont003/gen2224/gen2224/spack/var/spack/environments/gysela-deisa-irene-skl-draft/.spack-env/view/lib/python3.9/site-packages/distributed/comm/tcp.py", line 205, in read
    frames_nbytes = await stream.read_bytes(fmt_size)
asyncio.exceptions.CancelledError

During handling of the above exception, another exception occurred:

Traceback (most recent call last):
  File "/ccc/work/cont003/gen2224/gen2224/spack/var/spack/environments/gysela-deisa-irene-skl-draft/.spack-env/._view/whcr3wyhzgorszy3rfxsphyebtvfpqzk/lib/python3.9/asyncio/tasks.py", line 490, in wait_for
    return fut.result()
asyncio.exceptions.CancelledError

The above exception was the direct cause of the following exception:

Traceback (most recent call last):
  File "/ccc/work/cont003/gen2224/gen2224/spack/var/spack/environments/gysela-deisa-irene-skl-draft/.spack-env/view/lib/python3.9/site-packages/distributed/core.py", line 1081, in connect
    raise exc
  File "/ccc/work/cont003/gen2224/gen2224/spack/var/spack/environments/gysela-deisa-irene-skl-draft/.spack-env/view/lib/python3.9/site-packages/distributed/core.py", line 1065, in connect
    comm = await fut
  File "/ccc/work/cont003/gen2224/gen2224/spack/var/spack/environments/gysela-deisa-irene-skl-draft/.spack-env/view/lib/python3.9/site-packages/distributed/comm/core.py", line 324, in connect
    raise OSError(
OSError: Timed out during handshake while connecting to tcp://172.21.7.176:37112 after 30 s
  File "/ccc/work/cont003/gen2224/gen2224/spack/var/spack/environments/gysela-deisa-irene-skl-draft/.spack-env/view/lib/python3.9/site-packages/distributed/worker.py", line 4143, in get_data_from_worker
    return await retry_operation(_get_data, operation="get_data_from_worker")
  File "/ccc/work/cont003/gen2224/gen2224/spack/var/spack/environments/gysela-deisa-irene-skl-draft/.spack-env/view/lib/python3.9/site-packages/distributed/utils_comm.py", line 366, in retry_operation
    return await retry(
  File "/ccc/work/cont003/gen2224/gen2224/spack/var/spack/environments/gysela-deisa-irene-skl-draft/.spack-env/view/lib/python3.9/site-packages/distributed/utils_comm.py", line 351, in retry
    return await coro()
  File "/ccc/work/cont003/gen2224/gen2224/spack/var/spack/environments/gysela-deisa-irene-skl-draft/.spack-env/view/lib/python3.9/site-packages/distributed/worker.py", line 4120, in _get_data
    comm = await rpc.connect(worker)
  File "/ccc/work/cont003/gen2224/gen2224/spack/var/spack/environments/gysela-deisa-irene-skl-draft/.spack-env/view/lib/python3.9/site-packages/distributed/comm/core.py", line 319, in connect
    handshake = await asyncio.wait_for(comm.read(), time_left())
  File "/ccc/work/cont003/gen2224/gen2224/spack/var/spack/environments/gysela-deisa-irene-skl-draft/.spack-env/._view/whcr3wyhzgorszy3rfxsphyebtvfpqzk/lib/python3.9/asyncio/tasks.py", line 492, in wait_for
    raise exceptions.TimeoutError() from exc
asyncio.exceptions.TimeoutError

The above exception was the direct cause of the following exception:

Traceback (most recent call last):
  File "/ccc/work/cont003/gen2224/gen2224/spack/var/spack/environments/gysela-deisa-irene-skl-draft/.spack-env/view/lib/python3.9/site-packages/distributed/worker.py", line 2878, in gather_dep
    response = await get_data_from_worker(
  File "/ccc/work/cont003/gen2224/gen2224/spack/var/spack/environments/gysela-deisa-irene-skl-draft/.spack-env/view/lib/python3.9/site-packages/distributed/core.py", line 1081, in connect
    raise exc
  File "/ccc/work/cont003/gen2224/gen2224/spack/var/spack/environments/gysela-deisa-irene-skl-draft/.spack-env/view/lib/python3.9/site-packages/distributed/core.py", line 1065, in connect
    comm = await fut
  File "/ccc/work/cont003/gen2224/gen2224/spack/var/spack/environments/gysela-deisa-irene-skl-draft/.spack-env/view/lib/python3.9/site-packages/distributed/comm/core.py", line 324, in connect
    raise OSError(
OSError: Timed out during handshake while connecting to tcp://172.21.7.176:37112 after 30 s
  File "/ccc/work/cont003/gen2224/gen2224/spack/var/spack/environments/gysela-deisa-irene-skl-draft/.spack-env/view/lib/python3.9/site-packages/distributed/worker.py", line 4143, in get_data_from_worker
    return await retry_operation(_get_data, operation="get_data_from_worker")
  File "/ccc/work/cont003/gen2224/gen2224/spack/var/spack/environments/gysela-deisa-irene-skl-draft/.spack-env/view/lib/python3.9/site-packages/distributed/utils_comm.py", line 366, in retry_operation
    return await retry(
  File "/ccc/work/cont003/gen2224/gen2224/spack/var/spack/environments/gysela-deisa-irene-skl-draft/.spack-env/view/lib/python3.9/site-packages/distributed/utils_comm.py", line 351, in retry
    return await coro()
  File "/ccc/work/cont003/gen2224/gen2224/spack/var/spack/environments/gysela-deisa-irene-skl-draft/.spack-env/view/lib/python3.9/site-packages/distributed/worker.py", line 4120, in _get_data
    comm = await rpc.connect(worker)
  File "/ccc/work/cont003/gen2224/gen2224/spack/var/spack/environments/gysela-deisa-irene-skl-draft/.spack-env/view/lib/python3.9/site-packages/distributed/core.py", line 1081, in connect
    raise exc
  File "/ccc/work/cont003/gen2224/gen2224/spack/var/spack/environments/gysela-deisa-irene-skl-draft/.spack-env/view/lib/python3.9/site-packages/distributed/core.py", line 1065, in connect
    comm = await fut
  File "/ccc/work/cont003/gen2224/gen2224/spack/var/spack/environments/gysela-deisa-irene-skl-draft/.spack-env/view/lib/python3.9/site-packages/distributed/comm/core.py", line 324, in connect
    raise OSError(
OSError: Timed out during handshake while connecting to tcp://172.21.7.176:37112 after 30 s
distributed.worker - ERROR - Worker stream died during communication: tcp://172.21.7.176:37112
Traceback (most recent call last):
  File "/ccc/work/cont003/gen2224/gen2224/spack/var/spack/environments/gysela-deisa-irene-skl-draft/.spack-env/view/lib/python3.9/site-packages/distributed/comm/tcp.py", line 205, in read
    frames_nbytes = await stream.read_bytes(fmt_size)
asyncio.exceptions.CancelledError

During handling of the above exception, another exception occurred:

Traceback (most recent call last):
  File "/ccc/work/cont003/gen2224/gen2224/spack/var/spack/environments/gysela-deisa-irene-skl-draft/.spack-env/._view/whcr3wyhzgorszy3rfxsphyebtvfpqzk/lib/python3.9/asyncio/tasks.py", line 490, in wait_for
    return fut.result()
asyncio.exceptions.CancelledError

The above exception was the direct cause of the following exception:

Traceback (most recent call last):
  File "/ccc/work/cont003/gen2224/gen2224/spack/var/spack/environments/gysela-deisa-irene-skl-draft/.spack-env/view/lib/python3.9/site-packages/distributed/comm/core.py", line 319, in connect
    handshake = await asyncio.wait_for(comm.read(), time_left())
  File "/ccc/work/cont003/gen2224/gen2224/spack/var/spack/environments/gysela-deisa-irene-skl-draft/.spack-env/._view/whcr3wyhzgorszy3rfxsphyebtvfpqzk/lib/python3.9/asyncio/tasks.py", line 492, in wait_for
    raise exceptions.TimeoutError() from exc
asyncio.exceptions.TimeoutError

The above exception was the direct cause of the following exception:

Traceback (most recent call last):
  File "/ccc/work/cont003/gen2224/gen2224/spack/var/spack/environments/gysela-deisa-irene-skl-draft/.spack-env/view/lib/python3.9/site-packages/distributed/worker.py", line 2878, in gather_dep
    response = await get_data_from_worker(
  File "/ccc/work/cont003/gen2224/gen2224/spack/var/spack/environments/gysela-deisa-irene-skl-draft/.spack-env/view/lib/python3.9/site-packages/distributed/worker.py", line 4143, in get_data_from_worker
    return await retry_operation(_get_data, operation="get_data_from_worker")
  File "/ccc/work/cont003/gen2224/gen2224/spack/var/spack/environments/gysela-deisa-irene-skl-draft/.spack-env/view/lib/python3.9/site-packages/distributed/utils_comm.py", line 366, in retry_operation
    return await retry(
  File "/ccc/work/cont003/gen2224/gen2224/spack/var/spack/environments/gysela-deisa-irene-skl-draft/.spack-env/view/lib/python3.9/site-packages/distributed/utils_comm.py", line 351, in retry
    return await coro()
  File "/ccc/work/cont003/gen2224/gen2224/spack/var/spack/environments/gysela-deisa-irene-skl-draft/.spack-env/view/lib/python3.9/site-packages/distributed/worker.py", line 4120, in _get_data
    comm = await rpc.connect(worker)
  File "/ccc/work/cont003/gen2224/gen2224/spack/var/spack/environments/gysela-deisa-irene-skl-draft/.spack-env/view/lib/python3.9/site-packages/distributed/core.py", line 1081, in connect
    raise exc
  File "/ccc/work/cont003/gen2224/gen2224/spack/var/spack/environments/gysela-deisa-irene-skl-draft/.spack-env/view/lib/python3.9/site-packages/distributed/core.py", line 1065, in connect
    comm = await fut
  File "/ccc/work/cont003/gen2224/gen2224/spack/var/spack/environments/gysela-deisa-irene-skl-draft/.spack-env/view/lib/python3.9/site-packages/distributed/comm/core.py", line 324, in connect
    raise OSError(
OSError: Timed out during handshake while connecting to tcp://172.21.7.176:37112 after 30 s
distributed.worker - ERROR - Worker stream died during communication: tcp://172.21.7.176:37112
Traceback (most recent call last):
  File "/ccc/work/cont003/gen2224/gen2224/spack/var/spack/environments/gysela-deisa-irene-skl-draft/.spack-env/view/lib/python3.9/site-packages/distributed/comm/tcp.py", line 205, in read
    frames_nbytes = await stream.read_bytes(fmt_size)
asyncio.exceptions.CancelledError

During handling of the above exception, another exception occurred:

Traceback (most recent call last):
  File "/ccc/work/cont003/gen2224/gen2224/spack/var/spack/environments/gysela-deisa-irene-skl-draft/.spack-env/._view/whcr3wyhzgorszy3rfxsphyebtvfpqzk/lib/python3.9/asyncio/tasks.py", line 490, in wait_for
    return fut.result()
asyncio.exceptions.CancelledError

The above exception was the direct cause of the following exception:

Traceback (most recent call last):
  File "/ccc/work/cont003/gen2224/gen2224/spack/var/spack/environments/gysela-deisa-irene-skl-draft/.spack-env/view/lib/python3.9/site-packages/distributed/comm/core.py", line 319, in connect
    handshake = await asyncio.wait_for(comm.read(), time_left())
  File "/ccc/work/cont003/gen2224/gen2224/spack/var/spack/environments/gysela-deisa-irene-skl-draft/.spack-env/._view/whcr3wyhzgorszy3rfxsphyebtvfpqzk/lib/python3.9/asyncio/tasks.py", line 492, in wait_for
    raise exceptions.TimeoutError() from exc
asyncio.exceptions.TimeoutError

The above exception was the direct cause of the following exception:

Traceback (most recent call last):
  File "/ccc/work/cont003/gen2224/gen2224/spack/var/spack/environments/gysela-deisa-irene-skl-draft/.spack-env/view/lib/python3.9/site-packages/distributed/worker.py", line 2878, in gather_dep
    response = await get_data_from_worker(
  File "/ccc/work/cont003/gen2224/gen2224/spack/var/spack/environments/gysela-deisa-irene-skl-draft/.spack-env/view/lib/python3.9/site-packages/distributed/worker.py", line 4143, in get_data_from_worker
    return await retry_operation(_get_data, operation="get_data_from_worker")
  File "/ccc/work/cont003/gen2224/gen2224/spack/var/spack/environments/gysela-deisa-irene-skl-draft/.spack-env/view/lib/python3.9/site-packages/distributed/utils_comm.py", line 366, in retry_operation
    return await retry(
  File "/ccc/work/cont003/gen2224/gen2224/spack/var/spack/environments/gysela-deisa-irene-skl-draft/.spack-env/view/lib/python3.9/site-packages/distributed/utils_comm.py", line 351, in retry
    return await coro()
  File "/ccc/work/cont003/gen2224/gen2224/spack/var/spack/environments/gysela-deisa-irene-skl-draft/.spack-env/view/lib/python3.9/site-packages/distributed/worker.py", line 4120, in _get_data
    comm = await rpc.connect(worker)
  File "/ccc/work/cont003/gen2224/gen2224/spack/var/spack/environments/gysela-deisa-irene-skl-draft/.spack-env/view/lib/python3.9/site-packages/distributed/core.py", line 1081, in connect
    raise exc
  File "/ccc/work/cont003/gen2224/gen2224/spack/var/spack/environments/gysela-deisa-irene-skl-draft/.spack-env/view/lib/python3.9/site-packages/distributed/core.py", line 1065, in connect
    comm = await fut
  File "/ccc/work/cont003/gen2224/gen2224/spack/var/spack/environments/gysela-deisa-irene-skl-draft/.spack-env/view/lib/python3.9/site-packages/distributed/comm/core.py", line 324, in connect
    raise OSError(
OSError: Timed out during handshake while connecting to tcp://172.21.7.176:37112 after 30 s
distributed.worker - ERROR - Exception during execution of task ('array-b28294aa84e0af22f5c0bf428197c430', 7, 2, 0).
Traceback (most recent call last):
  File "/ccc/work/cont003/gen2224/gen2224/spack/var/spack/environments/gysela-deisa-irene-skl-draft/.spack-env/view/lib/python3.9/site-packages/distributed/worker.py", line 3439, in _prepare_args_for_execution
    data[k] = self.data[k]
  File "/ccc/work/cont003/gen2224/gen2224/spack/var/spack/environments/gysela-deisa-irene-skl-draft/.spack-env/view/lib/python3.9/site-packages/zict/buffer.py", line 72, in __getitem__
    raise KeyError(key)
KeyError: 'array-original-b28294aa84e0af22f5c0bf428197c430'

During handling of the above exception, another exception occurred:

Traceback (most recent call last):
  File "/ccc/work/cont003/gen2224/gen2224/spack/var/spack/environments/gysela-deisa-irene-skl-draft/.spack-env/view/lib/python3.9/site-packages/distributed/worker.py", line 3321, in execute
    args2, kwargs2 = self._prepare_args_for_execution(ts, args, kwargs)
  File "/ccc/work/cont003/gen2224/gen2224/spack/var/spack/environments/gysela-deisa-irene-skl-draft/.spack-env/view/lib/python3.9/site-packages/distributed/worker.py", line 3443, in _prepare_args_for_execution
    data[k] = Actor(type(self.actors[k]), self.address, k, self)
KeyError: 'array-original-b28294aa84e0af22f5c0bf428197c430'
distributed.worker - ERROR - Exception during execution of task ('array-b28294aa84e0af22f5c0bf428197c430', 8, 8, 2).
Traceback (most recent call last):
  File "/ccc/work/cont003/gen2224/gen2224/spack/var/spack/environments/gysela-deisa-irene-skl-draft/.spack-env/view/lib/python3.9/site-packages/distributed/worker.py", line 3439, in _prepare_args_for_execution
    data[k] = self.data[k]
  File "/ccc/work/cont003/gen2224/gen2224/spack/var/spack/environments/gysela-deisa-irene-skl-draft/.spack-env/view/lib/python3.9/site-packages/zict/buffer.py", line 72, in __getitem__
    raise KeyError(key)
KeyError: 'array-original-b28294aa84e0af22f5c0bf428197c430'

During handling of the above exception, another exception occurred:

Traceback (most recent call last):
  File "/ccc/work/cont003/gen2224/gen2224/spack/var/spack/environments/gysela-deisa-irene-skl-draft/.spack-env/view/lib/python3.9/site-packages/distributed/worker.py", line 3321, in execute
    args2, kwargs2 = self._prepare_args_for_execution(ts, args, kwargs)
  File "/ccc/work/cont003/gen2224/gen2224/spack/var/spack/environments/gysela-deisa-irene-skl-draft/.spack-env/view/lib/python3.9/site-packages/distributed/worker.py", line 3443, in _prepare_args_for_execution
    data[k] = Actor(type(self.actors[k]), self.address, k, self)
KeyError: 'array-original-b28294aa84e0af22f5c0bf428197c430'
distributed.worker - ERROR - Worker stream died during communication: tcp://172.21.7.176:37112
Traceback (most recent call last):
  File "/ccc/work/cont003/gen2224/gen2224/spack/var/spack/environments/gysela-deisa-irene-skl-draft/.spack-env/view/lib/python3.9/site-packages/distributed/comm/tcp.py", line 205, in read
    frames_nbytes = await stream.read_bytes(fmt_size)
asyncio.exceptions.CancelledError

During handling of the above exception, another exception occurred:

Traceback (most recent call last):
  File "/ccc/work/cont003/gen2224/gen2224/spack/var/spack/environments/gysela-deisa-irene-skl-draft/.spack-env/._view/whcr3wyhzgorszy3rfxsphyebtvfpqzk/lib/python3.9/asyncio/tasks.py", line 490, in wait_for
    return fut.result()
asyncio.exceptions.CancelledError

The above exception was the direct cause of the following exception:

Traceback (most recent call last):
  File "/ccc/work/cont003/gen2224/gen2224/spack/var/spack/environments/gysela-deisa-irene-skl-draft/.spack-env/view/lib/python3.9/site-packages/distributed/comm/core.py", line 319, in connect
    handshake = await asyncio.wait_for(comm.read(), time_left())
  File "/ccc/work/cont003/gen2224/gen2224/spack/var/spack/environments/gysela-deisa-irene-skl-draft/.spack-env/._view/whcr3wyhzgorszy3rfxsphyebtvfpqzk/lib/python3.9/asyncio/tasks.py", line 492, in wait_for
    raise exceptions.TimeoutError() from exc
asyncio.exceptions.TimeoutError

The above exception was the direct cause of the following exception:

Traceback (most recent call last):
  File "/ccc/work/cont003/gen2224/gen2224/spack/var/spack/environments/gysela-deisa-irene-skl-draft/.spack-env/view/lib/python3.9/site-packages/distributed/worker.py", line 2878, in gather_dep
    response = await get_data_from_worker(
  File "/ccc/work/cont003/gen2224/gen2224/spack/var/spack/environments/gysela-deisa-irene-skl-draft/.spack-env/view/lib/python3.9/site-packages/distributed/worker.py", line 4143, in get_data_from_worker
    return await retry_operation(_get_data, operation="get_data_from_worker")
  File "/ccc/work/cont003/gen2224/gen2224/spack/var/spack/environments/gysela-deisa-irene-skl-draft/.spack-env/view/lib/python3.9/site-packages/distributed/utils_comm.py", line 366, in retry_operation
    return await retry(
  File "/ccc/work/cont003/gen2224/gen2224/spack/var/spack/environments/gysela-deisa-irene-skl-draft/.spack-env/view/lib/python3.9/site-packages/distributed/utils_comm.py", line 351, in retry
    return await coro()
  File "/ccc/work/cont003/gen2224/gen2224/spack/var/spack/environments/gysela-deisa-irene-skl-draft/.spack-env/view/lib/python3.9/site-packages/distributed/worker.py", line 4120, in _get_data
    comm = await rpc.connect(worker)
  File "/ccc/work/cont003/gen2224/gen2224/spack/var/spack/environments/gysela-deisa-irene-skl-draft/.spack-env/view/lib/python3.9/site-packages/distributed/core.py", line 1081, in connect
    raise exc
  File "/ccc/work/cont003/gen2224/gen2224/spack/var/spack/environments/gysela-deisa-irene-skl-draft/.spack-env/view/lib/python3.9/site-packages/distributed/core.py", line 1065, in connect
    comm = await fut
  File "/ccc/work/cont003/gen2224/gen2224/spack/var/spack/environments/gysela-deisa-irene-skl-draft/.spack-env/view/lib/python3.9/site-packages/distributed/comm/core.py", line 324, in connect
    raise OSError(
OSError: Timed out during handshake while connecting to tcp://172.21.7.176:37112 after 30 s
distributed.core - INFO - Event loop was unresponsive in Worker for 3.32s.  This is often caused by long-running GIL-holding functions or moving large chunks of data. This can cause timeouts and instability.
distributed.worker - ERROR - Worker stream died during communication: tcp://172.21.9.92:42945
Traceback (most recent call last):
  File "/ccc/work/cont003/gen2224/gen2224/spack/var/spack/environments/gysela-deisa-irene-skl-draft/.spack-env/view/lib/python3.9/site-packages/distributed/comm/tcp.py", line 205, in read
    frames_nbytes = await stream.read_bytes(fmt_size)
asyncio.exceptions.CancelledError

During handling of the above exception, another exception occurred:

Traceback (most recent call last):
  File "/ccc/work/cont003/gen2224/gen2224/spack/var/spack/environments/gysela-deisa-irene-skl-draft/.spack-env/._view/whcr3wyhzgorszy3rfxsphyebtvfpqzk/lib/python3.9/asyncio/tasks.py", line 490, in wait_for
    return fut.result()
asyncio.exceptions.CancelledError

The above exception was the direct cause of the following exception:

Traceback (most recent call last):
  File "/ccc/work/cont003/gen2224/gen2224/spack/var/spack/environments/gysela-deisa-irene-skl-draft/.spack-env/view/lib/python3.9/site-packages/distributed/comm/core.py", line 319, in connect
    handshake = await asyncio.wait_for(comm.read(), time_left())
  File "/ccc/work/cont003/gen2224/gen2224/spack/var/spack/environments/gysela-deisa-irene-skl-draft/.spack-env/._view/whcr3wyhzgorszy3rfxsphyebtvfpqzk/lib/python3.9/asyncio/tasks.py", line 492, in wait_for
    raise exceptions.TimeoutError() from exc
asyncio.exceptions.TimeoutError

The above exception was the direct cause of the following exception:

Traceback (most recent call last):
  File "/ccc/work/cont003/gen2224/gen2224/spack/var/spack/environments/gysela-deisa-irene-skl-draft/.spack-env/view/lib/python3.9/site-packages/distributed/worker.py", line 2878, in gather_dep
    response = await get_data_from_worker(
  File "/ccc/work/cont003/gen2224/gen2224/spack/var/spack/environments/gysela-deisa-irene-skl-draft/.spack-env/view/lib/python3.9/site-packages/distributed/worker.py", line 4143, in get_data_from_worker
    return await retry_operation(_get_data, operation="get_data_from_worker")
  File "/ccc/work/cont003/gen2224/gen2224/spack/var/spack/environments/gysela-deisa-irene-skl-draft/.spack-env/view/lib/python3.9/site-packages/distributed/utils_comm.py", line 366, in retry_operation
    return await retry(
  File "/ccc/work/cont003/gen2224/gen2224/spack/var/spack/environments/gysela-deisa-irene-skl-draft/.spack-env/view/lib/python3.9/site-packages/distributed/utils_comm.py", line 351, in retry
    return await coro()
  File "/ccc/work/cont003/gen2224/gen2224/spack/var/spack/environments/gysela-deisa-irene-skl-draft/.spack-env/view/lib/python3.9/site-packages/distributed/worker.py", line 4120, in _get_data
    comm = await rpc.connect(worker)
  File "/ccc/work/cont003/gen2224/gen2224/spack/var/spack/environments/gysela-deisa-irene-skl-draft/.spack-env/view/lib/python3.9/site-packages/distributed/core.py", line 1081, in connect
    raise exc
  File "/ccc/work/cont003/gen2224/gen2224/spack/var/spack/environments/gysela-deisa-irene-skl-draft/.spack-env/view/lib/python3.9/site-packages/distributed/core.py", line 1065, in connect
    comm = await fut
  File "/ccc/work/cont003/gen2224/gen2224/spack/var/spack/environments/gysela-deisa-irene-skl-draft/.spack-env/view/lib/python3.9/site-packages/distributed/comm/core.py", line 324, in connect
    raise OSError(
OSError: Timed out during handshake while connecting to tcp://172.21.9.92:42945 after 30 s
distributed.worker - ERROR - Worker stream died during communication: tcp://172.21.9.92:42945
Traceback (most recent call last):
  File "/ccc/work/cont003/gen2224/gen2224/spack/var/spack/environments/gysela-deisa-irene-skl-draft/.spack-env/view/lib/python3.9/site-packages/distributed/comm/tcp.py", line 205, in read
    frames_nbytes = await stream.read_bytes(fmt_size)
asyncio.exceptions.CancelledError

During handling of the above exception, another exception occurred:

Traceback (most recent call last):
  File "/ccc/work/cont003/gen2224/gen2224/spack/var/spack/environments/gysela-deisa-irene-skl-draft/.spack-env/._view/whcr3wyhzgorszy3rfxsphyebtvfpqzk/lib/python3.9/asyncio/tasks.py", line 490, in wait_for
    return fut.result()
asyncio.exceptions.CancelledError

The above exception was the direct cause of the following exception:

Traceback (most recent call last):
  File "/ccc/work/cont003/gen2224/gen2224/spack/var/spack/environments/gysela-deisa-irene-skl-draft/.spack-env/view/lib/python3.9/site-packages/distributed/comm/core.py", line 319, in connect
    handshake = await asyncio.wait_for(comm.read(), time_left())
  File "/ccc/work/cont003/gen2224/gen2224/spack/var/spack/environments/gysela-deisa-irene-skl-draft/.spack-env/._view/whcr3wyhzgorszy3rfxsphyebtvfpqzk/lib/python3.9/asyncio/tasks.py", line 492, in wait_for
    raise exceptions.TimeoutError() from exc
asyncio.exceptions.TimeoutError

The above exception was the direct cause of the following exception:

Traceback (most recent call last):
  File "/ccc/work/cont003/gen2224/gen2224/spack/var/spack/environments/gysela-deisa-irene-skl-draft/.spack-env/view/lib/python3.9/site-packages/distributed/worker.py", line 2878, in gather_dep
    response = await get_data_from_worker(
  File "/ccc/work/cont003/gen2224/gen2224/spack/var/spack/environments/gysela-deisa-irene-skl-draft/.spack-env/view/lib/python3.9/site-packages/distributed/worker.py", line 4143, in get_data_from_worker
    return await retry_operation(_get_data, operation="get_data_from_worker")
  File "/ccc/work/cont003/gen2224/gen2224/spack/var/spack/environments/gysela-deisa-irene-skl-draft/.spack-env/view/lib/python3.9/site-packages/distributed/utils_comm.py", line 366, in retry_operation
    return await retry(
  File "/ccc/work/cont003/gen2224/gen2224/spack/var/spack/environments/gysela-deisa-irene-skl-draft/.spack-env/view/lib/python3.9/site-packages/distributed/utils_comm.py", line 351, in retry
    return await coro()
  File "/ccc/work/cont003/gen2224/gen2224/spack/var/spack/environments/gysela-deisa-irene-skl-draft/.spack-env/view/lib/python3.9/site-packages/distributed/worker.py", line 4120, in _get_data
    comm = await rpc.connect(worker)
  File "/ccc/work/cont003/gen2224/gen2224/spack/var/spack/environments/gysela-deisa-irene-skl-draft/.spack-env/view/lib/python3.9/site-packages/distributed/core.py", line 1081, in connect
    raise exc
  File "/ccc/work/cont003/gen2224/gen2224/spack/var/spack/environments/gysela-deisa-irene-skl-draft/.spack-env/view/lib/python3.9/site-packages/distributed/core.py", line 1065, in connect
    comm = await fut
  File "/ccc/work/cont003/gen2224/gen2224/spack/var/spack/environments/gysela-deisa-irene-skl-draft/.spack-env/view/lib/python3.9/site-packages/distributed/comm/core.py", line 324, in connect
    raise OSError(
OSError: Timed out during handshake while connecting to tcp://172.21.9.92:42945 after 30 s
distributed.worker - ERROR - Worker stream died during communication: tcp://172.21.9.92:42945
Traceback (most recent call last):
  File "/ccc/work/cont003/gen2224/gen2224/spack/var/spack/environments/gysela-deisa-irene-skl-draft/.spack-env/view/lib/python3.9/site-packages/distributed/comm/tcp.py", line 205, in read
    frames_nbytes = await stream.read_bytes(fmt_size)
asyncio.exceptions.CancelledError

During handling of the above exception, another exception occurred:

Traceback (most recent call last):
  File "/ccc/work/cont003/gen2224/gen2224/spack/var/spack/environments/gysela-deisa-irene-skl-draft/.spack-env/._view/whcr3wyhzgorszy3rfxsphyebtvfpqzk/lib/python3.9/asyncio/tasks.py", line 490, in wait_for
    return fut.result()
asyncio.exceptions.CancelledError

The above exception was the direct cause of the following exception:

Traceback (most recent call last):
  File "/ccc/work/cont003/gen2224/gen2224/spack/var/spack/environments/gysela-deisa-irene-skl-draft/.spack-env/view/lib/python3.9/site-packages/distributed/comm/core.py", line 319, in connect
    handshake = await asyncio.wait_for(comm.read(), time_left())
  File "/ccc/work/cont003/gen2224/gen2224/spack/var/spack/environments/gysela-deisa-irene-skl-draft/.spack-env/._view/whcr3wyhzgorszy3rfxsphyebtvfpqzk/lib/python3.9/asyncio/tasks.py", line 492, in wait_for
    raise exceptions.TimeoutError() from exc
asyncio.exceptions.TimeoutError

The above exception was the direct cause of the following exception:

Traceback (most recent call last):
  File "/ccc/work/cont003/gen2224/gen2224/spack/var/spack/environments/gysela-deisa-irene-skl-draft/.spack-env/view/lib/python3.9/site-packages/distributed/worker.py", line 2878, in gather_dep
    response = await get_data_from_worker(
  File "/ccc/work/cont003/gen2224/gen2224/spack/var/spack/environments/gysela-deisa-irene-skl-draft/.spack-env/view/lib/python3.9/site-packages/distributed/worker.py", line 4143, in get_data_from_worker
    return await retry_operation(_get_data, operation="get_data_from_worker")
  File "/ccc/work/cont003/gen2224/gen2224/spack/var/spack/environments/gysela-deisa-irene-skl-draft/.spack-env/view/lib/python3.9/site-packages/distributed/utils_comm.py", line 366, in retry_operation
    return await retry(
  File "/ccc/work/cont003/gen2224/gen2224/spack/var/spack/environments/gysela-deisa-irene-skl-draft/.spack-env/view/lib/python3.9/site-packages/distributed/utils_comm.py", line 351, in retry
    return await coro()
  File "/ccc/work/cont003/gen2224/gen2224/spack/var/spack/environments/gysela-deisa-irene-skl-draft/.spack-env/view/lib/python3.9/site-packages/distributed/worker.py", line 4120, in _get_data
    comm = await rpc.connect(worker)
  File "/ccc/work/cont003/gen2224/gen2224/spack/var/spack/environments/gysela-deisa-irene-skl-draft/.spack-env/view/lib/python3.9/site-packages/distributed/core.py", line 1081, in connect
    raise exc
  File "/ccc/work/cont003/gen2224/gen2224/spack/var/spack/environments/gysela-deisa-irene-skl-draft/.spack-env/view/lib/python3.9/site-packages/distributed/core.py", line 1065, in connect
    comm = await fut
  File "/ccc/work/cont003/gen2224/gen2224/spack/var/spack/environments/gysela-deisa-irene-skl-draft/.spack-env/view/lib/python3.9/site-packages/distributed/comm/core.py", line 324, in connect
    raise OSError(
OSError: Timed out during handshake while connecting to tcp://172.21.9.92:42945 after 30 s
distributed.worker - ERROR - Worker stream died during communication: tcp://172.21.9.92:42945
Traceback (most recent call last):
  File "/ccc/work/cont003/gen2224/gen2224/spack/var/spack/environments/gysela-deisa-irene-skl-draft/.spack-env/view/lib/python3.9/site-packages/distributed/comm/tcp.py", line 205, in read
    frames_nbytes = await stream.read_bytes(fmt_size)
asyncio.exceptions.CancelledError

During handling of the above exception, another exception occurred:

Traceback (most recent call last):
  File "/ccc/work/cont003/gen2224/gen2224/spack/var/spack/environments/gysela-deisa-irene-skl-draft/.spack-env/._view/whcr3wyhzgorszy3rfxsphyebtvfpqzk/lib/python3.9/asyncio/tasks.py", line 490, in wait_for
    return fut.result()
asyncio.exceptions.CancelledError

The above exception was the direct cause of the following exception:

Traceback (most recent call last):
distributed.worker - ERROR - Worker stream died during communication: tcp://172.21.9.92:42945
Traceback (most recent call last):
  File "/ccc/work/cont003/gen2224/gen2224/spack/var/spack/environments/gysela-deisa-irene-skl-draft/.spack-env/view/lib/python3.9/site-packages/distributed/comm/tcp.py", line 205, in read
    frames_nbytes = await stream.read_bytes(fmt_size)
asyncio.exceptions.CancelledError

During handling of the above exception, another exception occurred:

Traceback (most recent call last):
  File "/ccc/work/cont003/gen2224/gen2224/spack/var/spack/environments/gysela-deisa-irene-skl-draft/.spack-env/._view/whcr3wyhzgorszy3rfxsphyebtvfpqzk/lib/python3.9/asyncio/tasks.py", line 490, in wait_for
    return fut.result()
asyncio.exceptions.CancelledError

The above exception was the direct cause of the following exception:

Traceback (most recent call last):
  File "/ccc/work/cont003/gen2224/gen2224/spack/var/spack/environments/gysela-deisa-irene-skl-draft/.spack-env/view/lib/python3.9/site-packages/distributed/comm/core.py", line 319, in connect
    handshake = await asyncio.wait_for(comm.read(), time_left())
  File "/ccc/work/cont003/gen2224/gen2224/spack/var/spack/environments/gysela-deisa-irene-skl-draft/.spack-env/._view/whcr3wyhzgorszy3rfxsphyebtvfpqzk/lib/python3.9/asyncio/tasks.py", line 492, in wait_for
    raise exceptions.TimeoutError() from exc
asyncio.exceptions.TimeoutError

The above exception was the direct cause of the following exception:

Traceback (most recent call last):
  File "/ccc/work/cont003/gen2224/gen2224/spack/var/spack/environments/gysela-deisa-irene-skl-draft/.spack-env/view/lib/python3.9/site-packages/distributed/worker.py", line 2878, in gather_dep
    response = await get_data_from_worker(
  File "/ccc/work/cont003/gen2224/gen2224/spack/var/spack/environments/gysela-deisa-irene-skl-draft/.spack-env/view/lib/python3.9/site-packages/distributed/comm/core.py", line 319, in connect
    handshake = await asyncio.wait_for(comm.read(), time_left())
  File "/ccc/work/cont003/gen2224/gen2224/spack/var/spack/environments/gysela-deisa-irene-skl-draft/.spack-env/._view/whcr3wyhzgorszy3rfxsphyebtvfpqzk/lib/python3.9/asyncio/tasks.py", line 492, in wait_for
    raise exceptions.TimeoutError() from exc
asyncio.exceptions.TimeoutError

The above exception was the direct cause of the following exception:

Traceback (most recent call last):
  File "/ccc/work/cont003/gen2224/gen2224/spack/var/spack/environments/gysela-deisa-irene-skl-draft/.spack-env/view/lib/python3.9/site-packages/distributed/worker.py", line 2878, in gather_dep
    response = await get_data_from_worker(
  File "/ccc/work/cont003/gen2224/gen2224/spack/var/spack/environments/gysela-deisa-irene-skl-draft/.spack-env/view/lib/python3.9/site-packages/distributed/worker.py", line 4143, in get_data_from_worker
    return await retry_operation(_get_data, operation="get_data_from_worker")
  File "/ccc/work/cont003/gen2224/gen2224/spack/var/spack/environments/gysela-deisa-irene-skl-draft/.spack-env/view/lib/python3.9/site-packages/distributed/utils_comm.py", line 366, in retry_operation
    return await retry(
  File "/ccc/work/cont003/gen2224/gen2224/spack/var/spack/environments/gysela-deisa-irene-skl-draft/.spack-env/view/lib/python3.9/site-packages/distributed/utils_comm.py", line 351, in retry
    return await coro()
  File "/ccc/work/cont003/gen2224/gen2224/spack/var/spack/environments/gysela-deisa-irene-skl-draft/.spack-env/view/lib/python3.9/site-packages/distributed/worker.py", line 4120, in _get_data
    comm = await rpc.connect(worker)
  File "/ccc/work/cont003/gen2224/gen2224/spack/var/spack/environments/gysela-deisa-irene-skl-draft/.spack-env/view/lib/python3.9/site-packages/distributed/worker.py", line 4143, in get_data_from_worker
    return await retry_operation(_get_data, operation="get_data_from_worker")
  File "/ccc/work/cont003/gen2224/gen2224/spack/var/spack/environments/gysela-deisa-irene-skl-draft/.spack-env/view/lib/python3.9/site-packages/distributed/utils_comm.py", line 366, in retry_operation
    return await retry(
  File "/ccc/work/cont003/gen2224/gen2224/spack/var/spack/environments/gysela-deisa-irene-skl-draft/.spack-env/view/lib/python3.9/site-packages/distributed/utils_comm.py", line 351, in retry
    return await coro()
  File "/ccc/work/cont003/gen2224/gen2224/spack/var/spack/environments/gysela-deisa-irene-skl-draft/.spack-env/view/lib/python3.9/site-packages/distributed/worker.py", line 4120, in _get_data
    comm = await rpc.connect(worker)
  File "/ccc/work/cont003/gen2224/gen2224/spack/var/spack/environments/gysela-deisa-irene-skl-draft/.spack-env/view/lib/python3.9/site-packages/distributed/core.py", line 1081, in connect
    raise exc
  File "/ccc/work/cont003/gen2224/gen2224/spack/var/spack/environments/gysela-deisa-irene-skl-draft/.spack-env/view/lib/python3.9/site-packages/distributed/core.py", line 1065, in connect
    comm = await fut
  File "/ccc/work/cont003/gen2224/gen2224/spack/var/spack/environments/gysela-deisa-irene-skl-draft/.spack-env/view/lib/python3.9/site-packages/distributed/comm/core.py", line 324, in connect
    raise OSError(
OSError: Timed out during handshake while connecting to tcp://172.21.9.92:42945 after 30 s
  File "/ccc/work/cont003/gen2224/gen2224/spack/var/spack/environments/gysela-deisa-irene-skl-draft/.spack-env/view/lib/python3.9/site-packages/distributed/core.py", line 1081, in connect
    raise exc
  File "/ccc/work/cont003/gen2224/gen2224/spack/var/spack/environments/gysela-deisa-irene-skl-draft/.spack-env/view/lib/python3.9/site-packages/distributed/core.py", line 1065, in connect
    comm = await fut
  File "/ccc/work/cont003/gen2224/gen2224/spack/var/spack/environments/gysela-deisa-irene-skl-draft/.spack-env/view/lib/python3.9/site-packages/distributed/comm/core.py", line 324, in connect
    raise OSError(
OSError: Timed out during handshake while connecting to tcp://172.21.9.92:42945 after 30 s
distributed.worker - ERROR - Worker stream died during communication: tcp://172.21.9.92:42945
Traceback (most recent call last):
  File "/ccc/work/cont003/gen2224/gen2224/spack/var/spack/environments/gysela-deisa-irene-skl-draft/.spack-env/view/lib/python3.9/site-packages/distributed/comm/tcp.py", line 205, in read
    frames_nbytes = await stream.read_bytes(fmt_size)
asyncio.exceptions.CancelledError

During handling of the above exception, another exception occurred:

Traceback (most recent call last):
  File "/ccc/work/cont003/gen2224/gen2224/spack/var/spack/environments/gysela-deisa-irene-skl-draft/.spack-env/._view/whcr3wyhzgorszy3rfxsphyebtvfpqzk/lib/python3.9/asyncio/tasks.py", line 490, in wait_for
    return fut.result()
asyncio.exceptions.CancelledError

The above exception was the direct cause of the following exception:

Traceback (most recent call last):
distributed.worker - ERROR - Worker stream died during communication: tcp://172.21.9.92:42945
Traceback (most recent call last):
  File "/ccc/work/cont003/gen2224/gen2224/spack/var/spack/environments/gysela-deisa-irene-skl-draft/.spack-env/view/lib/python3.9/site-packages/distributed/comm/tcp.py", line 205, in read
    frames_nbytes = await stream.read_bytes(fmt_size)
asyncio.exceptions.CancelledError

During handling of the above exception, another exception occurred:

Traceback (most recent call last):
  File "/ccc/work/cont003/gen2224/gen2224/spack/var/spack/environments/gysela-deisa-irene-skl-draft/.spack-env/._view/whcr3wyhzgorszy3rfxsphyebtvfpqzk/lib/python3.9/asyncio/tasks.py", line 490, in wait_for
    return fut.result()
asyncio.exceptions.CancelledError

The above exception was the direct cause of the following exception:

Traceback (most recent call last):
  File "/ccc/work/cont003/gen2224/gen2224/spack/var/spack/environments/gysela-deisa-irene-skl-draft/.spack-env/view/lib/python3.9/site-packages/distributed/comm/core.py", line 319, in connect
    handshake = await asyncio.wait_for(comm.read(), time_left())
  File "/ccc/work/cont003/gen2224/gen2224/spack/var/spack/environments/gysela-deisa-irene-skl-draft/.spack-env/._view/whcr3wyhzgorszy3rfxsphyebtvfpqzk/lib/python3.9/asyncio/tasks.py", line 492, in wait_for
    raise exceptions.TimeoutError() from exc
asyncio.exceptions.TimeoutError

The above exception was the direct cause of the following exception:

Traceback (most recent call last):
  File "/ccc/work/cont003/gen2224/gen2224/spack/var/spack/environments/gysela-deisa-irene-skl-draft/.spack-env/view/lib/python3.9/site-packages/distributed/worker.py", line 2878, in gather_dep
    response = await get_data_from_worker(
  File "/ccc/work/cont003/gen2224/gen2224/spack/var/spack/environments/gysela-deisa-irene-skl-draft/.spack-env/view/lib/python3.9/site-packages/distributed/worker.py", line 4143, in get_data_from_worker
    return await retry_operation(_get_data, operation="get_data_from_worker")
  File "/ccc/work/cont003/gen2224/gen2224/spack/var/spack/environments/gysela-deisa-irene-skl-draft/.spack-env/view/lib/python3.9/site-packages/distributed/utils_comm.py", line 366, in retry_operation
    return await retry(
  File "/ccc/work/cont003/gen2224/gen2224/spack/var/spack/environments/gysela-deisa-irene-skl-draft/.spack-env/view/lib/python3.9/site-packages/distributed/utils_comm.py", line 351, in retry
    return await coro()
  File "/ccc/work/cont003/gen2224/gen2224/spack/var/spack/environments/gysela-deisa-irene-skl-draft/.spack-env/view/lib/python3.9/site-packages/distributed/worker.py", line 4120, in _get_data
    comm = await rpc.connect(worker)
  File "/ccc/work/cont003/gen2224/gen2224/spack/var/spack/environments/gysela-deisa-irene-skl-draft/.spack-env/view/lib/python3.9/site-packages/distributed/comm/core.py", line 319, in connect
    handshake = await asyncio.wait_for(comm.read(), time_left())
  File "/ccc/work/cont003/gen2224/gen2224/spack/var/spack/environments/gysela-deisa-irene-skl-draft/.spack-env/._view/whcr3wyhzgorszy3rfxsphyebtvfpqzk/lib/python3.9/asyncio/tasks.py", line 492, in wait_for
    raise exceptions.TimeoutError() from exc
asyncio.exceptions.TimeoutError

The above exception was the direct cause of the following exception:

Traceback (most recent call last):
  File "/ccc/work/cont003/gen2224/gen2224/spack/var/spack/environments/gysela-deisa-irene-skl-draft/.spack-env/view/lib/python3.9/site-packages/distributed/worker.py", line 2878, in gather_dep
    response = await get_data_from_worker(
  File "/ccc/work/cont003/gen2224/gen2224/spack/var/spack/environments/gysela-deisa-irene-skl-draft/.spack-env/view/lib/python3.9/site-packages/distributed/core.py", line 1081, in connect
    raise exc
  File "/ccc/work/cont003/gen2224/gen2224/spack/var/spack/environments/gysela-deisa-irene-skl-draft/.spack-env/view/lib/python3.9/site-packages/distributed/core.py", line 1065, in connect
    comm = await fut
  File "/ccc/work/cont003/gen2224/gen2224/spack/var/spack/environments/gysela-deisa-irene-skl-draft/.spack-env/view/lib/python3.9/site-packages/distributed/comm/core.py", line 324, in connect
    raise OSError(
OSError: Timed out during handshake while connecting to tcp://172.21.9.92:42945 after 30 s
  File "/ccc/work/cont003/gen2224/gen2224/spack/var/spack/environments/gysela-deisa-irene-skl-draft/.spack-env/view/lib/python3.9/site-packages/distributed/worker.py", line 4143, in get_data_from_worker
    return await retry_operation(_get_data, operation="get_data_from_worker")
  File "/ccc/work/cont003/gen2224/gen2224/spack/var/spack/environments/gysela-deisa-irene-skl-draft/.spack-env/view/lib/python3.9/site-packages/distributed/utils_comm.py", line 366, in retry_operation
    return await retry(
  File "/ccc/work/cont003/gen2224/gen2224/spack/var/spack/environments/gysela-deisa-irene-skl-draft/.spack-env/view/lib/python3.9/site-packages/distributed/utils_comm.py", line 351, in retry
    return await coro()
  File "/ccc/work/cont003/gen2224/gen2224/spack/var/spack/environments/gysela-deisa-irene-skl-draft/.spack-env/view/lib/python3.9/site-packages/distributed/worker.py", line 4120, in _get_data
    comm = await rpc.connect(worker)
  File "/ccc/work/cont003/gen2224/gen2224/spack/var/spack/environments/gysela-deisa-irene-skl-draft/.spack-env/view/lib/python3.9/site-packages/distributed/core.py", line 1081, in connect
    raise exc
  File "/ccc/work/cont003/gen2224/gen2224/spack/var/spack/environments/gysela-deisa-irene-skl-draft/.spack-env/view/lib/python3.9/site-packages/distributed/core.py", line 1065, in connect
    comm = await fut
  File "/ccc/work/cont003/gen2224/gen2224/spack/var/spack/environments/gysela-deisa-irene-skl-draft/.spack-env/view/lib/python3.9/site-packages/distributed/comm/core.py", line 324, in connect
    raise OSError(
OSError: Timed out during handshake while connecting to tcp://172.21.9.92:42945 after 30 s
distributed.worker - ERROR - Worker stream died during communication: tcp://172.21.9.92:42945
Traceback (most recent call last):
  File "/ccc/work/cont003/gen2224/gen2224/spack/var/spack/environments/gysela-deisa-irene-skl-draft/.spack-env/view/lib/python3.9/site-packages/distributed/comm/tcp.py", line 205, in read
    frames_nbytes = await stream.read_bytes(fmt_size)
asyncio.exceptions.CancelledError

During handling of the above exception, another exception occurred:

Traceback (most recent call last):
  File "/ccc/work/cont003/gen2224/gen2224/spack/var/spack/environments/gysela-deisa-irene-skl-draft/.spack-env/._view/whcr3wyhzgorszy3rfxsphyebtvfpqzk/lib/python3.9/asyncio/tasks.py", line 490, in wait_for
    return fut.result()
asyncio.exceptions.CancelledError

The above exception was the direct cause of the following exception:

Traceback (most recent call last):
  File "/ccc/work/cont003/gen2224/gen2224/spack/var/spack/environments/gysela-deisa-irene-skl-draft/.spack-env/view/lib/python3.9/site-packages/distributed/comm/core.py", line 319, in connect
    handshake = await asyncio.wait_for(comm.read(), time_left())
  File "/ccc/work/cont003/gen2224/gen2224/spack/var/spack/environments/gysela-deisa-irene-skl-draft/.spack-env/._view/whcr3wyhzgorszy3rfxsphyebtvfpqzk/lib/python3.9/asyncio/tasks.py", line 492, in wait_for
    raise exceptions.TimeoutError() from exc
asyncio.exceptions.TimeoutError

The above exception was the direct cause of the following exception:

Traceback (most recent call last):
  File "/ccc/work/cont003/gen2224/gen2224/spack/var/spack/environments/gysela-deisa-irene-skl-draft/.spack-env/view/lib/python3.9/site-packages/distributed/worker.py", line 2878, in gather_dep
    response = await get_data_from_worker(
  File "/ccc/work/cont003/gen2224/gen2224/spack/var/spack/environments/gysela-deisa-irene-skl-draft/.spack-env/view/lib/python3.9/site-packages/distributed/worker.py", line 4143, in get_data_from_worker
    return await retry_operation(_get_data, operation="get_data_from_worker")
  File "/ccc/work/cont003/gen2224/gen2224/spack/var/spack/environments/gysela-deisa-irene-skl-draft/.spack-env/view/lib/python3.9/site-packages/distributed/utils_comm.py", line 366, in retry_operation
    return await retry(
  File "/ccc/work/cont003/gen2224/gen2224/spack/var/spack/environments/gysela-deisa-irene-skl-draft/.spack-env/view/lib/python3.9/site-packages/distributed/utils_comm.py", line 351, in retry
    return await coro()
  File "/ccc/work/cont003/gen2224/gen2224/spack/var/spack/environments/gysela-deisa-irene-skl-draft/.spack-env/view/lib/python3.9/site-packages/distributed/worker.py", line 4120, in _get_data
    comm = await rpc.connect(worker)
  File "/ccc/work/cont003/gen2224/gen2224/spack/var/spack/environments/gysela-deisa-irene-skl-draft/.spack-env/view/lib/python3.9/site-packages/distributed/core.py", line 1081, in connect
    raise exc
  File "/ccc/work/cont003/gen2224/gen2224/spack/var/spack/environments/gysela-deisa-irene-skl-draft/.spack-env/view/lib/python3.9/site-packages/distributed/core.py", line 1065, in connect
    comm = await fut
  File "/ccc/work/cont003/gen2224/gen2224/spack/var/spack/environments/gysela-deisa-irene-skl-draft/.spack-env/view/lib/python3.9/site-packages/distributed/comm/core.py", line 324, in connect
    raise OSError(
OSError: Timed out during handshake while connecting to tcp://172.21.9.92:42945 after 30 s
distributed.worker - ERROR - Worker stream died during communication: tcp://172.21.9.92:42945
Traceback (most recent call last):
  File "/ccc/work/cont003/gen2224/gen2224/spack/var/spack/environments/gysela-deisa-irene-skl-draft/.spack-env/view/lib/python3.9/site-packages/distributed/comm/tcp.py", line 205, in read
    frames_nbytes = await stream.read_bytes(fmt_size)
asyncio.exceptions.CancelledError

During handling of the above exception, another exception occurred:

Traceback (most recent call last):
  File "/ccc/work/cont003/gen2224/gen2224/spack/var/spack/environments/gysela-deisa-irene-skl-draft/.spack-env/._view/whcr3wyhzgorszy3rfxsphyebtvfpqzk/lib/python3.9/asyncio/tasks.py", line 490, in wait_for
    return fut.result()
asyncio.exceptions.CancelledError

The above exception was the direct cause of the following exception:

Traceback (most recent call last):
  File "/ccc/work/cont003/gen2224/gen2224/spack/var/spack/environments/gysela-deisa-irene-skl-draft/.spack-env/view/lib/python3.9/site-packages/distributed/comm/core.py", line 319, in connect
    handshake = await asyncio.wait_for(comm.read(), time_left())
  File "/ccc/work/cont003/gen2224/gen2224/spack/var/spack/environments/gysela-deisa-irene-skl-draft/.spack-env/._view/whcr3wyhzgorszy3rfxsphyebtvfpqzk/lib/python3.9/asyncio/tasks.py", line 492, in wait_for
    raise exceptions.TimeoutError() from exc
asyncio.exceptions.TimeoutError

The above exception was the direct cause of the following exception:

Traceback (most recent call last):
  File "/ccc/work/cont003/gen2224/gen2224/spack/var/spack/environments/gysela-deisa-irene-skl-draft/.spack-env/view/lib/python3.9/site-packages/distributed/worker.py", line 2878, in gather_dep
    response = await get_data_from_worker(
  File "/ccc/work/cont003/gen2224/gen2224/spack/var/spack/environments/gysela-deisa-irene-skl-draft/.spack-env/view/lib/python3.9/site-packages/distributed/worker.py", line 4143, in get_data_from_worker
    return await retry_operation(_get_data, operation="get_data_from_worker")
  File "/ccc/work/cont003/gen2224/gen2224/spack/var/spack/environments/gysela-deisa-irene-skl-draft/.spack-env/view/lib/python3.9/site-packages/distributed/utils_comm.py", line 366, in retry_operation
    return await retry(
  File "/ccc/work/cont003/gen2224/gen2224/spack/var/spack/environments/gysela-deisa-irene-skl-draft/.spack-env/view/lib/python3.9/site-packages/distributed/utils_comm.py", line 351, in retry
    return await coro()
  File "/ccc/work/cont003/gen2224/gen2224/spack/var/spack/environments/gysela-deisa-irene-skl-draft/.spack-env/view/lib/python3.9/site-packages/distributed/worker.py", line 4120, in _get_data
    comm = await rpc.connect(worker)
  File "/ccc/work/cont003/gen2224/gen2224/spack/var/spack/environments/gysela-deisa-irene-skl-draft/.spack-env/view/lib/python3.9/site-packages/distributed/core.py", line 1081, in connect
    raise exc
  File "/ccc/work/cont003/gen2224/gen2224/spack/var/spack/environments/gysela-deisa-irene-skl-draft/.spack-env/view/lib/python3.9/site-packages/distributed/core.py", line 1065, in connect
    comm = await fut
  File "/ccc/work/cont003/gen2224/gen2224/spack/var/spack/environments/gysela-deisa-irene-skl-draft/.spack-env/view/lib/python3.9/site-packages/distributed/comm/core.py", line 324, in connect
    raise OSError(
OSError: Timed out during handshake while connecting to tcp://172.21.9.92:42945 after 30 s
distributed.core - INFO - Event loop was unresponsive in Worker for 33.81s.  This is often caused by long-running GIL-holding functions or moving large chunks of data. This can cause timeouts and instability.
distributed.comm.tcp - INFO - Connection from tcp://172.21.9.93:39968 closed before handshake completed
distributed.comm.tcp - INFO - Connection from tcp://172.21.9.76:55354 closed before handshake completed
distributed.comm.tcp - INFO - Connection from tcp://172.21.7.169:40914 closed before handshake completed
distributed.comm.tcp - INFO - Connection from tcp://172.21.9.93:39970 closed before handshake completed
distributed.comm.tcp - INFO - Connection from tcp://172.21.7.52:32922 closed before handshake completed
distributed.comm.tcp - INFO - Connection from tcp://172.21.7.100:47114 closed before handshake completed
distributed.comm.tcp - INFO - Connection from tcp://172.21.9.76:55356 closed before handshake completed
distributed.comm.tcp - INFO - Connection from tcp://172.21.7.52:32924 closed before handshake completed
distributed.comm.tcp - INFO - Connection from tcp://172.21.7.100:47116 closed before handshake completed
distributed.comm.tcp - INFO - Connection from tcp://172.21.0.191:39596 closed before handshake completed
distributed.comm.tcp - INFO - Connection from tcp://172.21.0.191:39628 closed before handshake completed
distributed.core - INFO - Event loop was unresponsive in Worker for 74.32s.  This is often caused by long-running GIL-holding functions or moving large chunks of data. This can cause timeouts and instability.
distributed.comm.tcp - INFO - Connection from tcp://172.21.7.100:58854 closed before handshake completed
distributed.comm.tcp - INFO - Connection from tcp://172.21.7.169:47734 closed before handshake completed
distributed.comm.tcp - INFO - Connection from tcp://172.21.7.52:43454 closed before handshake completed
distributed.comm.tcp - INFO - Connection from tcp://172.21.7.169:47736 closed before handshake completed
distributed.comm.tcp - INFO - Connection from tcp://172.21.9.76:33420 closed before handshake completed
distributed.comm.tcp - INFO - Connection from tcp://172.21.9.113:42994 closed before handshake completed
distributed.comm.tcp - INFO - Connection from tcp://172.21.9.76:33422 closed before handshake completed
distributed.comm.tcp - INFO - Connection from tcp://172.21.7.100:58856 closed before handshake completed
distributed.comm.tcp - INFO - Connection from tcp://172.21.9.93:44032 closed before handshake completed
distributed.comm.tcp - INFO - Connection from tcp://172.21.9.93:44034 closed before handshake completed
distributed.comm.tcp - INFO - Connection from tcp://172.21.7.52:43456 closed before handshake completed
distributed.comm.tcp - INFO - Connection from tcp://172.21.0.191:53268 closed before handshake completed
distributed.comm.tcp - INFO - Connection from tcp://172.21.0.191:53294 closed before handshake completed
slurmstepd-irene1973: error: *** STEP 8105091.1 ON irene1973 CANCELLED AT 2023-01-24T22:16:41 ***
distributed.dask_worker - INFO - Exiting on signal 15
distributed.dask_worker - INFO - Exiting on signal 15
distributed.nanny - INFO - Closing Nanny at 'tcp://172.21.7.176:33357'
distributed.nanny - INFO - Closing Nanny at 'tcp://172.21.7.176:36629'
distributed.dask_worker - INFO - Exiting on signal 15
distributed.dask_worker - INFO - Exiting on signal 15
distributed.nanny - INFO - Closing Nanny at 'tcp://172.21.7.169:35353'
distributed.nanny - INFO - Closing Nanny at 'tcp://172.21.7.169:36894'
distributed.dask_worker - INFO - Exiting on signal 15
distributed.dask_worker - INFO - Exiting on signal 15
distributed.nanny - INFO - Closing Nanny at 'tcp://172.21.7.52:35076'
distributed.nanny - INFO - Closing Nanny at 'tcp://172.21.7.52:45054'
distributed.dask_worker - INFO - Exiting on signal 15
distributed.dask_worker - INFO - Exiting on signal 15
distributed.dask_worker - INFO - Exiting on signal 15
distributed.nanny - INFO - Closing Nanny at 'tcp://172.21.9.113:34920'
distributed.dask_worker - INFO - Exiting on signal 15
distributed.nanny - INFO - Closing Nanny at 'tcp://172.21.9.113:38850'
distributed.nanny - INFO - Closing Nanny at 'tcp://172.21.9.93:40188'
distributed.nanny - INFO - Closing Nanny at 'tcp://172.21.9.93:42232'
distributed.worker - INFO - Stopping worker at tcp://172.21.7.176:37112
distributed.worker - INFO - Stopping worker at tcp://172.21.7.176:45049
distributed.worker - INFO - Stopping worker at tcp://172.21.7.52:38431
distributed.dask_worker - INFO - Exiting on signal 15
distributed.dask_worker - INFO - Exiting on signal 15
distributed.nanny - INFO - Closing Nanny at 'tcp://172.21.9.92:37434'
distributed.nanny - INFO - Closing Nanny at 'tcp://172.21.9.92:36006'
distributed.worker - INFO - Stopping worker at tcp://172.21.7.52:37647
distributed.dask_worker - INFO - Exiting on signal 15
distributed.dask_worker - INFO - Exiting on signal 15
distributed.nanny - INFO - Closing Nanny at 'tcp://172.21.7.100:34465'
distributed.nanny - INFO - Closing Nanny at 'tcp://172.21.7.100:36396'
distributed.dask_worker - INFO - Exiting on signal 15
distributed.dask_worker - INFO - Exiting on signal 15
distributed.nanny - INFO - Closing Nanny at 'tcp://172.21.9.76:36969'
distributed.nanny - INFO - Closing Nanny at 'tcp://172.21.9.76:43697'
distributed.worker - INFO - Stopping worker at tcp://172.21.9.113:38885
distributed.worker - INFO - Stopping worker at tcp://172.21.9.113:40497
distributed.worker - INFO - Stopping worker at tcp://172.21.9.93:33187
distributed.worker - INFO - Stopping worker at tcp://172.21.9.93:41946
distributed.worker - INFO - Stopping worker at tcp://172.21.9.76:33504
distributed.worker - INFO - Stopping worker at tcp://172.21.9.76:43128
distributed.worker - INFO - Stopping worker at tcp://172.21.7.100:42140
distributed.worker - INFO - Stopping worker at tcp://172.21.7.100:38272
distributed.worker - INFO - Stopping worker at tcp://172.21.7.169:41830
distributed.worker - INFO - Stopping worker at tcp://172.21.7.169:32848
distributed.worker - INFO - Stopping worker at tcp://172.21.9.92:37136
distributed.worker - INFO - Stopping worker at tcp://172.21.9.92:42945
distributed.nanny - WARNING - Worker process still alive after 1 seconds, killing
distributed.dask_worker - INFO - End worker
distributed.process - INFO - reaping stray process <SpawnProcess name='Dask Worker process (from Nanny)' pid=51390 parent=51253 started daemon>
distributed.nanny - WARNING - Worker process still alive after 1 seconds, killing
distributed.dask_worker - INFO - End worker
distributed.process - INFO - reaping stray process <SpawnProcess name='Dask Worker process (from Nanny)' pid=51389 parent=51254 started daemon>
distributed.nanny - WARNING - Worker process still alive after 1 seconds, killing
distributed.dask_worker - INFO - End worker
distributed.process - INFO - reaping stray process <SpawnProcess name='Dask Worker process (from Nanny)' pid=57787 parent=57655 started daemon>
distributed.nanny - WARNING - Worker process still alive after 1 seconds, killing
distributed.dask_worker - INFO - End worker
distributed.process - INFO - reaping stray process <SpawnProcess name='Dask Worker process (from Nanny)' pid=57786 parent=57654 started daemon>
Exception in thread AsyncProcess Dask Worker process (from Nanny) watch process join:
Traceback (most recent call last):
Exception in thread AsyncProcess Dask Worker process (from Nanny) watch process join:
Traceback (most recent call last):
Exception in thread AsyncProcess Dask Worker process (from Nanny) watch process join:
Traceback (most recent call last):
distributed.nanny - WARNING - Worker process still alive after 1 seconds, killing
distributed.nanny - WARNING - Worker process still alive after 1 seconds, killing
distributed.nanny - WARNING - Worker process still alive after 1 seconds, killing
distributed.nanny - WARNING - Worker process still alive after 1 seconds, killing
distributed.dask_worker - INFO - End worker
distributed.nanny - WARNING - Worker process still alive after 1 seconds, killing
distributed.process - INFO - reaping stray process <SpawnProcess name='Dask Worker process (from Nanny)' pid=27503 parent=27366 started daemon>
distributed.dask_worker - INFO - End worker
distributed.dask_worker - INFO - End worker
distributed.dask_worker - INFO - End worker
distributed.process - INFO - reaping stray process <SpawnProcess name='Dask Worker process (from Nanny)' pid=85175 parent=85036 started daemon>
distributed.process - INFO - reaping stray process <SpawnProcess name='Dask Worker process (from Nanny)' pid=97533 parent=97399 started daemon>
distributed.process - INFO - reaping stray process <SpawnProcess name='Dask Worker process (from Nanny)' pid=85176 parent=85037 started daemon>
distributed.dask_worker - INFO - End worker
distributed.nanny - WARNING - Worker process still alive after 1 seconds, killing
distributed.nanny - WARNING - Worker process still alive after 1 seconds, killing
distributed.process - INFO - reaping stray process <SpawnProcess name='Dask Worker process (from Nanny)' pid=27502 parent=27367 started daemon>
distributed.nanny - WARNING - Worker process still alive after 1 seconds, killing
distributed.nanny - WARNING - Worker process still alive after 1 seconds, killing
distributed.dask_worker - INFO - End worker
distributed.dask_worker - INFO - End worker
distributed.nanny - WARNING - Worker process still alive after 1 seconds, killing
distributed.process - INFO - reaping stray process <SpawnProcess name='Dask Worker process (from Nanny)' pid=10409 parent=10273 started daemon>
distributed.nanny - WARNING - Worker process still alive after 1 seconds, killing
distributed.process - INFO - reaping stray process <SpawnProcess name='Dask Worker process (from Nanny)' pid=53054 parent=52919 started daemon>
distributed.dask_worker - INFO - End worker
distributed.dask_worker - INFO - End worker
distributed.dask_worker - INFO - End worker
distributed.process - INFO - reaping stray process <SpawnProcess name='Dask Worker process (from Nanny)' pid=32844 parent=32709 started daemon>
distributed.process - INFO - reaping stray process <SpawnProcess name='Dask Worker process (from Nanny)' pid=32845 parent=32708 started daemon>
distributed.process - INFO - reaping stray process <SpawnProcess name='Dask Worker process (from Nanny)' pid=97532 parent=97398 started daemon>
distributed.dask_worker - INFO - End worker
distributed.process - INFO - reaping stray process <SpawnProcess name='Dask Worker process (from Nanny)' pid=10410 parent=10272 started daemon>
distributed.nanny - WARNING - Worker process still alive after 1 seconds, killing
distributed.dask_worker - INFO - End worker
distributed.process - INFO - reaping stray process <SpawnProcess name='Dask Worker process (from Nanny)' pid=53055 parent=52918 started daemon>
Exception in thread AsyncProcess Dask Worker process (from Nanny) watch process join:
Traceback (most recent call last):
Exception in thread AsyncProcess Dask Worker process (from Nanny) watch process join:
Traceback (most recent call last):
Exception in thread AsyncProcess Dask Worker process (from Nanny) watch process join:
Traceback (most recent call last):
Exception in thread AsyncProcess Dask Worker process (from Nanny) watch process join:
Traceback (most recent call last):
Exception in thread AsyncProcess Dask Worker process (from Nanny) watch process join:
Traceback (most recent call last):
Exception in thread AsyncProcess Dask Worker process (from Nanny) watch process join:
Traceback (most recent call last):
Exception in thread AsyncProcess Dask Worker process (from Nanny) watch process join:
Traceback (most recent call last):
Fatal Python error: _enter_buffered_busy: could not acquire lock for <_io.BufferedWriter name='<stderr>'> at interpreter shutdown, possibly due to daemon threads
Python runtime state: finalizing (tstate=0x9334c0)

Current thread 0x00002ad75ea6ab80 (most recent call first):
<no Python frame>
Fatal Python error: _enter_buffered_busy: could not acquire lock for <_io.BufferedWriter name='<stderr>'> at interpreter shutdown, possibly due to daemon threads
Python runtime state: finalizing (tstate=0x138f4c0)

Current thread 0x00002aea12de2b80 (most recent call first):
<no Python frame>
Fatal Python error: _enter_buffered_busy: could not acquire lock for <_io.BufferedWriter name='<stderr>'> at interpreter shutdown, possibly due to daemon threads
Python runtime state: finalizing (tstate=0x18064c0)

Current thread 0x00002b148ed91b80 (most recent call first):
<no Python frame>
Fatal Python error: _enter_buffered_busy: could not acquire lock for <_io.BufferedWriter name='<stderr>'> at interpreter shutdown, possibly due to daemon threads
Python runtime state: finalizing (tstate=0x5414c0)

Current thread 0x00002b1284a74b80 (most recent call first):
<no Python frame>
Fatal Python error: _enter_buffered_busy: could not acquire lock for <_io.BufferedWriter name='<stderr>'> at interpreter shutdown, possibly due to daemon threads
Python runtime state: finalizing (tstate=0x19044c0)

Current thread 0x00002b0b797e1b80 (most recent call first):
<no Python frame>
Fatal Python error: _enter_buffered_busy: could not acquire lock for <_io.BufferedWriter name='<stderr>'> at interpreter shutdown, possibly due to daemon threads
Python runtime state: finalizing (tstate=0x24144c0)

Current thread 0x00002b0421bf7b80 (most recent call first):
<no Python frame>
Fatal Python error: _enter_buffered_busy: could not acquire lock for <_io.BufferedWriter name='<stderr>'> at interpreter shutdown, possibly due to daemon threads
Python runtime state: finalizing (tstate=0x6414c0)

Current thread 0x00002b79a40d5b80 (most recent call first):
<no Python frame>
Fatal Python error: _enter_buffered_busy: could not acquire lock for <_io.BufferedWriter name='<stderr>'> at interpreter shutdown, possibly due to daemon threads
Python runtime state: finalizing (tstate=0xdef4c0)

Current thread 0x00002b39b3c92b80 (most recent call first):
<no Python frame>
Fatal Python error: _enter_buffered_busy: could not acquire lock for <_io.BufferedWriter name='<stderr>'> at interpreter shutdown, possibly due to daemon threads
Python runtime state: finalizing (tstate=0x113e4c0)

Current thread 0x00002b9229f62b80 (most recent call first):
<no Python frame>
Fatal Python error: _enter_buffered_busy: could not acquire lock for <_io.BufferedWriter name='<stderr>'> at interpreter shutdown, possibly due to daemon threads
Python runtime state: finalizing (tstate=0x22934c0)

Current thread 0x00002b413b3d4b80 (most recent call first):
<no Python frame>
srun: error: irene2289: tasks 10-11: Aborted (core dumped)
srun: error: irene2290: tasks 12-13: Aborted (core dumped)
srun: error: irene2097: tasks 6-7: Aborted (core dumped)
srun: error: irene2021: tasks 2-3: Aborted (core dumped)
srun: error: irene2090: task 4: Aborted (core dumped)
srun: error: irene2310: task 14: Aborted (core dumped)
