distributed.nanny - INFO -         Start Nanny at: 'tcp://172.21.3.63:39467'
distributed.nanny - INFO -         Start Nanny at: 'tcp://172.21.3.63:39226'
distributed.nanny - INFO -         Start Nanny at: 'tcp://172.21.3.55:33220'
distributed.nanny - INFO -         Start Nanny at: 'tcp://172.21.3.59:35735'
distributed.nanny - INFO -         Start Nanny at: 'tcp://172.21.3.55:36027'
distributed.nanny - INFO -         Start Nanny at: 'tcp://172.21.3.59:37227'
distributed.nanny - INFO -         Start Nanny at: 'tcp://172.21.3.58:36905'
distributed.nanny - INFO -         Start Nanny at: 'tcp://172.21.3.58:46410'
distributed.nanny - INFO -         Start Nanny at: 'tcp://172.21.3.68:44906'
distributed.nanny - INFO -         Start Nanny at: 'tcp://172.21.3.68:37933'
distributed.nanny - INFO -         Start Nanny at: 'tcp://172.21.3.65:46248'
distributed.nanny - INFO -         Start Nanny at: 'tcp://172.21.3.65:39874'
distributed.nanny - INFO -         Start Nanny at: 'tcp://172.21.3.53:43579'
distributed.nanny - INFO -         Start Nanny at: 'tcp://172.21.3.54:33600'
distributed.nanny - INFO -         Start Nanny at: 'tcp://172.21.3.64:40797'
distributed.nanny - INFO -         Start Nanny at: 'tcp://172.21.3.64:42859'
distributed.nanny - INFO -         Start Nanny at: 'tcp://172.21.3.62:45819'
distributed.nanny - INFO -         Start Nanny at: 'tcp://172.21.3.62:35581'
distributed.nanny - INFO -         Start Nanny at: 'tcp://172.21.3.60:45329'
distributed.nanny - INFO -         Start Nanny at: 'tcp://172.21.3.60:34384'
distributed.nanny - INFO -         Start Nanny at: 'tcp://172.21.3.53:42449'
distributed.nanny - INFO -         Start Nanny at: 'tcp://172.21.3.66:44408'
distributed.nanny - INFO -         Start Nanny at: 'tcp://172.21.3.56:43046'
distributed.nanny - INFO -         Start Nanny at: 'tcp://172.21.3.56:43273'
distributed.nanny - INFO -         Start Nanny at: 'tcp://172.21.3.54:35187'
distributed.nanny - INFO -         Start Nanny at: 'tcp://172.21.3.66:41578'
distributed.nanny - INFO -         Start Nanny at: 'tcp://172.21.3.57:34891'
distributed.nanny - INFO -         Start Nanny at: 'tcp://172.21.3.61:46236'
distributed.nanny - INFO -         Start Nanny at: 'tcp://172.21.3.67:45472'
distributed.nanny - INFO -         Start Nanny at: 'tcp://172.21.3.61:40640'
distributed.nanny - INFO -         Start Nanny at: 'tcp://172.21.3.57:35328'
distributed.nanny - INFO -         Start Nanny at: 'tcp://172.21.3.67:37133'
distributed.worker - INFO -       Start worker at:    tcp://172.21.3.63:38269
distributed.worker - INFO -       Start worker at:    tcp://172.21.3.59:36358
distributed.worker - INFO -       Start worker at:    tcp://172.21.3.65:39258
distributed.worker - INFO -          Listening to:    tcp://172.21.3.63:38269
distributed.worker - INFO -       Start worker at:    tcp://172.21.3.55:45182
distributed.worker - INFO -          Listening to:    tcp://172.21.3.55:45182
distributed.worker - INFO -          dashboard at:          172.21.3.55:36288
distributed.worker - INFO -       Start worker at:    tcp://172.21.3.68:40392
distributed.worker - INFO -          Listening to:    tcp://172.21.3.68:40392
distributed.worker - INFO -          Listening to:    tcp://172.21.3.59:36358
distributed.worker - INFO -          Listening to:    tcp://172.21.3.65:39258
distributed.worker - INFO -          dashboard at:          172.21.3.63:43894
distributed.worker - INFO -       Start worker at:    tcp://172.21.3.53:45280
distributed.worker - INFO - Waiting to connect to:     tcp://172.21.3.51:8786
distributed.worker - INFO -       Start worker at:    tcp://172.21.3.68:41624
distributed.worker - INFO -          Listening to:    tcp://172.21.3.68:41624
distributed.worker - INFO -          dashboard at:          172.21.3.59:37795
distributed.worker - INFO -       Start worker at:    tcp://172.21.3.65:35516
distributed.worker - INFO -       Start worker at:    tcp://172.21.3.63:46066
distributed.worker - INFO -          Listening to:    tcp://172.21.3.53:45280
distributed.worker - INFO -       Start worker at:    tcp://172.21.3.55:46303
distributed.worker - INFO -          dashboard at:          172.21.3.68:35868
distributed.worker - INFO - Waiting to connect to:     tcp://172.21.3.51:8786
distributed.worker - INFO - Waiting to connect to:     tcp://172.21.3.51:8786
distributed.worker - INFO -          dashboard at:          172.21.3.65:41680
distributed.worker - INFO - Waiting to connect to:     tcp://172.21.3.51:8786
distributed.worker - INFO -          dashboard at:          172.21.3.53:40851
distributed.worker - INFO - -------------------------------------------------
distributed.worker - INFO - -------------------------------------------------
distributed.worker - INFO -       Start worker at:    tcp://172.21.3.59:46492
distributed.worker - INFO - Waiting to connect to:     tcp://172.21.3.51:8786
distributed.worker - INFO - -------------------------------------------------
distributed.worker - INFO -       Start worker at:    tcp://172.21.3.53:43613
distributed.worker - INFO -          Listening to:    tcp://172.21.3.55:46303
distributed.worker - INFO -          dashboard at:          172.21.3.68:43736
distributed.worker - INFO - Waiting to connect to:     tcp://172.21.3.51:8786
distributed.worker - INFO - -------------------------------------------------
distributed.worker - INFO -          Listening to:    tcp://172.21.3.65:35516
distributed.worker - INFO -          Listening to:    tcp://172.21.3.63:46066
distributed.worker - INFO - Waiting to connect to:     tcp://172.21.3.51:8786
distributed.worker - INFO -               Threads:                         24
distributed.worker - INFO -               Threads:                         24
distributed.worker - INFO -               Threads:                         24
distributed.worker - INFO - -------------------------------------------------
distributed.worker - INFO -               Threads:                         24
distributed.worker - INFO - -------------------------------------------------
distributed.worker - INFO -          dashboard at:          172.21.3.55:35221
distributed.worker - INFO - -------------------------------------------------
distributed.worker - INFO -          Listening to:    tcp://172.21.3.59:46492
distributed.worker - INFO -          dashboard at:          172.21.3.65:34114
distributed.worker - INFO -          dashboard at:          172.21.3.63:39684
distributed.worker - INFO -          Listening to:    tcp://172.21.3.53:43613
distributed.worker - INFO -                Memory:                 172.73 GiB
distributed.worker - INFO -                Memory:                 172.73 GiB
distributed.worker - INFO -                Memory:                 172.73 GiB
distributed.worker - INFO -               Threads:                         24
distributed.worker - INFO - Waiting to connect to:     tcp://172.21.3.51:8786
distributed.worker - INFO -               Threads:                         24
distributed.worker - INFO - Waiting to connect to:     tcp://172.21.3.51:8786
distributed.worker - INFO -       Start worker at:    tcp://172.21.3.58:38266
distributed.worker - INFO -               Threads:                         24
distributed.worker - INFO -          dashboard at:          172.21.3.59:41762
distributed.worker - INFO - Waiting to connect to:     tcp://172.21.3.51:8786
distributed.worker - INFO -                Memory:                 172.73 GiB
distributed.worker - INFO -          dashboard at:          172.21.3.53:41423
distributed.worker - INFO -       Local Directory: /tmp/dask-worker-space/worker-1w59ttos
distributed.worker - INFO -          Listening to:    tcp://172.21.3.58:38266
distributed.worker - INFO -       Local Directory: /tmp/dask-worker-space/worker-joszo16n
distributed.worker - INFO -       Local Directory: /tmp/dask-worker-space/worker-um5bv29h
distributed.worker - INFO -                Memory:                 172.73 GiB
distributed.worker - INFO -       Local Directory: /tmp/dask-worker-space/worker-73ehldqc
distributed.worker - INFO -                Memory:                 172.73 GiB
distributed.worker - INFO - -------------------------------------------------
distributed.worker - INFO -          dashboard at:          172.21.3.58:34254
distributed.worker - INFO -                Memory:                 172.73 GiB
distributed.worker - INFO - Waiting to connect to:     tcp://172.21.3.51:8786
distributed.worker - INFO - -------------------------------------------------
distributed.worker - INFO - -------------------------------------------------
distributed.worker - INFO - Waiting to connect to:     tcp://172.21.3.51:8786
distributed.worker - INFO -               Threads:                         24
distributed.worker - INFO - Waiting to connect to:     tcp://172.21.3.51:8786
distributed.worker - INFO - -------------------------------------------------
distributed.worker - INFO - -------------------------------------------------
distributed.worker - INFO -               Threads:                         24
distributed.worker - INFO -               Threads:                         24
distributed.worker - INFO -       Local Directory: /tmp/dask-worker-space/worker-p0gz2v7e
distributed.worker - INFO - -------------------------------------------------
distributed.worker - INFO - -------------------------------------------------
distributed.worker - INFO -       Local Directory: /tmp/dask-worker-space/worker-npp3pqt_
distributed.worker - INFO - -------------------------------------------------
distributed.worker - INFO -       Local Directory: /tmp/dask-worker-space/worker-rk3nzg5d
distributed.worker - INFO - -------------------------------------------------
distributed.worker - INFO - -------------------------------------------------
distributed.worker - INFO -                Memory:                 172.73 GiB
distributed.worker - INFO -               Threads:                         24
distributed.worker - INFO - -------------------------------------------------
distributed.worker - INFO -               Threads:                         24
distributed.worker - INFO -                Memory:                 172.73 GiB
distributed.worker - INFO -                Memory:                 172.73 GiB
distributed.worker - INFO -               Threads:                         24
distributed.worker - INFO -       Local Directory: /tmp/dask-worker-space/worker-f56gzsdk
distributed.worker - INFO -       Start worker at:    tcp://172.21.3.58:33860
distributed.worker - INFO -                Memory:                 172.73 GiB
distributed.worker - INFO - -------------------------------------------------
distributed.worker - INFO -       Local Directory: /tmp/dask-worker-space/worker-432oe544
distributed.worker - INFO - -------------------------------------------------
distributed.worker - INFO - -------------------------------------------------
distributed.worker - INFO -          Listening to:    tcp://172.21.3.58:33860
distributed.worker - INFO -       Local Directory: /tmp/dask-worker-space/worker-18uv_6t4
distributed.worker - INFO -       Local Directory: /tmp/dask-worker-space/worker-_2vrahwe
distributed.worker - INFO - -------------------------------------------------
distributed.worker - INFO -                Memory:                 172.73 GiB
distributed.worker - INFO -                Memory:                 172.73 GiB
distributed.worker - INFO - -------------------------------------------------
distributed.worker - INFO - -------------------------------------------------
distributed.worker - INFO -       Local Directory: /tmp/dask-worker-space/worker-eodxae2u
distributed.worker - INFO -          dashboard at:          172.21.3.58:45730
distributed.worker - INFO - -------------------------------------------------
distributed.worker - INFO - Waiting to connect to:     tcp://172.21.3.51:8786
distributed.worker - INFO - -------------------------------------------------
distributed.worker - INFO -               Threads:                         24
distributed.worker - INFO -                Memory:                 172.73 GiB
distributed.worker - INFO -       Local Directory: /tmp/dask-worker-space/worker-55b89rc1
distributed.worker - INFO - -------------------------------------------------
distributed.worker - INFO -       Local Directory: /tmp/dask-worker-space/worker-ky1qzjdf
distributed.worker - INFO - -------------------------------------------------
distributed.worker - INFO -       Start worker at:    tcp://172.21.3.64:36233
distributed.worker - INFO -          Listening to:    tcp://172.21.3.64:36233
distributed.worker - INFO -       Start worker at:    tcp://172.21.3.64:38495
distributed.worker - INFO -          dashboard at:          172.21.3.64:40853
distributed.worker - INFO - Waiting to connect to:     tcp://172.21.3.51:8786
distributed.worker - INFO -          Listening to:    tcp://172.21.3.64:38495
distributed.worker - INFO - -------------------------------------------------
distributed.worker - INFO -               Threads:                         24
distributed.worker - INFO -          dashboard at:          172.21.3.64:35256
distributed.worker - INFO -                Memory:                 172.73 GiB
distributed.worker - INFO - Waiting to connect to:     tcp://172.21.3.51:8786
distributed.worker - INFO -       Local Directory: /tmp/dask-worker-space/worker-wmuewtoj
distributed.worker - INFO - -------------------------------------------------
distributed.worker - INFO -               Threads:                         24
distributed.worker - INFO - -------------------------------------------------
distributed.worker - INFO -                Memory:                 172.73 GiB
distributed.worker - INFO -       Local Directory: /tmp/dask-worker-space/worker-2sx6337m
distributed.worker - INFO - -------------------------------------------------
distributed.worker - INFO -       Start worker at:    tcp://172.21.3.56:41339
distributed.worker - INFO -          Listening to:    tcp://172.21.3.56:41339
distributed.worker - INFO -          dashboard at:          172.21.3.56:39794
distributed.worker - INFO - Waiting to connect to:     tcp://172.21.3.51:8786
distributed.worker - INFO -       Start worker at:    tcp://172.21.3.56:35530
distributed.worker - INFO - -------------------------------------------------
distributed.worker - INFO -               Threads:                         24
distributed.worker - INFO -          Listening to:    tcp://172.21.3.56:35530
distributed.worker - INFO -                Memory:                 172.73 GiB
distributed.worker - INFO -          dashboard at:          172.21.3.56:33111
distributed.worker - INFO -       Local Directory: /tmp/dask-worker-space/worker-k4f5g3wm
distributed.worker - INFO - Waiting to connect to:     tcp://172.21.3.51:8786
distributed.worker - INFO - -------------------------------------------------
distributed.worker - INFO - -------------------------------------------------
distributed.worker - INFO -               Threads:                         24
distributed.worker - INFO -                Memory:                 172.73 GiB
distributed.worker - INFO -       Local Directory: /tmp/dask-worker-space/worker-ikks1dmw
distributed.worker - INFO - -------------------------------------------------
distributed.worker - INFO -         Registered to:     tcp://172.21.3.51:8786
distributed.worker - INFO - -------------------------------------------------
distributed.core - INFO - Starting established connection
distributed.worker - INFO -       Start worker at:    tcp://172.21.3.54:46347
distributed.worker - INFO -       Start worker at:    tcp://172.21.3.54:43587
distributed.worker - INFO -          Listening to:    tcp://172.21.3.54:43587
distributed.worker - INFO -          dashboard at:          172.21.3.54:39443
distributed.worker - INFO -          Listening to:    tcp://172.21.3.54:46347
distributed.worker - INFO -          dashboard at:          172.21.3.54:36579
distributed.worker - INFO - Waiting to connect to:     tcp://172.21.3.51:8786
distributed.worker - INFO - -------------------------------------------------
distributed.worker - INFO - Waiting to connect to:     tcp://172.21.3.51:8786
distributed.worker - INFO - -------------------------------------------------
distributed.worker - INFO -               Threads:                         24
distributed.worker - INFO -               Threads:                         24
distributed.worker - INFO -                Memory:                 172.73 GiB
distributed.worker - INFO -                Memory:                 172.73 GiB
distributed.worker - INFO -       Local Directory: /tmp/dask-worker-space/worker-5eopkb5e
distributed.worker - INFO -       Local Directory: /tmp/dask-worker-space/worker-_rgs2hc4
distributed.worker - INFO - -------------------------------------------------
distributed.worker - INFO - -------------------------------------------------
distributed.worker - INFO -         Registered to:     tcp://172.21.3.51:8786
distributed.worker - INFO - -------------------------------------------------
distributed.core - INFO - Starting established connection
distributed.worker - INFO -         Registered to:     tcp://172.21.3.51:8786
distributed.worker - INFO - -------------------------------------------------
distributed.core - INFO - Starting established connection
distributed.worker - INFO -         Registered to:     tcp://172.21.3.51:8786
distributed.worker - INFO - -------------------------------------------------
distributed.core - INFO - Starting established connection
distributed.worker - INFO -       Start worker at:    tcp://172.21.3.66:40912
distributed.worker - INFO -          Listening to:    tcp://172.21.3.66:40912
distributed.worker - INFO -          dashboard at:          172.21.3.66:46552
distributed.worker - INFO - Waiting to connect to:     tcp://172.21.3.51:8786
distributed.worker - INFO -       Start worker at:    tcp://172.21.3.66:43890
distributed.worker - INFO -          Listening to:    tcp://172.21.3.66:43890
distributed.worker - INFO -          dashboard at:          172.21.3.66:46465
distributed.worker - INFO - -------------------------------------------------
distributed.worker - INFO - Waiting to connect to:     tcp://172.21.3.51:8786
distributed.worker - INFO -               Threads:                         24
distributed.worker - INFO - -------------------------------------------------
distributed.worker - INFO -                Memory:                 172.73 GiB
distributed.worker - INFO -               Threads:                         24
distributed.worker - INFO -       Local Directory: /tmp/dask-worker-space/worker-zi29k2c4
distributed.worker - INFO -                Memory:                 172.73 GiB
distributed.worker - INFO - -------------------------------------------------
distributed.worker - INFO -       Local Directory: /tmp/dask-worker-space/worker-wwk1ts1p
distributed.worker - INFO - -------------------------------------------------
distributed.worker - INFO -       Start worker at:    tcp://172.21.3.62:45089
distributed.worker - INFO -          Listening to:    tcp://172.21.3.62:45089
distributed.worker - INFO -          dashboard at:          172.21.3.62:35269
distributed.worker - INFO - Waiting to connect to:     tcp://172.21.3.51:8786
distributed.worker - INFO - -------------------------------------------------
distributed.worker - INFO -               Threads:                         24
distributed.worker - INFO -                Memory:                 172.73 GiB
distributed.worker - INFO -       Local Directory: /tmp/dask-worker-space/worker-g7zzma6l
distributed.worker - INFO - -------------------------------------------------
distributed.worker - INFO -       Start worker at:    tcp://172.21.3.62:45537
distributed.worker - INFO -          Listening to:    tcp://172.21.3.62:45537
distributed.worker - INFO -          dashboard at:          172.21.3.62:39859
distributed.worker - INFO - Waiting to connect to:     tcp://172.21.3.51:8786
distributed.worker - INFO - -------------------------------------------------
distributed.worker - INFO -               Threads:                         24
distributed.worker - INFO -                Memory:                 172.73 GiB
distributed.worker - INFO -       Local Directory: /tmp/dask-worker-space/worker-3s_hi02d
distributed.worker - INFO - -------------------------------------------------
distributed.worker - INFO -         Registered to:     tcp://172.21.3.51:8786
distributed.worker - INFO - -------------------------------------------------
distributed.core - INFO - Starting established connection
distributed.worker - INFO -         Registered to:     tcp://172.21.3.51:8786
distributed.worker - INFO - -------------------------------------------------
distributed.core - INFO - Starting established connection
distributed.worker - INFO -         Registered to:     tcp://172.21.3.51:8786
distributed.worker - INFO - -------------------------------------------------
distributed.core - INFO - Starting established connection
distributed.worker - INFO -         Registered to:     tcp://172.21.3.51:8786
distributed.worker - INFO - -------------------------------------------------
distributed.core - INFO - Starting established connection
distributed.worker - INFO -         Registered to:     tcp://172.21.3.51:8786
distributed.worker - INFO - -------------------------------------------------
distributed.worker - INFO -       Start worker at:    tcp://172.21.3.60:41166
distributed.worker - INFO -          Listening to:    tcp://172.21.3.60:41166
distributed.worker - INFO -       Start worker at:    tcp://172.21.3.60:40862
distributed.worker - INFO -          dashboard at:          172.21.3.60:46812
distributed.worker - INFO -          Listening to:    tcp://172.21.3.60:40862
distributed.worker - INFO - Waiting to connect to:     tcp://172.21.3.51:8786
distributed.worker - INFO - -------------------------------------------------
distributed.worker - INFO -          dashboard at:          172.21.3.60:34228
distributed.worker - INFO -               Threads:                         24
distributed.worker - INFO - Waiting to connect to:     tcp://172.21.3.51:8786
distributed.worker - INFO - -------------------------------------------------
distributed.worker - INFO -                Memory:                 172.73 GiB
distributed.worker - INFO -               Threads:                         24
distributed.worker - INFO -       Local Directory: /tmp/dask-worker-space/worker-wq63xu38
distributed.worker - INFO -                Memory:                 172.73 GiB
distributed.worker - INFO -       Local Directory: /tmp/dask-worker-space/worker-vguhykf7
distributed.worker - INFO - -------------------------------------------------
distributed.worker - INFO - -------------------------------------------------
distributed.core - INFO - Starting established connection
distributed.worker - INFO -         Registered to:     tcp://172.21.3.51:8786
distributed.worker - INFO - -------------------------------------------------
distributed.core - INFO - Starting established connection
distributed.worker - INFO -         Registered to:     tcp://172.21.3.51:8786
distributed.worker - INFO - -------------------------------------------------
distributed.core - INFO - Starting established connection
distributed.worker - INFO -         Registered to:     tcp://172.21.3.51:8786
distributed.worker - INFO - -------------------------------------------------
distributed.core - INFO - Starting established connection
distributed.worker - INFO -         Registered to:     tcp://172.21.3.51:8786
distributed.worker - INFO - -------------------------------------------------
distributed.core - INFO - Starting established connection
distributed.worker - INFO -         Registered to:     tcp://172.21.3.51:8786
distributed.worker - INFO - -------------------------------------------------
distributed.core - INFO - Starting established connection
distributed.worker - INFO -         Registered to:     tcp://172.21.3.51:8786
distributed.worker - INFO - -------------------------------------------------
distributed.core - INFO - Starting established connection
distributed.worker - INFO -         Registered to:     tcp://172.21.3.51:8786
distributed.worker - INFO - -------------------------------------------------
distributed.core - INFO - Starting established connection
distributed.worker - INFO -         Registered to:     tcp://172.21.3.51:8786
distributed.worker - INFO - -------------------------------------------------
distributed.core - INFO - Starting established connection
distributed.worker - INFO -         Registered to:     tcp://172.21.3.51:8786
distributed.worker - INFO - -------------------------------------------------
distributed.core - INFO - Starting established connection
distributed.worker - INFO -         Registered to:     tcp://172.21.3.51:8786
distributed.worker - INFO - -------------------------------------------------
distributed.core - INFO - Starting established connection
distributed.worker - INFO -         Registered to:     tcp://172.21.3.51:8786
distributed.worker - INFO - -------------------------------------------------
distributed.core - INFO - Starting established connection
distributed.worker - INFO -         Registered to:     tcp://172.21.3.51:8786
distributed.worker - INFO - -------------------------------------------------
distributed.core - INFO - Starting established connection
distributed.worker - INFO -         Registered to:     tcp://172.21.3.51:8786
distributed.worker - INFO - -------------------------------------------------
distributed.core - INFO - Starting established connection
distributed.worker - INFO -         Registered to:     tcp://172.21.3.51:8786
distributed.worker - INFO - -------------------------------------------------
distributed.core - INFO - Starting established connection
distributed.worker - INFO -         Registered to:     tcp://172.21.3.51:8786
distributed.worker - INFO - -------------------------------------------------
distributed.core - INFO - Starting established connection
distributed.worker - INFO -         Registered to:     tcp://172.21.3.51:8786
distributed.worker - INFO - -------------------------------------------------
distributed.core - INFO - Starting established connection
distributed.worker - INFO -       Start worker at:    tcp://172.21.3.57:45485
distributed.worker - INFO -          Listening to:    tcp://172.21.3.57:45485
distributed.worker - INFO -          dashboard at:          172.21.3.57:45937
distributed.worker - INFO -       Start worker at:    tcp://172.21.3.57:33383
distributed.worker - INFO - Waiting to connect to:     tcp://172.21.3.51:8786
distributed.worker - INFO -          Listening to:    tcp://172.21.3.57:33383
distributed.worker - INFO - -------------------------------------------------
distributed.worker - INFO -          dashboard at:          172.21.3.57:38408
distributed.worker - INFO -               Threads:                         24
distributed.worker - INFO - Waiting to connect to:     tcp://172.21.3.51:8786
distributed.worker - INFO -                Memory:                 172.73 GiB
distributed.worker - INFO - -------------------------------------------------
distributed.worker - INFO -       Local Directory: /tmp/dask-worker-space/worker-grqz2525
distributed.worker - INFO -               Threads:                         24
distributed.worker - INFO -                Memory:                 172.73 GiB
distributed.worker - INFO - -------------------------------------------------
distributed.worker - INFO -       Local Directory: /tmp/dask-worker-space/worker-s2lbqmww
distributed.worker - INFO - -------------------------------------------------
distributed.worker - INFO -         Registered to:     tcp://172.21.3.51:8786
distributed.worker - INFO - -------------------------------------------------
distributed.core - INFO - Starting established connection
distributed.worker - INFO -       Start worker at:    tcp://172.21.3.67:40189
distributed.worker - INFO -          Listening to:    tcp://172.21.3.67:40189
distributed.worker - INFO -          dashboard at:          172.21.3.67:36828
distributed.worker - INFO -       Start worker at:    tcp://172.21.3.67:45795
distributed.worker - INFO - Waiting to connect to:     tcp://172.21.3.51:8786
distributed.worker - INFO - -------------------------------------------------
distributed.worker - INFO -          Listening to:    tcp://172.21.3.67:45795
distributed.worker - INFO -               Threads:                         24
distributed.worker - INFO -          dashboard at:          172.21.3.67:41399
distributed.worker - INFO - Waiting to connect to:     tcp://172.21.3.51:8786
distributed.worker - INFO -                Memory:                 172.73 GiB
distributed.worker - INFO - -------------------------------------------------
distributed.worker - INFO -       Local Directory: /tmp/dask-worker-space/worker-sg50fkef
distributed.worker - INFO -               Threads:                         24
distributed.worker - INFO - -------------------------------------------------
distributed.worker - INFO -                Memory:                 172.73 GiB
distributed.worker - INFO -       Local Directory: /tmp/dask-worker-space/worker-bhpvq5kd
distributed.worker - INFO - -------------------------------------------------
distributed.worker - INFO -         Registered to:     tcp://172.21.3.51:8786
distributed.worker - INFO - -------------------------------------------------
distributed.worker - INFO -       Start worker at:    tcp://172.21.3.61:35875
distributed.worker - INFO -       Start worker at:    tcp://172.21.3.61:42946
distributed.worker - INFO -          Listening to:    tcp://172.21.3.61:42946
distributed.worker - INFO -          dashboard at:          172.21.3.61:39954
distributed.worker - INFO -          Listening to:    tcp://172.21.3.61:35875
distributed.worker - INFO - Waiting to connect to:     tcp://172.21.3.51:8786
distributed.worker - INFO -          dashboard at:          172.21.3.61:35559
distributed.worker - INFO - -------------------------------------------------
distributed.worker - INFO -               Threads:                         24
distributed.worker - INFO - Waiting to connect to:     tcp://172.21.3.51:8786
distributed.worker - INFO - -------------------------------------------------
distributed.worker - INFO -                Memory:                 172.73 GiB
distributed.worker - INFO -               Threads:                         24
distributed.worker - INFO -       Local Directory: /tmp/dask-worker-space/worker-ph499rb1
distributed.worker - INFO -                Memory:                 172.73 GiB
distributed.worker - INFO -       Local Directory: /tmp/dask-worker-space/worker-nodik081
distributed.worker - INFO - -------------------------------------------------
distributed.worker - INFO - -------------------------------------------------
distributed.core - INFO - Starting established connection
distributed.worker - INFO -         Registered to:     tcp://172.21.3.51:8786
distributed.worker - INFO - -------------------------------------------------
distributed.core - INFO - Starting established connection
distributed.worker - INFO -         Registered to:     tcp://172.21.3.51:8786
distributed.worker - INFO - -------------------------------------------------
distributed.core - INFO - Starting established connection
distributed.worker - INFO -         Registered to:     tcp://172.21.3.51:8786
distributed.worker - INFO - -------------------------------------------------
distributed.core - INFO - Starting established connection
distributed.worker - INFO -         Registered to:     tcp://172.21.3.51:8786
distributed.worker - INFO - -------------------------------------------------
distributed.core - INFO - Starting established connection
distributed.worker - INFO -         Registered to:     tcp://172.21.3.51:8786
distributed.worker - INFO - -------------------------------------------------
distributed.core - INFO - Starting established connection
distributed.worker - ERROR - Worker stream died during communication: tcp://172.21.3.57:45485
Traceback (most recent call last):
  File "/ccc/work/cont003/gen2224/gen2224/spack/var/spack/environments/gysela-deisa-irene-skl-draft/.spack-env/view/lib/python3.9/site-packages/distributed/comm/tcp.py", line 205, in read
    frames_nbytes = await stream.read_bytes(fmt_size)
asyncio.exceptions.CancelledError

During handling of the above exception, another exception occurred:

Traceback (most recent call last):
  File "/ccc/work/cont003/gen2224/gen2224/spack/var/spack/environments/gysela-deisa-irene-skl-draft/.spack-env/._view/whcr3wyhzgorszy3rfxsphyebtvfpqzk/lib/python3.9/asyncio/tasks.py", line 490, in wait_for
    return fut.result()
asyncio.exceptions.CancelledError

The above exception was the direct cause of the following exception:

Traceback (most recent call last):
  File "/ccc/work/cont003/gen2224/gen2224/spack/var/spack/environments/gysela-deisa-irene-skl-draft/.spack-env/view/lib/python3.9/site-packages/distributed/comm/core.py", line 319, in connect
    handshake = await asyncio.wait_for(comm.read(), time_left())
  File "/ccc/work/cont003/gen2224/gen2224/spack/var/spack/environments/gysela-deisa-irene-skl-draft/.spack-env/._view/whcr3wyhzgorszy3rfxsphyebtvfpqzk/lib/python3.9/asyncio/tasks.py", line 492, in wait_for
    raise exceptions.TimeoutError() from exc
asyncio.exceptions.TimeoutError

The above exception was the direct cause of the following exception:

Traceback (most recent call last):
  File "/ccc/work/cont003/gen2224/gen2224/spack/var/spack/environments/gysela-deisa-irene-skl-draft/.spack-env/view/lib/python3.9/site-packages/distributed/worker.py", line 2878, in gather_dep
    response = await get_data_from_worker(
  File "/ccc/work/cont003/gen2224/gen2224/spack/var/spack/environments/gysela-deisa-irene-skl-draft/.spack-env/view/lib/python3.9/site-packages/distributed/worker.py", line 4143, in get_data_from_worker
    return await retry_operation(_get_data, operation="get_data_from_worker")
  File "/ccc/work/cont003/gen2224/gen2224/spack/var/spack/environments/gysela-deisa-irene-skl-draft/.spack-env/view/lib/python3.9/site-packages/distributed/utils_comm.py", line 366, in retry_operation
    return await retry(
  File "/ccc/work/cont003/gen2224/gen2224/spack/var/spack/environments/gysela-deisa-irene-skl-draft/.spack-env/view/lib/python3.9/site-packages/distributed/utils_comm.py", line 351, in retry
    return await coro()
  File "/ccc/work/cont003/gen2224/gen2224/spack/var/spack/environments/gysela-deisa-irene-skl-draft/.spack-env/view/lib/python3.9/site-packages/distributed/worker.py", line 4120, in _get_data
    comm = await rpc.connect(worker)
  File "/ccc/work/cont003/gen2224/gen2224/spack/var/spack/environments/gysela-deisa-irene-skl-draft/.spack-env/view/lib/python3.9/site-packages/distributed/core.py", line 1081, in connect
    raise exc
  File "/ccc/work/cont003/gen2224/gen2224/spack/var/spack/environments/gysela-deisa-irene-skl-draft/.spack-env/view/lib/python3.9/site-packages/distributed/core.py", line 1065, in connect
    comm = await fut
  File "/ccc/work/cont003/gen2224/gen2224/spack/var/spack/environments/gysela-deisa-irene-skl-draft/.spack-env/view/lib/python3.9/site-packages/distributed/comm/core.py", line 324, in connect
    raise OSError(
OSError: Timed out during handshake while connecting to tcp://172.21.3.57:45485 after 30 s
distributed.worker - ERROR - Worker stream died during communication: tcp://172.21.3.57:45485
Traceback (most recent call last):
  File "/ccc/work/cont003/gen2224/gen2224/spack/var/spack/environments/gysela-deisa-irene-skl-draft/.spack-env/view/lib/python3.9/site-packages/distributed/comm/tcp.py", line 205, in read
    frames_nbytes = await stream.read_bytes(fmt_size)
asyncio.exceptions.CancelledError

During handling of the above exception, another exception occurred:

Traceback (most recent call last):
  File "/ccc/work/cont003/gen2224/gen2224/spack/var/spack/environments/gysela-deisa-irene-skl-draft/.spack-env/._view/whcr3wyhzgorszy3rfxsphyebtvfpqzk/lib/python3.9/asyncio/tasks.py", line 490, in wait_for
    return fut.result()
asyncio.exceptions.CancelledError

The above exception was the direct cause of the following exception:

Traceback (most recent call last):
  File "/ccc/work/cont003/gen2224/gen2224/spack/var/spack/environments/gysela-deisa-irene-skl-draft/.spack-env/view/lib/python3.9/site-packages/distributed/comm/core.py", line 319, in connect
    handshake = await asyncio.wait_for(comm.read(), time_left())
  File "/ccc/work/cont003/gen2224/gen2224/spack/var/spack/environments/gysela-deisa-irene-skl-draft/.spack-env/._view/whcr3wyhzgorszy3rfxsphyebtvfpqzk/lib/python3.9/asyncio/tasks.py", line 492, in wait_for
    raise exceptions.TimeoutError() from exc
asyncio.exceptions.TimeoutError

The above exception was the direct cause of the following exception:

Traceback (most recent call last):
  File "/ccc/work/cont003/gen2224/gen2224/spack/var/spack/environments/gysela-deisa-irene-skl-draft/.spack-env/view/lib/python3.9/site-packages/distributed/worker.py", line 2878, in gather_dep
    response = await get_data_from_worker(
  File "/ccc/work/cont003/gen2224/gen2224/spack/var/spack/environments/gysela-deisa-irene-skl-draft/.spack-env/view/lib/python3.9/site-packages/distributed/worker.py", line 4143, in get_data_from_worker
    return await retry_operation(_get_data, operation="get_data_from_worker")
  File "/ccc/work/cont003/gen2224/gen2224/spack/var/spack/environments/gysela-deisa-irene-skl-draft/.spack-env/view/lib/python3.9/site-packages/distributed/utils_comm.py", line 366, in retry_operation
    return await retry(
  File "/ccc/work/cont003/gen2224/gen2224/spack/var/spack/environments/gysela-deisa-irene-skl-draft/.spack-env/view/lib/python3.9/site-packages/distributed/utils_comm.py", line 351, in retry
    return await coro()
  File "/ccc/work/cont003/gen2224/gen2224/spack/var/spack/environments/gysela-deisa-irene-skl-draft/.spack-env/view/lib/python3.9/site-packages/distributed/worker.py", line 4120, in _get_data
    comm = await rpc.connect(worker)
  File "/ccc/work/cont003/gen2224/gen2224/spack/var/spack/environments/gysela-deisa-irene-skl-draft/.spack-env/view/lib/python3.9/site-packages/distributed/core.py", line 1081, in connect
    raise exc
  File "/ccc/work/cont003/gen2224/gen2224/spack/var/spack/environments/gysela-deisa-irene-skl-draft/.spack-env/view/lib/python3.9/site-packages/distributed/core.py", line 1065, in connect
    comm = await fut
  File "/ccc/work/cont003/gen2224/gen2224/spack/var/spack/environments/gysela-deisa-irene-skl-draft/.spack-env/view/lib/python3.9/site-packages/distributed/comm/core.py", line 324, in connect
    raise OSError(
OSError: Timed out during handshake while connecting to tcp://172.21.3.57:45485 after 30 s
distributed.worker - ERROR - Worker stream died during communication: tcp://172.21.3.57:45485
Traceback (most recent call last):
  File "/ccc/work/cont003/gen2224/gen2224/spack/var/spack/environments/gysela-deisa-irene-skl-draft/.spack-env/view/lib/python3.9/site-packages/distributed/comm/tcp.py", line 205, in read
    frames_nbytes = await stream.read_bytes(fmt_size)
asyncio.exceptions.CancelledError

During handling of the above exception, another exception occurred:

Traceback (most recent call last):
  File "/ccc/work/cont003/gen2224/gen2224/spack/var/spack/environments/gysela-deisa-irene-skl-draft/.spack-env/._view/whcr3wyhzgorszy3rfxsphyebtvfpqzk/lib/python3.9/asyncio/tasks.py", line 490, in wait_for
    return fut.result()
asyncio.exceptions.CancelledError

The above exception was the direct cause of the following exception:

Traceback (most recent call last):
distributed.worker - ERROR - Worker stream died during communication: tcp://172.21.3.57:45485
Traceback (most recent call last):
  File "/ccc/work/cont003/gen2224/gen2224/spack/var/spack/environments/gysela-deisa-irene-skl-draft/.spack-env/view/lib/python3.9/site-packages/distributed/comm/tcp.py", line 205, in read
    frames_nbytes = await stream.read_bytes(fmt_size)
asyncio.exceptions.CancelledError

During handling of the above exception, another exception occurred:

Traceback (most recent call last):
  File "/ccc/work/cont003/gen2224/gen2224/spack/var/spack/environments/gysela-deisa-irene-skl-draft/.spack-env/._view/whcr3wyhzgorszy3rfxsphyebtvfpqzk/lib/python3.9/asyncio/tasks.py", line 490, in wait_for
    return fut.result()
asyncio.exceptions.CancelledError

The above exception was the direct cause of the following exception:

Traceback (most recent call last):
distributed.worker - ERROR - Worker stream died during communication: tcp://172.21.3.57:45485
Traceback (most recent call last):
  File "/ccc/work/cont003/gen2224/gen2224/spack/var/spack/environments/gysela-deisa-irene-skl-draft/.spack-env/view/lib/python3.9/site-packages/distributed/comm/tcp.py", line 205, in read
    frames_nbytes = await stream.read_bytes(fmt_size)
asyncio.exceptions.CancelledError

During handling of the above exception, another exception occurred:

Traceback (most recent call last):
  File "/ccc/work/cont003/gen2224/gen2224/spack/var/spack/environments/gysela-deisa-irene-skl-draft/.spack-env/._view/whcr3wyhzgorszy3rfxsphyebtvfpqzk/lib/python3.9/asyncio/tasks.py", line 490, in wait_for
    return fut.result()
asyncio.exceptions.CancelledError

The above exception was the direct cause of the following exception:

Traceback (most recent call last):
distributed.worker - ERROR - Worker stream died during communication: tcp://172.21.3.57:45485
Traceback (most recent call last):
  File "/ccc/work/cont003/gen2224/gen2224/spack/var/spack/environments/gysela-deisa-irene-skl-draft/.spack-env/view/lib/python3.9/site-packages/distributed/comm/tcp.py", line 205, in read
    frames_nbytes = await stream.read_bytes(fmt_size)
asyncio.exceptions.CancelledError

During handling of the above exception, another exception occurred:

Traceback (most recent call last):
  File "/ccc/work/cont003/gen2224/gen2224/spack/var/spack/environments/gysela-deisa-irene-skl-draft/.spack-env/._view/whcr3wyhzgorszy3rfxsphyebtvfpqzk/lib/python3.9/asyncio/tasks.py", line 490, in wait_for
    return fut.result()
asyncio.exceptions.CancelledError

The above exception was the direct cause of the following exception:

Traceback (most recent call last):
  File "/ccc/work/cont003/gen2224/gen2224/spack/var/spack/environments/gysela-deisa-irene-skl-draft/.spack-env/view/lib/python3.9/site-packages/distributed/comm/core.py", line 319, in connect
    handshake = await asyncio.wait_for(comm.read(), time_left())
  File "/ccc/work/cont003/gen2224/gen2224/spack/var/spack/environments/gysela-deisa-irene-skl-draft/.spack-env/._view/whcr3wyhzgorszy3rfxsphyebtvfpqzk/lib/python3.9/asyncio/tasks.py", line 492, in wait_for
    raise exceptions.TimeoutError() from exc
asyncio.exceptions.TimeoutError

The above exception was the direct cause of the following exception:

Traceback (most recent call last):
  File "/ccc/work/cont003/gen2224/gen2224/spack/var/spack/environments/gysela-deisa-irene-skl-draft/.spack-env/view/lib/python3.9/site-packages/distributed/worker.py", line 2878, in gather_dep
    response = await get_data_from_worker(
  File "/ccc/work/cont003/gen2224/gen2224/spack/var/spack/environments/gysela-deisa-irene-skl-draft/.spack-env/view/lib/python3.9/site-packages/distributed/comm/core.py", line 319, in connect
    handshake = await asyncio.wait_for(comm.read(), time_left())
  File "/ccc/work/cont003/gen2224/gen2224/spack/var/spack/environments/gysela-deisa-irene-skl-draft/.spack-env/._view/whcr3wyhzgorszy3rfxsphyebtvfpqzk/lib/python3.9/asyncio/tasks.py", line 492, in wait_for
    raise exceptions.TimeoutError() from exc
asyncio.exceptions.TimeoutError

The above exception was the direct cause of the following exception:

Traceback (most recent call last):
  File "/ccc/work/cont003/gen2224/gen2224/spack/var/spack/environments/gysela-deisa-irene-skl-draft/.spack-env/view/lib/python3.9/site-packages/distributed/worker.py", line 2878, in gather_dep
    response = await get_data_from_worker(
distributed.worker - ERROR - Worker stream died during communication: tcp://172.21.3.57:45485
Traceback (most recent call last):
  File "/ccc/work/cont003/gen2224/gen2224/spack/var/spack/environments/gysela-deisa-irene-skl-draft/.spack-env/view/lib/python3.9/site-packages/distributed/comm/tcp.py", line 205, in read
    frames_nbytes = await stream.read_bytes(fmt_size)
asyncio.exceptions.CancelledError

During handling of the above exception, another exception occurred:

Traceback (most recent call last):
  File "/ccc/work/cont003/gen2224/gen2224/spack/var/spack/environments/gysela-deisa-irene-skl-draft/.spack-env/._view/whcr3wyhzgorszy3rfxsphyebtvfpqzk/lib/python3.9/asyncio/tasks.py", line 490, in wait_for
    return fut.result()
asyncio.exceptions.CancelledError

The above exception was the direct cause of the following exception:

Traceback (most recent call last):
  File "/ccc/work/cont003/gen2224/gen2224/spack/var/spack/environments/gysela-deisa-irene-skl-draft/.spack-env/view/lib/python3.9/site-packages/distributed/comm/core.py", line 319, in connect
    handshake = await asyncio.wait_for(comm.read(), time_left())
  File "/ccc/work/cont003/gen2224/gen2224/spack/var/spack/environments/gysela-deisa-irene-skl-draft/.spack-env/._view/whcr3wyhzgorszy3rfxsphyebtvfpqzk/lib/python3.9/asyncio/tasks.py", line 492, in wait_for
    raise exceptions.TimeoutError() from exc
asyncio.exceptions.TimeoutError

The above exception was the direct cause of the following exception:

Traceback (most recent call last):
  File "/ccc/work/cont003/gen2224/gen2224/spack/var/spack/environments/gysela-deisa-irene-skl-draft/.spack-env/view/lib/python3.9/site-packages/distributed/worker.py", line 2878, in gather_dep
    response = await get_data_from_worker(
  File "/ccc/work/cont003/gen2224/gen2224/spack/var/spack/environments/gysela-deisa-irene-skl-draft/.spack-env/view/lib/python3.9/site-packages/distributed/comm/core.py", line 319, in connect
    handshake = await asyncio.wait_for(comm.read(), time_left())
  File "/ccc/work/cont003/gen2224/gen2224/spack/var/spack/environments/gysela-deisa-irene-skl-draft/.spack-env/._view/whcr3wyhzgorszy3rfxsphyebtvfpqzk/lib/python3.9/asyncio/tasks.py", line 492, in wait_for
    raise exceptions.TimeoutError() from exc
asyncio.exceptions.TimeoutError

The above exception was the direct cause of the following exception:

Traceback (most recent call last):
  File "/ccc/work/cont003/gen2224/gen2224/spack/var/spack/environments/gysela-deisa-irene-skl-draft/.spack-env/view/lib/python3.9/site-packages/distributed/worker.py", line 2878, in gather_dep
    response = await get_data_from_worker(
  File "/ccc/work/cont003/gen2224/gen2224/spack/var/spack/environments/gysela-deisa-irene-skl-draft/.spack-env/view/lib/python3.9/site-packages/distributed/worker.py", line 4143, in get_data_from_worker
    return await retry_operation(_get_data, operation="get_data_from_worker")
  File "/ccc/work/cont003/gen2224/gen2224/spack/var/spack/environments/gysela-deisa-irene-skl-draft/.spack-env/view/lib/python3.9/site-packages/distributed/utils_comm.py", line 366, in retry_operation
    return await retry(
  File "/ccc/work/cont003/gen2224/gen2224/spack/var/spack/environments/gysela-deisa-irene-skl-draft/.spack-env/view/lib/python3.9/site-packages/distributed/utils_comm.py", line 351, in retry
    return await coro()
  File "/ccc/work/cont003/gen2224/gen2224/spack/var/spack/environments/gysela-deisa-irene-skl-draft/.spack-env/view/lib/python3.9/site-packages/distributed/worker.py", line 4120, in _get_data
    comm = await rpc.connect(worker)
  File "/ccc/work/cont003/gen2224/gen2224/spack/var/spack/environments/gysela-deisa-irene-skl-draft/.spack-env/view/lib/python3.9/site-packages/distributed/worker.py", line 4143, in get_data_from_worker
    return await retry_operation(_get_data, operation="get_data_from_worker")
  File "/ccc/work/cont003/gen2224/gen2224/spack/var/spack/environments/gysela-deisa-irene-skl-draft/.spack-env/view/lib/python3.9/site-packages/distributed/utils_comm.py", line 366, in retry_operation
    return await retry(
  File "/ccc/work/cont003/gen2224/gen2224/spack/var/spack/environments/gysela-deisa-irene-skl-draft/.spack-env/view/lib/python3.9/site-packages/distributed/utils_comm.py", line 351, in retry
    return await coro()
  File "/ccc/work/cont003/gen2224/gen2224/spack/var/spack/environments/gysela-deisa-irene-skl-draft/.spack-env/view/lib/python3.9/site-packages/distributed/worker.py", line 4120, in _get_data
    comm = await rpc.connect(worker)
  File "/ccc/work/cont003/gen2224/gen2224/spack/var/spack/environments/gysela-deisa-irene-skl-draft/.spack-env/view/lib/python3.9/site-packages/distributed/comm/core.py", line 319, in connect
    handshake = await asyncio.wait_for(comm.read(), time_left())
  File "/ccc/work/cont003/gen2224/gen2224/spack/var/spack/environments/gysela-deisa-irene-skl-draft/.spack-env/._view/whcr3wyhzgorszy3rfxsphyebtvfpqzk/lib/python3.9/asyncio/tasks.py", line 492, in wait_for
    raise exceptions.TimeoutError() from exc
asyncio.exceptions.TimeoutError

The above exception was the direct cause of the following exception:

Traceback (most recent call last):
  File "/ccc/work/cont003/gen2224/gen2224/spack/var/spack/environments/gysela-deisa-irene-skl-draft/.spack-env/view/lib/python3.9/site-packages/distributed/worker.py", line 2878, in gather_dep
    response = await get_data_from_worker(
  File "/ccc/work/cont003/gen2224/gen2224/spack/var/spack/environments/gysela-deisa-irene-skl-draft/.spack-env/view/lib/python3.9/site-packages/distributed/worker.py", line 4143, in get_data_from_worker
    return await retry_operation(_get_data, operation="get_data_from_worker")
  File "/ccc/work/cont003/gen2224/gen2224/spack/var/spack/environments/gysela-deisa-irene-skl-draft/.spack-env/view/lib/python3.9/site-packages/distributed/utils_comm.py", line 366, in retry_operation
    return await retry(
  File "/ccc/work/cont003/gen2224/gen2224/spack/var/spack/environments/gysela-deisa-irene-skl-draft/.spack-env/view/lib/python3.9/site-packages/distributed/utils_comm.py", line 351, in retry
    return await coro()
  File "/ccc/work/cont003/gen2224/gen2224/spack/var/spack/environments/gysela-deisa-irene-skl-draft/.spack-env/view/lib/python3.9/site-packages/distributed/worker.py", line 4120, in _get_data
    comm = await rpc.connect(worker)
  File "/ccc/work/cont003/gen2224/gen2224/spack/var/spack/environments/gysela-deisa-irene-skl-draft/.spack-env/view/lib/python3.9/site-packages/distributed/worker.py", line 4143, in get_data_from_worker
    return await retry_operation(_get_data, operation="get_data_from_worker")
  File "/ccc/work/cont003/gen2224/gen2224/spack/var/spack/environments/gysela-deisa-irene-skl-draft/.spack-env/view/lib/python3.9/site-packages/distributed/utils_comm.py", line 366, in retry_operation
    return await retry(
  File "/ccc/work/cont003/gen2224/gen2224/spack/var/spack/environments/gysela-deisa-irene-skl-draft/.spack-env/view/lib/python3.9/site-packages/distributed/utils_comm.py", line 351, in retry
    return await coro()
  File "/ccc/work/cont003/gen2224/gen2224/spack/var/spack/environments/gysela-deisa-irene-skl-draft/.spack-env/view/lib/python3.9/site-packages/distributed/worker.py", line 4120, in _get_data
    comm = await rpc.connect(worker)
  File "/ccc/work/cont003/gen2224/gen2224/spack/var/spack/environments/gysela-deisa-irene-skl-draft/.spack-env/view/lib/python3.9/site-packages/distributed/core.py", line 1081, in connect
    raise exc
  File "/ccc/work/cont003/gen2224/gen2224/spack/var/spack/environments/gysela-deisa-irene-skl-draft/.spack-env/view/lib/python3.9/site-packages/distributed/core.py", line 1065, in connect
    comm = await fut
  File "/ccc/work/cont003/gen2224/gen2224/spack/var/spack/environments/gysela-deisa-irene-skl-draft/.spack-env/view/lib/python3.9/site-packages/distributed/comm/core.py", line 324, in connect
    raise OSError(
OSError: Timed out during handshake while connecting to tcp://172.21.3.57:45485 after 30 s
distributed.worker - ERROR - Worker stream died during communication: tcp://172.21.3.57:45485
Traceback (most recent call last):
  File "/ccc/work/cont003/gen2224/gen2224/spack/var/spack/environments/gysela-deisa-irene-skl-draft/.spack-env/view/lib/python3.9/site-packages/distributed/comm/tcp.py", line 205, in read
    frames_nbytes = await stream.read_bytes(fmt_size)
asyncio.exceptions.CancelledError

During handling of the above exception, another exception occurred:

Traceback (most recent call last):
  File "/ccc/work/cont003/gen2224/gen2224/spack/var/spack/environments/gysela-deisa-irene-skl-draft/.spack-env/._view/whcr3wyhzgorszy3rfxsphyebtvfpqzk/lib/python3.9/asyncio/tasks.py", line 490, in wait_for
    return fut.result()
asyncio.exceptions.CancelledError

The above exception was the direct cause of the following exception:

Traceback (most recent call last):
  File "/ccc/work/cont003/gen2224/gen2224/spack/var/spack/environments/gysela-deisa-irene-skl-draft/.spack-env/view/lib/python3.9/site-packages/distributed/core.py", line 1081, in connect
    raise exc
  File "/ccc/work/cont003/gen2224/gen2224/spack/var/spack/environments/gysela-deisa-irene-skl-draft/.spack-env/view/lib/python3.9/site-packages/distributed/core.py", line 1065, in connect
    comm = await fut
  File "/ccc/work/cont003/gen2224/gen2224/spack/var/spack/environments/gysela-deisa-irene-skl-draft/.spack-env/view/lib/python3.9/site-packages/distributed/comm/core.py", line 324, in connect
    raise OSError(
OSError: Timed out during handshake while connecting to tcp://172.21.3.57:45485 after 30 s
  File "/ccc/work/cont003/gen2224/gen2224/spack/var/spack/environments/gysela-deisa-irene-skl-draft/.spack-env/view/lib/python3.9/site-packages/distributed/worker.py", line 4143, in get_data_from_worker
    return await retry_operation(_get_data, operation="get_data_from_worker")
  File "/ccc/work/cont003/gen2224/gen2224/spack/var/spack/environments/gysela-deisa-irene-skl-draft/.spack-env/view/lib/python3.9/site-packages/distributed/utils_comm.py", line 366, in retry_operation
    return await retry(
  File "/ccc/work/cont003/gen2224/gen2224/spack/var/spack/environments/gysela-deisa-irene-skl-draft/.spack-env/view/lib/python3.9/site-packages/distributed/utils_comm.py", line 351, in retry
    return await coro()
  File "/ccc/work/cont003/gen2224/gen2224/spack/var/spack/environments/gysela-deisa-irene-skl-draft/.spack-env/view/lib/python3.9/site-packages/distributed/worker.py", line 4120, in _get_data
    comm = await rpc.connect(worker)
  File "/ccc/work/cont003/gen2224/gen2224/spack/var/spack/environments/gysela-deisa-irene-skl-draft/.spack-env/view/lib/python3.9/site-packages/distributed/core.py", line 1081, in connect
    raise exc
  File "/ccc/work/cont003/gen2224/gen2224/spack/var/spack/environments/gysela-deisa-irene-skl-draft/.spack-env/view/lib/python3.9/site-packages/distributed/core.py", line 1065, in connect
    comm = await fut
  File "/ccc/work/cont003/gen2224/gen2224/spack/var/spack/environments/gysela-deisa-irene-skl-draft/.spack-env/view/lib/python3.9/site-packages/distributed/comm/core.py", line 324, in connect
    raise OSError(
OSError: Timed out during handshake while connecting to tcp://172.21.3.57:45485 after 30 s
  File "/ccc/work/cont003/gen2224/gen2224/spack/var/spack/environments/gysela-deisa-irene-skl-draft/.spack-env/view/lib/python3.9/site-packages/distributed/core.py", line 1081, in connect
    raise exc
  File "/ccc/work/cont003/gen2224/gen2224/spack/var/spack/environments/gysela-deisa-irene-skl-draft/.spack-env/view/lib/python3.9/site-packages/distributed/core.py", line 1065, in connect
    comm = await fut
  File "/ccc/work/cont003/gen2224/gen2224/spack/var/spack/environments/gysela-deisa-irene-skl-draft/.spack-env/view/lib/python3.9/site-packages/distributed/comm/core.py", line 324, in connect
    raise OSError(
OSError: Timed out during handshake while connecting to tcp://172.21.3.57:45485 after 30 s
distributed.worker - ERROR - Worker stream died during communication: tcp://172.21.3.57:45485
Traceback (most recent call last):
  File "/ccc/work/cont003/gen2224/gen2224/spack/var/spack/environments/gysela-deisa-irene-skl-draft/.spack-env/view/lib/python3.9/site-packages/distributed/comm/tcp.py", line 205, in read
    frames_nbytes = await stream.read_bytes(fmt_size)
asyncio.exceptions.CancelledError

During handling of the above exception, another exception occurred:

Traceback (most recent call last):
  File "/ccc/work/cont003/gen2224/gen2224/spack/var/spack/environments/gysela-deisa-irene-skl-draft/.spack-env/._view/whcr3wyhzgorszy3rfxsphyebtvfpqzk/lib/python3.9/asyncio/tasks.py", line 490, in wait_for
    return fut.result()
asyncio.exceptions.CancelledError

The above exception was the direct cause of the following exception:

Traceback (most recent call last):
  File "/ccc/work/cont003/gen2224/gen2224/spack/var/spack/environments/gysela-deisa-irene-skl-draft/.spack-env/view/lib/python3.9/site-packages/distributed/comm/core.py", line 319, in connect
    handshake = await asyncio.wait_for(comm.read(), time_left())
  File "/ccc/work/cont003/gen2224/gen2224/spack/var/spack/environments/gysela-deisa-irene-skl-draft/.spack-env/._view/whcr3wyhzgorszy3rfxsphyebtvfpqzk/lib/python3.9/asyncio/tasks.py", line 492, in wait_for
    raise exceptions.TimeoutError() from exc
asyncio.exceptions.TimeoutError

The above exception was the direct cause of the following exception:

Traceback (most recent call last):
  File "/ccc/work/cont003/gen2224/gen2224/spack/var/spack/environments/gysela-deisa-irene-skl-draft/.spack-env/view/lib/python3.9/site-packages/distributed/worker.py", line 2878, in gather_dep
    response = await get_data_from_worker(
  File "/ccc/work/cont003/gen2224/gen2224/spack/var/spack/environments/gysela-deisa-irene-skl-draft/.spack-env/view/lib/python3.9/site-packages/distributed/core.py", line 1081, in connect
    raise exc
  File "/ccc/work/cont003/gen2224/gen2224/spack/var/spack/environments/gysela-deisa-irene-skl-draft/.spack-env/view/lib/python3.9/site-packages/distributed/core.py", line 1065, in connect
    comm = await fut
  File "/ccc/work/cont003/gen2224/gen2224/spack/var/spack/environments/gysela-deisa-irene-skl-draft/.spack-env/view/lib/python3.9/site-packages/distributed/comm/core.py", line 324, in connect
    raise OSError(
OSError: Timed out during handshake while connecting to tcp://172.21.3.57:45485 after 30 s
distributed.worker - ERROR - Worker stream died during communication: tcp://172.21.3.57:45485
Traceback (most recent call last):
  File "/ccc/work/cont003/gen2224/gen2224/spack/var/spack/environments/gysela-deisa-irene-skl-draft/.spack-env/view/lib/python3.9/site-packages/distributed/comm/tcp.py", line 205, in read
    frames_nbytes = await stream.read_bytes(fmt_size)
asyncio.exceptions.CancelledError

During handling of the above exception, another exception occurred:

Traceback (most recent call last):
  File "/ccc/work/cont003/gen2224/gen2224/spack/var/spack/environments/gysela-deisa-irene-skl-draft/.spack-env/._view/whcr3wyhzgorszy3rfxsphyebtvfpqzk/lib/python3.9/asyncio/tasks.py", line 490, in wait_for
    return fut.result()
asyncio.exceptions.CancelledError

The above exception was the direct cause of the following exception:

Traceback (most recent call last):
distributed.worker - ERROR - Worker stream died during communication: tcp://172.21.3.57:45485
Traceback (most recent call last):
  File "/ccc/work/cont003/gen2224/gen2224/spack/var/spack/environments/gysela-deisa-irene-skl-draft/.spack-env/view/lib/python3.9/site-packages/distributed/comm/tcp.py", line 205, in read
    frames_nbytes = await stream.read_bytes(fmt_size)
asyncio.exceptions.CancelledError

During handling of the above exception, another exception occurred:

Traceback (most recent call last):
  File "/ccc/work/cont003/gen2224/gen2224/spack/var/spack/environments/gysela-deisa-irene-skl-draft/.spack-env/._view/whcr3wyhzgorszy3rfxsphyebtvfpqzk/lib/python3.9/asyncio/tasks.py", line 490, in wait_for
    return fut.result()
asyncio.exceptions.CancelledError

The above exception was the direct cause of the following exception:

Traceback (most recent call last):
  File "/ccc/work/cont003/gen2224/gen2224/spack/var/spack/environments/gysela-deisa-irene-skl-draft/.spack-env/view/lib/python3.9/site-packages/distributed/comm/core.py", line 319, in connect
    handshake = await asyncio.wait_for(comm.read(), time_left())
  File "/ccc/work/cont003/gen2224/gen2224/spack/var/spack/environments/gysela-deisa-irene-skl-draft/.spack-env/._view/whcr3wyhzgorszy3rfxsphyebtvfpqzk/lib/python3.9/asyncio/tasks.py", line 492, in wait_for
    raise exceptions.TimeoutError() from exc
asyncio.exceptions.TimeoutError

The above exception was the direct cause of the following exception:

Traceback (most recent call last):
  File "/ccc/work/cont003/gen2224/gen2224/spack/var/spack/environments/gysela-deisa-irene-skl-draft/.spack-env/view/lib/python3.9/site-packages/distributed/worker.py", line 2878, in gather_dep
    response = await get_data_from_worker(
  File "/ccc/work/cont003/gen2224/gen2224/spack/var/spack/environments/gysela-deisa-irene-skl-draft/.spack-env/view/lib/python3.9/site-packages/distributed/worker.py", line 4143, in get_data_from_worker
    return await retry_operation(_get_data, operation="get_data_from_worker")
  File "/ccc/work/cont003/gen2224/gen2224/spack/var/spack/environments/gysela-deisa-irene-skl-draft/.spack-env/view/lib/python3.9/site-packages/distributed/utils_comm.py", line 366, in retry_operation
    return await retry(
  File "/ccc/work/cont003/gen2224/gen2224/spack/var/spack/environments/gysela-deisa-irene-skl-draft/.spack-env/view/lib/python3.9/site-packages/distributed/utils_comm.py", line 351, in retry
    return await coro()
  File "/ccc/work/cont003/gen2224/gen2224/spack/var/spack/environments/gysela-deisa-irene-skl-draft/.spack-env/view/lib/python3.9/site-packages/distributed/worker.py", line 4120, in _get_data
    comm = await rpc.connect(worker)
distributed.worker - ERROR - Worker stream died during communication: tcp://172.21.3.57:45485
Traceback (most recent call last):
  File "/ccc/work/cont003/gen2224/gen2224/spack/var/spack/environments/gysela-deisa-irene-skl-draft/.spack-env/view/lib/python3.9/site-packages/distributed/comm/tcp.py", line 205, in read
    frames_nbytes = await stream.read_bytes(fmt_size)
asyncio.exceptions.CancelledError

During handling of the above exception, another exception occurred:

Traceback (most recent call last):
  File "/ccc/work/cont003/gen2224/gen2224/spack/var/spack/environments/gysela-deisa-irene-skl-draft/.spack-env/._view/whcr3wyhzgorszy3rfxsphyebtvfpqzk/lib/python3.9/asyncio/tasks.py", line 490, in wait_for
    return fut.result()
asyncio.exceptions.CancelledError

The above exception was the direct cause of the following exception:

Traceback (most recent call last):
  File "/ccc/work/cont003/gen2224/gen2224/spack/var/spack/environments/gysela-deisa-irene-skl-draft/.spack-env/view/lib/python3.9/site-packages/distributed/comm/core.py", line 319, in connect
    handshake = await asyncio.wait_for(comm.read(), time_left())
  File "/ccc/work/cont003/gen2224/gen2224/spack/var/spack/environments/gysela-deisa-irene-skl-draft/.spack-env/._view/whcr3wyhzgorszy3rfxsphyebtvfpqzk/lib/python3.9/asyncio/tasks.py", line 492, in wait_for
    raise exceptions.TimeoutError() from exc
asyncio.exceptions.TimeoutError

The above exception was the direct cause of the following exception:

Traceback (most recent call last):
  File "/ccc/work/cont003/gen2224/gen2224/spack/var/spack/environments/gysela-deisa-irene-skl-draft/.spack-env/view/lib/python3.9/site-packages/distributed/worker.py", line 2878, in gather_dep
    response = await get_data_from_worker(
  File "/ccc/work/cont003/gen2224/gen2224/spack/var/spack/environments/gysela-deisa-irene-skl-draft/.spack-env/view/lib/python3.9/site-packages/distributed/comm/core.py", line 319, in connect
    handshake = await asyncio.wait_for(comm.read(), time_left())
  File "/ccc/work/cont003/gen2224/gen2224/spack/var/spack/environments/gysela-deisa-irene-skl-draft/.spack-env/._view/whcr3wyhzgorszy3rfxsphyebtvfpqzk/lib/python3.9/asyncio/tasks.py", line 492, in wait_for
    raise exceptions.TimeoutError() from exc
asyncio.exceptions.TimeoutError

The above exception was the direct cause of the following exception:

Traceback (most recent call last):
  File "/ccc/work/cont003/gen2224/gen2224/spack/var/spack/environments/gysela-deisa-irene-skl-draft/.spack-env/view/lib/python3.9/site-packages/distributed/worker.py", line 2878, in gather_dep
    response = await get_data_from_worker(
  File "/ccc/work/cont003/gen2224/gen2224/spack/var/spack/environments/gysela-deisa-irene-skl-draft/.spack-env/view/lib/python3.9/site-packages/distributed/worker.py", line 4143, in get_data_from_worker
    return await retry_operation(_get_data, operation="get_data_from_worker")
  File "/ccc/work/cont003/gen2224/gen2224/spack/var/spack/environments/gysela-deisa-irene-skl-draft/.spack-env/view/lib/python3.9/site-packages/distributed/utils_comm.py", line 366, in retry_operation
    return await retry(
  File "/ccc/work/cont003/gen2224/gen2224/spack/var/spack/environments/gysela-deisa-irene-skl-draft/.spack-env/view/lib/python3.9/site-packages/distributed/utils_comm.py", line 351, in retry
    return await coro()
  File "/ccc/work/cont003/gen2224/gen2224/spack/var/spack/environments/gysela-deisa-irene-skl-draft/.spack-env/view/lib/python3.9/site-packages/distributed/worker.py", line 4120, in _get_data
    comm = await rpc.connect(worker)
  File "/ccc/work/cont003/gen2224/gen2224/spack/var/spack/environments/gysela-deisa-irene-skl-draft/.spack-env/view/lib/python3.9/site-packages/distributed/core.py", line 1081, in connect
    raise exc
  File "/ccc/work/cont003/gen2224/gen2224/spack/var/spack/environments/gysela-deisa-irene-skl-draft/.spack-env/view/lib/python3.9/site-packages/distributed/core.py", line 1065, in connect
    comm = await fut
  File "/ccc/work/cont003/gen2224/gen2224/spack/var/spack/environments/gysela-deisa-irene-skl-draft/.spack-env/view/lib/python3.9/site-packages/distributed/comm/core.py", line 324, in connect
    raise OSError(
OSError: Timed out during handshake while connecting to tcp://172.21.3.57:45485 after 30 s
  File "/ccc/work/cont003/gen2224/gen2224/spack/var/spack/environments/gysela-deisa-irene-skl-draft/.spack-env/view/lib/python3.9/site-packages/distributed/comm/core.py", line 319, in connect
    handshake = await asyncio.wait_for(comm.read(), time_left())
  File "/ccc/work/cont003/gen2224/gen2224/spack/var/spack/environments/gysela-deisa-irene-skl-draft/.spack-env/._view/whcr3wyhzgorszy3rfxsphyebtvfpqzk/lib/python3.9/asyncio/tasks.py", line 492, in wait_for
    raise exceptions.TimeoutError() from exc
asyncio.exceptions.TimeoutError

The above exception was the direct cause of the following exception:

Traceback (most recent call last):
  File "/ccc/work/cont003/gen2224/gen2224/spack/var/spack/environments/gysela-deisa-irene-skl-draft/.spack-env/view/lib/python3.9/site-packages/distributed/worker.py", line 2878, in gather_dep
    response = await get_data_from_worker(
  File "/ccc/work/cont003/gen2224/gen2224/spack/var/spack/environments/gysela-deisa-irene-skl-draft/.spack-env/view/lib/python3.9/site-packages/distributed/worker.py", line 4143, in get_data_from_worker
    return await retry_operation(_get_data, operation="get_data_from_worker")
  File "/ccc/work/cont003/gen2224/gen2224/spack/var/spack/environments/gysela-deisa-irene-skl-draft/.spack-env/view/lib/python3.9/site-packages/distributed/utils_comm.py", line 366, in retry_operation
    return await retry(
  File "/ccc/work/cont003/gen2224/gen2224/spack/var/spack/environments/gysela-deisa-irene-skl-draft/.spack-env/view/lib/python3.9/site-packages/distributed/utils_comm.py", line 351, in retry
    return await coro()
  File "/ccc/work/cont003/gen2224/gen2224/spack/var/spack/environments/gysela-deisa-irene-skl-draft/.spack-env/view/lib/python3.9/site-packages/distributed/worker.py", line 4120, in _get_data
    comm = await rpc.connect(worker)
  File "/ccc/work/cont003/gen2224/gen2224/spack/var/spack/environments/gysela-deisa-irene-skl-draft/.spack-env/view/lib/python3.9/site-packages/distributed/worker.py", line 4143, in get_data_from_worker
    return await retry_operation(_get_data, operation="get_data_from_worker")
  File "/ccc/work/cont003/gen2224/gen2224/spack/var/spack/environments/gysela-deisa-irene-skl-draft/.spack-env/view/lib/python3.9/site-packages/distributed/utils_comm.py", line 366, in retry_operation
    return await retry(
  File "/ccc/work/cont003/gen2224/gen2224/spack/var/spack/environments/gysela-deisa-irene-skl-draft/.spack-env/view/lib/python3.9/site-packages/distributed/utils_comm.py", line 351, in retry
    return await coro()
  File "/ccc/work/cont003/gen2224/gen2224/spack/var/spack/environments/gysela-deisa-irene-skl-draft/.spack-env/view/lib/python3.9/site-packages/distributed/worker.py", line 4120, in _get_data
    comm = await rpc.connect(worker)
  File "/ccc/work/cont003/gen2224/gen2224/spack/var/spack/environments/gysela-deisa-irene-skl-draft/.spack-env/view/lib/python3.9/site-packages/distributed/core.py", line 1081, in connect
    raise exc
  File "/ccc/work/cont003/gen2224/gen2224/spack/var/spack/environments/gysela-deisa-irene-skl-draft/.spack-env/view/lib/python3.9/site-packages/distributed/core.py", line 1065, in connect
    comm = await fut
  File "/ccc/work/cont003/gen2224/gen2224/spack/var/spack/environments/gysela-deisa-irene-skl-draft/.spack-env/view/lib/python3.9/site-packages/distributed/comm/core.py", line 324, in connect
    raise OSError(
OSError: Timed out during handshake while connecting to tcp://172.21.3.57:45485 after 30 s
  File "/ccc/work/cont003/gen2224/gen2224/spack/var/spack/environments/gysela-deisa-irene-skl-draft/.spack-env/view/lib/python3.9/site-packages/distributed/worker.py", line 4143, in get_data_from_worker
    return await retry_operation(_get_data, operation="get_data_from_worker")
  File "/ccc/work/cont003/gen2224/gen2224/spack/var/spack/environments/gysela-deisa-irene-skl-draft/.spack-env/view/lib/python3.9/site-packages/distributed/utils_comm.py", line 366, in retry_operation
    return await retry(
  File "/ccc/work/cont003/gen2224/gen2224/spack/var/spack/environments/gysela-deisa-irene-skl-draft/.spack-env/view/lib/python3.9/site-packages/distributed/utils_comm.py", line 351, in retry
    return await coro()
  File "/ccc/work/cont003/gen2224/gen2224/spack/var/spack/environments/gysela-deisa-irene-skl-draft/.spack-env/view/lib/python3.9/site-packages/distributed/worker.py", line 4120, in _get_data
    comm = await rpc.connect(worker)
  File "/ccc/work/cont003/gen2224/gen2224/spack/var/spack/environments/gysela-deisa-irene-skl-draft/.spack-env/view/lib/python3.9/site-packages/distributed/core.py", line 1081, in connect
    raise exc
  File "/ccc/work/cont003/gen2224/gen2224/spack/var/spack/environments/gysela-deisa-irene-skl-draft/.spack-env/view/lib/python3.9/site-packages/distributed/core.py", line 1065, in connect
    comm = await fut
  File "/ccc/work/cont003/gen2224/gen2224/spack/var/spack/environments/gysela-deisa-irene-skl-draft/.spack-env/view/lib/python3.9/site-packages/distributed/comm/core.py", line 324, in connect
    raise OSError(
OSError: Timed out during handshake while connecting to tcp://172.21.3.57:45485 after 30 s
  File "/ccc/work/cont003/gen2224/gen2224/spack/var/spack/environments/gysela-deisa-irene-skl-draft/.spack-env/view/lib/python3.9/site-packages/distributed/core.py", line 1081, in connect
    raise exc
  File "/ccc/work/cont003/gen2224/gen2224/spack/var/spack/environments/gysela-deisa-irene-skl-draft/.spack-env/view/lib/python3.9/site-packages/distributed/core.py", line 1065, in connect
    comm = await fut
  File "/ccc/work/cont003/gen2224/gen2224/spack/var/spack/environments/gysela-deisa-irene-skl-draft/.spack-env/view/lib/python3.9/site-packages/distributed/comm/core.py", line 324, in connect
    raise OSError(
OSError: Timed out during handshake while connecting to tcp://172.21.3.57:45485 after 30 s
  File "/ccc/work/cont003/gen2224/gen2224/spack/var/spack/environments/gysela-deisa-irene-skl-draft/.spack-env/view/lib/python3.9/site-packages/distributed/core.py", line 1081, in connect
    raise exc
  File "/ccc/work/cont003/gen2224/gen2224/spack/var/spack/environments/gysela-deisa-irene-skl-draft/.spack-env/view/lib/python3.9/site-packages/distributed/core.py", line 1065, in connect
    comm = await fut
  File "/ccc/work/cont003/gen2224/gen2224/spack/var/spack/environments/gysela-deisa-irene-skl-draft/.spack-env/view/lib/python3.9/site-packages/distributed/comm/core.py", line 324, in connect
    raise OSError(
OSError: Timed out during handshake while connecting to tcp://172.21.3.57:45485 after 30 s
distributed.worker - ERROR - Worker stream died during communication: tcp://172.21.3.57:45485
Traceback (most recent call last):
  File "/ccc/work/cont003/gen2224/gen2224/spack/var/spack/environments/gysela-deisa-irene-skl-draft/.spack-env/view/lib/python3.9/site-packages/distributed/comm/tcp.py", line 205, in read
    frames_nbytes = await stream.read_bytes(fmt_size)
asyncio.exceptions.CancelledError

During handling of the above exception, another exception occurred:

Traceback (most recent call last):
  File "/ccc/work/cont003/gen2224/gen2224/spack/var/spack/environments/gysela-deisa-irene-skl-draft/.spack-env/._view/whcr3wyhzgorszy3rfxsphyebtvfpqzk/lib/python3.9/asyncio/tasks.py", line 490, in wait_for
    return fut.result()
asyncio.exceptions.CancelledError

The above exception was the direct cause of the following exception:

Traceback (most recent call last):
  File "/ccc/work/cont003/gen2224/gen2224/spack/var/spack/environments/gysela-deisa-irene-skl-draft/.spack-env/view/lib/python3.9/site-packages/distributed/comm/core.py", line 319, in connect
    handshake = await asyncio.wait_for(comm.read(), time_left())
  File "/ccc/work/cont003/gen2224/gen2224/spack/var/spack/environments/gysela-deisa-irene-skl-draft/.spack-env/._view/whcr3wyhzgorszy3rfxsphyebtvfpqzk/lib/python3.9/asyncio/tasks.py", line 492, in wait_for
    raise exceptions.TimeoutError() from exc
asyncio.exceptions.TimeoutError

The above exception was the direct cause of the following exception:

Traceback (most recent call last):
  File "/ccc/work/cont003/gen2224/gen2224/spack/var/spack/environments/gysela-deisa-irene-skl-draft/.spack-env/view/lib/python3.9/site-packages/distributed/worker.py", line 2878, in gather_dep
    response = await get_data_from_worker(
  File "/ccc/work/cont003/gen2224/gen2224/spack/var/spack/environments/gysela-deisa-irene-skl-draft/.spack-env/view/lib/python3.9/site-packages/distributed/worker.py", line 4143, in get_data_from_worker
    return await retry_operation(_get_data, operation="get_data_from_worker")
  File "/ccc/work/cont003/gen2224/gen2224/spack/var/spack/environments/gysela-deisa-irene-skl-draft/.spack-env/view/lib/python3.9/site-packages/distributed/utils_comm.py", line 366, in retry_operation
    return await retry(
  File "/ccc/work/cont003/gen2224/gen2224/spack/var/spack/environments/gysela-deisa-irene-skl-draft/.spack-env/view/lib/python3.9/site-packages/distributed/utils_comm.py", line 351, in retry
    return await coro()
  File "/ccc/work/cont003/gen2224/gen2224/spack/var/spack/environments/gysela-deisa-irene-skl-draft/.spack-env/view/lib/python3.9/site-packages/distributed/worker.py", line 4120, in _get_data
    comm = await rpc.connect(worker)
  File "/ccc/work/cont003/gen2224/gen2224/spack/var/spack/environments/gysela-deisa-irene-skl-draft/.spack-env/view/lib/python3.9/site-packages/distributed/core.py", line 1081, in connect
    raise exc
  File "/ccc/work/cont003/gen2224/gen2224/spack/var/spack/environments/gysela-deisa-irene-skl-draft/.spack-env/view/lib/python3.9/site-packages/distributed/core.py", line 1065, in connect
    comm = await fut
  File "/ccc/work/cont003/gen2224/gen2224/spack/var/spack/environments/gysela-deisa-irene-skl-draft/.spack-env/view/lib/python3.9/site-packages/distributed/comm/core.py", line 324, in connect
    raise OSError(
OSError: Timed out during handshake while connecting to tcp://172.21.3.57:45485 after 30 s
distributed.worker - ERROR - Worker stream died during communication: tcp://172.21.3.57:45485
Traceback (most recent call last):
  File "/ccc/work/cont003/gen2224/gen2224/spack/var/spack/environments/gysela-deisa-irene-skl-draft/.spack-env/view/lib/python3.9/site-packages/distributed/comm/tcp.py", line 205, in read
    frames_nbytes = await stream.read_bytes(fmt_size)
asyncio.exceptions.CancelledError

During handling of the above exception, another exception occurred:

Traceback (most recent call last):
  File "/ccc/work/cont003/gen2224/gen2224/spack/var/spack/environments/gysela-deisa-irene-skl-draft/.spack-env/._view/whcr3wyhzgorszy3rfxsphyebtvfpqzk/lib/python3.9/asyncio/tasks.py", line 490, in wait_for
    return fut.result()
asyncio.exceptions.CancelledError

The above exception was the direct cause of the following exception:

Traceback (most recent call last):
  File "/ccc/work/cont003/gen2224/gen2224/spack/var/spack/environments/gysela-deisa-irene-skl-draft/.spack-env/view/lib/python3.9/site-packages/distributed/comm/core.py", line 319, in connect
    handshake = await asyncio.wait_for(comm.read(), time_left())
  File "/ccc/work/cont003/gen2224/gen2224/spack/var/spack/environments/gysela-deisa-irene-skl-draft/.spack-env/._view/whcr3wyhzgorszy3rfxsphyebtvfpqzk/lib/python3.9/asyncio/tasks.py", line 492, in wait_for
    raise exceptions.TimeoutError() from exc
asyncio.exceptions.TimeoutError

The above exception was the direct cause of the following exception:

Traceback (most recent call last):
  File "/ccc/work/cont003/gen2224/gen2224/spack/var/spack/environments/gysela-deisa-irene-skl-draft/.spack-env/view/lib/python3.9/site-packages/distributed/worker.py", line 2878, in gather_dep
    response = await get_data_from_worker(
  File "/ccc/work/cont003/gen2224/gen2224/spack/var/spack/environments/gysela-deisa-irene-skl-draft/.spack-env/view/lib/python3.9/site-packages/distributed/worker.py", line 4143, in get_data_from_worker
    return await retry_operation(_get_data, operation="get_data_from_worker")
  File "/ccc/work/cont003/gen2224/gen2224/spack/var/spack/environments/gysela-deisa-irene-skl-draft/.spack-env/view/lib/python3.9/site-packages/distributed/utils_comm.py", line 366, in retry_operation
    return await retry(
  File "/ccc/work/cont003/gen2224/gen2224/spack/var/spack/environments/gysela-deisa-irene-skl-draft/.spack-env/view/lib/python3.9/site-packages/distributed/utils_comm.py", line 351, in retry
    return await coro()
  File "/ccc/work/cont003/gen2224/gen2224/spack/var/spack/environments/gysela-deisa-irene-skl-draft/.spack-env/view/lib/python3.9/site-packages/distributed/worker.py", line 4120, in _get_data
    comm = await rpc.connect(worker)
  File "/ccc/work/cont003/gen2224/gen2224/spack/var/spack/environments/gysela-deisa-irene-skl-draft/.spack-env/view/lib/python3.9/site-packages/distributed/core.py", line 1081, in connect
    raise exc
  File "/ccc/work/cont003/gen2224/gen2224/spack/var/spack/environments/gysela-deisa-irene-skl-draft/.spack-env/view/lib/python3.9/site-packages/distributed/core.py", line 1065, in connect
    comm = await fut
  File "/ccc/work/cont003/gen2224/gen2224/spack/var/spack/environments/gysela-deisa-irene-skl-draft/.spack-env/view/lib/python3.9/site-packages/distributed/comm/core.py", line 324, in connect
    raise OSError(
OSError: Timed out during handshake while connecting to tcp://172.21.3.57:45485 after 30 s
distributed.worker - ERROR - Worker stream died during communication: tcp://172.21.3.57:45485
Traceback (most recent call last):
  File "/ccc/work/cont003/gen2224/gen2224/spack/var/spack/environments/gysela-deisa-irene-skl-draft/.spack-env/view/lib/python3.9/site-packages/distributed/comm/tcp.py", line 205, in read
    frames_nbytes = await stream.read_bytes(fmt_size)
asyncio.exceptions.CancelledError

During handling of the above exception, another exception occurred:

Traceback (most recent call last):
  File "/ccc/work/cont003/gen2224/gen2224/spack/var/spack/environments/gysela-deisa-irene-skl-draft/.spack-env/._view/whcr3wyhzgorszy3rfxsphyebtvfpqzk/lib/python3.9/asyncio/tasks.py", line 490, in wait_for
    return fut.result()
asyncio.exceptions.CancelledError

The above exception was the direct cause of the following exception:

Traceback (most recent call last):
  File "/ccc/work/cont003/gen2224/gen2224/spack/var/spack/environments/gysela-deisa-irene-skl-draft/.spack-env/view/lib/python3.9/site-packages/distributed/comm/core.py", line 319, in connect
    handshake = await asyncio.wait_for(comm.read(), time_left())
  File "/ccc/work/cont003/gen2224/gen2224/spack/var/spack/environments/gysela-deisa-irene-skl-draft/.spack-env/._view/whcr3wyhzgorszy3rfxsphyebtvfpqzk/lib/python3.9/asyncio/tasks.py", line 492, in wait_for
    raise exceptions.TimeoutError() from exc
asyncio.exceptions.TimeoutError

The above exception was the direct cause of the following exception:

Traceback (most recent call last):
  File "/ccc/work/cont003/gen2224/gen2224/spack/var/spack/environments/gysela-deisa-irene-skl-draft/.spack-env/view/lib/python3.9/site-packages/distributed/worker.py", line 2878, in gather_dep
    response = await get_data_from_worker(
  File "/ccc/work/cont003/gen2224/gen2224/spack/var/spack/environments/gysela-deisa-irene-skl-draft/.spack-env/view/lib/python3.9/site-packages/distributed/worker.py", line 4143, in get_data_from_worker
    return await retry_operation(_get_data, operation="get_data_from_worker")
  File "/ccc/work/cont003/gen2224/gen2224/spack/var/spack/environments/gysela-deisa-irene-skl-draft/.spack-env/view/lib/python3.9/site-packages/distributed/utils_comm.py", line 366, in retry_operation
    return await retry(
  File "/ccc/work/cont003/gen2224/gen2224/spack/var/spack/environments/gysela-deisa-irene-skl-draft/.spack-env/view/lib/python3.9/site-packages/distributed/utils_comm.py", line 351, in retry
    return await coro()
  File "/ccc/work/cont003/gen2224/gen2224/spack/var/spack/environments/gysela-deisa-irene-skl-draft/.spack-env/view/lib/python3.9/site-packages/distributed/worker.py", line 4120, in _get_data
    comm = await rpc.connect(worker)
  File "/ccc/work/cont003/gen2224/gen2224/spack/var/spack/environments/gysela-deisa-irene-skl-draft/.spack-env/view/lib/python3.9/site-packages/distributed/core.py", line 1081, in connect
    raise exc
  File "/ccc/work/cont003/gen2224/gen2224/spack/var/spack/environments/gysela-deisa-irene-skl-draft/.spack-env/view/lib/python3.9/site-packages/distributed/core.py", line 1065, in connect
    comm = await fut
  File "/ccc/work/cont003/gen2224/gen2224/spack/var/spack/environments/gysela-deisa-irene-skl-draft/.spack-env/view/lib/python3.9/site-packages/distributed/comm/core.py", line 324, in connect
    raise OSError(
OSError: Timed out during handshake while connecting to tcp://172.21.3.57:45485 after 30 s
distributed.worker - ERROR - Worker stream died during communication: tcp://172.21.3.57:45485
Traceback (most recent call last):
  File "/ccc/work/cont003/gen2224/gen2224/spack/var/spack/environments/gysela-deisa-irene-skl-draft/.spack-env/view/lib/python3.9/site-packages/distributed/comm/tcp.py", line 205, in read
    frames_nbytes = await stream.read_bytes(fmt_size)
asyncio.exceptions.CancelledError

During handling of the above exception, another exception occurred:

Traceback (most recent call last):
  File "/ccc/work/cont003/gen2224/gen2224/spack/var/spack/environments/gysela-deisa-irene-skl-draft/.spack-env/._view/whcr3wyhzgorszy3rfxsphyebtvfpqzk/lib/python3.9/asyncio/tasks.py", line 490, in wait_for
    return fut.result()
asyncio.exceptions.CancelledError

The above exception was the direct cause of the following exception:

Traceback (most recent call last):
  File "/ccc/work/cont003/gen2224/gen2224/spack/var/spack/environments/gysela-deisa-irene-skl-draft/.spack-env/view/lib/python3.9/site-packages/distributed/comm/core.py", line 319, in connect
    handshake = await asyncio.wait_for(comm.read(), time_left())
  File "/ccc/work/cont003/gen2224/gen2224/spack/var/spack/environments/gysela-deisa-irene-skl-draft/.spack-env/._view/whcr3wyhzgorszy3rfxsphyebtvfpqzk/lib/python3.9/asyncio/tasks.py", line 492, in wait_for
    raise exceptions.TimeoutError() from exc
asyncio.exceptions.TimeoutError

The above exception was the direct cause of the following exception:

Traceback (most recent call last):
  File "/ccc/work/cont003/gen2224/gen2224/spack/var/spack/environments/gysela-deisa-irene-skl-draft/.spack-env/view/lib/python3.9/site-packages/distributed/worker.py", line 2878, in gather_dep
    response = await get_data_from_worker(
  File "/ccc/work/cont003/gen2224/gen2224/spack/var/spack/environments/gysela-deisa-irene-skl-draft/.spack-env/view/lib/python3.9/site-packages/distributed/worker.py", line 4143, in get_data_from_worker
    return await retry_operation(_get_data, operation="get_data_from_worker")
  File "/ccc/work/cont003/gen2224/gen2224/spack/var/spack/environments/gysela-deisa-irene-skl-draft/.spack-env/view/lib/python3.9/site-packages/distributed/utils_comm.py", line 366, in retry_operation
    return await retry(
  File "/ccc/work/cont003/gen2224/gen2224/spack/var/spack/environments/gysela-deisa-irene-skl-draft/.spack-env/view/lib/python3.9/site-packages/distributed/utils_comm.py", line 351, in retry
    return await coro()
  File "/ccc/work/cont003/gen2224/gen2224/spack/var/spack/environments/gysela-deisa-irene-skl-draft/.spack-env/view/lib/python3.9/site-packages/distributed/worker.py", line 4120, in _get_data
    comm = await rpc.connect(worker)
  File "/ccc/work/cont003/gen2224/gen2224/spack/var/spack/environments/gysela-deisa-irene-skl-draft/.spack-env/view/lib/python3.9/site-packages/distributed/core.py", line 1081, in connect
    raise exc
  File "/ccc/work/cont003/gen2224/gen2224/spack/var/spack/environments/gysela-deisa-irene-skl-draft/.spack-env/view/lib/python3.9/site-packages/distributed/core.py", line 1065, in connect
    comm = await fut
  File "/ccc/work/cont003/gen2224/gen2224/spack/var/spack/environments/gysela-deisa-irene-skl-draft/.spack-env/view/lib/python3.9/site-packages/distributed/comm/core.py", line 324, in connect
    raise OSError(
OSError: Timed out during handshake while connecting to tcp://172.21.3.57:45485 after 30 s
distributed.worker - ERROR - Worker stream died during communication: tcp://172.21.3.57:45485
Traceback (most recent call last):
  File "/ccc/work/cont003/gen2224/gen2224/spack/var/spack/environments/gysela-deisa-irene-skl-draft/.spack-env/view/lib/python3.9/site-packages/distributed/comm/tcp.py", line 205, in read
    frames_nbytes = await stream.read_bytes(fmt_size)
asyncio.exceptions.CancelledError

During handling of the above exception, another exception occurred:

Traceback (most recent call last):
  File "/ccc/work/cont003/gen2224/gen2224/spack/var/spack/environments/gysela-deisa-irene-skl-draft/.spack-env/._view/whcr3wyhzgorszy3rfxsphyebtvfpqzk/lib/python3.9/asyncio/tasks.py", line 490, in wait_for
    return fut.result()
asyncio.exceptions.CancelledError

The above exception was the direct cause of the following exception:

Traceback (most recent call last):
  File "/ccc/work/cont003/gen2224/gen2224/spack/var/spack/environments/gysela-deisa-irene-skl-draft/.spack-env/view/lib/python3.9/site-packages/distributed/comm/core.py", line 319, in connect
    handshake = await asyncio.wait_for(comm.read(), time_left())
  File "/ccc/work/cont003/gen2224/gen2224/spack/var/spack/environments/gysela-deisa-irene-skl-draft/.spack-env/._view/whcr3wyhzgorszy3rfxsphyebtvfpqzk/lib/python3.9/asyncio/tasks.py", line 492, in wait_for
    raise exceptions.TimeoutError() from exc
asyncio.exceptions.TimeoutError

The above exception was the direct cause of the following exception:

Traceback (most recent call last):
  File "/ccc/work/cont003/gen2224/gen2224/spack/var/spack/environments/gysela-deisa-irene-skl-draft/.spack-env/view/lib/python3.9/site-packages/distributed/worker.py", line 2878, in gather_dep
    response = await get_data_from_worker(
  File "/ccc/work/cont003/gen2224/gen2224/spack/var/spack/environments/gysela-deisa-irene-skl-draft/.spack-env/view/lib/python3.9/site-packages/distributed/worker.py", line 4143, in get_data_from_worker
    return await retry_operation(_get_data, operation="get_data_from_worker")
  File "/ccc/work/cont003/gen2224/gen2224/spack/var/spack/environments/gysela-deisa-irene-skl-draft/.spack-env/view/lib/python3.9/site-packages/distributed/utils_comm.py", line 366, in retry_operation
    return await retry(
  File "/ccc/work/cont003/gen2224/gen2224/spack/var/spack/environments/gysela-deisa-irene-skl-draft/.spack-env/view/lib/python3.9/site-packages/distributed/utils_comm.py", line 351, in retry
    return await coro()
  File "/ccc/work/cont003/gen2224/gen2224/spack/var/spack/environments/gysela-deisa-irene-skl-draft/.spack-env/view/lib/python3.9/site-packages/distributed/worker.py", line 4120, in _get_data
    comm = await rpc.connect(worker)
  File "/ccc/work/cont003/gen2224/gen2224/spack/var/spack/environments/gysela-deisa-irene-skl-draft/.spack-env/view/lib/python3.9/site-packages/distributed/core.py", line 1081, in connect
    raise exc
  File "/ccc/work/cont003/gen2224/gen2224/spack/var/spack/environments/gysela-deisa-irene-skl-draft/.spack-env/view/lib/python3.9/site-packages/distributed/core.py", line 1065, in connect
    comm = await fut
  File "/ccc/work/cont003/gen2224/gen2224/spack/var/spack/environments/gysela-deisa-irene-skl-draft/.spack-env/view/lib/python3.9/site-packages/distributed/comm/core.py", line 324, in connect
    raise OSError(
OSError: Timed out during handshake while connecting to tcp://172.21.3.57:45485 after 30 s
distributed.worker - ERROR - Worker stream died during communication: tcp://172.21.3.57:45485
Traceback (most recent call last):
  File "/ccc/work/cont003/gen2224/gen2224/spack/var/spack/environments/gysela-deisa-irene-skl-draft/.spack-env/view/lib/python3.9/site-packages/distributed/comm/tcp.py", line 205, in read
    frames_nbytes = await stream.read_bytes(fmt_size)
asyncio.exceptions.CancelledError

During handling of the above exception, another exception occurred:

Traceback (most recent call last):
  File "/ccc/work/cont003/gen2224/gen2224/spack/var/spack/environments/gysela-deisa-irene-skl-draft/.spack-env/._view/whcr3wyhzgorszy3rfxsphyebtvfpqzk/lib/python3.9/asyncio/tasks.py", line 490, in wait_for
    return fut.result()
asyncio.exceptions.CancelledError

The above exception was the direct cause of the following exception:

Traceback (most recent call last):
  File "/ccc/work/cont003/gen2224/gen2224/spack/var/spack/environments/gysela-deisa-irene-skl-draft/.spack-env/view/lib/python3.9/site-packages/distributed/comm/core.py", line 319, in connect
    handshake = await asyncio.wait_for(comm.read(), time_left())
  File "/ccc/work/cont003/gen2224/gen2224/spack/var/spack/environments/gysela-deisa-irene-skl-draft/.spack-env/._view/whcr3wyhzgorszy3rfxsphyebtvfpqzk/lib/python3.9/asyncio/tasks.py", line 492, in wait_for
    raise exceptions.TimeoutError() from exc
asyncio.exceptions.TimeoutError

The above exception was the direct cause of the following exception:

Traceback (most recent call last):
  File "/ccc/work/cont003/gen2224/gen2224/spack/var/spack/environments/gysela-deisa-irene-skl-draft/.spack-env/view/lib/python3.9/site-packages/distributed/worker.py", line 2878, in gather_dep
    response = await get_data_from_worker(
  File "/ccc/work/cont003/gen2224/gen2224/spack/var/spack/environments/gysela-deisa-irene-skl-draft/.spack-env/view/lib/python3.9/site-packages/distributed/worker.py", line 4143, in get_data_from_worker
    return await retry_operation(_get_data, operation="get_data_from_worker")
  File "/ccc/work/cont003/gen2224/gen2224/spack/var/spack/environments/gysela-deisa-irene-skl-draft/.spack-env/view/lib/python3.9/site-packages/distributed/utils_comm.py", line 366, in retry_operation
    return await retry(
  File "/ccc/work/cont003/gen2224/gen2224/spack/var/spack/environments/gysela-deisa-irene-skl-draft/.spack-env/view/lib/python3.9/site-packages/distributed/utils_comm.py", line 351, in retry
    return await coro()
  File "/ccc/work/cont003/gen2224/gen2224/spack/var/spack/environments/gysela-deisa-irene-skl-draft/.spack-env/view/lib/python3.9/site-packages/distributed/worker.py", line 4120, in _get_data
    comm = await rpc.connect(worker)
  File "/ccc/work/cont003/gen2224/gen2224/spack/var/spack/environments/gysela-deisa-irene-skl-draft/.spack-env/view/lib/python3.9/site-packages/distributed/core.py", line 1081, in connect
    raise exc
  File "/ccc/work/cont003/gen2224/gen2224/spack/var/spack/environments/gysela-deisa-irene-skl-draft/.spack-env/view/lib/python3.9/site-packages/distributed/core.py", line 1065, in connect
    comm = await fut
  File "/ccc/work/cont003/gen2224/gen2224/spack/var/spack/environments/gysela-deisa-irene-skl-draft/.spack-env/view/lib/python3.9/site-packages/distributed/comm/core.py", line 324, in connect
    raise OSError(
OSError: Timed out during handshake while connecting to tcp://172.21.3.57:45485 after 30 s
distributed.worker - ERROR - Worker stream died during communication: tcp://172.21.3.57:45485
Traceback (most recent call last):
  File "/ccc/work/cont003/gen2224/gen2224/spack/var/spack/environments/gysela-deisa-irene-skl-draft/.spack-env/view/lib/python3.9/site-packages/distributed/comm/tcp.py", line 205, in read
    frames_nbytes = await stream.read_bytes(fmt_size)
asyncio.exceptions.CancelledError

During handling of the above exception, another exception occurred:

Traceback (most recent call last):
  File "/ccc/work/cont003/gen2224/gen2224/spack/var/spack/environments/gysela-deisa-irene-skl-draft/.spack-env/._view/whcr3wyhzgorszy3rfxsphyebtvfpqzk/lib/python3.9/asyncio/tasks.py", line 490, in wait_for
    return fut.result()
asyncio.exceptions.CancelledError

The above exception was the direct cause of the following exception:

Traceback (most recent call last):
distributed.worker - ERROR - Worker stream died during communication: tcp://172.21.3.57:45485
Traceback (most recent call last):
  File "/ccc/work/cont003/gen2224/gen2224/spack/var/spack/environments/gysela-deisa-irene-skl-draft/.spack-env/view/lib/python3.9/site-packages/distributed/comm/tcp.py", line 205, in read
    frames_nbytes = await stream.read_bytes(fmt_size)
asyncio.exceptions.CancelledError

During handling of the above exception, another exception occurred:

Traceback (most recent call last):
  File "/ccc/work/cont003/gen2224/gen2224/spack/var/spack/environments/gysela-deisa-irene-skl-draft/.spack-env/._view/whcr3wyhzgorszy3rfxsphyebtvfpqzk/lib/python3.9/asyncio/tasks.py", line 490, in wait_for
    return fut.result()
asyncio.exceptions.CancelledError

The above exception was the direct cause of the following exception:

Traceback (most recent call last):
  File "/ccc/work/cont003/gen2224/gen2224/spack/var/spack/environments/gysela-deisa-irene-skl-draft/.spack-env/view/lib/python3.9/site-packages/distributed/comm/core.py", line 319, in connect
    handshake = await asyncio.wait_for(comm.read(), time_left())
  File "/ccc/work/cont003/gen2224/gen2224/spack/var/spack/environments/gysela-deisa-irene-skl-draft/.spack-env/._view/whcr3wyhzgorszy3rfxsphyebtvfpqzk/lib/python3.9/asyncio/tasks.py", line 492, in wait_for
    raise exceptions.TimeoutError() from exc
asyncio.exceptions.TimeoutError

The above exception was the direct cause of the following exception:

Traceback (most recent call last):
  File "/ccc/work/cont003/gen2224/gen2224/spack/var/spack/environments/gysela-deisa-irene-skl-draft/.spack-env/view/lib/python3.9/site-packages/distributed/worker.py", line 2878, in gather_dep
    response = await get_data_from_worker(
  File "/ccc/work/cont003/gen2224/gen2224/spack/var/spack/environments/gysela-deisa-irene-skl-draft/.spack-env/view/lib/python3.9/site-packages/distributed/comm/core.py", line 319, in connect
    handshake = await asyncio.wait_for(comm.read(), time_left())
  File "/ccc/work/cont003/gen2224/gen2224/spack/var/spack/environments/gysela-deisa-irene-skl-draft/.spack-env/._view/whcr3wyhzgorszy3rfxsphyebtvfpqzk/lib/python3.9/asyncio/tasks.py", line 492, in wait_for
    raise exceptions.TimeoutError() from exc
asyncio.exceptions.TimeoutError

The above exception was the direct cause of the following exception:

Traceback (most recent call last):
  File "/ccc/work/cont003/gen2224/gen2224/spack/var/spack/environments/gysela-deisa-irene-skl-draft/.spack-env/view/lib/python3.9/site-packages/distributed/worker.py", line 2878, in gather_dep
    response = await get_data_from_worker(
  File "/ccc/work/cont003/gen2224/gen2224/spack/var/spack/environments/gysela-deisa-irene-skl-draft/.spack-env/view/lib/python3.9/site-packages/distributed/worker.py", line 4143, in get_data_from_worker
    return await retry_operation(_get_data, operation="get_data_from_worker")
  File "/ccc/work/cont003/gen2224/gen2224/spack/var/spack/environments/gysela-deisa-irene-skl-draft/.spack-env/view/lib/python3.9/site-packages/distributed/utils_comm.py", line 366, in retry_operation
    return await retry(
  File "/ccc/work/cont003/gen2224/gen2224/spack/var/spack/environments/gysela-deisa-irene-skl-draft/.spack-env/view/lib/python3.9/site-packages/distributed/utils_comm.py", line 351, in retry
    return await coro()
  File "/ccc/work/cont003/gen2224/gen2224/spack/var/spack/environments/gysela-deisa-irene-skl-draft/.spack-env/view/lib/python3.9/site-packages/distributed/worker.py", line 4120, in _get_data
    comm = await rpc.connect(worker)
  File "/ccc/work/cont003/gen2224/gen2224/spack/var/spack/environments/gysela-deisa-irene-skl-draft/.spack-env/view/lib/python3.9/site-packages/distributed/worker.py", line 4143, in get_data_from_worker
    return await retry_operation(_get_data, operation="get_data_from_worker")
  File "/ccc/work/cont003/gen2224/gen2224/spack/var/spack/environments/gysela-deisa-irene-skl-draft/.spack-env/view/lib/python3.9/site-packages/distributed/utils_comm.py", line 366, in retry_operation
    return await retry(
  File "/ccc/work/cont003/gen2224/gen2224/spack/var/spack/environments/gysela-deisa-irene-skl-draft/.spack-env/view/lib/python3.9/site-packages/distributed/utils_comm.py", line 351, in retry
    return await coro()
  File "/ccc/work/cont003/gen2224/gen2224/spack/var/spack/environments/gysela-deisa-irene-skl-draft/.spack-env/view/lib/python3.9/site-packages/distributed/worker.py", line 4120, in _get_data
    comm = await rpc.connect(worker)
distributed.worker - ERROR - Worker stream died during communication: tcp://172.21.3.57:45485
Traceback (most recent call last):
  File "/ccc/work/cont003/gen2224/gen2224/spack/var/spack/environments/gysela-deisa-irene-skl-draft/.spack-env/view/lib/python3.9/site-packages/distributed/comm/tcp.py", line 205, in read
    frames_nbytes = await stream.read_bytes(fmt_size)
asyncio.exceptions.CancelledError

During handling of the above exception, another exception occurred:

Traceback (most recent call last):
  File "/ccc/work/cont003/gen2224/gen2224/spack/var/spack/environments/gysela-deisa-irene-skl-draft/.spack-env/._view/whcr3wyhzgorszy3rfxsphyebtvfpqzk/lib/python3.9/asyncio/tasks.py", line 490, in wait_for
    return fut.result()
asyncio.exceptions.CancelledError

The above exception was the direct cause of the following exception:

Traceback (most recent call last):
  File "/ccc/work/cont003/gen2224/gen2224/spack/var/spack/environments/gysela-deisa-irene-skl-draft/.spack-env/view/lib/python3.9/site-packages/distributed/core.py", line 1081, in connect
    raise exc
  File "/ccc/work/cont003/gen2224/gen2224/spack/var/spack/environments/gysela-deisa-irene-skl-draft/.spack-env/view/lib/python3.9/site-packages/distributed/core.py", line 1065, in connect
    comm = await fut
  File "/ccc/work/cont003/gen2224/gen2224/spack/var/spack/environments/gysela-deisa-irene-skl-draft/.spack-env/view/lib/python3.9/site-packages/distributed/comm/core.py", line 324, in connect
    raise OSError(
OSError: Timed out during handshake while connecting to tcp://172.21.3.57:45485 after 30 s
  File "/ccc/work/cont003/gen2224/gen2224/spack/var/spack/environments/gysela-deisa-irene-skl-draft/.spack-env/view/lib/python3.9/site-packages/distributed/core.py", line 1081, in connect
    raise exc
  File "/ccc/work/cont003/gen2224/gen2224/spack/var/spack/environments/gysela-deisa-irene-skl-draft/.spack-env/view/lib/python3.9/site-packages/distributed/core.py", line 1065, in connect
    comm = await fut
  File "/ccc/work/cont003/gen2224/gen2224/spack/var/spack/environments/gysela-deisa-irene-skl-draft/.spack-env/view/lib/python3.9/site-packages/distributed/comm/core.py", line 324, in connect
    raise OSError(
OSError: Timed out during handshake while connecting to tcp://172.21.3.57:45485 after 30 s
  File "/ccc/work/cont003/gen2224/gen2224/spack/var/spack/environments/gysela-deisa-irene-skl-draft/.spack-env/view/lib/python3.9/site-packages/distributed/comm/core.py", line 319, in connect
    handshake = await asyncio.wait_for(comm.read(), time_left())
  File "/ccc/work/cont003/gen2224/gen2224/spack/var/spack/environments/gysela-deisa-irene-skl-draft/.spack-env/._view/whcr3wyhzgorszy3rfxsphyebtvfpqzk/lib/python3.9/asyncio/tasks.py", line 492, in wait_for
    raise exceptions.TimeoutError() from exc
asyncio.exceptions.TimeoutError

The above exception was the direct cause of the following exception:

Traceback (most recent call last):
  File "/ccc/work/cont003/gen2224/gen2224/spack/var/spack/environments/gysela-deisa-irene-skl-draft/.spack-env/view/lib/python3.9/site-packages/distributed/worker.py", line 2878, in gather_dep
    response = await get_data_from_worker(
distributed.worker - ERROR - Worker stream died during communication: tcp://172.21.3.57:45485
Traceback (most recent call last):
  File "/ccc/work/cont003/gen2224/gen2224/spack/var/spack/environments/gysela-deisa-irene-skl-draft/.spack-env/view/lib/python3.9/site-packages/distributed/comm/tcp.py", line 205, in read
    frames_nbytes = await stream.read_bytes(fmt_size)
asyncio.exceptions.CancelledError

During handling of the above exception, another exception occurred:

Traceback (most recent call last):
  File "/ccc/work/cont003/gen2224/gen2224/spack/var/spack/environments/gysela-deisa-irene-skl-draft/.spack-env/._view/whcr3wyhzgorszy3rfxsphyebtvfpqzk/lib/python3.9/asyncio/tasks.py", line 490, in wait_for
    return fut.result()
asyncio.exceptions.CancelledError

The above exception was the direct cause of the following exception:

Traceback (most recent call last):
  File "/ccc/work/cont003/gen2224/gen2224/spack/var/spack/environments/gysela-deisa-irene-skl-draft/.spack-env/view/lib/python3.9/site-packages/distributed/worker.py", line 4143, in get_data_from_worker
    return await retry_operation(_get_data, operation="get_data_from_worker")
  File "/ccc/work/cont003/gen2224/gen2224/spack/var/spack/environments/gysela-deisa-irene-skl-draft/.spack-env/view/lib/python3.9/site-packages/distributed/utils_comm.py", line 366, in retry_operation
    return await retry(
  File "/ccc/work/cont003/gen2224/gen2224/spack/var/spack/environments/gysela-deisa-irene-skl-draft/.spack-env/view/lib/python3.9/site-packages/distributed/utils_comm.py", line 351, in retry
    return await coro()
  File "/ccc/work/cont003/gen2224/gen2224/spack/var/spack/environments/gysela-deisa-irene-skl-draft/.spack-env/view/lib/python3.9/site-packages/distributed/worker.py", line 4120, in _get_data
    comm = await rpc.connect(worker)
  File "/ccc/work/cont003/gen2224/gen2224/spack/var/spack/environments/gysela-deisa-irene-skl-draft/.spack-env/view/lib/python3.9/site-packages/distributed/comm/core.py", line 319, in connect
    handshake = await asyncio.wait_for(comm.read(), time_left())
  File "/ccc/work/cont003/gen2224/gen2224/spack/var/spack/environments/gysela-deisa-irene-skl-draft/.spack-env/._view/whcr3wyhzgorszy3rfxsphyebtvfpqzk/lib/python3.9/asyncio/tasks.py", line 492, in wait_for
    raise exceptions.TimeoutError() from exc
asyncio.exceptions.TimeoutError

The above exception was the direct cause of the following exception:

Traceback (most recent call last):
  File "/ccc/work/cont003/gen2224/gen2224/spack/var/spack/environments/gysela-deisa-irene-skl-draft/.spack-env/view/lib/python3.9/site-packages/distributed/worker.py", line 2878, in gather_dep
    response = await get_data_from_worker(
  File "/ccc/work/cont003/gen2224/gen2224/spack/var/spack/environments/gysela-deisa-irene-skl-draft/.spack-env/view/lib/python3.9/site-packages/distributed/core.py", line 1081, in connect
    raise exc
  File "/ccc/work/cont003/gen2224/gen2224/spack/var/spack/environments/gysela-deisa-irene-skl-draft/.spack-env/view/lib/python3.9/site-packages/distributed/core.py", line 1065, in connect
    comm = await fut
  File "/ccc/work/cont003/gen2224/gen2224/spack/var/spack/environments/gysela-deisa-irene-skl-draft/.spack-env/view/lib/python3.9/site-packages/distributed/comm/core.py", line 324, in connect
    raise OSError(
OSError: Timed out during handshake while connecting to tcp://172.21.3.57:45485 after 30 s
  File "/ccc/work/cont003/gen2224/gen2224/spack/var/spack/environments/gysela-deisa-irene-skl-draft/.spack-env/view/lib/python3.9/site-packages/distributed/worker.py", line 4143, in get_data_from_worker
    return await retry_operation(_get_data, operation="get_data_from_worker")
  File "/ccc/work/cont003/gen2224/gen2224/spack/var/spack/environments/gysela-deisa-irene-skl-draft/.spack-env/view/lib/python3.9/site-packages/distributed/utils_comm.py", line 366, in retry_operation
    return await retry(
  File "/ccc/work/cont003/gen2224/gen2224/spack/var/spack/environments/gysela-deisa-irene-skl-draft/.spack-env/view/lib/python3.9/site-packages/distributed/utils_comm.py", line 351, in retry
    return await coro()
  File "/ccc/work/cont003/gen2224/gen2224/spack/var/spack/environments/gysela-deisa-irene-skl-draft/.spack-env/view/lib/python3.9/site-packages/distributed/worker.py", line 4120, in _get_data
    comm = await rpc.connect(worker)
distributed.worker - ERROR - Worker stream died during communication: tcp://172.21.3.57:45485
Traceback (most recent call last):
  File "/ccc/work/cont003/gen2224/gen2224/spack/var/spack/environments/gysela-deisa-irene-skl-draft/.spack-env/view/lib/python3.9/site-packages/distributed/comm/tcp.py", line 205, in read
    frames_nbytes = await stream.read_bytes(fmt_size)
asyncio.exceptions.CancelledError

During handling of the above exception, another exception occurred:

Traceback (most recent call last):
  File "/ccc/work/cont003/gen2224/gen2224/spack/var/spack/environments/gysela-deisa-irene-skl-draft/.spack-env/._view/whcr3wyhzgorszy3rfxsphyebtvfpqzk/lib/python3.9/asyncio/tasks.py", line 490, in wait_for
    return fut.result()
asyncio.exceptions.CancelledError

The above exception was the direct cause of the following exception:

Traceback (most recent call last):
  File "/ccc/work/cont003/gen2224/gen2224/spack/var/spack/environments/gysela-deisa-irene-skl-draft/.spack-env/view/lib/python3.9/site-packages/distributed/core.py", line 1081, in connect
    raise exc
  File "/ccc/work/cont003/gen2224/gen2224/spack/var/spack/environments/gysela-deisa-irene-skl-draft/.spack-env/view/lib/python3.9/site-packages/distributed/core.py", line 1065, in connect
    comm = await fut
  File "/ccc/work/cont003/gen2224/gen2224/spack/var/spack/environments/gysela-deisa-irene-skl-draft/.spack-env/view/lib/python3.9/site-packages/distributed/comm/core.py", line 324, in connect
    raise OSError(
OSError: Timed out during handshake while connecting to tcp://172.21.3.57:45485 after 30 s
  File "/ccc/work/cont003/gen2224/gen2224/spack/var/spack/environments/gysela-deisa-irene-skl-draft/.spack-env/view/lib/python3.9/site-packages/distributed/comm/core.py", line 319, in connect
    handshake = await asyncio.wait_for(comm.read(), time_left())
  File "/ccc/work/cont003/gen2224/gen2224/spack/var/spack/environments/gysela-deisa-irene-skl-draft/.spack-env/._view/whcr3wyhzgorszy3rfxsphyebtvfpqzk/lib/python3.9/asyncio/tasks.py", line 492, in wait_for
    raise exceptions.TimeoutError() from exc
asyncio.exceptions.TimeoutError

The above exception was the direct cause of the following exception:

Traceback (most recent call last):
  File "/ccc/work/cont003/gen2224/gen2224/spack/var/spack/environments/gysela-deisa-irene-skl-draft/.spack-env/view/lib/python3.9/site-packages/distributed/worker.py", line 2878, in gather_dep
    response = await get_data_from_worker(
  File "/ccc/work/cont003/gen2224/gen2224/spack/var/spack/environments/gysela-deisa-irene-skl-draft/.spack-env/view/lib/python3.9/site-packages/distributed/worker.py", line 4143, in get_data_from_worker
    return await retry_operation(_get_data, operation="get_data_from_worker")
  File "/ccc/work/cont003/gen2224/gen2224/spack/var/spack/environments/gysela-deisa-irene-skl-draft/.spack-env/view/lib/python3.9/site-packages/distributed/utils_comm.py", line 366, in retry_operation
    return await retry(
  File "/ccc/work/cont003/gen2224/gen2224/spack/var/spack/environments/gysela-deisa-irene-skl-draft/.spack-env/view/lib/python3.9/site-packages/distributed/utils_comm.py", line 351, in retry
    return await coro()
  File "/ccc/work/cont003/gen2224/gen2224/spack/var/spack/environments/gysela-deisa-irene-skl-draft/.spack-env/view/lib/python3.9/site-packages/distributed/worker.py", line 4120, in _get_data
    comm = await rpc.connect(worker)
  File "/ccc/work/cont003/gen2224/gen2224/spack/var/spack/environments/gysela-deisa-irene-skl-draft/.spack-env/view/lib/python3.9/site-packages/distributed/core.py", line 1081, in connect
    raise exc
  File "/ccc/work/cont003/gen2224/gen2224/spack/var/spack/environments/gysela-deisa-irene-skl-draft/.spack-env/view/lib/python3.9/site-packages/distributed/core.py", line 1065, in connect
    comm = await fut
  File "/ccc/work/cont003/gen2224/gen2224/spack/var/spack/environments/gysela-deisa-irene-skl-draft/.spack-env/view/lib/python3.9/site-packages/distributed/comm/core.py", line 324, in connect
    raise OSError(
OSError: Timed out during handshake while connecting to tcp://172.21.3.57:45485 after 30 s
distributed.worker - ERROR - Worker stream died during communication: tcp://172.21.3.57:45485
Traceback (most recent call last):
  File "/ccc/work/cont003/gen2224/gen2224/spack/var/spack/environments/gysela-deisa-irene-skl-draft/.spack-env/view/lib/python3.9/site-packages/distributed/comm/tcp.py", line 205, in read
    frames_nbytes = await stream.read_bytes(fmt_size)
asyncio.exceptions.CancelledError

During handling of the above exception, another exception occurred:

Traceback (most recent call last):
  File "/ccc/work/cont003/gen2224/gen2224/spack/var/spack/environments/gysela-deisa-irene-skl-draft/.spack-env/._view/whcr3wyhzgorszy3rfxsphyebtvfpqzk/lib/python3.9/asyncio/tasks.py", line 490, in wait_for
    return fut.result()
asyncio.exceptions.CancelledError

The above exception was the direct cause of the following exception:

Traceback (most recent call last):
  File "/ccc/work/cont003/gen2224/gen2224/spack/var/spack/environments/gysela-deisa-irene-skl-draft/.spack-env/view/lib/python3.9/site-packages/distributed/comm/core.py", line 319, in connect
    handshake = await asyncio.wait_for(comm.read(), time_left())
  File "/ccc/work/cont003/gen2224/gen2224/spack/var/spack/environments/gysela-deisa-irene-skl-draft/.spack-env/._view/whcr3wyhzgorszy3rfxsphyebtvfpqzk/lib/python3.9/asyncio/tasks.py", line 492, in wait_for
    raise exceptions.TimeoutError() from exc
asyncio.exceptions.TimeoutError

The above exception was the direct cause of the following exception:

Traceback (most recent call last):
  File "/ccc/work/cont003/gen2224/gen2224/spack/var/spack/environments/gysela-deisa-irene-skl-draft/.spack-env/view/lib/python3.9/site-packages/distributed/worker.py", line 2878, in gather_dep
    response = await get_data_from_worker(
  File "/ccc/work/cont003/gen2224/gen2224/spack/var/spack/environments/gysela-deisa-irene-skl-draft/.spack-env/view/lib/python3.9/site-packages/distributed/worker.py", line 4143, in get_data_from_worker
    return await retry_operation(_get_data, operation="get_data_from_worker")
  File "/ccc/work/cont003/gen2224/gen2224/spack/var/spack/environments/gysela-deisa-irene-skl-draft/.spack-env/view/lib/python3.9/site-packages/distributed/utils_comm.py", line 366, in retry_operation
    return await retry(
  File "/ccc/work/cont003/gen2224/gen2224/spack/var/spack/environments/gysela-deisa-irene-skl-draft/.spack-env/view/lib/python3.9/site-packages/distributed/utils_comm.py", line 351, in retry
    return await coro()
  File "/ccc/work/cont003/gen2224/gen2224/spack/var/spack/environments/gysela-deisa-irene-skl-draft/.spack-env/view/lib/python3.9/site-packages/distributed/worker.py", line 4120, in _get_data
    comm = await rpc.connect(worker)
  File "/ccc/work/cont003/gen2224/gen2224/spack/var/spack/environments/gysela-deisa-irene-skl-draft/.spack-env/view/lib/python3.9/site-packages/distributed/core.py", line 1081, in connect
    raise exc
  File "/ccc/work/cont003/gen2224/gen2224/spack/var/spack/environments/gysela-deisa-irene-skl-draft/.spack-env/view/lib/python3.9/site-packages/distributed/core.py", line 1065, in connect
    comm = await fut
  File "/ccc/work/cont003/gen2224/gen2224/spack/var/spack/environments/gysela-deisa-irene-skl-draft/.spack-env/view/lib/python3.9/site-packages/distributed/comm/core.py", line 324, in connect
    raise OSError(
OSError: Timed out during handshake while connecting to tcp://172.21.3.57:45485 after 30 s
distributed.utils - ERROR - 'array-original-3f48072de5e5a51716fc264ce77dff1f'
Traceback (most recent call last):
  File "/ccc/work/cont003/gen2224/gen2224/spack/var/spack/environments/gysela-deisa-irene-skl-draft/.spack-env/view/lib/python3.9/site-packages/distributed/utils.py", line 684, in log_errors
    yield
  File "/ccc/work/cont003/gen2224/gen2224/spack/var/spack/environments/gysela-deisa-irene-skl-draft/.spack-env/view/lib/python3.9/site-packages/distributed/worker.py", line 2929, in gather_dep
    ts = self.tasks[d]
KeyError: 'array-original-3f48072de5e5a51716fc264ce77dff1f'
tornado.application - ERROR - Exception in callback functools.partial(<bound method IOLoop._discard_future_result of <tornado.platform.asyncio.AsyncIOLoop object at 0x2ba1169a48b0>>, <Task finished name='Task-6974' coro=<Worker.gather_dep() done, defined at /ccc/work/cont003/gen2224/gen2224/spack/var/spack/environments/gysela-deisa-irene-skl-draft/.spack-env/view/lib/python3.9/site-packages/distributed/worker.py:2823> exception=KeyError('array-original-3f48072de5e5a51716fc264ce77dff1f')>)
Traceback (most recent call last):
  File "/ccc/work/cont003/gen2224/gen2224/spack/var/spack/environments/gysela-deisa-irene-skl-draft/.spack-env/view/lib/python3.9/site-packages/tornado/ioloop.py", line 741, in _run_callback
    ret = callback()
  File "/ccc/work/cont003/gen2224/gen2224/spack/var/spack/environments/gysela-deisa-irene-skl-draft/.spack-env/view/lib/python3.9/site-packages/tornado/ioloop.py", line 765, in _discard_future_result
    future.result()
  File "/ccc/work/cont003/gen2224/gen2224/spack/var/spack/environments/gysela-deisa-irene-skl-draft/.spack-env/view/lib/python3.9/site-packages/distributed/worker.py", line 2929, in gather_dep
    ts = self.tasks[d]
KeyError: 'array-original-3f48072de5e5a51716fc264ce77dff1f'
distributed.worker - ERROR - Worker stream died during communication: tcp://172.21.3.57:45485
Traceback (most recent call last):
  File "/ccc/work/cont003/gen2224/gen2224/spack/var/spack/environments/gysela-deisa-irene-skl-draft/.spack-env/view/lib/python3.9/site-packages/distributed/comm/tcp.py", line 205, in read
    frames_nbytes = await stream.read_bytes(fmt_size)
asyncio.exceptions.CancelledError

During handling of the above exception, another exception occurred:

Traceback (most recent call last):
  File "/ccc/work/cont003/gen2224/gen2224/spack/var/spack/environments/gysela-deisa-irene-skl-draft/.spack-env/._view/whcr3wyhzgorszy3rfxsphyebtvfpqzk/lib/python3.9/asyncio/tasks.py", line 490, in wait_for
    return fut.result()
asyncio.exceptions.CancelledError

The above exception was the direct cause of the following exception:

Traceback (most recent call last):
  File "/ccc/work/cont003/gen2224/gen2224/spack/var/spack/environments/gysela-deisa-irene-skl-draft/.spack-env/view/lib/python3.9/site-packages/distributed/comm/core.py", line 319, in connect
    handshake = await asyncio.wait_for(comm.read(), time_left())
  File "/ccc/work/cont003/gen2224/gen2224/spack/var/spack/environments/gysela-deisa-irene-skl-draft/.spack-env/._view/whcr3wyhzgorszy3rfxsphyebtvfpqzk/lib/python3.9/asyncio/tasks.py", line 492, in wait_for
    raise exceptions.TimeoutError() from exc
asyncio.exceptions.TimeoutError

The above exception was the direct cause of the following exception:

Traceback (most recent call last):
  File "/ccc/work/cont003/gen2224/gen2224/spack/var/spack/environments/gysela-deisa-irene-skl-draft/.spack-env/view/lib/python3.9/site-packages/distributed/worker.py", line 2878, in gather_dep
    response = await get_data_from_worker(
  File "/ccc/work/cont003/gen2224/gen2224/spack/var/spack/environments/gysela-deisa-irene-skl-draft/.spack-env/view/lib/python3.9/site-packages/distributed/worker.py", line 4143, in get_data_from_worker
    return await retry_operation(_get_data, operation="get_data_from_worker")
  File "/ccc/work/cont003/gen2224/gen2224/spack/var/spack/environments/gysela-deisa-irene-skl-draft/.spack-env/view/lib/python3.9/site-packages/distributed/utils_comm.py", line 366, in retry_operation
    return await retry(
  File "/ccc/work/cont003/gen2224/gen2224/spack/var/spack/environments/gysela-deisa-irene-skl-draft/.spack-env/view/lib/python3.9/site-packages/distributed/utils_comm.py", line 351, in retry
    return await coro()
  File "/ccc/work/cont003/gen2224/gen2224/spack/var/spack/environments/gysela-deisa-irene-skl-draft/.spack-env/view/lib/python3.9/site-packages/distributed/worker.py", line 4120, in _get_data
    comm = await rpc.connect(worker)
  File "/ccc/work/cont003/gen2224/gen2224/spack/var/spack/environments/gysela-deisa-irene-skl-draft/.spack-env/view/lib/python3.9/site-packages/distributed/core.py", line 1081, in connect
    raise exc
  File "/ccc/work/cont003/gen2224/gen2224/spack/var/spack/environments/gysela-deisa-irene-skl-draft/.spack-env/view/lib/python3.9/site-packages/distributed/core.py", line 1065, in connect
    comm = await fut
  File "/ccc/work/cont003/gen2224/gen2224/spack/var/spack/environments/gysela-deisa-irene-skl-draft/.spack-env/view/lib/python3.9/site-packages/distributed/comm/core.py", line 324, in connect
    raise OSError(
OSError: Timed out during handshake while connecting to tcp://172.21.3.57:45485 after 30 s
distributed.utils - ERROR - 'array-original-3f48072de5e5a51716fc264ce77dff1f'
Traceback (most recent call last):
  File "/ccc/work/cont003/gen2224/gen2224/spack/var/spack/environments/gysela-deisa-irene-skl-draft/.spack-env/view/lib/python3.9/site-packages/distributed/utils.py", line 684, in log_errors
    yield
  File "/ccc/work/cont003/gen2224/gen2224/spack/var/spack/environments/gysela-deisa-irene-skl-draft/.spack-env/view/lib/python3.9/site-packages/distributed/worker.py", line 2929, in gather_dep
    ts = self.tasks[d]
KeyError: 'array-original-3f48072de5e5a51716fc264ce77dff1f'
tornado.application - ERROR - Exception in callback functools.partial(<bound method IOLoop._discard_future_result of <tornado.platform.asyncio.AsyncIOLoop object at 0x2b71818828b0>>, <Task finished name='Task-6972' coro=<Worker.gather_dep() done, defined at /ccc/work/cont003/gen2224/gen2224/spack/var/spack/environments/gysela-deisa-irene-skl-draft/.spack-env/view/lib/python3.9/site-packages/distributed/worker.py:2823> exception=KeyError('array-original-3f48072de5e5a51716fc264ce77dff1f')>)
Traceback (most recent call last):
  File "/ccc/work/cont003/gen2224/gen2224/spack/var/spack/environments/gysela-deisa-irene-skl-draft/.spack-env/view/lib/python3.9/site-packages/tornado/ioloop.py", line 741, in _run_callback
    ret = callback()
  File "/ccc/work/cont003/gen2224/gen2224/spack/var/spack/environments/gysela-deisa-irene-skl-draft/.spack-env/view/lib/python3.9/site-packages/tornado/ioloop.py", line 765, in _discard_future_result
    future.result()
  File "/ccc/work/cont003/gen2224/gen2224/spack/var/spack/environments/gysela-deisa-irene-skl-draft/.spack-env/view/lib/python3.9/site-packages/distributed/worker.py", line 2929, in gather_dep
    ts = self.tasks[d]
KeyError: 'array-original-3f48072de5e5a51716fc264ce77dff1f'
distributed.utils - ERROR - 'array-original-3f48072de5e5a51716fc264ce77dff1f'
Traceback (most recent call last):
  File "/ccc/work/cont003/gen2224/gen2224/spack/var/spack/environments/gysela-deisa-irene-skl-draft/.spack-env/view/lib/python3.9/site-packages/distributed/utils.py", line 684, in log_errors
    yield
  File "/ccc/work/cont003/gen2224/gen2224/spack/var/spack/environments/gysela-deisa-irene-skl-draft/.spack-env/view/lib/python3.9/site-packages/distributed/worker.py", line 2929, in gather_dep
    ts = self.tasks[d]
KeyError: 'array-original-3f48072de5e5a51716fc264ce77dff1f'
tornado.application - ERROR - Exception in callback functools.partial(<bound method IOLoop._discard_future_result of <tornado.platform.asyncio.AsyncIOLoop object at 0x2b818370c8b0>>, <Task finished name='Task-6973' coro=<Worker.gather_dep() done, defined at /ccc/work/cont003/gen2224/gen2224/spack/var/spack/environments/gysela-deisa-irene-skl-draft/.spack-env/view/lib/python3.9/site-packages/distributed/worker.py:2823> exception=KeyError('array-original-3f48072de5e5a51716fc264ce77dff1f')>)
Traceback (most recent call last):
  File "/ccc/work/cont003/gen2224/gen2224/spack/var/spack/environments/gysela-deisa-irene-skl-draft/.spack-env/view/lib/python3.9/site-packages/tornado/ioloop.py", line 741, in _run_callback
    ret = callback()
  File "/ccc/work/cont003/gen2224/gen2224/spack/var/spack/environments/gysela-deisa-irene-skl-draft/.spack-env/view/lib/python3.9/site-packages/tornado/ioloop.py", line 765, in _discard_future_result
    future.result()
  File "/ccc/work/cont003/gen2224/gen2224/spack/var/spack/environments/gysela-deisa-irene-skl-draft/.spack-env/view/lib/python3.9/site-packages/distributed/worker.py", line 2929, in gather_dep
    ts = self.tasks[d]
KeyError: 'array-original-3f48072de5e5a51716fc264ce77dff1f'
distributed.utils - ERROR - 'array-original-3f48072de5e5a51716fc264ce77dff1f'
Traceback (most recent call last):
  File "/ccc/work/cont003/gen2224/gen2224/spack/var/spack/environments/gysela-deisa-irene-skl-draft/.spack-env/view/lib/python3.9/site-packages/distributed/utils.py", line 684, in log_errors
    yield
  File "/ccc/work/cont003/gen2224/gen2224/spack/var/spack/environments/gysela-deisa-irene-skl-draft/.spack-env/view/lib/python3.9/site-packages/distributed/worker.py", line 2929, in gather_dep
    ts = self.tasks[d]
KeyError: 'array-original-3f48072de5e5a51716fc264ce77dff1f'
tornado.application - ERROR - Exception in callback functools.partial(<bound method IOLoop._discard_future_result of <tornado.platform.asyncio.AsyncIOLoop object at 0x2ac5e7dfa8e0>>, <Task finished name='Task-6974' coro=<Worker.gather_dep() done, defined at /ccc/work/cont003/gen2224/gen2224/spack/var/spack/environments/gysela-deisa-irene-skl-draft/.spack-env/view/lib/python3.9/site-packages/distributed/worker.py:2823> exception=KeyError('array-original-3f48072de5e5a51716fc264ce77dff1f')>)
Traceback (most recent call last):
  File "/ccc/work/cont003/gen2224/gen2224/spack/var/spack/environments/gysela-deisa-irene-skl-draft/.spack-env/view/lib/python3.9/site-packages/tornado/ioloop.py", line 741, in _run_callback
    ret = callback()
  File "/ccc/work/cont003/gen2224/gen2224/spack/var/spack/environments/gysela-deisa-irene-skl-draft/.spack-env/view/lib/python3.9/site-packages/tornado/ioloop.py", line 765, in _discard_future_result
    future.result()
  File "/ccc/work/cont003/gen2224/gen2224/spack/var/spack/environments/gysela-deisa-irene-skl-draft/.spack-env/view/lib/python3.9/site-packages/distributed/worker.py", line 2929, in gather_dep
    ts = self.tasks[d]
KeyError: 'array-original-3f48072de5e5a51716fc264ce77dff1f'
distributed.worker - ERROR - Worker stream died during communication: tcp://172.21.3.57:45485
Traceback (most recent call last):
  File "/ccc/work/cont003/gen2224/gen2224/spack/var/spack/environments/gysela-deisa-irene-skl-draft/.spack-env/view/lib/python3.9/site-packages/distributed/comm/tcp.py", line 205, in read
    frames_nbytes = await stream.read_bytes(fmt_size)
asyncio.exceptions.CancelledError

During handling of the above exception, another exception occurred:

Traceback (most recent call last):
  File "/ccc/work/cont003/gen2224/gen2224/spack/var/spack/environments/gysela-deisa-irene-skl-draft/.spack-env/._view/whcr3wyhzgorszy3rfxsphyebtvfpqzk/lib/python3.9/asyncio/tasks.py", line 490, in wait_for
    return fut.result()
asyncio.exceptions.CancelledError

The above exception was the direct cause of the following exception:

Traceback (most recent call last):
  File "/ccc/work/cont003/gen2224/gen2224/spack/var/spack/environments/gysela-deisa-irene-skl-draft/.spack-env/view/lib/python3.9/site-packages/distributed/comm/core.py", line 319, in connect
    handshake = await asyncio.wait_for(comm.read(), time_left())
  File "/ccc/work/cont003/gen2224/gen2224/spack/var/spack/environments/gysela-deisa-irene-skl-draft/.spack-env/._view/whcr3wyhzgorszy3rfxsphyebtvfpqzk/lib/python3.9/asyncio/tasks.py", line 492, in wait_for
    raise exceptions.TimeoutError() from exc
asyncio.exceptions.TimeoutError

The above exception was the direct cause of the following exception:

Traceback (most recent call last):
  File "/ccc/work/cont003/gen2224/gen2224/spack/var/spack/environments/gysela-deisa-irene-skl-draft/.spack-env/view/lib/python3.9/site-packages/distributed/worker.py", line 2878, in gather_dep
    response = await get_data_from_worker(
  File "/ccc/work/cont003/gen2224/gen2224/spack/var/spack/environments/gysela-deisa-irene-skl-draft/.spack-env/view/lib/python3.9/site-packages/distributed/worker.py", line 4143, in get_data_from_worker
    return await retry_operation(_get_data, operation="get_data_from_worker")
  File "/ccc/work/cont003/gen2224/gen2224/spack/var/spack/environments/gysela-deisa-irene-skl-draft/.spack-env/view/lib/python3.9/site-packages/distributed/utils_comm.py", line 366, in retry_operation
    return await retry(
  File "/ccc/work/cont003/gen2224/gen2224/spack/var/spack/environments/gysela-deisa-irene-skl-draft/.spack-env/view/lib/python3.9/site-packages/distributed/utils_comm.py", line 351, in retry
    return await coro()
  File "/ccc/work/cont003/gen2224/gen2224/spack/var/spack/environments/gysela-deisa-irene-skl-draft/.spack-env/view/lib/python3.9/site-packages/distributed/worker.py", line 4120, in _get_data
    comm = await rpc.connect(worker)
  File "/ccc/work/cont003/gen2224/gen2224/spack/var/spack/environments/gysela-deisa-irene-skl-draft/.spack-env/view/lib/python3.9/site-packages/distributed/core.py", line 1081, in connect
    raise exc
  File "/ccc/work/cont003/gen2224/gen2224/spack/var/spack/environments/gysela-deisa-irene-skl-draft/.spack-env/view/lib/python3.9/site-packages/distributed/core.py", line 1065, in connect
    comm = await fut
  File "/ccc/work/cont003/gen2224/gen2224/spack/var/spack/environments/gysela-deisa-irene-skl-draft/.spack-env/view/lib/python3.9/site-packages/distributed/comm/core.py", line 324, in connect
    raise OSError(
OSError: Timed out during handshake while connecting to tcp://172.21.3.57:45485 after 30 s
distributed.worker - ERROR - Worker stream died during communication: tcp://172.21.3.57:45485
Traceback (most recent call last):
  File "/ccc/work/cont003/gen2224/gen2224/spack/var/spack/environments/gysela-deisa-irene-skl-draft/.spack-env/view/lib/python3.9/site-packages/distributed/comm/tcp.py", line 205, in read
    frames_nbytes = await stream.read_bytes(fmt_size)
asyncio.exceptions.CancelledError

During handling of the above exception, another exception occurred:

Traceback (most recent call last):
  File "/ccc/work/cont003/gen2224/gen2224/spack/var/spack/environments/gysela-deisa-irene-skl-draft/.spack-env/._view/whcr3wyhzgorszy3rfxsphyebtvfpqzk/lib/python3.9/asyncio/tasks.py", line 490, in wait_for
    return fut.result()
asyncio.exceptions.CancelledError

The above exception was the direct cause of the following exception:

Traceback (most recent call last):
  File "/ccc/work/cont003/gen2224/gen2224/spack/var/spack/environments/gysela-deisa-irene-skl-draft/.spack-env/view/lib/python3.9/site-packages/distributed/comm/core.py", line 319, in connect
    handshake = await asyncio.wait_for(comm.read(), time_left())
  File "/ccc/work/cont003/gen2224/gen2224/spack/var/spack/environments/gysela-deisa-irene-skl-draft/.spack-env/._view/whcr3wyhzgorszy3rfxsphyebtvfpqzk/lib/python3.9/asyncio/tasks.py", line 492, in wait_for
    raise exceptions.TimeoutError() from exc
asyncio.exceptions.TimeoutError

The above exception was the direct cause of the following exception:

Traceback (most recent call last):
  File "/ccc/work/cont003/gen2224/gen2224/spack/var/spack/environments/gysela-deisa-irene-skl-draft/.spack-env/view/lib/python3.9/site-packages/distributed/worker.py", line 2878, in gather_dep
    response = await get_data_from_worker(
  File "/ccc/work/cont003/gen2224/gen2224/spack/var/spack/environments/gysela-deisa-irene-skl-draft/.spack-env/view/lib/python3.9/site-packages/distributed/worker.py", line 4143, in get_data_from_worker
    return await retry_operation(_get_data, operation="get_data_from_worker")
  File "/ccc/work/cont003/gen2224/gen2224/spack/var/spack/environments/gysela-deisa-irene-skl-draft/.spack-env/view/lib/python3.9/site-packages/distributed/utils_comm.py", line 366, in retry_operation
    return await retry(
  File "/ccc/work/cont003/gen2224/gen2224/spack/var/spack/environments/gysela-deisa-irene-skl-draft/.spack-env/view/lib/python3.9/site-packages/distributed/utils_comm.py", line 351, in retry
    return await coro()
  File "/ccc/work/cont003/gen2224/gen2224/spack/var/spack/environments/gysela-deisa-irene-skl-draft/.spack-env/view/lib/python3.9/site-packages/distributed/worker.py", line 4120, in _get_data
    comm = await rpc.connect(worker)
  File "/ccc/work/cont003/gen2224/gen2224/spack/var/spack/environments/gysela-deisa-irene-skl-draft/.spack-env/view/lib/python3.9/site-packages/distributed/core.py", line 1081, in connect
    raise exc
  File "/ccc/work/cont003/gen2224/gen2224/spack/var/spack/environments/gysela-deisa-irene-skl-draft/.spack-env/view/lib/python3.9/site-packages/distributed/core.py", line 1065, in connect
    comm = await fut
  File "/ccc/work/cont003/gen2224/gen2224/spack/var/spack/environments/gysela-deisa-irene-skl-draft/.spack-env/view/lib/python3.9/site-packages/distributed/comm/core.py", line 324, in connect
    raise OSError(
OSError: Timed out during handshake while connecting to tcp://172.21.3.57:45485 after 30 s
distributed.utils - ERROR - 'array-original-3f48072de5e5a51716fc264ce77dff1f'
Traceback (most recent call last):
  File "/ccc/work/cont003/gen2224/gen2224/spack/var/spack/environments/gysela-deisa-irene-skl-draft/.spack-env/view/lib/python3.9/site-packages/distributed/utils.py", line 684, in log_errors
    yield
  File "/ccc/work/cont003/gen2224/gen2224/spack/var/spack/environments/gysela-deisa-irene-skl-draft/.spack-env/view/lib/python3.9/site-packages/distributed/worker.py", line 2929, in gather_dep
    ts = self.tasks[d]
KeyError: 'array-original-3f48072de5e5a51716fc264ce77dff1f'
tornado.application - ERROR - Exception in callback functools.partial(<bound method IOLoop._discard_future_result of <tornado.platform.asyncio.AsyncIOLoop object at 0x2b3c0f7578b0>>, <Task finished name='Task-6973' coro=<Worker.gather_dep() done, defined at /ccc/work/cont003/gen2224/gen2224/spack/var/spack/environments/gysela-deisa-irene-skl-draft/.spack-env/view/lib/python3.9/site-packages/distributed/worker.py:2823> exception=KeyError('array-original-3f48072de5e5a51716fc264ce77dff1f')>)
Traceback (most recent call last):
  File "/ccc/work/cont003/gen2224/gen2224/spack/var/spack/environments/gysela-deisa-irene-skl-draft/.spack-env/view/lib/python3.9/site-packages/tornado/ioloop.py", line 741, in _run_callback
    ret = callback()
  File "/ccc/work/cont003/gen2224/gen2224/spack/var/spack/environments/gysela-deisa-irene-skl-draft/.spack-env/view/lib/python3.9/site-packages/tornado/ioloop.py", line 765, in _discard_future_result
    future.result()
  File "/ccc/work/cont003/gen2224/gen2224/spack/var/spack/environments/gysela-deisa-irene-skl-draft/.spack-env/view/lib/python3.9/site-packages/distributed/worker.py", line 2929, in gather_dep
    ts = self.tasks[d]
KeyError: 'array-original-3f48072de5e5a51716fc264ce77dff1f'
distributed.worker - ERROR - Worker stream died during communication: tcp://172.21.3.57:45485
Traceback (most recent call last):
  File "/ccc/work/cont003/gen2224/gen2224/spack/var/spack/environments/gysela-deisa-irene-skl-draft/.spack-env/view/lib/python3.9/site-packages/distributed/comm/tcp.py", line 205, in read
    frames_nbytes = await stream.read_bytes(fmt_size)
asyncio.exceptions.CancelledError

During handling of the above exception, another exception occurred:

Traceback (most recent call last):
  File "/ccc/work/cont003/gen2224/gen2224/spack/var/spack/environments/gysela-deisa-irene-skl-draft/.spack-env/._view/whcr3wyhzgorszy3rfxsphyebtvfpqzk/lib/python3.9/asyncio/tasks.py", line 490, in wait_for
    return fut.result()
asyncio.exceptions.CancelledError

The above exception was the direct cause of the following exception:

Traceback (most recent call last):
  File "/ccc/work/cont003/gen2224/gen2224/spack/var/spack/environments/gysela-deisa-irene-skl-draft/.spack-env/view/lib/python3.9/site-packages/distributed/comm/core.py", line 319, in connect
    handshake = await asyncio.wait_for(comm.read(), time_left())
  File "/ccc/work/cont003/gen2224/gen2224/spack/var/spack/environments/gysela-deisa-irene-skl-draft/.spack-env/._view/whcr3wyhzgorszy3rfxsphyebtvfpqzk/lib/python3.9/asyncio/tasks.py", line 492, in wait_for
    raise exceptions.TimeoutError() from exc
asyncio.exceptions.TimeoutError

The above exception was the direct cause of the following exception:

Traceback (most recent call last):
  File "/ccc/work/cont003/gen2224/gen2224/spack/var/spack/environments/gysela-deisa-irene-skl-draft/.spack-env/view/lib/python3.9/site-packages/distributed/worker.py", line 2878, in gather_dep
    response = await get_data_from_worker(
  File "/ccc/work/cont003/gen2224/gen2224/spack/var/spack/environments/gysela-deisa-irene-skl-draft/.spack-env/view/lib/python3.9/site-packages/distributed/worker.py", line 4143, in get_data_from_worker
    return await retry_operation(_get_data, operation="get_data_from_worker")
  File "/ccc/work/cont003/gen2224/gen2224/spack/var/spack/environments/gysela-deisa-irene-skl-draft/.spack-env/view/lib/python3.9/site-packages/distributed/utils_comm.py", line 366, in retry_operation
    return await retry(
  File "/ccc/work/cont003/gen2224/gen2224/spack/var/spack/environments/gysela-deisa-irene-skl-draft/.spack-env/view/lib/python3.9/site-packages/distributed/utils_comm.py", line 351, in retry
    return await coro()
  File "/ccc/work/cont003/gen2224/gen2224/spack/var/spack/environments/gysela-deisa-irene-skl-draft/.spack-env/view/lib/python3.9/site-packages/distributed/worker.py", line 4120, in _get_data
    comm = await rpc.connect(worker)
  File "/ccc/work/cont003/gen2224/gen2224/spack/var/spack/environments/gysela-deisa-irene-skl-draft/.spack-env/view/lib/python3.9/site-packages/distributed/core.py", line 1081, in connect
    raise exc
  File "/ccc/work/cont003/gen2224/gen2224/spack/var/spack/environments/gysela-deisa-irene-skl-draft/.spack-env/view/lib/python3.9/site-packages/distributed/core.py", line 1065, in connect
    comm = await fut
  File "/ccc/work/cont003/gen2224/gen2224/spack/var/spack/environments/gysela-deisa-irene-skl-draft/.spack-env/view/lib/python3.9/site-packages/distributed/comm/core.py", line 324, in connect
    raise OSError(
OSError: Timed out during handshake while connecting to tcp://172.21.3.57:45485 after 30 s
distributed.worker - ERROR - Task array-original-3f48072de5e5a51716fc264ce77dff1f found in illegal state memory. Only states `flight`, `resumed` and `cancelled` possible.
Traceback (most recent call last):
  File "/ccc/work/cont003/gen2224/gen2224/spack/var/spack/environments/gysela-deisa-irene-skl-draft/.spack-env/view/lib/python3.9/site-packages/distributed/worker.py", line 2852, in gather_dep
    to_gather_keys, cancelled_keys, cause = self._filter_deps_for_fetch(
  File "/ccc/work/cont003/gen2224/gen2224/spack/var/spack/environments/gysela-deisa-irene-skl-draft/.spack-env/view/lib/python3.9/site-packages/distributed/worker.py", line 2759, in _filter_deps_for_fetch
    raise RuntimeError(
RuntimeError: Task array-original-3f48072de5e5a51716fc264ce77dff1f found in illegal state memory. Only states `flight`, `resumed` and `cancelled` possible.
distributed.utils - ERROR - Task array-original-3f48072de5e5a51716fc264ce77dff1f found in illegal state memory. Only states `flight`, `resumed` and `cancelled` possible.
Traceback (most recent call last):
  File "/ccc/work/cont003/gen2224/gen2224/spack/var/spack/environments/gysela-deisa-irene-skl-draft/.spack-env/view/lib/python3.9/site-packages/distributed/utils.py", line 684, in log_errors
    yield
  File "/ccc/work/cont003/gen2224/gen2224/spack/var/spack/environments/gysela-deisa-irene-skl-draft/.spack-env/view/lib/python3.9/site-packages/distributed/worker.py", line 2852, in gather_dep
    to_gather_keys, cancelled_keys, cause = self._filter_deps_for_fetch(
  File "/ccc/work/cont003/gen2224/gen2224/spack/var/spack/environments/gysela-deisa-irene-skl-draft/.spack-env/view/lib/python3.9/site-packages/distributed/worker.py", line 2759, in _filter_deps_for_fetch
    raise RuntimeError(
RuntimeError: Task array-original-3f48072de5e5a51716fc264ce77dff1f found in illegal state memory. Only states `flight`, `resumed` and `cancelled` possible.
distributed.worker - ERROR - Exception during execution of task ('array-3f48072de5e5a51716fc264ce77dff1f', 2, 7, 2).
Traceback (most recent call last):
  File "/ccc/work/cont003/gen2224/gen2224/spack/var/spack/environments/gysela-deisa-irene-skl-draft/.spack-env/view/lib/python3.9/site-packages/distributed/worker.py", line 3439, in _prepare_args_for_execution
    data[k] = self.data[k]
  File "/ccc/work/cont003/gen2224/gen2224/spack/var/spack/environments/gysela-deisa-irene-skl-draft/.spack-env/view/lib/python3.9/site-packages/zict/buffer.py", line 72, in __getitem__
    raise KeyError(key)
KeyError: 'array-original-3f48072de5e5a51716fc264ce77dff1f'

During handling of the above exception, another exception occurred:

Traceback (most recent call last):
  File "/ccc/work/cont003/gen2224/gen2224/spack/var/spack/environments/gysela-deisa-irene-skl-draft/.spack-env/view/lib/python3.9/site-packages/distributed/worker.py", line 3321, in execute
    args2, kwargs2 = self._prepare_args_for_execution(ts, args, kwargs)
  File "/ccc/work/cont003/gen2224/gen2224/spack/var/spack/environments/gysela-deisa-irene-skl-draft/.spack-env/view/lib/python3.9/site-packages/distributed/worker.py", line 3443, in _prepare_args_for_execution
    data[k] = Actor(type(self.actors[k]), self.address, k, self)
KeyError: 'array-original-3f48072de5e5a51716fc264ce77dff1f'
distributed.worker - ERROR - Exception during execution of task ('array-3f48072de5e5a51716fc264ce77dff1f', 8, 1, 1).
Traceback (most recent call last):
  File "/ccc/work/cont003/gen2224/gen2224/spack/var/spack/environments/gysela-deisa-irene-skl-draft/.spack-env/view/lib/python3.9/site-packages/distributed/worker.py", line 3439, in _prepare_args_for_execution
    data[k] = self.data[k]
  File "/ccc/work/cont003/gen2224/gen2224/spack/var/spack/environments/gysela-deisa-irene-skl-draft/.spack-env/view/lib/python3.9/site-packages/zict/buffer.py", line 72, in __getitem__
    raise KeyError(key)
KeyError: 'array-original-3f48072de5e5a51716fc264ce77dff1f'

During handling of the above exception, another exception occurred:

Traceback (most recent call last):
  File "/ccc/work/cont003/gen2224/gen2224/spack/var/spack/environments/gysela-deisa-irene-skl-draft/.spack-env/view/lib/python3.9/site-packages/distributed/worker.py", line 3321, in execute
    args2, kwargs2 = self._prepare_args_for_execution(ts, args, kwargs)
  File "/ccc/work/cont003/gen2224/gen2224/spack/var/spack/environments/gysela-deisa-irene-skl-draft/.spack-env/view/lib/python3.9/site-packages/distributed/worker.py", line 3443, in _prepare_args_for_execution
    data[k] = Actor(type(self.actors[k]), self.address, k, self)
KeyError: 'array-original-3f48072de5e5a51716fc264ce77dff1f'
distributed.worker - ERROR - Exception during execution of task ('array-3f48072de5e5a51716fc264ce77dff1f', 9, 6, 2).
Traceback (most recent call last):
  File "/ccc/work/cont003/gen2224/gen2224/spack/var/spack/environments/gysela-deisa-irene-skl-draft/.spack-env/view/lib/python3.9/site-packages/distributed/worker.py", line 3439, in _prepare_args_for_execution
    data[k] = self.data[k]
  File "/ccc/work/cont003/gen2224/gen2224/spack/var/spack/environments/gysela-deisa-irene-skl-draft/.spack-env/view/lib/python3.9/site-packages/zict/buffer.py", line 72, in __getitem__
    raise KeyError(key)
KeyError: 'array-original-3f48072de5e5a51716fc264ce77dff1f'

During handling of the above exception, another exception occurred:

Traceback (most recent call last):
  File "/ccc/work/cont003/gen2224/gen2224/spack/var/spack/environments/gysela-deisa-irene-skl-draft/.spack-env/view/lib/python3.9/site-packages/distributed/worker.py", line 3321, in execute
    args2, kwargs2 = self._prepare_args_for_execution(ts, args, kwargs)
  File "/ccc/work/cont003/gen2224/gen2224/spack/var/spack/environments/gysela-deisa-irene-skl-draft/.spack-env/view/lib/python3.9/site-packages/distributed/worker.py", line 3443, in _prepare_args_for_execution
    data[k] = Actor(type(self.actors[k]), self.address, k, self)
KeyError: 'array-original-3f48072de5e5a51716fc264ce77dff1f'
tornado.application - ERROR - Exception in callback functools.partial(<bound method IOLoop._discard_future_result of <tornado.platform.asyncio.AsyncIOLoop object at 0x2ae9787ae8e0>>, <Task finished name='Task-7193' coro=<Worker.gather_dep() done, defined at /ccc/work/cont003/gen2224/gen2224/spack/var/spack/environments/gysela-deisa-irene-skl-draft/.spack-env/view/lib/python3.9/site-packages/distributed/worker.py:2823> exception=RuntimeError('Task array-original-3f48072de5e5a51716fc264ce77dff1f found in illegal state memory. Only states `flight`, `resumed` and `cancelled` possible.')>)
Traceback (most recent call last):
  File "/ccc/work/cont003/gen2224/gen2224/spack/var/spack/environments/gysela-deisa-irene-skl-draft/.spack-env/view/lib/python3.9/site-packages/tornado/ioloop.py", line 741, in _run_callback
    ret = callback()
  File "/ccc/work/cont003/gen2224/gen2224/spack/var/spack/environments/gysela-deisa-irene-skl-draft/.spack-env/view/lib/python3.9/site-packages/tornado/ioloop.py", line 765, in _discard_future_result
    future.result()
  File "/ccc/work/cont003/gen2224/gen2224/spack/var/spack/environments/gysela-deisa-irene-skl-draft/.spack-env/view/lib/python3.9/site-packages/distributed/worker.py", line 2852, in gather_dep
    to_gather_keys, cancelled_keys, cause = self._filter_deps_for_fetch(
  File "/ccc/work/cont003/gen2224/gen2224/spack/var/spack/environments/gysela-deisa-irene-skl-draft/.spack-env/view/lib/python3.9/site-packages/distributed/worker.py", line 2759, in _filter_deps_for_fetch
    raise RuntimeError(
RuntimeError: Task array-original-3f48072de5e5a51716fc264ce77dff1f found in illegal state memory. Only states `flight`, `resumed` and `cancelled` possible.
distributed.worker - ERROR - Exception during execution of task ('array-3f48072de5e5a51716fc264ce77dff1f', 9, 3, 2).
Traceback (most recent call last):
  File "/ccc/work/cont003/gen2224/gen2224/spack/var/spack/environments/gysela-deisa-irene-skl-draft/.spack-env/view/lib/python3.9/site-packages/distributed/worker.py", line 3439, in _prepare_args_for_execution
    data[k] = self.data[k]
  File "/ccc/work/cont003/gen2224/gen2224/spack/var/spack/environments/gysela-deisa-irene-skl-draft/.spack-env/view/lib/python3.9/site-packages/zict/buffer.py", line 72, in __getitem__
    raise KeyError(key)
KeyError: 'array-original-3f48072de5e5a51716fc264ce77dff1f'

During handling of the above exception, another exception occurred:

Traceback (most recent call last):
  File "/ccc/work/cont003/gen2224/gen2224/spack/var/spack/environments/gysela-deisa-irene-skl-draft/.spack-env/view/lib/python3.9/site-packages/distributed/worker.py", line 3321, in execute
    args2, kwargs2 = self._prepare_args_for_execution(ts, args, kwargs)
  File "/ccc/work/cont003/gen2224/gen2224/spack/var/spack/environments/gysela-deisa-irene-skl-draft/.spack-env/view/lib/python3.9/site-packages/distributed/worker.py", line 3443, in _prepare_args_for_execution
    data[k] = Actor(type(self.actors[k]), self.address, k, self)
KeyError: 'array-original-3f48072de5e5a51716fc264ce77dff1f'
distributed.worker - ERROR - Worker stream died during communication: tcp://172.21.3.57:45485
Traceback (most recent call last):
  File "/ccc/work/cont003/gen2224/gen2224/spack/var/spack/environments/gysela-deisa-irene-skl-draft/.spack-env/view/lib/python3.9/site-packages/distributed/comm/tcp.py", line 205, in read
    frames_nbytes = await stream.read_bytes(fmt_size)
asyncio.exceptions.CancelledError

During handling of the above exception, another exception occurred:

Traceback (most recent call last):
  File "/ccc/work/cont003/gen2224/gen2224/spack/var/spack/environments/gysela-deisa-irene-skl-draft/.spack-env/._view/whcr3wyhzgorszy3rfxsphyebtvfpqzk/lib/python3.9/asyncio/tasks.py", line 490, in wait_for
    return fut.result()
asyncio.exceptions.CancelledError

The above exception was the direct cause of the following exception:

Traceback (most recent call last):
  File "/ccc/work/cont003/gen2224/gen2224/spack/var/spack/environments/gysela-deisa-irene-skl-draft/.spack-env/view/lib/python3.9/site-packages/distributed/comm/core.py", line 319, in connect
    handshake = await asyncio.wait_for(comm.read(), time_left())
  File "/ccc/work/cont003/gen2224/gen2224/spack/var/spack/environments/gysela-deisa-irene-skl-draft/.spack-env/._view/whcr3wyhzgorszy3rfxsphyebtvfpqzk/lib/python3.9/asyncio/tasks.py", line 492, in wait_for
    raise exceptions.TimeoutError() from exc
asyncio.exceptions.TimeoutError

The above exception was the direct cause of the following exception:

Traceback (most recent call last):
  File "/ccc/work/cont003/gen2224/gen2224/spack/var/spack/environments/gysela-deisa-irene-skl-draft/.spack-env/view/lib/python3.9/site-packages/distributed/worker.py", line 2878, in gather_dep
    response = await get_data_from_worker(
  File "/ccc/work/cont003/gen2224/gen2224/spack/var/spack/environments/gysela-deisa-irene-skl-draft/.spack-env/view/lib/python3.9/site-packages/distributed/worker.py", line 4143, in get_data_from_worker
    return await retry_operation(_get_data, operation="get_data_from_worker")
  File "/ccc/work/cont003/gen2224/gen2224/spack/var/spack/environments/gysela-deisa-irene-skl-draft/.spack-env/view/lib/python3.9/site-packages/distributed/utils_comm.py", line 366, in retry_operation
    return await retry(
  File "/ccc/work/cont003/gen2224/gen2224/spack/var/spack/environments/gysela-deisa-irene-skl-draft/.spack-env/view/lib/python3.9/site-packages/distributed/utils_comm.py", line 351, in retry
    return await coro()
  File "/ccc/work/cont003/gen2224/gen2224/spack/var/spack/environments/gysela-deisa-irene-skl-draft/.spack-env/view/lib/python3.9/site-packages/distributed/worker.py", line 4120, in _get_data
    comm = await rpc.connect(worker)
  File "/ccc/work/cont003/gen2224/gen2224/spack/var/spack/environments/gysela-deisa-irene-skl-draft/.spack-env/view/lib/python3.9/site-packages/distributed/core.py", line 1081, in connect
    raise exc
  File "/ccc/work/cont003/gen2224/gen2224/spack/var/spack/environments/gysela-deisa-irene-skl-draft/.spack-env/view/lib/python3.9/site-packages/distributed/core.py", line 1065, in connect
    comm = await fut
  File "/ccc/work/cont003/gen2224/gen2224/spack/var/spack/environments/gysela-deisa-irene-skl-draft/.spack-env/view/lib/python3.9/site-packages/distributed/comm/core.py", line 324, in connect
    raise OSError(
OSError: Timed out during handshake while connecting to tcp://172.21.3.57:45485 after 30 s
distributed.worker - ERROR - Worker stream died during communication: tcp://172.21.3.64:36233
Traceback (most recent call last):
  File "/ccc/work/cont003/gen2224/gen2224/spack/var/spack/environments/gysela-deisa-irene-skl-draft/.spack-env/view/lib/python3.9/site-packages/distributed/comm/tcp.py", line 205, in read
    frames_nbytes = await stream.read_bytes(fmt_size)
asyncio.exceptions.CancelledError

During handling of the above exception, another exception occurred:

Traceback (most recent call last):
  File "/ccc/work/cont003/gen2224/gen2224/spack/var/spack/environments/gysela-deisa-irene-skl-draft/.spack-env/._view/whcr3wyhzgorszy3rfxsphyebtvfpqzk/lib/python3.9/asyncio/tasks.py", line 490, in wait_for
    return fut.result()
asyncio.exceptions.CancelledError

The above exception was the direct cause of the following exception:

Traceback (most recent call last):
  File "/ccc/work/cont003/gen2224/gen2224/spack/var/spack/environments/gysela-deisa-irene-skl-draft/.spack-env/view/lib/python3.9/site-packages/distributed/comm/core.py", line 319, in connect
    handshake = await asyncio.wait_for(comm.read(), time_left())
  File "/ccc/work/cont003/gen2224/gen2224/spack/var/spack/environments/gysela-deisa-irene-skl-draft/.spack-env/._view/whcr3wyhzgorszy3rfxsphyebtvfpqzk/lib/python3.9/asyncio/tasks.py", line 492, in wait_for
    raise exceptions.TimeoutError() from exc
asyncio.exceptions.TimeoutError

The above exception was the direct cause of the following exception:

Traceback (most recent call last):
  File "/ccc/work/cont003/gen2224/gen2224/spack/var/spack/environments/gysela-deisa-irene-skl-draft/.spack-env/view/lib/python3.9/site-packages/distributed/worker.py", line 2878, in gather_dep
    response = await get_data_from_worker(
  File "/ccc/work/cont003/gen2224/gen2224/spack/var/spack/environments/gysela-deisa-irene-skl-draft/.spack-env/view/lib/python3.9/site-packages/distributed/worker.py", line 4143, in get_data_from_worker
    return await retry_operation(_get_data, operation="get_data_from_worker")
  File "/ccc/work/cont003/gen2224/gen2224/spack/var/spack/environments/gysela-deisa-irene-skl-draft/.spack-env/view/lib/python3.9/site-packages/distributed/utils_comm.py", line 366, in retry_operation
    return await retry(
  File "/ccc/work/cont003/gen2224/gen2224/spack/var/spack/environments/gysela-deisa-irene-skl-draft/.spack-env/view/lib/python3.9/site-packages/distributed/utils_comm.py", line 351, in retry
    return await coro()
  File "/ccc/work/cont003/gen2224/gen2224/spack/var/spack/environments/gysela-deisa-irene-skl-draft/.spack-env/view/lib/python3.9/site-packages/distributed/worker.py", line 4120, in _get_data
    comm = await rpc.connect(worker)
  File "/ccc/work/cont003/gen2224/gen2224/spack/var/spack/environments/gysela-deisa-irene-skl-draft/.spack-env/view/lib/python3.9/site-packages/distributed/core.py", line 1081, in connect
    raise exc
  File "/ccc/work/cont003/gen2224/gen2224/spack/var/spack/environments/gysela-deisa-irene-skl-draft/.spack-env/view/lib/python3.9/site-packages/distributed/core.py", line 1065, in connect
    comm = await fut
  File "/ccc/work/cont003/gen2224/gen2224/spack/var/spack/environments/gysela-deisa-irene-skl-draft/.spack-env/view/lib/python3.9/site-packages/distributed/comm/core.py", line 324, in connect
    raise OSError(
OSError: Timed out during handshake while connecting to tcp://172.21.3.64:36233 after 30 s
distributed.worker - ERROR - Worker stream died during communication: tcp://172.21.3.64:36233
Traceback (most recent call last):
  File "/ccc/work/cont003/gen2224/gen2224/spack/var/spack/environments/gysela-deisa-irene-skl-draft/.spack-env/view/lib/python3.9/site-packages/distributed/comm/tcp.py", line 205, in read
    frames_nbytes = await stream.read_bytes(fmt_size)
asyncio.exceptions.CancelledError

During handling of the above exception, another exception occurred:

Traceback (most recent call last):
  File "/ccc/work/cont003/gen2224/gen2224/spack/var/spack/environments/gysela-deisa-irene-skl-draft/.spack-env/._view/whcr3wyhzgorszy3rfxsphyebtvfpqzk/lib/python3.9/asyncio/tasks.py", line 490, in wait_for
    return fut.result()
asyncio.exceptions.CancelledError

The above exception was the direct cause of the following exception:

Traceback (most recent call last):
distributed.worker - ERROR - Worker stream died during communication: tcp://172.21.3.64:36233
Traceback (most recent call last):
  File "/ccc/work/cont003/gen2224/gen2224/spack/var/spack/environments/gysela-deisa-irene-skl-draft/.spack-env/view/lib/python3.9/site-packages/distributed/comm/tcp.py", line 205, in read
    frames_nbytes = await stream.read_bytes(fmt_size)
asyncio.exceptions.CancelledError

During handling of the above exception, another exception occurred:

Traceback (most recent call last):
  File "/ccc/work/cont003/gen2224/gen2224/spack/var/spack/environments/gysela-deisa-irene-skl-draft/.spack-env/._view/whcr3wyhzgorszy3rfxsphyebtvfpqzk/lib/python3.9/asyncio/tasks.py", line 490, in wait_for
    return fut.result()
asyncio.exceptions.CancelledError

The above exception was the direct cause of the following exception:

Traceback (most recent call last):
  File "/ccc/work/cont003/gen2224/gen2224/spack/var/spack/environments/gysela-deisa-irene-skl-draft/.spack-env/view/lib/python3.9/site-packages/distributed/comm/core.py", line 319, in connect
    handshake = await asyncio.wait_for(comm.read(), time_left())
  File "/ccc/work/cont003/gen2224/gen2224/spack/var/spack/environments/gysela-deisa-irene-skl-draft/.spack-env/._view/whcr3wyhzgorszy3rfxsphyebtvfpqzk/lib/python3.9/asyncio/tasks.py", line 492, in wait_for
    raise exceptions.TimeoutError() from exc
asyncio.exceptions.TimeoutError

The above exception was the direct cause of the following exception:

Traceback (most recent call last):
  File "/ccc/work/cont003/gen2224/gen2224/spack/var/spack/environments/gysela-deisa-irene-skl-draft/.spack-env/view/lib/python3.9/site-packages/distributed/worker.py", line 2878, in gather_dep
    response = await get_data_from_worker(
  File "/ccc/work/cont003/gen2224/gen2224/spack/var/spack/environments/gysela-deisa-irene-skl-draft/.spack-env/view/lib/python3.9/site-packages/distributed/comm/core.py", line 319, in connect
    handshake = await asyncio.wait_for(comm.read(), time_left())
  File "/ccc/work/cont003/gen2224/gen2224/spack/var/spack/environments/gysela-deisa-irene-skl-draft/.spack-env/._view/whcr3wyhzgorszy3rfxsphyebtvfpqzk/lib/python3.9/asyncio/tasks.py", line 492, in wait_for
    raise exceptions.TimeoutError() from exc
asyncio.exceptions.TimeoutError

The above exception was the direct cause of the following exception:

Traceback (most recent call last):
  File "/ccc/work/cont003/gen2224/gen2224/spack/var/spack/environments/gysela-deisa-irene-skl-draft/.spack-env/view/lib/python3.9/site-packages/distributed/worker.py", line 2878, in gather_dep
    response = await get_data_from_worker(
  File "/ccc/work/cont003/gen2224/gen2224/spack/var/spack/environments/gysela-deisa-irene-skl-draft/.spack-env/view/lib/python3.9/site-packages/distributed/worker.py", line 4143, in get_data_from_worker
    return await retry_operation(_get_data, operation="get_data_from_worker")
  File "/ccc/work/cont003/gen2224/gen2224/spack/var/spack/environments/gysela-deisa-irene-skl-draft/.spack-env/view/lib/python3.9/site-packages/distributed/utils_comm.py", line 366, in retry_operation
    return await retry(
  File "/ccc/work/cont003/gen2224/gen2224/spack/var/spack/environments/gysela-deisa-irene-skl-draft/.spack-env/view/lib/python3.9/site-packages/distributed/utils_comm.py", line 351, in retry
    return await coro()
  File "/ccc/work/cont003/gen2224/gen2224/spack/var/spack/environments/gysela-deisa-irene-skl-draft/.spack-env/view/lib/python3.9/site-packages/distributed/worker.py", line 4120, in _get_data
    comm = await rpc.connect(worker)
  File "/ccc/work/cont003/gen2224/gen2224/spack/var/spack/environments/gysela-deisa-irene-skl-draft/.spack-env/view/lib/python3.9/site-packages/distributed/worker.py", line 4143, in get_data_from_worker
    return await retry_operation(_get_data, operation="get_data_from_worker")
  File "/ccc/work/cont003/gen2224/gen2224/spack/var/spack/environments/gysela-deisa-irene-skl-draft/.spack-env/view/lib/python3.9/site-packages/distributed/utils_comm.py", line 366, in retry_operation
    return await retry(
  File "/ccc/work/cont003/gen2224/gen2224/spack/var/spack/environments/gysela-deisa-irene-skl-draft/.spack-env/view/lib/python3.9/site-packages/distributed/utils_comm.py", line 351, in retry
    return await coro()
  File "/ccc/work/cont003/gen2224/gen2224/spack/var/spack/environments/gysela-deisa-irene-skl-draft/.spack-env/view/lib/python3.9/site-packages/distributed/worker.py", line 4120, in _get_data
    comm = await rpc.connect(worker)
  File "/ccc/work/cont003/gen2224/gen2224/spack/var/spack/environments/gysela-deisa-irene-skl-draft/.spack-env/view/lib/python3.9/site-packages/distributed/core.py", line 1081, in connect
    raise exc
  File "/ccc/work/cont003/gen2224/gen2224/spack/var/spack/environments/gysela-deisa-irene-skl-draft/.spack-env/view/lib/python3.9/site-packages/distributed/core.py", line 1065, in connect
    comm = await fut
  File "/ccc/work/cont003/gen2224/gen2224/spack/var/spack/environments/gysela-deisa-irene-skl-draft/.spack-env/view/lib/python3.9/site-packages/distributed/comm/core.py", line 324, in connect
    raise OSError(
OSError: Timed out during handshake while connecting to tcp://172.21.3.64:36233 after 30 s
  File "/ccc/work/cont003/gen2224/gen2224/spack/var/spack/environments/gysela-deisa-irene-skl-draft/.spack-env/view/lib/python3.9/site-packages/distributed/core.py", line 1081, in connect
    raise exc
  File "/ccc/work/cont003/gen2224/gen2224/spack/var/spack/environments/gysela-deisa-irene-skl-draft/.spack-env/view/lib/python3.9/site-packages/distributed/core.py", line 1065, in connect
    comm = await fut
  File "/ccc/work/cont003/gen2224/gen2224/spack/var/spack/environments/gysela-deisa-irene-skl-draft/.spack-env/view/lib/python3.9/site-packages/distributed/comm/core.py", line 324, in connect
    raise OSError(
OSError: Timed out during handshake while connecting to tcp://172.21.3.64:36233 after 30 s
distributed.worker - ERROR - Worker stream died during communication: tcp://172.21.3.64:36233
Traceback (most recent call last):
  File "/ccc/work/cont003/gen2224/gen2224/spack/var/spack/environments/gysela-deisa-irene-skl-draft/.spack-env/view/lib/python3.9/site-packages/distributed/comm/tcp.py", line 205, in read
    frames_nbytes = await stream.read_bytes(fmt_size)
asyncio.exceptions.CancelledError

During handling of the above exception, another exception occurred:

Traceback (most recent call last):
  File "/ccc/work/cont003/gen2224/gen2224/spack/var/spack/environments/gysela-deisa-irene-skl-draft/.spack-env/._view/whcr3wyhzgorszy3rfxsphyebtvfpqzk/lib/python3.9/asyncio/tasks.py", line 490, in wait_for
    return fut.result()
asyncio.exceptions.CancelledError

The above exception was the direct cause of the following exception:

Traceback (most recent call last):
  File "/ccc/work/cont003/gen2224/gen2224/spack/var/spack/environments/gysela-deisa-irene-skl-draft/.spack-env/view/lib/python3.9/site-packages/distributed/comm/core.py", line 319, in connect
    handshake = await asyncio.wait_for(comm.read(), time_left())
  File "/ccc/work/cont003/gen2224/gen2224/spack/var/spack/environments/gysela-deisa-irene-skl-draft/.spack-env/._view/whcr3wyhzgorszy3rfxsphyebtvfpqzk/lib/python3.9/asyncio/tasks.py", line 492, in wait_for
    raise exceptions.TimeoutError() from exc
asyncio.exceptions.TimeoutError

The above exception was the direct cause of the following exception:

Traceback (most recent call last):
  File "/ccc/work/cont003/gen2224/gen2224/spack/var/spack/environments/gysela-deisa-irene-skl-draft/.spack-env/view/lib/python3.9/site-packages/distributed/worker.py", line 2878, in gather_dep
    response = await get_data_from_worker(
  File "/ccc/work/cont003/gen2224/gen2224/spack/var/spack/environments/gysela-deisa-irene-skl-draft/.spack-env/view/lib/python3.9/site-packages/distributed/worker.py", line 4143, in get_data_from_worker
    return await retry_operation(_get_data, operation="get_data_from_worker")
  File "/ccc/work/cont003/gen2224/gen2224/spack/var/spack/environments/gysela-deisa-irene-skl-draft/.spack-env/view/lib/python3.9/site-packages/distributed/utils_comm.py", line 366, in retry_operation
    return await retry(
  File "/ccc/work/cont003/gen2224/gen2224/spack/var/spack/environments/gysela-deisa-irene-skl-draft/.spack-env/view/lib/python3.9/site-packages/distributed/utils_comm.py", line 351, in retry
    return await coro()
  File "/ccc/work/cont003/gen2224/gen2224/spack/var/spack/environments/gysela-deisa-irene-skl-draft/.spack-env/view/lib/python3.9/site-packages/distributed/worker.py", line 4120, in _get_data
    comm = await rpc.connect(worker)
distributed.worker - ERROR - Worker stream died during communication: tcp://172.21.3.64:36233
Traceback (most recent call last):
  File "/ccc/work/cont003/gen2224/gen2224/spack/var/spack/environments/gysela-deisa-irene-skl-draft/.spack-env/view/lib/python3.9/site-packages/distributed/comm/tcp.py", line 205, in read
    frames_nbytes = await stream.read_bytes(fmt_size)
asyncio.exceptions.CancelledError

During handling of the above exception, another exception occurred:

Traceback (most recent call last):
  File "/ccc/work/cont003/gen2224/gen2224/spack/var/spack/environments/gysela-deisa-irene-skl-draft/.spack-env/._view/whcr3wyhzgorszy3rfxsphyebtvfpqzk/lib/python3.9/asyncio/tasks.py", line 490, in wait_for
    return fut.result()
asyncio.exceptions.CancelledError

The above exception was the direct cause of the following exception:

Traceback (most recent call last):
  File "/ccc/work/cont003/gen2224/gen2224/spack/var/spack/environments/gysela-deisa-irene-skl-draft/.spack-env/view/lib/python3.9/site-packages/distributed/core.py", line 1081, in connect
    raise exc
  File "/ccc/work/cont003/gen2224/gen2224/spack/var/spack/environments/gysela-deisa-irene-skl-draft/.spack-env/view/lib/python3.9/site-packages/distributed/core.py", line 1065, in connect
    comm = await fut
  File "/ccc/work/cont003/gen2224/gen2224/spack/var/spack/environments/gysela-deisa-irene-skl-draft/.spack-env/view/lib/python3.9/site-packages/distributed/comm/core.py", line 324, in connect
    raise OSError(
OSError: Timed out during handshake while connecting to tcp://172.21.3.64:36233 after 30 s
  File "/ccc/work/cont003/gen2224/gen2224/spack/var/spack/environments/gysela-deisa-irene-skl-draft/.spack-env/view/lib/python3.9/site-packages/distributed/comm/core.py", line 319, in connect
    handshake = await asyncio.wait_for(comm.read(), time_left())
  File "/ccc/work/cont003/gen2224/gen2224/spack/var/spack/environments/gysela-deisa-irene-skl-draft/.spack-env/._view/whcr3wyhzgorszy3rfxsphyebtvfpqzk/lib/python3.9/asyncio/tasks.py", line 492, in wait_for
    raise exceptions.TimeoutError() from exc
asyncio.exceptions.TimeoutError

The above exception was the direct cause of the following exception:

Traceback (most recent call last):
  File "/ccc/work/cont003/gen2224/gen2224/spack/var/spack/environments/gysela-deisa-irene-skl-draft/.spack-env/view/lib/python3.9/site-packages/distributed/worker.py", line 2878, in gather_dep
    response = await get_data_from_worker(
  File "/ccc/work/cont003/gen2224/gen2224/spack/var/spack/environments/gysela-deisa-irene-skl-draft/.spack-env/view/lib/python3.9/site-packages/distributed/worker.py", line 4143, in get_data_from_worker
    return await retry_operation(_get_data, operation="get_data_from_worker")
  File "/ccc/work/cont003/gen2224/gen2224/spack/var/spack/environments/gysela-deisa-irene-skl-draft/.spack-env/view/lib/python3.9/site-packages/distributed/utils_comm.py", line 366, in retry_operation
    return await retry(
  File "/ccc/work/cont003/gen2224/gen2224/spack/var/spack/environments/gysela-deisa-irene-skl-draft/.spack-env/view/lib/python3.9/site-packages/distributed/utils_comm.py", line 351, in retry
    return await coro()
  File "/ccc/work/cont003/gen2224/gen2224/spack/var/spack/environments/gysela-deisa-irene-skl-draft/.spack-env/view/lib/python3.9/site-packages/distributed/worker.py", line 4120, in _get_data
    comm = await rpc.connect(worker)
  File "/ccc/work/cont003/gen2224/gen2224/spack/var/spack/environments/gysela-deisa-irene-skl-draft/.spack-env/view/lib/python3.9/site-packages/distributed/core.py", line 1081, in connect
    raise exc
  File "/ccc/work/cont003/gen2224/gen2224/spack/var/spack/environments/gysela-deisa-irene-skl-draft/.spack-env/view/lib/python3.9/site-packages/distributed/core.py", line 1065, in connect
    comm = await fut
  File "/ccc/work/cont003/gen2224/gen2224/spack/var/spack/environments/gysela-deisa-irene-skl-draft/.spack-env/view/lib/python3.9/site-packages/distributed/comm/core.py", line 324, in connect
    raise OSError(
OSError: Timed out during handshake while connecting to tcp://172.21.3.64:36233 after 30 s
distributed.worker - ERROR - Worker stream died during communication: tcp://172.21.3.64:36233
Traceback (most recent call last):
  File "/ccc/work/cont003/gen2224/gen2224/spack/var/spack/environments/gysela-deisa-irene-skl-draft/.spack-env/view/lib/python3.9/site-packages/distributed/comm/tcp.py", line 205, in read
    frames_nbytes = await stream.read_bytes(fmt_size)
asyncio.exceptions.CancelledError

During handling of the above exception, another exception occurred:

Traceback (most recent call last):
  File "/ccc/work/cont003/gen2224/gen2224/spack/var/spack/environments/gysela-deisa-irene-skl-draft/.spack-env/._view/whcr3wyhzgorszy3rfxsphyebtvfpqzk/lib/python3.9/asyncio/tasks.py", line 490, in wait_for
    return fut.result()
asyncio.exceptions.CancelledError

The above exception was the direct cause of the following exception:

Traceback (most recent call last):
  File "/ccc/work/cont003/gen2224/gen2224/spack/var/spack/environments/gysela-deisa-irene-skl-draft/.spack-env/view/lib/python3.9/site-packages/distributed/comm/core.py", line 319, in connect
    handshake = await asyncio.wait_for(comm.read(), time_left())
  File "/ccc/work/cont003/gen2224/gen2224/spack/var/spack/environments/gysela-deisa-irene-skl-draft/.spack-env/._view/whcr3wyhzgorszy3rfxsphyebtvfpqzk/lib/python3.9/asyncio/tasks.py", line 492, in wait_for
    raise exceptions.TimeoutError() from exc
asyncio.exceptions.TimeoutError

The above exception was the direct cause of the following exception:

Traceback (most recent call last):
  File "/ccc/work/cont003/gen2224/gen2224/spack/var/spack/environments/gysela-deisa-irene-skl-draft/.spack-env/view/lib/python3.9/site-packages/distributed/worker.py", line 2878, in gather_dep
    response = await get_data_from_worker(
  File "/ccc/work/cont003/gen2224/gen2224/spack/var/spack/environments/gysela-deisa-irene-skl-draft/.spack-env/view/lib/python3.9/site-packages/distributed/worker.py", line 4143, in get_data_from_worker
    return await retry_operation(_get_data, operation="get_data_from_worker")
  File "/ccc/work/cont003/gen2224/gen2224/spack/var/spack/environments/gysela-deisa-irene-skl-draft/.spack-env/view/lib/python3.9/site-packages/distributed/utils_comm.py", line 366, in retry_operation
    return await retry(
  File "/ccc/work/cont003/gen2224/gen2224/spack/var/spack/environments/gysela-deisa-irene-skl-draft/.spack-env/view/lib/python3.9/site-packages/distributed/utils_comm.py", line 351, in retry
    return await coro()
  File "/ccc/work/cont003/gen2224/gen2224/spack/var/spack/environments/gysela-deisa-irene-skl-draft/.spack-env/view/lib/python3.9/site-packages/distributed/worker.py", line 4120, in _get_data
    comm = await rpc.connect(worker)
  File "/ccc/work/cont003/gen2224/gen2224/spack/var/spack/environments/gysela-deisa-irene-skl-draft/.spack-env/view/lib/python3.9/site-packages/distributed/core.py", line 1081, in connect
    raise exc
  File "/ccc/work/cont003/gen2224/gen2224/spack/var/spack/environments/gysela-deisa-irene-skl-draft/.spack-env/view/lib/python3.9/site-packages/distributed/core.py", line 1065, in connect
    comm = await fut
  File "/ccc/work/cont003/gen2224/gen2224/spack/var/spack/environments/gysela-deisa-irene-skl-draft/.spack-env/view/lib/python3.9/site-packages/distributed/comm/core.py", line 324, in connect
    raise OSError(
OSError: Timed out during handshake while connecting to tcp://172.21.3.64:36233 after 30 s
distributed.worker - ERROR - Worker stream died during communication: tcp://172.21.3.64:36233
Traceback (most recent call last):
  File "/ccc/work/cont003/gen2224/gen2224/spack/var/spack/environments/gysela-deisa-irene-skl-draft/.spack-env/view/lib/python3.9/site-packages/distributed/comm/tcp.py", line 205, in read
    frames_nbytes = await stream.read_bytes(fmt_size)
asyncio.exceptions.CancelledError

During handling of the above exception, another exception occurred:

Traceback (most recent call last):
  File "/ccc/work/cont003/gen2224/gen2224/spack/var/spack/environments/gysela-deisa-irene-skl-draft/.spack-env/._view/whcr3wyhzgorszy3rfxsphyebtvfpqzk/lib/python3.9/asyncio/tasks.py", line 490, in wait_for
    return fut.result()
asyncio.exceptions.CancelledError

The above exception was the direct cause of the following exception:

Traceback (most recent call last):
  File "/ccc/work/cont003/gen2224/gen2224/spack/var/spack/environments/gysela-deisa-irene-skl-draft/.spack-env/view/lib/python3.9/site-packages/distributed/comm/core.py", line 319, in connect
    handshake = await asyncio.wait_for(comm.read(), time_left())
  File "/ccc/work/cont003/gen2224/gen2224/spack/var/spack/environments/gysela-deisa-irene-skl-draft/.spack-env/._view/whcr3wyhzgorszy3rfxsphyebtvfpqzk/lib/python3.9/asyncio/tasks.py", line 492, in wait_for
    raise exceptions.TimeoutError() from exc
asyncio.exceptions.TimeoutError

The above exception was the direct cause of the following exception:

Traceback (most recent call last):
  File "/ccc/work/cont003/gen2224/gen2224/spack/var/spack/environments/gysela-deisa-irene-skl-draft/.spack-env/view/lib/python3.9/site-packages/distributed/worker.py", line 2878, in gather_dep
    response = await get_data_from_worker(
  File "/ccc/work/cont003/gen2224/gen2224/spack/var/spack/environments/gysela-deisa-irene-skl-draft/.spack-env/view/lib/python3.9/site-packages/distributed/worker.py", line 4143, in get_data_from_worker
    return await retry_operation(_get_data, operation="get_data_from_worker")
  File "/ccc/work/cont003/gen2224/gen2224/spack/var/spack/environments/gysela-deisa-irene-skl-draft/.spack-env/view/lib/python3.9/site-packages/distributed/utils_comm.py", line 366, in retry_operation
    return await retry(
  File "/ccc/work/cont003/gen2224/gen2224/spack/var/spack/environments/gysela-deisa-irene-skl-draft/.spack-env/view/lib/python3.9/site-packages/distributed/utils_comm.py", line 351, in retry
    return await coro()
  File "/ccc/work/cont003/gen2224/gen2224/spack/var/spack/environments/gysela-deisa-irene-skl-draft/.spack-env/view/lib/python3.9/site-packages/distributed/worker.py", line 4120, in _get_data
    comm = await rpc.connect(worker)
  File "/ccc/work/cont003/gen2224/gen2224/spack/var/spack/environments/gysela-deisa-irene-skl-draft/.spack-env/view/lib/python3.9/site-packages/distributed/core.py", line 1081, in connect
    raise exc
  File "/ccc/work/cont003/gen2224/gen2224/spack/var/spack/environments/gysela-deisa-irene-skl-draft/.spack-env/view/lib/python3.9/site-packages/distributed/core.py", line 1065, in connect
    comm = await fut
  File "/ccc/work/cont003/gen2224/gen2224/spack/var/spack/environments/gysela-deisa-irene-skl-draft/.spack-env/view/lib/python3.9/site-packages/distributed/comm/core.py", line 324, in connect
    raise OSError(
OSError: Timed out during handshake while connecting to tcp://172.21.3.64:36233 after 30 s
distributed.worker - ERROR - Worker stream died during communication: tcp://172.21.3.64:36233
Traceback (most recent call last):
  File "/ccc/work/cont003/gen2224/gen2224/spack/var/spack/environments/gysela-deisa-irene-skl-draft/.spack-env/view/lib/python3.9/site-packages/distributed/comm/tcp.py", line 205, in read
    frames_nbytes = await stream.read_bytes(fmt_size)
asyncio.exceptions.CancelledError

During handling of the above exception, another exception occurred:

Traceback (most recent call last):
  File "/ccc/work/cont003/gen2224/gen2224/spack/var/spack/environments/gysela-deisa-irene-skl-draft/.spack-env/._view/whcr3wyhzgorszy3rfxsphyebtvfpqzk/lib/python3.9/asyncio/tasks.py", line 490, in wait_for
    return fut.result()
asyncio.exceptions.CancelledError

The above exception was the direct cause of the following exception:

Traceback (most recent call last):
  File "/ccc/work/cont003/gen2224/gen2224/spack/var/spack/environments/gysela-deisa-irene-skl-draft/.spack-env/view/lib/python3.9/site-packages/distributed/comm/core.py", line 319, in connect
    handshake = await asyncio.wait_for(comm.read(), time_left())
  File "/ccc/work/cont003/gen2224/gen2224/spack/var/spack/environments/gysela-deisa-irene-skl-draft/.spack-env/._view/whcr3wyhzgorszy3rfxsphyebtvfpqzk/lib/python3.9/asyncio/tasks.py", line 492, in wait_for
    raise exceptions.TimeoutError() from exc
asyncio.exceptions.TimeoutError

The above exception was the direct cause of the following exception:

Traceback (most recent call last):
  File "/ccc/work/cont003/gen2224/gen2224/spack/var/spack/environments/gysela-deisa-irene-skl-draft/.spack-env/view/lib/python3.9/site-packages/distributed/worker.py", line 2878, in gather_dep
    response = await get_data_from_worker(
  File "/ccc/work/cont003/gen2224/gen2224/spack/var/spack/environments/gysela-deisa-irene-skl-draft/.spack-env/view/lib/python3.9/site-packages/distributed/worker.py", line 4143, in get_data_from_worker
    return await retry_operation(_get_data, operation="get_data_from_worker")
  File "/ccc/work/cont003/gen2224/gen2224/spack/var/spack/environments/gysela-deisa-irene-skl-draft/.spack-env/view/lib/python3.9/site-packages/distributed/utils_comm.py", line 366, in retry_operation
    return await retry(
  File "/ccc/work/cont003/gen2224/gen2224/spack/var/spack/environments/gysela-deisa-irene-skl-draft/.spack-env/view/lib/python3.9/site-packages/distributed/utils_comm.py", line 351, in retry
    return await coro()
  File "/ccc/work/cont003/gen2224/gen2224/spack/var/spack/environments/gysela-deisa-irene-skl-draft/.spack-env/view/lib/python3.9/site-packages/distributed/worker.py", line 4120, in _get_data
    comm = await rpc.connect(worker)
  File "/ccc/work/cont003/gen2224/gen2224/spack/var/spack/environments/gysela-deisa-irene-skl-draft/.spack-env/view/lib/python3.9/site-packages/distributed/core.py", line 1081, in connect
    raise exc
  File "/ccc/work/cont003/gen2224/gen2224/spack/var/spack/environments/gysela-deisa-irene-skl-draft/.spack-env/view/lib/python3.9/site-packages/distributed/core.py", line 1065, in connect
    comm = await fut
  File "/ccc/work/cont003/gen2224/gen2224/spack/var/spack/environments/gysela-deisa-irene-skl-draft/.spack-env/view/lib/python3.9/site-packages/distributed/comm/core.py", line 324, in connect
    raise OSError(
OSError: Timed out during handshake while connecting to tcp://172.21.3.64:36233 after 30 s
distributed.core - INFO - Event loop was unresponsive in Worker for 259.82s.  This is often caused by long-running GIL-holding functions or moving large chunks of data. This can cause timeouts and instability.
distributed.comm.tcp - INFO - Connection from tcp://172.21.3.59:59106 closed before handshake completed
distributed.comm.tcp - INFO - Connection from tcp://172.21.3.61:59210 closed before handshake completed
distributed.comm.tcp - INFO - Connection from tcp://172.21.3.63:50696 closed before handshake completed
distributed.comm.tcp - INFO - Connection from tcp://172.21.3.63:50698 closed before handshake completed
distributed.comm.tcp - INFO - Connection from tcp://172.21.3.65:60116 closed before handshake completed
distributed.comm.tcp - INFO - Connection from tcp://172.21.3.67:34744 closed before handshake completed
distributed.comm.tcp - INFO - Connection from tcp://172.21.3.53:50574 closed before handshake completed
distributed.comm.tcp - INFO - Connection from tcp://172.21.3.65:60118 closed before handshake completed
distributed.comm.tcp - INFO - Connection from tcp://172.21.3.67:34746 closed before handshake completed
distributed.comm.tcp - INFO - Connection from tcp://172.21.3.61:59212 closed before handshake completed
distributed.comm.tcp - INFO - Connection from tcp://172.21.3.59:59108 closed before handshake completed
distributed.comm.tcp - INFO - Connection from tcp://172.21.3.57:47320 closed before handshake completed
distributed.comm.tcp - INFO - Connection from tcp://172.21.3.55:44808 closed before handshake completed
distributed.comm.tcp - INFO - Connection from tcp://172.21.3.64:43300 closed before handshake completed
distributed.comm.tcp - INFO - Connection from tcp://172.21.3.58:47540 closed before handshake completed
distributed.comm.tcp - INFO - Connection from tcp://172.21.3.54:44808 closed before handshake completed
distributed.comm.tcp - INFO - Connection from tcp://172.21.3.56:53092 closed before handshake completed
distributed.comm.tcp - INFO - Connection from tcp://172.21.3.68:51496 closed before handshake completed
distributed.comm.tcp - INFO - Connection from tcp://172.21.3.68:51498 closed before handshake completed
distributed.comm.tcp - INFO - Connection from tcp://172.21.3.62:46828 closed before handshake completed
distributed.comm.tcp - INFO - Connection from tcp://172.21.3.58:47542 closed before handshake completed
distributed.comm.tcp - INFO - Connection from tcp://172.21.3.66:48186 closed before handshake completed
distributed.comm.tcp - INFO - Connection from tcp://172.21.3.54:44810 closed before handshake completed
distributed.comm.tcp - INFO - Connection from tcp://172.21.3.56:53094 closed before handshake completed
distributed.comm.tcp - INFO - Connection from tcp://172.21.3.60:49608 closed before handshake completed
distributed.comm.tcp - INFO - Connection from tcp://172.21.3.64:43302 closed before handshake completed
distributed.comm.tcp - INFO - Connection from tcp://172.21.3.62:46830 closed before handshake completed
distributed.comm.tcp - INFO - Connection from tcp://172.21.3.66:48188 closed before handshake completed
distributed.comm.tcp - INFO - Connection from tcp://172.21.3.60:49610 closed before handshake completed
distributed.comm.tcp - INFO - Connection from tcp://172.21.3.51:37094 closed before handshake completed
distributed.core - INFO - Event loop was unresponsive in Worker for 250.94s.  This is often caused by long-running GIL-holding functions or moving large chunks of data. This can cause timeouts and instability.
distributed.utils - ERROR - 'array-original-3f48072de5e5a51716fc264ce77dff1f'
Traceback (most recent call last):
  File "/ccc/work/cont003/gen2224/gen2224/spack/var/spack/environments/gysela-deisa-irene-skl-draft/.spack-env/view/lib/python3.9/site-packages/distributed/utils.py", line 684, in log_errors
    yield
  File "/ccc/work/cont003/gen2224/gen2224/spack/var/spack/environments/gysela-deisa-irene-skl-draft/.spack-env/view/lib/python3.9/site-packages/distributed/worker.py", line 2929, in gather_dep
    ts = self.tasks[d]
KeyError: 'array-original-3f48072de5e5a51716fc264ce77dff1f'
tornado.application - ERROR - Exception in callback functools.partial(<bound method IOLoop._discard_future_result of <tornado.platform.asyncio.AsyncIOLoop object at 0x2ba90a0ff8e0>>, <Task finished name='Task-7203' coro=<Worker.gather_dep() done, defined at /ccc/work/cont003/gen2224/gen2224/spack/var/spack/environments/gysela-deisa-irene-skl-draft/.spack-env/view/lib/python3.9/site-packages/distributed/worker.py:2823> exception=KeyError('array-original-3f48072de5e5a51716fc264ce77dff1f')>)
Traceback (most recent call last):
  File "/ccc/work/cont003/gen2224/gen2224/spack/var/spack/environments/gysela-deisa-irene-skl-draft/.spack-env/view/lib/python3.9/site-packages/tornado/ioloop.py", line 741, in _run_callback
    ret = callback()
  File "/ccc/work/cont003/gen2224/gen2224/spack/var/spack/environments/gysela-deisa-irene-skl-draft/.spack-env/view/lib/python3.9/site-packages/tornado/ioloop.py", line 765, in _discard_future_result
    future.result()
  File "/ccc/work/cont003/gen2224/gen2224/spack/var/spack/environments/gysela-deisa-irene-skl-draft/.spack-env/view/lib/python3.9/site-packages/distributed/worker.py", line 2929, in gather_dep
    ts = self.tasks[d]
KeyError: 'array-original-3f48072de5e5a51716fc264ce77dff1f'
distributed.comm.tcp - INFO - Connection from tcp://172.21.3.67:37568 closed before handshake completed
distributed.comm.tcp - INFO - Connection from tcp://172.21.3.67:37570 closed before handshake completed
distributed.comm.tcp - INFO - Connection from tcp://172.21.3.68:42232 closed before handshake completed
distributed.comm.tcp - INFO - Connection from tcp://172.21.3.68:42234 closed before handshake completed
distributed.comm.tcp - INFO - Connection from tcp://172.21.3.53:48126 closed before handshake completed
distributed.core - INFO - Event loop was unresponsive in Worker for 121.90s.  This is often caused by long-running GIL-holding functions or moving large chunks of data. This can cause timeouts and instability.
distributed.comm.tcp - INFO - Connection from tcp://172.21.3.64:59344 closed before handshake completed
distributed.comm.tcp - INFO - Connection from tcp://172.21.3.66:50964 closed before handshake completed
distributed.comm.tcp - INFO - Connection from tcp://172.21.3.66:50966 closed before handshake completed
distributed.comm.tcp - INFO - Connection from tcp://172.21.3.51:34500 closed before handshake completed
distributed.comm.tcp - INFO - Connection from tcp://172.21.3.51:34560 closed before handshake completed
