distributed.nanny - INFO -         Start Nanny at: 'tcp://172.21.6.170:41540'
distributed.nanny - INFO -         Start Nanny at: 'tcp://172.21.6.171:34729'
distributed.nanny - INFO -         Start Nanny at: 'tcp://172.21.7.166:35076'
distributed.nanny - INFO -         Start Nanny at: 'tcp://172.21.6.169:42946'
distributed.nanny - INFO -         Start Nanny at: 'tcp://172.21.6.169:40869'
distributed.nanny - INFO -         Start Nanny at: 'tcp://172.21.6.170:40762'
distributed.nanny - INFO -         Start Nanny at: 'tcp://172.21.6.171:33934'
distributed.nanny - INFO -         Start Nanny at: 'tcp://172.21.7.166:32933'
distributed.worker - INFO -       Start worker at:   tcp://172.21.6.169:37977
distributed.worker - INFO -          Listening to:   tcp://172.21.6.169:37977
distributed.worker - INFO -       Start worker at:   tcp://172.21.7.166:44392
distributed.worker - INFO -          dashboard at:         172.21.6.169:44269
distributed.worker - INFO - Waiting to connect to:    tcp://172.21.6.164:8786
distributed.worker - INFO -          Listening to:   tcp://172.21.7.166:44392
distributed.worker - INFO -       Start worker at:   tcp://172.21.6.169:42219
distributed.worker - INFO -          Listening to:   tcp://172.21.6.169:42219
distributed.worker - INFO -       Start worker at:   tcp://172.21.6.170:36076
distributed.worker - INFO -          Listening to:   tcp://172.21.6.170:36076
distributed.worker - INFO -          dashboard at:         172.21.7.166:40240
distributed.worker - INFO - -------------------------------------------------
distributed.worker - INFO -          dashboard at:         172.21.6.170:33480
distributed.worker - INFO - Waiting to connect to:    tcp://172.21.6.164:8786
distributed.worker - INFO - Waiting to connect to:    tcp://172.21.6.164:8786
distributed.worker - INFO -          dashboard at:         172.21.6.169:44603
distributed.worker - INFO - -------------------------------------------------
distributed.worker - INFO - -------------------------------------------------
distributed.worker - INFO -               Threads:                         24
distributed.worker - INFO -       Start worker at:   tcp://172.21.6.170:42875
distributed.worker - INFO -       Start worker at:   tcp://172.21.6.171:40876
distributed.worker - INFO -               Threads:                         24
distributed.worker - INFO - Waiting to connect to:    tcp://172.21.6.164:8786
distributed.worker - INFO -               Threads:                         24
distributed.worker - INFO -       Start worker at:   tcp://172.21.6.171:44057
distributed.worker - INFO -                Memory:                 172.73 GiB
distributed.worker - INFO - -------------------------------------------------
distributed.worker - INFO -          Listening to:   tcp://172.21.6.170:42875
distributed.worker - INFO -          Listening to:   tcp://172.21.6.171:40876
distributed.worker - INFO -       Local Directory: /tmp/dask-worker-space/worker-6mcfssim
distributed.worker - INFO -                Memory:                 172.73 GiB
distributed.worker - INFO -                Memory:                 172.73 GiB
distributed.worker - INFO -          Listening to:   tcp://172.21.6.171:44057
distributed.worker - INFO -       Start worker at:   tcp://172.21.7.166:39118
distributed.worker - INFO -       Local Directory: /tmp/dask-worker-space/worker-0lih3x68
distributed.worker - INFO -       Local Directory: /tmp/dask-worker-space/worker-0lvcbvvt
distributed.worker - INFO -          dashboard at:         172.21.6.171:37016
distributed.worker - INFO - -------------------------------------------------
distributed.worker - INFO -               Threads:                         24
distributed.worker - INFO -          dashboard at:         172.21.6.170:43262
distributed.worker - INFO - Waiting to connect to:    tcp://172.21.6.164:8786
distributed.worker - INFO -          Listening to:   tcp://172.21.7.166:39118
distributed.worker - INFO -                Memory:                 172.73 GiB
distributed.worker - INFO - Waiting to connect to:    tcp://172.21.6.164:8786
distributed.worker - INFO -          dashboard at:         172.21.6.171:38194
distributed.worker - INFO -          dashboard at:         172.21.7.166:33044
distributed.worker - INFO - -------------------------------------------------
distributed.worker - INFO - -------------------------------------------------
distributed.worker - INFO - -------------------------------------------------
distributed.worker - INFO - Waiting to connect to:    tcp://172.21.6.164:8786
distributed.worker - INFO -       Local Directory: /tmp/dask-worker-space/worker-brtjvtlp
distributed.worker - INFO - -------------------------------------------------
distributed.worker - INFO - Waiting to connect to:    tcp://172.21.6.164:8786
distributed.worker - INFO - -------------------------------------------------
distributed.worker - INFO - -------------------------------------------------
distributed.worker - INFO -               Threads:                         24
distributed.worker - INFO -               Threads:                         24
distributed.worker - INFO -               Threads:                         24
distributed.worker - INFO -                Memory:                 172.73 GiB
distributed.worker - INFO - -------------------------------------------------
distributed.worker - INFO -                Memory:                 172.73 GiB
distributed.worker - INFO -       Local Directory: /tmp/dask-worker-space/worker-la4azbde
distributed.worker - INFO -               Threads:                         24
distributed.worker - INFO -       Local Directory: /tmp/dask-worker-space/worker-q1ca6nml
distributed.worker - INFO - -------------------------------------------------
distributed.worker - INFO -                Memory:                 172.73 GiB
distributed.worker - INFO - -------------------------------------------------
distributed.worker - INFO -       Local Directory: /tmp/dask-worker-space/worker-_chqrwab
distributed.worker - INFO - -------------------------------------------------
distributed.worker - INFO -                Memory:                 172.73 GiB
distributed.worker - INFO -       Local Directory: /tmp/dask-worker-space/worker-i9bihp2x
distributed.worker - INFO - -------------------------------------------------
distributed.worker - INFO -         Registered to:    tcp://172.21.6.164:8786
distributed.worker - INFO - -------------------------------------------------
distributed.core - INFO - Starting established connection
distributed.worker - INFO -         Registered to:    tcp://172.21.6.164:8786
distributed.worker - INFO - -------------------------------------------------
distributed.core - INFO - Starting established connection
distributed.worker - INFO -         Registered to:    tcp://172.21.6.164:8786
distributed.worker - INFO - -------------------------------------------------
distributed.core - INFO - Starting established connection
distributed.worker - INFO -         Registered to:    tcp://172.21.6.164:8786
distributed.worker - INFO - -------------------------------------------------
distributed.core - INFO - Starting established connection
distributed.worker - INFO -         Registered to:    tcp://172.21.6.164:8786
distributed.worker - INFO - -------------------------------------------------
distributed.core - INFO - Starting established connection
distributed.worker - INFO -         Registered to:    tcp://172.21.6.164:8786
distributed.worker - INFO - -------------------------------------------------
distributed.core - INFO - Starting established connection
distributed.worker - INFO -         Registered to:    tcp://172.21.6.164:8786
distributed.worker - INFO - -------------------------------------------------
distributed.core - INFO - Starting established connection
distributed.worker - INFO -         Registered to:    tcp://172.21.6.164:8786
distributed.worker - INFO - -------------------------------------------------
distributed.core - INFO - Starting established connection
distributed.worker - ERROR - Worker stream died during communication: tcp://172.21.7.166:44392
Traceback (most recent call last):
  File "/ccc/work/cont003/gen2224/gen2224/spack/var/spack/environments/gysela-deisa-irene-skl-draft/.spack-env/view/lib/python3.9/site-packages/distributed/comm/tcp.py", line 205, in read
    frames_nbytes = await stream.read_bytes(fmt_size)
asyncio.exceptions.CancelledError

During handling of the above exception, another exception occurred:

Traceback (most recent call last):
  File "/ccc/work/cont003/gen2224/gen2224/spack/var/spack/environments/gysela-deisa-irene-skl-draft/.spack-env/._view/whcr3wyhzgorszy3rfxsphyebtvfpqzk/lib/python3.9/asyncio/tasks.py", line 490, in wait_for
    return fut.result()
asyncio.exceptions.CancelledError

The above exception was the direct cause of the following exception:

Traceback (most recent call last):
distributed.worker - ERROR - Worker stream died during communication: tcp://172.21.7.166:44392
Traceback (most recent call last):
  File "/ccc/work/cont003/gen2224/gen2224/spack/var/spack/environments/gysela-deisa-irene-skl-draft/.spack-env/view/lib/python3.9/site-packages/distributed/comm/tcp.py", line 205, in read
    frames_nbytes = await stream.read_bytes(fmt_size)
asyncio.exceptions.CancelledError

During handling of the above exception, another exception occurred:

Traceback (most recent call last):
  File "/ccc/work/cont003/gen2224/gen2224/spack/var/spack/environments/gysela-deisa-irene-skl-draft/.spack-env/._view/whcr3wyhzgorszy3rfxsphyebtvfpqzk/lib/python3.9/asyncio/tasks.py", line 490, in wait_for
    return fut.result()
asyncio.exceptions.CancelledError

The above exception was the direct cause of the following exception:

Traceback (most recent call last):
  File "/ccc/work/cont003/gen2224/gen2224/spack/var/spack/environments/gysela-deisa-irene-skl-draft/.spack-env/view/lib/python3.9/site-packages/distributed/comm/core.py", line 319, in connect
    handshake = await asyncio.wait_for(comm.read(), time_left())
  File "/ccc/work/cont003/gen2224/gen2224/spack/var/spack/environments/gysela-deisa-irene-skl-draft/.spack-env/._view/whcr3wyhzgorszy3rfxsphyebtvfpqzk/lib/python3.9/asyncio/tasks.py", line 492, in wait_for
    raise exceptions.TimeoutError() from exc
asyncio.exceptions.TimeoutError

The above exception was the direct cause of the following exception:

Traceback (most recent call last):
  File "/ccc/work/cont003/gen2224/gen2224/spack/var/spack/environments/gysela-deisa-irene-skl-draft/.spack-env/view/lib/python3.9/site-packages/distributed/worker.py", line 2878, in gather_dep
    response = await get_data_from_worker(
  File "/ccc/work/cont003/gen2224/gen2224/spack/var/spack/environments/gysela-deisa-irene-skl-draft/.spack-env/view/lib/python3.9/site-packages/distributed/comm/core.py", line 319, in connect
    handshake = await asyncio.wait_for(comm.read(), time_left())
  File "/ccc/work/cont003/gen2224/gen2224/spack/var/spack/environments/gysela-deisa-irene-skl-draft/.spack-env/._view/whcr3wyhzgorszy3rfxsphyebtvfpqzk/lib/python3.9/asyncio/tasks.py", line 492, in wait_for
    raise exceptions.TimeoutError() from exc
asyncio.exceptions.TimeoutError

The above exception was the direct cause of the following exception:

Traceback (most recent call last):
  File "/ccc/work/cont003/gen2224/gen2224/spack/var/spack/environments/gysela-deisa-irene-skl-draft/.spack-env/view/lib/python3.9/site-packages/distributed/worker.py", line 2878, in gather_dep
    response = await get_data_from_worker(
  File "/ccc/work/cont003/gen2224/gen2224/spack/var/spack/environments/gysela-deisa-irene-skl-draft/.spack-env/view/lib/python3.9/site-packages/distributed/worker.py", line 4143, in get_data_from_worker
    return await retry_operation(_get_data, operation="get_data_from_worker")
  File "/ccc/work/cont003/gen2224/gen2224/spack/var/spack/environments/gysela-deisa-irene-skl-draft/.spack-env/view/lib/python3.9/site-packages/distributed/utils_comm.py", line 366, in retry_operation
    return await retry(
  File "/ccc/work/cont003/gen2224/gen2224/spack/var/spack/environments/gysela-deisa-irene-skl-draft/.spack-env/view/lib/python3.9/site-packages/distributed/utils_comm.py", line 351, in retry
    return await coro()
  File "/ccc/work/cont003/gen2224/gen2224/spack/var/spack/environments/gysela-deisa-irene-skl-draft/.spack-env/view/lib/python3.9/site-packages/distributed/worker.py", line 4120, in _get_data
    comm = await rpc.connect(worker)
distributed.worker - ERROR - Worker stream died during communication: tcp://172.21.7.166:44392
Traceback (most recent call last):
  File "/ccc/work/cont003/gen2224/gen2224/spack/var/spack/environments/gysela-deisa-irene-skl-draft/.spack-env/view/lib/python3.9/site-packages/distributed/comm/tcp.py", line 205, in read
    frames_nbytes = await stream.read_bytes(fmt_size)
asyncio.exceptions.CancelledError

During handling of the above exception, another exception occurred:

Traceback (most recent call last):
  File "/ccc/work/cont003/gen2224/gen2224/spack/var/spack/environments/gysela-deisa-irene-skl-draft/.spack-env/._view/whcr3wyhzgorszy3rfxsphyebtvfpqzk/lib/python3.9/asyncio/tasks.py", line 490, in wait_for
    return fut.result()
asyncio.exceptions.CancelledError

The above exception was the direct cause of the following exception:

Traceback (most recent call last):
  File "/ccc/work/cont003/gen2224/gen2224/spack/var/spack/environments/gysela-deisa-irene-skl-draft/.spack-env/view/lib/python3.9/site-packages/distributed/worker.py", line 4143, in get_data_from_worker
    return await retry_operation(_get_data, operation="get_data_from_worker")
  File "/ccc/work/cont003/gen2224/gen2224/spack/var/spack/environments/gysela-deisa-irene-skl-draft/.spack-env/view/lib/python3.9/site-packages/distributed/utils_comm.py", line 366, in retry_operation
    return await retry(
  File "/ccc/work/cont003/gen2224/gen2224/spack/var/spack/environments/gysela-deisa-irene-skl-draft/.spack-env/view/lib/python3.9/site-packages/distributed/utils_comm.py", line 351, in retry
    return await coro()
  File "/ccc/work/cont003/gen2224/gen2224/spack/var/spack/environments/gysela-deisa-irene-skl-draft/.spack-env/view/lib/python3.9/site-packages/distributed/worker.py", line 4120, in _get_data
    comm = await rpc.connect(worker)
  File "/ccc/work/cont003/gen2224/gen2224/spack/var/spack/environments/gysela-deisa-irene-skl-draft/.spack-env/view/lib/python3.9/site-packages/distributed/core.py", line 1081, in connect
    raise exc
  File "/ccc/work/cont003/gen2224/gen2224/spack/var/spack/environments/gysela-deisa-irene-skl-draft/.spack-env/view/lib/python3.9/site-packages/distributed/core.py", line 1065, in connect
    comm = await fut
  File "/ccc/work/cont003/gen2224/gen2224/spack/var/spack/environments/gysela-deisa-irene-skl-draft/.spack-env/view/lib/python3.9/site-packages/distributed/comm/core.py", line 324, in connect
    raise OSError(
OSError: Timed out during handshake while connecting to tcp://172.21.7.166:44392 after 30 s
  File "/ccc/work/cont003/gen2224/gen2224/spack/var/spack/environments/gysela-deisa-irene-skl-draft/.spack-env/view/lib/python3.9/site-packages/distributed/comm/core.py", line 319, in connect
    handshake = await asyncio.wait_for(comm.read(), time_left())
  File "/ccc/work/cont003/gen2224/gen2224/spack/var/spack/environments/gysela-deisa-irene-skl-draft/.spack-env/._view/whcr3wyhzgorszy3rfxsphyebtvfpqzk/lib/python3.9/asyncio/tasks.py", line 492, in wait_for
    raise exceptions.TimeoutError() from exc
asyncio.exceptions.TimeoutError

The above exception was the direct cause of the following exception:

Traceback (most recent call last):
  File "/ccc/work/cont003/gen2224/gen2224/spack/var/spack/environments/gysela-deisa-irene-skl-draft/.spack-env/view/lib/python3.9/site-packages/distributed/worker.py", line 2878, in gather_dep
    response = await get_data_from_worker(
  File "/ccc/work/cont003/gen2224/gen2224/spack/var/spack/environments/gysela-deisa-irene-skl-draft/.spack-env/view/lib/python3.9/site-packages/distributed/core.py", line 1081, in connect
    raise exc
  File "/ccc/work/cont003/gen2224/gen2224/spack/var/spack/environments/gysela-deisa-irene-skl-draft/.spack-env/view/lib/python3.9/site-packages/distributed/core.py", line 1065, in connect
    comm = await fut
  File "/ccc/work/cont003/gen2224/gen2224/spack/var/spack/environments/gysela-deisa-irene-skl-draft/.spack-env/view/lib/python3.9/site-packages/distributed/comm/core.py", line 324, in connect
    raise OSError(
OSError: Timed out during handshake while connecting to tcp://172.21.7.166:44392 after 30 s
distributed.worker - ERROR - Worker stream died during communication: tcp://172.21.7.166:44392
Traceback (most recent call last):
  File "/ccc/work/cont003/gen2224/gen2224/spack/var/spack/environments/gysela-deisa-irene-skl-draft/.spack-env/view/lib/python3.9/site-packages/distributed/comm/tcp.py", line 205, in read
    frames_nbytes = await stream.read_bytes(fmt_size)
asyncio.exceptions.CancelledError

During handling of the above exception, another exception occurred:

Traceback (most recent call last):
  File "/ccc/work/cont003/gen2224/gen2224/spack/var/spack/environments/gysela-deisa-irene-skl-draft/.spack-env/._view/whcr3wyhzgorszy3rfxsphyebtvfpqzk/lib/python3.9/asyncio/tasks.py", line 490, in wait_for
    return fut.result()
asyncio.exceptions.CancelledError

The above exception was the direct cause of the following exception:

Traceback (most recent call last):
  File "/ccc/work/cont003/gen2224/gen2224/spack/var/spack/environments/gysela-deisa-irene-skl-draft/.spack-env/view/lib/python3.9/site-packages/distributed/worker.py", line 4143, in get_data_from_worker
    return await retry_operation(_get_data, operation="get_data_from_worker")
  File "/ccc/work/cont003/gen2224/gen2224/spack/var/spack/environments/gysela-deisa-irene-skl-draft/.spack-env/view/lib/python3.9/site-packages/distributed/utils_comm.py", line 366, in retry_operation
    return await retry(
  File "/ccc/work/cont003/gen2224/gen2224/spack/var/spack/environments/gysela-deisa-irene-skl-draft/.spack-env/view/lib/python3.9/site-packages/distributed/utils_comm.py", line 351, in retry
    return await coro()
  File "/ccc/work/cont003/gen2224/gen2224/spack/var/spack/environments/gysela-deisa-irene-skl-draft/.spack-env/view/lib/python3.9/site-packages/distributed/worker.py", line 4120, in _get_data
    comm = await rpc.connect(worker)
  File "/ccc/work/cont003/gen2224/gen2224/spack/var/spack/environments/gysela-deisa-irene-skl-draft/.spack-env/view/lib/python3.9/site-packages/distributed/comm/core.py", line 319, in connect
    handshake = await asyncio.wait_for(comm.read(), time_left())
  File "/ccc/work/cont003/gen2224/gen2224/spack/var/spack/environments/gysela-deisa-irene-skl-draft/.spack-env/._view/whcr3wyhzgorszy3rfxsphyebtvfpqzk/lib/python3.9/asyncio/tasks.py", line 492, in wait_for
    raise exceptions.TimeoutError() from exc
asyncio.exceptions.TimeoutError

The above exception was the direct cause of the following exception:

Traceback (most recent call last):
  File "/ccc/work/cont003/gen2224/gen2224/spack/var/spack/environments/gysela-deisa-irene-skl-draft/.spack-env/view/lib/python3.9/site-packages/distributed/worker.py", line 2878, in gather_dep
    response = await get_data_from_worker(
  File "/ccc/work/cont003/gen2224/gen2224/spack/var/spack/environments/gysela-deisa-irene-skl-draft/.spack-env/view/lib/python3.9/site-packages/distributed/core.py", line 1081, in connect
    raise exc
  File "/ccc/work/cont003/gen2224/gen2224/spack/var/spack/environments/gysela-deisa-irene-skl-draft/.spack-env/view/lib/python3.9/site-packages/distributed/core.py", line 1065, in connect
    comm = await fut
  File "/ccc/work/cont003/gen2224/gen2224/spack/var/spack/environments/gysela-deisa-irene-skl-draft/.spack-env/view/lib/python3.9/site-packages/distributed/comm/core.py", line 324, in connect
    raise OSError(
OSError: Timed out during handshake while connecting to tcp://172.21.7.166:44392 after 30 s
  File "/ccc/work/cont003/gen2224/gen2224/spack/var/spack/environments/gysela-deisa-irene-skl-draft/.spack-env/view/lib/python3.9/site-packages/distributed/worker.py", line 4143, in get_data_from_worker
    return await retry_operation(_get_data, operation="get_data_from_worker")
  File "/ccc/work/cont003/gen2224/gen2224/spack/var/spack/environments/gysela-deisa-irene-skl-draft/.spack-env/view/lib/python3.9/site-packages/distributed/utils_comm.py", line 366, in retry_operation
    return await retry(
  File "/ccc/work/cont003/gen2224/gen2224/spack/var/spack/environments/gysela-deisa-irene-skl-draft/.spack-env/view/lib/python3.9/site-packages/distributed/utils_comm.py", line 351, in retry
    return await coro()
  File "/ccc/work/cont003/gen2224/gen2224/spack/var/spack/environments/gysela-deisa-irene-skl-draft/.spack-env/view/lib/python3.9/site-packages/distributed/worker.py", line 4120, in _get_data
    comm = await rpc.connect(worker)
  File "/ccc/work/cont003/gen2224/gen2224/spack/var/spack/environments/gysela-deisa-irene-skl-draft/.spack-env/view/lib/python3.9/site-packages/distributed/core.py", line 1081, in connect
    raise exc
  File "/ccc/work/cont003/gen2224/gen2224/spack/var/spack/environments/gysela-deisa-irene-skl-draft/.spack-env/view/lib/python3.9/site-packages/distributed/core.py", line 1065, in connect
    comm = await fut
  File "/ccc/work/cont003/gen2224/gen2224/spack/var/spack/environments/gysela-deisa-irene-skl-draft/.spack-env/view/lib/python3.9/site-packages/distributed/comm/core.py", line 324, in connect
    raise OSError(
OSError: Timed out during handshake while connecting to tcp://172.21.7.166:44392 after 30 s
distributed.worker - ERROR - Worker stream died during communication: tcp://172.21.6.170:42875
Traceback (most recent call last):
  File "/ccc/work/cont003/gen2224/gen2224/spack/var/spack/environments/gysela-deisa-irene-skl-draft/.spack-env/view/lib/python3.9/site-packages/distributed/comm/tcp.py", line 205, in read
    frames_nbytes = await stream.read_bytes(fmt_size)
asyncio.exceptions.CancelledError

During handling of the above exception, another exception occurred:

Traceback (most recent call last):
  File "/ccc/work/cont003/gen2224/gen2224/spack/var/spack/environments/gysela-deisa-irene-skl-draft/.spack-env/._view/whcr3wyhzgorszy3rfxsphyebtvfpqzk/lib/python3.9/asyncio/tasks.py", line 490, in wait_for
    return fut.result()
asyncio.exceptions.CancelledError

The above exception was the direct cause of the following exception:

Traceback (most recent call last):
  File "/ccc/work/cont003/gen2224/gen2224/spack/var/spack/environments/gysela-deisa-irene-skl-draft/.spack-env/view/lib/python3.9/site-packages/distributed/comm/core.py", line 319, in connect
    handshake = await asyncio.wait_for(comm.read(), time_left())
  File "/ccc/work/cont003/gen2224/gen2224/spack/var/spack/environments/gysela-deisa-irene-skl-draft/.spack-env/._view/whcr3wyhzgorszy3rfxsphyebtvfpqzk/lib/python3.9/asyncio/tasks.py", line 492, in wait_for
    raise exceptions.TimeoutError() from exc
asyncio.exceptions.TimeoutError

The above exception was the direct cause of the following exception:

Traceback (most recent call last):
  File "/ccc/work/cont003/gen2224/gen2224/spack/var/spack/environments/gysela-deisa-irene-skl-draft/.spack-env/view/lib/python3.9/site-packages/distributed/worker.py", line 2878, in gather_dep
    response = await get_data_from_worker(
  File "/ccc/work/cont003/gen2224/gen2224/spack/var/spack/environments/gysela-deisa-irene-skl-draft/.spack-env/view/lib/python3.9/site-packages/distributed/worker.py", line 4143, in get_data_from_worker
    return await retry_operation(_get_data, operation="get_data_from_worker")
  File "/ccc/work/cont003/gen2224/gen2224/spack/var/spack/environments/gysela-deisa-irene-skl-draft/.spack-env/view/lib/python3.9/site-packages/distributed/utils_comm.py", line 366, in retry_operation
    return await retry(
  File "/ccc/work/cont003/gen2224/gen2224/spack/var/spack/environments/gysela-deisa-irene-skl-draft/.spack-env/view/lib/python3.9/site-packages/distributed/utils_comm.py", line 351, in retry
    return await coro()
  File "/ccc/work/cont003/gen2224/gen2224/spack/var/spack/environments/gysela-deisa-irene-skl-draft/.spack-env/view/lib/python3.9/site-packages/distributed/worker.py", line 4120, in _get_data
    comm = await rpc.connect(worker)
  File "/ccc/work/cont003/gen2224/gen2224/spack/var/spack/environments/gysela-deisa-irene-skl-draft/.spack-env/view/lib/python3.9/site-packages/distributed/core.py", line 1081, in connect
    raise exc
  File "/ccc/work/cont003/gen2224/gen2224/spack/var/spack/environments/gysela-deisa-irene-skl-draft/.spack-env/view/lib/python3.9/site-packages/distributed/core.py", line 1065, in connect
    comm = await fut
  File "/ccc/work/cont003/gen2224/gen2224/spack/var/spack/environments/gysela-deisa-irene-skl-draft/.spack-env/view/lib/python3.9/site-packages/distributed/comm/core.py", line 324, in connect
    raise OSError(
OSError: Timed out during handshake while connecting to tcp://172.21.6.170:42875 after 30 s
distributed.worker - ERROR - Worker stream died during communication: tcp://172.21.6.170:42875
Traceback (most recent call last):
  File "/ccc/work/cont003/gen2224/gen2224/spack/var/spack/environments/gysela-deisa-irene-skl-draft/.spack-env/view/lib/python3.9/site-packages/distributed/comm/tcp.py", line 205, in read
    frames_nbytes = await stream.read_bytes(fmt_size)
asyncio.exceptions.CancelledError

During handling of the above exception, another exception occurred:

Traceback (most recent call last):
  File "/ccc/work/cont003/gen2224/gen2224/spack/var/spack/environments/gysela-deisa-irene-skl-draft/.spack-env/._view/whcr3wyhzgorszy3rfxsphyebtvfpqzk/lib/python3.9/asyncio/tasks.py", line 490, in wait_for
    return fut.result()
asyncio.exceptions.CancelledError

The above exception was the direct cause of the following exception:

Traceback (most recent call last):
  File "/ccc/work/cont003/gen2224/gen2224/spack/var/spack/environments/gysela-deisa-irene-skl-draft/.spack-env/view/lib/python3.9/site-packages/distributed/comm/core.py", line 319, in connect
    handshake = await asyncio.wait_for(comm.read(), time_left())
  File "/ccc/work/cont003/gen2224/gen2224/spack/var/spack/environments/gysela-deisa-irene-skl-draft/.spack-env/._view/whcr3wyhzgorszy3rfxsphyebtvfpqzk/lib/python3.9/asyncio/tasks.py", line 492, in wait_for
    raise exceptions.TimeoutError() from exc
asyncio.exceptions.TimeoutError

The above exception was the direct cause of the following exception:

Traceback (most recent call last):
  File "/ccc/work/cont003/gen2224/gen2224/spack/var/spack/environments/gysela-deisa-irene-skl-draft/.spack-env/view/lib/python3.9/site-packages/distributed/worker.py", line 2878, in gather_dep
    response = await get_data_from_worker(
  File "/ccc/work/cont003/gen2224/gen2224/spack/var/spack/environments/gysela-deisa-irene-skl-draft/.spack-env/view/lib/python3.9/site-packages/distributed/worker.py", line 4143, in get_data_from_worker
    return await retry_operation(_get_data, operation="get_data_from_worker")
  File "/ccc/work/cont003/gen2224/gen2224/spack/var/spack/environments/gysela-deisa-irene-skl-draft/.spack-env/view/lib/python3.9/site-packages/distributed/utils_comm.py", line 366, in retry_operation
    return await retry(
  File "/ccc/work/cont003/gen2224/gen2224/spack/var/spack/environments/gysela-deisa-irene-skl-draft/.spack-env/view/lib/python3.9/site-packages/distributed/utils_comm.py", line 351, in retry
    return await coro()
  File "/ccc/work/cont003/gen2224/gen2224/spack/var/spack/environments/gysela-deisa-irene-skl-draft/.spack-env/view/lib/python3.9/site-packages/distributed/worker.py", line 4120, in _get_data
    comm = await rpc.connect(worker)
  File "/ccc/work/cont003/gen2224/gen2224/spack/var/spack/environments/gysela-deisa-irene-skl-draft/.spack-env/view/lib/python3.9/site-packages/distributed/core.py", line 1081, in connect
    raise exc
  File "/ccc/work/cont003/gen2224/gen2224/spack/var/spack/environments/gysela-deisa-irene-skl-draft/.spack-env/view/lib/python3.9/site-packages/distributed/core.py", line 1065, in connect
    comm = await fut
  File "/ccc/work/cont003/gen2224/gen2224/spack/var/spack/environments/gysela-deisa-irene-skl-draft/.spack-env/view/lib/python3.9/site-packages/distributed/comm/core.py", line 324, in connect
    raise OSError(
OSError: Timed out during handshake while connecting to tcp://172.21.6.170:42875 after 30 s
distributed.worker - ERROR - Worker stream died during communication: tcp://172.21.6.169:42219
Traceback (most recent call last):
  File "/ccc/work/cont003/gen2224/gen2224/spack/var/spack/environments/gysela-deisa-irene-skl-draft/.spack-env/view/lib/python3.9/site-packages/distributed/comm/tcp.py", line 205, in read
    frames_nbytes = await stream.read_bytes(fmt_size)
asyncio.exceptions.CancelledError

During handling of the above exception, another exception occurred:

Traceback (most recent call last):
  File "/ccc/work/cont003/gen2224/gen2224/spack/var/spack/environments/gysela-deisa-irene-skl-draft/.spack-env/._view/whcr3wyhzgorszy3rfxsphyebtvfpqzk/lib/python3.9/asyncio/tasks.py", line 490, in wait_for
    return fut.result()
asyncio.exceptions.CancelledError

The above exception was the direct cause of the following exception:

Traceback (most recent call last):
  File "/ccc/work/cont003/gen2224/gen2224/spack/var/spack/environments/gysela-deisa-irene-skl-draft/.spack-env/view/lib/python3.9/site-packages/distributed/comm/core.py", line 319, in connect
    handshake = await asyncio.wait_for(comm.read(), time_left())
  File "/ccc/work/cont003/gen2224/gen2224/spack/var/spack/environments/gysela-deisa-irene-skl-draft/.spack-env/._view/whcr3wyhzgorszy3rfxsphyebtvfpqzk/lib/python3.9/asyncio/tasks.py", line 492, in wait_for
    raise exceptions.TimeoutError() from exc
asyncio.exceptions.TimeoutError

The above exception was the direct cause of the following exception:

Traceback (most recent call last):
  File "/ccc/work/cont003/gen2224/gen2224/spack/var/spack/environments/gysela-deisa-irene-skl-draft/.spack-env/view/lib/python3.9/site-packages/distributed/worker.py", line 2878, in gather_dep
    response = await get_data_from_worker(
  File "/ccc/work/cont003/gen2224/gen2224/spack/var/spack/environments/gysela-deisa-irene-skl-draft/.spack-env/view/lib/python3.9/site-packages/distributed/worker.py", line 4143, in get_data_from_worker
    return await retry_operation(_get_data, operation="get_data_from_worker")
  File "/ccc/work/cont003/gen2224/gen2224/spack/var/spack/environments/gysela-deisa-irene-skl-draft/.spack-env/view/lib/python3.9/site-packages/distributed/utils_comm.py", line 366, in retry_operation
    return await retry(
  File "/ccc/work/cont003/gen2224/gen2224/spack/var/spack/environments/gysela-deisa-irene-skl-draft/.spack-env/view/lib/python3.9/site-packages/distributed/utils_comm.py", line 351, in retry
    return await coro()
  File "/ccc/work/cont003/gen2224/gen2224/spack/var/spack/environments/gysela-deisa-irene-skl-draft/.spack-env/view/lib/python3.9/site-packages/distributed/worker.py", line 4120, in _get_data
    comm = await rpc.connect(worker)
  File "/ccc/work/cont003/gen2224/gen2224/spack/var/spack/environments/gysela-deisa-irene-skl-draft/.spack-env/view/lib/python3.9/site-packages/distributed/core.py", line 1081, in connect
    raise exc
  File "/ccc/work/cont003/gen2224/gen2224/spack/var/spack/environments/gysela-deisa-irene-skl-draft/.spack-env/view/lib/python3.9/site-packages/distributed/core.py", line 1065, in connect
    comm = await fut
  File "/ccc/work/cont003/gen2224/gen2224/spack/var/spack/environments/gysela-deisa-irene-skl-draft/.spack-env/view/lib/python3.9/site-packages/distributed/comm/core.py", line 324, in connect
    raise OSError(
OSError: Timed out during handshake while connecting to tcp://172.21.6.169:42219 after 30 s
distributed.core - INFO - Event loop was unresponsive in Worker for 275.20s.  This is often caused by long-running GIL-holding functions or moving large chunks of data. This can cause timeouts and instability.
distributed.core - INFO - Event loop was unresponsive in Worker for 259.67s.  This is often caused by long-running GIL-holding functions or moving large chunks of data. This can cause timeouts and instability.
distributed.comm.tcp - INFO - Connection from tcp://172.21.6.169:48660 closed before handshake completed
distributed.core - INFO - Event loop was unresponsive in Worker for 16.25s.  This is often caused by long-running GIL-holding functions or moving large chunks of data. This can cause timeouts and instability.
distributed.comm.tcp - INFO - Connection from tcp://172.21.7.166:57816 closed before handshake completed
distributed.comm.tcp - INFO - Connection from tcp://172.21.6.169:37096 closed before handshake completed
distributed.core - INFO - Event loop was unresponsive in Worker for 405.45s.  This is often caused by long-running GIL-holding functions or moving large chunks of data. This can cause timeouts and instability.
distributed.worker - ERROR - 'array-original-881dfe07e42781980f1c167f1a8c600d'
Traceback (most recent call last):
  File "/ccc/work/cont003/gen2224/gen2224/spack/var/spack/environments/gysela-deisa-irene-skl-draft/.spack-env/view/lib/python3.9/site-packages/distributed/worker.py", line 2885, in gather_dep
    self._update_metrics_received_data(
  File "/ccc/work/cont003/gen2224/gen2224/spack/var/spack/environments/gysela-deisa-irene-skl-draft/.spack-env/view/lib/python3.9/site-packages/distributed/worker.py", line 2782, in _update_metrics_received_data
    total_bytes = sum(self.tasks[key].get_nbytes() for key in data)
  File "/ccc/work/cont003/gen2224/gen2224/spack/var/spack/environments/gysela-deisa-irene-skl-draft/.spack-env/view/lib/python3.9/site-packages/distributed/worker.py", line 2782, in <genexpr>
    total_bytes = sum(self.tasks[key].get_nbytes() for key in data)
KeyError: 'array-original-881dfe07e42781980f1c167f1a8c600d'
distributed.comm.tcp - INFO - Connection from tcp://172.21.7.166:38468 closed before handshake completed
distributed.comm.tcp - INFO - Connection from tcp://172.21.6.170:44768 closed before handshake completed
distributed.comm.tcp - INFO - Connection from tcp://172.21.6.171:39546 closed before handshake completed
distributed.comm.tcp - INFO - Connection from tcp://172.21.6.170:44770 closed before handshake completed
distributed.utils - ERROR - 'array-original-881dfe07e42781980f1c167f1a8c600d'
Traceback (most recent call last):
  File "/ccc/work/cont003/gen2224/gen2224/spack/var/spack/environments/gysela-deisa-irene-skl-draft/.spack-env/view/lib/python3.9/site-packages/distributed/worker.py", line 2885, in gather_dep
    self._update_metrics_received_data(
  File "/ccc/work/cont003/gen2224/gen2224/spack/var/spack/environments/gysela-deisa-irene-skl-draft/.spack-env/view/lib/python3.9/site-packages/distributed/worker.py", line 2782, in _update_metrics_received_data
    total_bytes = sum(self.tasks[key].get_nbytes() for key in data)
  File "/ccc/work/cont003/gen2224/gen2224/spack/var/spack/environments/gysela-deisa-irene-skl-draft/.spack-env/view/lib/python3.9/site-packages/distributed/worker.py", line 2782, in <genexpr>
    total_bytes = sum(self.tasks[key].get_nbytes() for key in data)
KeyError: 'array-original-881dfe07e42781980f1c167f1a8c600d'

During handling of the above exception, another exception occurred:

Traceback (most recent call last):
  File "/ccc/work/cont003/gen2224/gen2224/spack/var/spack/environments/gysela-deisa-irene-skl-draft/.spack-env/view/lib/python3.9/site-packages/distributed/worker.py", line 2915, in gather_dep
    ts = self.tasks[k]
KeyError: 'array-original-881dfe07e42781980f1c167f1a8c600d'

During handling of the above exception, another exception occurred:

Traceback (most recent call last):
  File "/ccc/work/cont003/gen2224/gen2224/spack/var/spack/environments/gysela-deisa-irene-skl-draft/.spack-env/view/lib/python3.9/site-packages/distributed/utils.py", line 684, in log_errors
    yield
  File "/ccc/work/cont003/gen2224/gen2224/spack/var/spack/environments/gysela-deisa-irene-skl-draft/.spack-env/view/lib/python3.9/site-packages/distributed/worker.py", line 2929, in gather_dep
    ts = self.tasks[d]
KeyError: 'array-original-881dfe07e42781980f1c167f1a8c600d'
tornado.application - ERROR - Exception in callback functools.partial(<bound method IOLoop._discard_future_result of <tornado.platform.asyncio.AsyncIOLoop object at 0x2ab950bfb700>>, <Task finished name='Task-5800' coro=<Worker.gather_dep() done, defined at /ccc/work/cont003/gen2224/gen2224/spack/var/spack/environments/gysela-deisa-irene-skl-draft/.spack-env/view/lib/python3.9/site-packages/distributed/worker.py:2823> exception=KeyError('array-original-881dfe07e42781980f1c167f1a8c600d')>)
Traceback (most recent call last):
  File "/ccc/work/cont003/gen2224/gen2224/spack/var/spack/environments/gysela-deisa-irene-skl-draft/.spack-env/view/lib/python3.9/site-packages/distributed/worker.py", line 2885, in gather_dep
    self._update_metrics_received_data(
  File "/ccc/work/cont003/gen2224/gen2224/spack/var/spack/environments/gysela-deisa-irene-skl-draft/.spack-env/view/lib/python3.9/site-packages/distributed/worker.py", line 2782, in _update_metrics_received_data
    total_bytes = sum(self.tasks[key].get_nbytes() for key in data)
  File "/ccc/work/cont003/gen2224/gen2224/spack/var/spack/environments/gysela-deisa-irene-skl-draft/.spack-env/view/lib/python3.9/site-packages/distributed/worker.py", line 2782, in <genexpr>
    total_bytes = sum(self.tasks[key].get_nbytes() for key in data)
KeyError: 'array-original-881dfe07e42781980f1c167f1a8c600d'

During handling of the above exception, another exception occurred:

Traceback (most recent call last):
  File "/ccc/work/cont003/gen2224/gen2224/spack/var/spack/environments/gysela-deisa-irene-skl-draft/.spack-env/view/lib/python3.9/site-packages/distributed/worker.py", line 2915, in gather_dep
    ts = self.tasks[k]
KeyError: 'array-original-881dfe07e42781980f1c167f1a8c600d'

During handling of the above exception, another exception occurred:

Traceback (most recent call last):
  File "/ccc/work/cont003/gen2224/gen2224/spack/var/spack/environments/gysela-deisa-irene-skl-draft/.spack-env/view/lib/python3.9/site-packages/tornado/ioloop.py", line 741, in _run_callback
    ret = callback()
  File "/ccc/work/cont003/gen2224/gen2224/spack/var/spack/environments/gysela-deisa-irene-skl-draft/.spack-env/view/lib/python3.9/site-packages/tornado/ioloop.py", line 765, in _discard_future_result
    future.result()
  File "/ccc/work/cont003/gen2224/gen2224/spack/var/spack/environments/gysela-deisa-irene-skl-draft/.spack-env/view/lib/python3.9/site-packages/distributed/worker.py", line 2929, in gather_dep
    ts = self.tasks[d]
KeyError: 'array-original-881dfe07e42781980f1c167f1a8c600d'
distributed.core - INFO - Event loop was unresponsive in Worker for 42.51s.  This is often caused by long-running GIL-holding functions or moving large chunks of data. This can cause timeouts and instability.
distributed.core - INFO - Event loop was unresponsive in Worker for 14.83s.  This is often caused by long-running GIL-holding functions or moving large chunks of data. This can cause timeouts and instability.
distributed.core - INFO - Event loop was unresponsive in Worker for 105.52s.  This is often caused by long-running GIL-holding functions or moving large chunks of data. This can cause timeouts and instability.
distributed.worker - INFO - Stopping worker at tcp://172.21.6.169:37977
distributed.worker - INFO - Stopping worker at tcp://172.21.7.166:44392
distributed.worker - INFO - Stopping worker at tcp://172.21.6.169:42219
distributed.worker - INFO - Stopping worker at tcp://172.21.6.170:42875
distributed.worker - INFO - Stopping worker at tcp://172.21.6.170:36076
distributed.worker - INFO - Stopping worker at tcp://172.21.7.166:39118
distributed.worker - INFO - Stopping worker at tcp://172.21.6.171:44057
distributed.worker - INFO - Stopping worker at tcp://172.21.6.171:40876
distributed.nanny - INFO -         Start Nanny at: 'tcp://172.21.6.169:40869'
distributed.nanny - INFO -         Start Nanny at: 'tcp://172.21.6.169:42946'
distributed.nanny - INFO -         Start Nanny at: 'tcp://172.21.6.171:34729'
distributed.nanny - INFO -         Start Nanny at: 'tcp://172.21.7.166:32933'
distributed.nanny - INFO -         Start Nanny at: 'tcp://172.21.7.166:35076'
distributed.nanny - INFO -         Start Nanny at: 'tcp://172.21.6.170:41540'
distributed.nanny - INFO -         Start Nanny at: 'tcp://172.21.6.170:40762'
distributed.nanny - INFO -         Start Nanny at: 'tcp://172.21.6.171:33934'
distributed.nanny - INFO - Worker closed
distributed.nanny - INFO - Worker closed
distributed.nanny - INFO - Worker closed
distributed.nanny - INFO - Worker closed
distributed.nanny - INFO - Worker closed
distributed.nanny - INFO - Worker closed
distributed.nanny - INFO - Worker closed
distributed.nanny - INFO - Worker closed
distributed.nanny - INFO - Closing Nanny at 'tcp://172.21.6.171:33934'
distributed.dask_worker - INFO - End worker
distributed.nanny - INFO - Closing Nanny at 'tcp://172.21.6.171:34729'
distributed.dask_worker - INFO - End worker
distributed.nanny - INFO - Closing Nanny at 'tcp://172.21.6.170:40762'
distributed.dask_worker - INFO - End worker
distributed.nanny - INFO - Closing Nanny at 'tcp://172.21.6.170:41540'
distributed.dask_worker - INFO - End worker
distributed.nanny - INFO - Closing Nanny at 'tcp://172.21.6.169:40869'
distributed.dask_worker - INFO - End worker
distributed.nanny - INFO - Closing Nanny at 'tcp://172.21.6.169:42946'
distributed.dask_worker - INFO - End worker
distributed.nanny - INFO - Closing Nanny at 'tcp://172.21.7.166:35076'
distributed.dask_worker - INFO - End worker
distributed.nanny - INFO - Closing Nanny at 'tcp://172.21.7.166:32933'
distributed.dask_worker - INFO - End worker
