distributed.nanny - INFO -         Start Nanny at: 'tcp://172.21.3.74:37182'
distributed.nanny - INFO -         Start Nanny at: 'tcp://172.21.3.82:42704'
distributed.nanny - INFO -         Start Nanny at: 'tcp://172.21.3.79:44849'
distributed.nanny - INFO -         Start Nanny at: 'tcp://172.21.3.82:43788'
distributed.nanny - INFO -         Start Nanny at: 'tcp://172.21.3.87:44380'
distributed.nanny - INFO -         Start Nanny at: 'tcp://172.21.3.88:33651'
distributed.nanny - INFO -         Start Nanny at: 'tcp://172.21.3.80:37033'
distributed.nanny - INFO -         Start Nanny at: 'tcp://172.21.3.86:38537'
distributed.nanny - INFO -         Start Nanny at: 'tcp://172.21.3.80:43197'
distributed.nanny - INFO -         Start Nanny at: 'tcp://172.21.3.86:35268'
distributed.nanny - INFO -         Start Nanny at: 'tcp://172.21.3.74:34731'
distributed.nanny - INFO -         Start Nanny at: 'tcp://172.21.3.88:43943'
distributed.nanny - INFO -         Start Nanny at: 'tcp://172.21.3.87:38987'
distributed.nanny - INFO -         Start Nanny at: 'tcp://172.21.3.79:34380'
distributed.nanny - INFO -         Start Nanny at: 'tcp://172.21.3.81:33294'
distributed.nanny - INFO -         Start Nanny at: 'tcp://172.21.3.81:39657'
distributed.worker - INFO -       Start worker at:    tcp://172.21.3.87:36481
distributed.worker - INFO -          Listening to:    tcp://172.21.3.87:36481
distributed.worker - INFO -          dashboard at:          172.21.3.87:44174
distributed.worker - INFO - Waiting to connect to:     tcp://172.21.3.72:8786
distributed.worker - INFO - -------------------------------------------------
distributed.worker - INFO -               Threads:                         24
distributed.worker - INFO -                Memory:                 172.73 GiB
distributed.worker - INFO -       Local Directory: /tmp/dask-worker-space/worker-juh0b15g
distributed.worker - INFO - -------------------------------------------------
distributed.worker - INFO -       Start worker at:    tcp://172.21.3.87:41603
distributed.worker - INFO -          Listening to:    tcp://172.21.3.87:41603
distributed.worker - INFO -       Start worker at:    tcp://172.21.3.86:35653
distributed.worker - INFO -          dashboard at:          172.21.3.87:34836
distributed.worker - INFO -          Listening to:    tcp://172.21.3.86:35653
distributed.worker - INFO -          dashboard at:          172.21.3.86:36760
distributed.worker - INFO - Waiting to connect to:     tcp://172.21.3.72:8786
distributed.worker - INFO -       Start worker at:    tcp://172.21.3.86:42319
distributed.worker - INFO - -------------------------------------------------
distributed.worker - INFO - Waiting to connect to:     tcp://172.21.3.72:8786
distributed.worker - INFO -               Threads:                         24
distributed.worker - INFO - -------------------------------------------------
distributed.worker - INFO -                Memory:                 172.73 GiB
distributed.worker - INFO -          Listening to:    tcp://172.21.3.86:42319
distributed.worker - INFO -               Threads:                         24
distributed.worker - INFO -       Local Directory: /tmp/dask-worker-space/worker-l79c16rl
distributed.worker - INFO -          dashboard at:          172.21.3.86:41512
distributed.worker - INFO - -------------------------------------------------
distributed.worker - INFO -                Memory:                 172.73 GiB
distributed.worker - INFO - Waiting to connect to:     tcp://172.21.3.72:8786
distributed.worker - INFO - -------------------------------------------------
distributed.worker - INFO -       Local Directory: /tmp/dask-worker-space/worker-9o2xll95
distributed.worker - INFO -               Threads:                         24
distributed.worker - INFO - -------------------------------------------------
distributed.worker - INFO -                Memory:                 172.73 GiB
distributed.worker - INFO -       Local Directory: /tmp/dask-worker-space/worker-xib6vc4w
distributed.worker - INFO - -------------------------------------------------
distributed.worker - INFO -       Start worker at:    tcp://172.21.3.74:43859
distributed.worker - INFO -       Start worker at:    tcp://172.21.3.79:45306
distributed.worker - INFO -       Start worker at:    tcp://172.21.3.82:37680
distributed.worker - INFO -       Start worker at:    tcp://172.21.3.80:41498
distributed.worker - INFO -          Listening to:    tcp://172.21.3.80:41498
distributed.worker - INFO -          Listening to:    tcp://172.21.3.74:43859
distributed.worker - INFO -          Listening to:    tcp://172.21.3.79:45306
distributed.worker - INFO -          Listening to:    tcp://172.21.3.82:37680
distributed.worker - INFO -          dashboard at:          172.21.3.80:34876
distributed.worker - INFO - Waiting to connect to:     tcp://172.21.3.72:8786
distributed.worker - INFO -          dashboard at:          172.21.3.74:45852
distributed.worker - INFO -          dashboard at:          172.21.3.79:35712
distributed.worker - INFO -          dashboard at:          172.21.3.82:32847
distributed.worker - INFO - -------------------------------------------------
distributed.worker - INFO - Waiting to connect to:     tcp://172.21.3.72:8786
distributed.worker - INFO - Waiting to connect to:     tcp://172.21.3.72:8786
distributed.worker - INFO - Waiting to connect to:     tcp://172.21.3.72:8786
distributed.worker - INFO -               Threads:                         24
distributed.worker - INFO -       Start worker at:    tcp://172.21.3.74:45382
distributed.worker - INFO -       Start worker at:    tcp://172.21.3.79:36113
distributed.worker - INFO - -------------------------------------------------
distributed.worker - INFO -                Memory:                 172.73 GiB
distributed.worker - INFO - -------------------------------------------------
distributed.worker - INFO - -------------------------------------------------
distributed.worker - INFO -               Threads:                         24
distributed.worker - INFO -       Local Directory: /tmp/dask-worker-space/worker-txfdfgys
distributed.worker - INFO -          Listening to:    tcp://172.21.3.74:45382
distributed.worker - INFO -               Threads:                         24
distributed.worker - INFO -                Memory:                 172.73 GiB
distributed.worker - INFO - -------------------------------------------------
distributed.worker - INFO -               Threads:                         24
distributed.worker - INFO -          Listening to:    tcp://172.21.3.79:36113
distributed.worker - INFO -       Local Directory: /tmp/dask-worker-space/worker-ae6qiy80
distributed.worker - INFO -          dashboard at:          172.21.3.74:39171
distributed.worker - INFO -          dashboard at:          172.21.3.79:41034
distributed.worker - INFO - -------------------------------------------------
distributed.worker - INFO -                Memory:                 172.73 GiB
distributed.worker - INFO -                Memory:                 172.73 GiB
distributed.worker - INFO - Waiting to connect to:     tcp://172.21.3.72:8786
distributed.worker - INFO -       Local Directory: /tmp/dask-worker-space/worker-wwjtmlb4
distributed.worker - INFO -       Local Directory: /tmp/dask-worker-space/worker-4lo3_hyb
distributed.worker - INFO - Waiting to connect to:     tcp://172.21.3.72:8786
distributed.worker - INFO - -------------------------------------------------
distributed.worker - INFO - -------------------------------------------------
distributed.worker - INFO -               Threads:                         24
distributed.worker - INFO -               Threads:                         24
distributed.worker - INFO - -------------------------------------------------
distributed.worker - INFO - -------------------------------------------------
distributed.worker - INFO -                Memory:                 172.73 GiB
distributed.worker - INFO -                Memory:                 172.73 GiB
distributed.worker - INFO -       Local Directory: /tmp/dask-worker-space/worker-5xlev9qa
distributed.worker - INFO -       Local Directory: /tmp/dask-worker-space/worker-lvyjvere
distributed.worker - INFO - -------------------------------------------------
distributed.worker - INFO - -------------------------------------------------
distributed.worker - INFO -       Start worker at:    tcp://172.21.3.88:36990
distributed.worker - INFO -          Listening to:    tcp://172.21.3.88:36990
distributed.worker - INFO -       Start worker at:    tcp://172.21.3.88:40705
distributed.worker - INFO -       Start worker at:    tcp://172.21.3.82:33688
distributed.worker - INFO -          dashboard at:          172.21.3.88:43883
distributed.worker - INFO -          Listening to:    tcp://172.21.3.88:40705
distributed.worker - INFO -          Listening to:    tcp://172.21.3.82:33688
distributed.worker - INFO - Waiting to connect to:     tcp://172.21.3.72:8786
distributed.worker - INFO -          dashboard at:          172.21.3.82:43521
distributed.worker - INFO -       Start worker at:    tcp://172.21.3.80:35493
distributed.worker - INFO - -------------------------------------------------
distributed.worker - INFO - Waiting to connect to:     tcp://172.21.3.72:8786
distributed.worker - INFO -          Listening to:    tcp://172.21.3.80:35493
distributed.worker - INFO -          dashboard at:          172.21.3.88:46425
distributed.worker - INFO - -------------------------------------------------
distributed.worker - INFO -          dashboard at:          172.21.3.80:40511
distributed.worker - INFO -               Threads:                         24
distributed.worker - INFO -               Threads:                         24
distributed.worker - INFO - Waiting to connect to:     tcp://172.21.3.72:8786
distributed.worker - INFO - Waiting to connect to:     tcp://172.21.3.72:8786
distributed.worker - INFO -                Memory:                 172.73 GiB
distributed.worker - INFO - -------------------------------------------------
distributed.worker - INFO - -------------------------------------------------
distributed.worker - INFO -       Local Directory: /tmp/dask-worker-space/worker-sp7sh9pd
distributed.worker - INFO -               Threads:                         24
distributed.worker - INFO -                Memory:                 172.73 GiB
distributed.worker - INFO - -------------------------------------------------
distributed.worker - INFO -                Memory:                 172.73 GiB
distributed.worker - INFO -               Threads:                         24
distributed.worker - INFO -       Local Directory: /tmp/dask-worker-space/worker-7czduvra
distributed.worker - INFO -       Local Directory: /tmp/dask-worker-space/worker-edjbswyi
distributed.worker - INFO - -------------------------------------------------
distributed.worker - INFO -                Memory:                 172.73 GiB
distributed.worker - INFO -       Local Directory: /tmp/dask-worker-space/worker-xk0ql4r6
distributed.worker - INFO - -------------------------------------------------
distributed.worker - INFO - -------------------------------------------------
distributed.worker - INFO -         Registered to:     tcp://172.21.3.72:8786
distributed.worker - INFO - -------------------------------------------------
distributed.core - INFO - Starting established connection
distributed.worker - INFO -         Registered to:     tcp://172.21.3.72:8786
distributed.worker - INFO - -------------------------------------------------
distributed.core - INFO - Starting established connection
distributed.worker - INFO -         Registered to:     tcp://172.21.3.72:8786
distributed.worker - INFO - -------------------------------------------------
distributed.core - INFO - Starting established connection
distributed.worker - INFO -         Registered to:     tcp://172.21.3.72:8786
distributed.worker - INFO - -------------------------------------------------
distributed.core - INFO - Starting established connection
distributed.worker - INFO -         Registered to:     tcp://172.21.3.72:8786
distributed.worker - INFO - -------------------------------------------------
distributed.core - INFO - Starting established connection
distributed.worker - INFO -         Registered to:     tcp://172.21.3.72:8786
distributed.worker - INFO - -------------------------------------------------
distributed.core - INFO - Starting established connection
distributed.worker - INFO -         Registered to:     tcp://172.21.3.72:8786
distributed.worker - INFO - -------------------------------------------------
distributed.core - INFO - Starting established connection
distributed.worker - INFO -         Registered to:     tcp://172.21.3.72:8786
distributed.worker - INFO - -------------------------------------------------
distributed.core - INFO - Starting established connection
distributed.worker - INFO -         Registered to:     tcp://172.21.3.72:8786
distributed.worker - INFO - -------------------------------------------------
distributed.core - INFO - Starting established connection
distributed.worker - INFO -         Registered to:     tcp://172.21.3.72:8786
distributed.worker - INFO - -------------------------------------------------
distributed.core - INFO - Starting established connection
distributed.worker - INFO -         Registered to:     tcp://172.21.3.72:8786
distributed.worker - INFO - -------------------------------------------------
distributed.core - INFO - Starting established connection
distributed.worker - INFO -         Registered to:     tcp://172.21.3.72:8786
distributed.worker - INFO - -------------------------------------------------
distributed.core - INFO - Starting established connection
distributed.worker - INFO -         Registered to:     tcp://172.21.3.72:8786
distributed.worker - INFO - -------------------------------------------------
distributed.core - INFO - Starting established connection
distributed.worker - INFO -         Registered to:     tcp://172.21.3.72:8786
distributed.worker - INFO - -------------------------------------------------
distributed.core - INFO - Starting established connection
distributed.worker - INFO -       Start worker at:    tcp://172.21.3.81:32795
distributed.worker - INFO -          Listening to:    tcp://172.21.3.81:32795
distributed.worker - INFO -       Start worker at:    tcp://172.21.3.81:45638
distributed.worker - INFO -          Listening to:    tcp://172.21.3.81:45638
distributed.worker - INFO -          dashboard at:          172.21.3.81:40136
distributed.worker - INFO - Waiting to connect to:     tcp://172.21.3.72:8786
distributed.worker - INFO - -------------------------------------------------
distributed.worker - INFO -          dashboard at:          172.21.3.81:37766
distributed.worker - INFO -               Threads:                         24
distributed.worker - INFO - Waiting to connect to:     tcp://172.21.3.72:8786
distributed.worker - INFO -                Memory:                 172.73 GiB
distributed.worker - INFO -       Local Directory: /tmp/dask-worker-space/worker-oip39ux6
distributed.worker - INFO - -------------------------------------------------
distributed.worker - INFO - -------------------------------------------------
distributed.worker - INFO -               Threads:                         24
distributed.worker - INFO -                Memory:                 172.73 GiB
distributed.worker - INFO -       Local Directory: /tmp/dask-worker-space/worker-n7ayrqmg
distributed.worker - INFO - -------------------------------------------------
distributed.worker - INFO -         Registered to:     tcp://172.21.3.72:8786
distributed.worker - INFO - -------------------------------------------------
distributed.core - INFO - Starting established connection
distributed.worker - INFO -         Registered to:     tcp://172.21.3.72:8786
distributed.worker - INFO - -------------------------------------------------
distributed.core - INFO - Starting established connection
distributed.worker - ERROR - Worker stream died during communication: tcp://172.21.3.81:45638
Traceback (most recent call last):
  File "/ccc/work/cont003/gen2224/gen2224/spack/var/spack/environments/gysela-deisa-irene-skl-draft/.spack-env/view/lib/python3.9/site-packages/distributed/comm/tcp.py", line 205, in read
    frames_nbytes = await stream.read_bytes(fmt_size)
asyncio.exceptions.CancelledError

During handling of the above exception, another exception occurred:

Traceback (most recent call last):
  File "/ccc/work/cont003/gen2224/gen2224/spack/var/spack/environments/gysela-deisa-irene-skl-draft/.spack-env/._view/whcr3wyhzgorszy3rfxsphyebtvfpqzk/lib/python3.9/asyncio/tasks.py", line 490, in wait_for
    return fut.result()
asyncio.exceptions.CancelledError

The above exception was the direct cause of the following exception:

Traceback (most recent call last):
  File "/ccc/work/cont003/gen2224/gen2224/spack/var/spack/environments/gysela-deisa-irene-skl-draft/.spack-env/view/lib/python3.9/site-packages/distributed/comm/core.py", line 319, in connect
    handshake = await asyncio.wait_for(comm.read(), time_left())
  File "/ccc/work/cont003/gen2224/gen2224/spack/var/spack/environments/gysela-deisa-irene-skl-draft/.spack-env/._view/whcr3wyhzgorszy3rfxsphyebtvfpqzk/lib/python3.9/asyncio/tasks.py", line 492, in wait_for
    raise exceptions.TimeoutError() from exc
asyncio.exceptions.TimeoutError

The above exception was the direct cause of the following exception:

Traceback (most recent call last):
  File "/ccc/work/cont003/gen2224/gen2224/spack/var/spack/environments/gysela-deisa-irene-skl-draft/.spack-env/view/lib/python3.9/site-packages/distributed/worker.py", line 2878, in gather_dep
    response = await get_data_from_worker(
distributed.worker - ERROR - Worker stream died during communication: tcp://172.21.3.81:45638
Traceback (most recent call last):
  File "/ccc/work/cont003/gen2224/gen2224/spack/var/spack/environments/gysela-deisa-irene-skl-draft/.spack-env/view/lib/python3.9/site-packages/distributed/comm/tcp.py", line 205, in read
    frames_nbytes = await stream.read_bytes(fmt_size)
asyncio.exceptions.CancelledError

During handling of the above exception, another exception occurred:

Traceback (most recent call last):
  File "/ccc/work/cont003/gen2224/gen2224/spack/var/spack/environments/gysela-deisa-irene-skl-draft/.spack-env/._view/whcr3wyhzgorszy3rfxsphyebtvfpqzk/lib/python3.9/asyncio/tasks.py", line 490, in wait_for
    return fut.result()
asyncio.exceptions.CancelledError

The above exception was the direct cause of the following exception:

Traceback (most recent call last):
  File "/ccc/work/cont003/gen2224/gen2224/spack/var/spack/environments/gysela-deisa-irene-skl-draft/.spack-env/view/lib/python3.9/site-packages/distributed/worker.py", line 4143, in get_data_from_worker
    return await retry_operation(_get_data, operation="get_data_from_worker")
  File "/ccc/work/cont003/gen2224/gen2224/spack/var/spack/environments/gysela-deisa-irene-skl-draft/.spack-env/view/lib/python3.9/site-packages/distributed/utils_comm.py", line 366, in retry_operation
    return await retry(
  File "/ccc/work/cont003/gen2224/gen2224/spack/var/spack/environments/gysela-deisa-irene-skl-draft/.spack-env/view/lib/python3.9/site-packages/distributed/utils_comm.py", line 351, in retry
    return await coro()
  File "/ccc/work/cont003/gen2224/gen2224/spack/var/spack/environments/gysela-deisa-irene-skl-draft/.spack-env/view/lib/python3.9/site-packages/distributed/worker.py", line 4120, in _get_data
    comm = await rpc.connect(worker)
distributed.worker - ERROR - Worker stream died during communication: tcp://172.21.3.81:45638
Traceback (most recent call last):
  File "/ccc/work/cont003/gen2224/gen2224/spack/var/spack/environments/gysela-deisa-irene-skl-draft/.spack-env/view/lib/python3.9/site-packages/distributed/comm/tcp.py", line 205, in read
    frames_nbytes = await stream.read_bytes(fmt_size)
asyncio.exceptions.CancelledError

During handling of the above exception, another exception occurred:

Traceback (most recent call last):
  File "/ccc/work/cont003/gen2224/gen2224/spack/var/spack/environments/gysela-deisa-irene-skl-draft/.spack-env/._view/whcr3wyhzgorszy3rfxsphyebtvfpqzk/lib/python3.9/asyncio/tasks.py", line 490, in wait_for
    return fut.result()
asyncio.exceptions.CancelledError

The above exception was the direct cause of the following exception:

Traceback (most recent call last):
distributed.worker - ERROR - Worker stream died during communication: tcp://172.21.3.81:45638
Traceback (most recent call last):
  File "/ccc/work/cont003/gen2224/gen2224/spack/var/spack/environments/gysela-deisa-irene-skl-draft/.spack-env/view/lib/python3.9/site-packages/distributed/comm/tcp.py", line 205, in read
    frames_nbytes = await stream.read_bytes(fmt_size)
asyncio.exceptions.CancelledError

During handling of the above exception, another exception occurred:

Traceback (most recent call last):
  File "/ccc/work/cont003/gen2224/gen2224/spack/var/spack/environments/gysela-deisa-irene-skl-draft/.spack-env/._view/whcr3wyhzgorszy3rfxsphyebtvfpqzk/lib/python3.9/asyncio/tasks.py", line 490, in wait_for
    return fut.result()
asyncio.exceptions.CancelledError

The above exception was the direct cause of the following exception:

Traceback (most recent call last):
distributed.worker - ERROR - Worker stream died during communication: tcp://172.21.3.81:45638
Traceback (most recent call last):
  File "/ccc/work/cont003/gen2224/gen2224/spack/var/spack/environments/gysela-deisa-irene-skl-draft/.spack-env/view/lib/python3.9/site-packages/distributed/comm/tcp.py", line 205, in read
    frames_nbytes = await stream.read_bytes(fmt_size)
asyncio.exceptions.CancelledError

During handling of the above exception, another exception occurred:

Traceback (most recent call last):
  File "/ccc/work/cont003/gen2224/gen2224/spack/var/spack/environments/gysela-deisa-irene-skl-draft/.spack-env/._view/whcr3wyhzgorszy3rfxsphyebtvfpqzk/lib/python3.9/asyncio/tasks.py", line 490, in wait_for
    return fut.result()
asyncio.exceptions.CancelledError

The above exception was the direct cause of the following exception:

Traceback (most recent call last):
  File "/ccc/work/cont003/gen2224/gen2224/spack/var/spack/environments/gysela-deisa-irene-skl-draft/.spack-env/view/lib/python3.9/site-packages/distributed/comm/core.py", line 319, in connect
    handshake = await asyncio.wait_for(comm.read(), time_left())
  File "/ccc/work/cont003/gen2224/gen2224/spack/var/spack/environments/gysela-deisa-irene-skl-draft/.spack-env/._view/whcr3wyhzgorszy3rfxsphyebtvfpqzk/lib/python3.9/asyncio/tasks.py", line 492, in wait_for
    raise exceptions.TimeoutError() from exc
asyncio.exceptions.TimeoutError

The above exception was the direct cause of the following exception:

Traceback (most recent call last):
  File "/ccc/work/cont003/gen2224/gen2224/spack/var/spack/environments/gysela-deisa-irene-skl-draft/.spack-env/view/lib/python3.9/site-packages/distributed/worker.py", line 2878, in gather_dep
    response = await get_data_from_worker(
  File "/ccc/work/cont003/gen2224/gen2224/spack/var/spack/environments/gysela-deisa-irene-skl-draft/.spack-env/view/lib/python3.9/site-packages/distributed/core.py", line 1081, in connect
    raise exc
  File "/ccc/work/cont003/gen2224/gen2224/spack/var/spack/environments/gysela-deisa-irene-skl-draft/.spack-env/view/lib/python3.9/site-packages/distributed/core.py", line 1065, in connect
    comm = await fut
  File "/ccc/work/cont003/gen2224/gen2224/spack/var/spack/environments/gysela-deisa-irene-skl-draft/.spack-env/view/lib/python3.9/site-packages/distributed/comm/core.py", line 324, in connect
    raise OSError(
OSError: Timed out during handshake while connecting to tcp://172.21.3.81:45638 after 30 s
  File "/ccc/work/cont003/gen2224/gen2224/spack/var/spack/environments/gysela-deisa-irene-skl-draft/.spack-env/view/lib/python3.9/site-packages/distributed/comm/core.py", line 319, in connect
    handshake = await asyncio.wait_for(comm.read(), time_left())
  File "/ccc/work/cont003/gen2224/gen2224/spack/var/spack/environments/gysela-deisa-irene-skl-draft/.spack-env/._view/whcr3wyhzgorszy3rfxsphyebtvfpqzk/lib/python3.9/asyncio/tasks.py", line 492, in wait_for
    raise exceptions.TimeoutError() from exc
asyncio.exceptions.TimeoutError

The above exception was the direct cause of the following exception:

Traceback (most recent call last):
  File "/ccc/work/cont003/gen2224/gen2224/spack/var/spack/environments/gysela-deisa-irene-skl-draft/.spack-env/view/lib/python3.9/site-packages/distributed/worker.py", line 2878, in gather_dep
    response = await get_data_from_worker(
  File "/ccc/work/cont003/gen2224/gen2224/spack/var/spack/environments/gysela-deisa-irene-skl-draft/.spack-env/view/lib/python3.9/site-packages/distributed/comm/core.py", line 319, in connect
    handshake = await asyncio.wait_for(comm.read(), time_left())
  File "/ccc/work/cont003/gen2224/gen2224/spack/var/spack/environments/gysela-deisa-irene-skl-draft/.spack-env/._view/whcr3wyhzgorszy3rfxsphyebtvfpqzk/lib/python3.9/asyncio/tasks.py", line 492, in wait_for
    raise exceptions.TimeoutError() from exc
asyncio.exceptions.TimeoutError

The above exception was the direct cause of the following exception:

Traceback (most recent call last):
  File "/ccc/work/cont003/gen2224/gen2224/spack/var/spack/environments/gysela-deisa-irene-skl-draft/.spack-env/view/lib/python3.9/site-packages/distributed/worker.py", line 2878, in gather_dep
    response = await get_data_from_worker(
  File "/ccc/work/cont003/gen2224/gen2224/spack/var/spack/environments/gysela-deisa-irene-skl-draft/.spack-env/view/lib/python3.9/site-packages/distributed/comm/core.py", line 319, in connect
    handshake = await asyncio.wait_for(comm.read(), time_left())
  File "/ccc/work/cont003/gen2224/gen2224/spack/var/spack/environments/gysela-deisa-irene-skl-draft/.spack-env/._view/whcr3wyhzgorszy3rfxsphyebtvfpqzk/lib/python3.9/asyncio/tasks.py", line 492, in wait_for
    raise exceptions.TimeoutError() from exc
asyncio.exceptions.TimeoutError

The above exception was the direct cause of the following exception:

Traceback (most recent call last):
  File "/ccc/work/cont003/gen2224/gen2224/spack/var/spack/environments/gysela-deisa-irene-skl-draft/.spack-env/view/lib/python3.9/site-packages/distributed/worker.py", line 2878, in gather_dep
    response = await get_data_from_worker(
  File "/ccc/work/cont003/gen2224/gen2224/spack/var/spack/environments/gysela-deisa-irene-skl-draft/.spack-env/view/lib/python3.9/site-packages/distributed/worker.py", line 4143, in get_data_from_worker
    return await retry_operation(_get_data, operation="get_data_from_worker")
  File "/ccc/work/cont003/gen2224/gen2224/spack/var/spack/environments/gysela-deisa-irene-skl-draft/.spack-env/view/lib/python3.9/site-packages/distributed/utils_comm.py", line 366, in retry_operation
    return await retry(
  File "/ccc/work/cont003/gen2224/gen2224/spack/var/spack/environments/gysela-deisa-irene-skl-draft/.spack-env/view/lib/python3.9/site-packages/distributed/utils_comm.py", line 351, in retry
    return await coro()
  File "/ccc/work/cont003/gen2224/gen2224/spack/var/spack/environments/gysela-deisa-irene-skl-draft/.spack-env/view/lib/python3.9/site-packages/distributed/worker.py", line 4120, in _get_data
    comm = await rpc.connect(worker)
distributed.worker - ERROR - Worker stream died during communication: tcp://172.21.3.81:45638
Traceback (most recent call last):
  File "/ccc/work/cont003/gen2224/gen2224/spack/var/spack/environments/gysela-deisa-irene-skl-draft/.spack-env/view/lib/python3.9/site-packages/distributed/comm/tcp.py", line 205, in read
    frames_nbytes = await stream.read_bytes(fmt_size)
asyncio.exceptions.CancelledError

During handling of the above exception, another exception occurred:

Traceback (most recent call last):
  File "/ccc/work/cont003/gen2224/gen2224/spack/var/spack/environments/gysela-deisa-irene-skl-draft/.spack-env/._view/whcr3wyhzgorszy3rfxsphyebtvfpqzk/lib/python3.9/asyncio/tasks.py", line 490, in wait_for
    return fut.result()
asyncio.exceptions.CancelledError

The above exception was the direct cause of the following exception:

Traceback (most recent call last):
  File "/ccc/work/cont003/gen2224/gen2224/spack/var/spack/environments/gysela-deisa-irene-skl-draft/.spack-env/view/lib/python3.9/site-packages/distributed/worker.py", line 4143, in get_data_from_worker
    return await retry_operation(_get_data, operation="get_data_from_worker")
  File "/ccc/work/cont003/gen2224/gen2224/spack/var/spack/environments/gysela-deisa-irene-skl-draft/.spack-env/view/lib/python3.9/site-packages/distributed/utils_comm.py", line 366, in retry_operation
    return await retry(
  File "/ccc/work/cont003/gen2224/gen2224/spack/var/spack/environments/gysela-deisa-irene-skl-draft/.spack-env/view/lib/python3.9/site-packages/distributed/utils_comm.py", line 351, in retry
    return await coro()
  File "/ccc/work/cont003/gen2224/gen2224/spack/var/spack/environments/gysela-deisa-irene-skl-draft/.spack-env/view/lib/python3.9/site-packages/distributed/worker.py", line 4120, in _get_data
    comm = await rpc.connect(worker)
  File "/ccc/work/cont003/gen2224/gen2224/spack/var/spack/environments/gysela-deisa-irene-skl-draft/.spack-env/view/lib/python3.9/site-packages/distributed/worker.py", line 4143, in get_data_from_worker
    return await retry_operation(_get_data, operation="get_data_from_worker")
  File "/ccc/work/cont003/gen2224/gen2224/spack/var/spack/environments/gysela-deisa-irene-skl-draft/.spack-env/view/lib/python3.9/site-packages/distributed/utils_comm.py", line 366, in retry_operation
    return await retry(
  File "/ccc/work/cont003/gen2224/gen2224/spack/var/spack/environments/gysela-deisa-irene-skl-draft/.spack-env/view/lib/python3.9/site-packages/distributed/utils_comm.py", line 351, in retry
    return await coro()
  File "/ccc/work/cont003/gen2224/gen2224/spack/var/spack/environments/gysela-deisa-irene-skl-draft/.spack-env/view/lib/python3.9/site-packages/distributed/worker.py", line 4120, in _get_data
    comm = await rpc.connect(worker)
  File "/ccc/work/cont003/gen2224/gen2224/spack/var/spack/environments/gysela-deisa-irene-skl-draft/.spack-env/view/lib/python3.9/site-packages/distributed/worker.py", line 4143, in get_data_from_worker
    return await retry_operation(_get_data, operation="get_data_from_worker")
  File "/ccc/work/cont003/gen2224/gen2224/spack/var/spack/environments/gysela-deisa-irene-skl-draft/.spack-env/view/lib/python3.9/site-packages/distributed/utils_comm.py", line 366, in retry_operation
    return await retry(
  File "/ccc/work/cont003/gen2224/gen2224/spack/var/spack/environments/gysela-deisa-irene-skl-draft/.spack-env/view/lib/python3.9/site-packages/distributed/utils_comm.py", line 351, in retry
    return await coro()
  File "/ccc/work/cont003/gen2224/gen2224/spack/var/spack/environments/gysela-deisa-irene-skl-draft/.spack-env/view/lib/python3.9/site-packages/distributed/worker.py", line 4120, in _get_data
    comm = await rpc.connect(worker)
  File "/ccc/work/cont003/gen2224/gen2224/spack/var/spack/environments/gysela-deisa-irene-skl-draft/.spack-env/view/lib/python3.9/site-packages/distributed/core.py", line 1081, in connect
    raise exc
  File "/ccc/work/cont003/gen2224/gen2224/spack/var/spack/environments/gysela-deisa-irene-skl-draft/.spack-env/view/lib/python3.9/site-packages/distributed/core.py", line 1065, in connect
    comm = await fut
  File "/ccc/work/cont003/gen2224/gen2224/spack/var/spack/environments/gysela-deisa-irene-skl-draft/.spack-env/view/lib/python3.9/site-packages/distributed/comm/core.py", line 324, in connect
    raise OSError(
OSError: Timed out during handshake while connecting to tcp://172.21.3.81:45638 after 30 s
  File "/ccc/work/cont003/gen2224/gen2224/spack/var/spack/environments/gysela-deisa-irene-skl-draft/.spack-env/view/lib/python3.9/site-packages/distributed/comm/core.py", line 319, in connect
    handshake = await asyncio.wait_for(comm.read(), time_left())
  File "/ccc/work/cont003/gen2224/gen2224/spack/var/spack/environments/gysela-deisa-irene-skl-draft/.spack-env/._view/whcr3wyhzgorszy3rfxsphyebtvfpqzk/lib/python3.9/asyncio/tasks.py", line 492, in wait_for
    raise exceptions.TimeoutError() from exc
asyncio.exceptions.TimeoutError

The above exception was the direct cause of the following exception:

Traceback (most recent call last):
  File "/ccc/work/cont003/gen2224/gen2224/spack/var/spack/environments/gysela-deisa-irene-skl-draft/.spack-env/view/lib/python3.9/site-packages/distributed/worker.py", line 2878, in gather_dep
    response = await get_data_from_worker(
  File "/ccc/work/cont003/gen2224/gen2224/spack/var/spack/environments/gysela-deisa-irene-skl-draft/.spack-env/view/lib/python3.9/site-packages/distributed/core.py", line 1081, in connect
    raise exc
  File "/ccc/work/cont003/gen2224/gen2224/spack/var/spack/environments/gysela-deisa-irene-skl-draft/.spack-env/view/lib/python3.9/site-packages/distributed/core.py", line 1065, in connect
    comm = await fut
  File "/ccc/work/cont003/gen2224/gen2224/spack/var/spack/environments/gysela-deisa-irene-skl-draft/.spack-env/view/lib/python3.9/site-packages/distributed/comm/core.py", line 324, in connect
    raise OSError(
OSError: Timed out during handshake while connecting to tcp://172.21.3.81:45638 after 30 s
  File "/ccc/work/cont003/gen2224/gen2224/spack/var/spack/environments/gysela-deisa-irene-skl-draft/.spack-env/view/lib/python3.9/site-packages/distributed/core.py", line 1081, in connect
    raise exc
  File "/ccc/work/cont003/gen2224/gen2224/spack/var/spack/environments/gysela-deisa-irene-skl-draft/.spack-env/view/lib/python3.9/site-packages/distributed/core.py", line 1065, in connect
    comm = await fut
  File "/ccc/work/cont003/gen2224/gen2224/spack/var/spack/environments/gysela-deisa-irene-skl-draft/.spack-env/view/lib/python3.9/site-packages/distributed/comm/core.py", line 324, in connect
    raise OSError(
OSError: Timed out during handshake while connecting to tcp://172.21.3.81:45638 after 30 s
  File "/ccc/work/cont003/gen2224/gen2224/spack/var/spack/environments/gysela-deisa-irene-skl-draft/.spack-env/view/lib/python3.9/site-packages/distributed/core.py", line 1081, in connect
    raise exc
  File "/ccc/work/cont003/gen2224/gen2224/spack/var/spack/environments/gysela-deisa-irene-skl-draft/.spack-env/view/lib/python3.9/site-packages/distributed/core.py", line 1065, in connect
    comm = await fut
  File "/ccc/work/cont003/gen2224/gen2224/spack/var/spack/environments/gysela-deisa-irene-skl-draft/.spack-env/view/lib/python3.9/site-packages/distributed/comm/core.py", line 324, in connect
    raise OSError(
OSError: Timed out during handshake while connecting to tcp://172.21.3.81:45638 after 30 s
  File "/ccc/work/cont003/gen2224/gen2224/spack/var/spack/environments/gysela-deisa-irene-skl-draft/.spack-env/view/lib/python3.9/site-packages/distributed/worker.py", line 4143, in get_data_from_worker
    return await retry_operation(_get_data, operation="get_data_from_worker")
  File "/ccc/work/cont003/gen2224/gen2224/spack/var/spack/environments/gysela-deisa-irene-skl-draft/.spack-env/view/lib/python3.9/site-packages/distributed/utils_comm.py", line 366, in retry_operation
    return await retry(
  File "/ccc/work/cont003/gen2224/gen2224/spack/var/spack/environments/gysela-deisa-irene-skl-draft/.spack-env/view/lib/python3.9/site-packages/distributed/utils_comm.py", line 351, in retry
    return await coro()
  File "/ccc/work/cont003/gen2224/gen2224/spack/var/spack/environments/gysela-deisa-irene-skl-draft/.spack-env/view/lib/python3.9/site-packages/distributed/worker.py", line 4120, in _get_data
    comm = await rpc.connect(worker)
distributed.worker - ERROR - Worker stream died during communication: tcp://172.21.3.81:45638
Traceback (most recent call last):
  File "/ccc/work/cont003/gen2224/gen2224/spack/var/spack/environments/gysela-deisa-irene-skl-draft/.spack-env/view/lib/python3.9/site-packages/distributed/comm/tcp.py", line 205, in read
    frames_nbytes = await stream.read_bytes(fmt_size)
asyncio.exceptions.CancelledError

During handling of the above exception, another exception occurred:

Traceback (most recent call last):
  File "/ccc/work/cont003/gen2224/gen2224/spack/var/spack/environments/gysela-deisa-irene-skl-draft/.spack-env/._view/whcr3wyhzgorszy3rfxsphyebtvfpqzk/lib/python3.9/asyncio/tasks.py", line 490, in wait_for
    return fut.result()
asyncio.exceptions.CancelledError

The above exception was the direct cause of the following exception:

Traceback (most recent call last):
distributed.worker - ERROR - Worker stream died during communication: tcp://172.21.3.81:45638
Traceback (most recent call last):
  File "/ccc/work/cont003/gen2224/gen2224/spack/var/spack/environments/gysela-deisa-irene-skl-draft/.spack-env/view/lib/python3.9/site-packages/distributed/comm/tcp.py", line 205, in read
    frames_nbytes = await stream.read_bytes(fmt_size)
asyncio.exceptions.CancelledError

During handling of the above exception, another exception occurred:

Traceback (most recent call last):
  File "/ccc/work/cont003/gen2224/gen2224/spack/var/spack/environments/gysela-deisa-irene-skl-draft/.spack-env/._view/whcr3wyhzgorszy3rfxsphyebtvfpqzk/lib/python3.9/asyncio/tasks.py", line 490, in wait_for
    return fut.result()
asyncio.exceptions.CancelledError

The above exception was the direct cause of the following exception:

Traceback (most recent call last):
  File "/ccc/work/cont003/gen2224/gen2224/spack/var/spack/environments/gysela-deisa-irene-skl-draft/.spack-env/view/lib/python3.9/site-packages/distributed/core.py", line 1081, in connect
    raise exc
  File "/ccc/work/cont003/gen2224/gen2224/spack/var/spack/environments/gysela-deisa-irene-skl-draft/.spack-env/view/lib/python3.9/site-packages/distributed/core.py", line 1065, in connect
    comm = await fut
  File "/ccc/work/cont003/gen2224/gen2224/spack/var/spack/environments/gysela-deisa-irene-skl-draft/.spack-env/view/lib/python3.9/site-packages/distributed/comm/core.py", line 324, in connect
    raise OSError(
OSError: Timed out during handshake while connecting to tcp://172.21.3.81:45638 after 30 s
  File "/ccc/work/cont003/gen2224/gen2224/spack/var/spack/environments/gysela-deisa-irene-skl-draft/.spack-env/view/lib/python3.9/site-packages/distributed/comm/core.py", line 319, in connect
    handshake = await asyncio.wait_for(comm.read(), time_left())
  File "/ccc/work/cont003/gen2224/gen2224/spack/var/spack/environments/gysela-deisa-irene-skl-draft/.spack-env/._view/whcr3wyhzgorszy3rfxsphyebtvfpqzk/lib/python3.9/asyncio/tasks.py", line 492, in wait_for
    raise exceptions.TimeoutError() from exc
asyncio.exceptions.TimeoutError

The above exception was the direct cause of the following exception:

Traceback (most recent call last):
  File "/ccc/work/cont003/gen2224/gen2224/spack/var/spack/environments/gysela-deisa-irene-skl-draft/.spack-env/view/lib/python3.9/site-packages/distributed/worker.py", line 2878, in gather_dep
    response = await get_data_from_worker(
  File "/ccc/work/cont003/gen2224/gen2224/spack/var/spack/environments/gysela-deisa-irene-skl-draft/.spack-env/view/lib/python3.9/site-packages/distributed/comm/core.py", line 319, in connect
    handshake = await asyncio.wait_for(comm.read(), time_left())
  File "/ccc/work/cont003/gen2224/gen2224/spack/var/spack/environments/gysela-deisa-irene-skl-draft/.spack-env/._view/whcr3wyhzgorszy3rfxsphyebtvfpqzk/lib/python3.9/asyncio/tasks.py", line 492, in wait_for
    raise exceptions.TimeoutError() from exc
asyncio.exceptions.TimeoutError

The above exception was the direct cause of the following exception:

Traceback (most recent call last):
  File "/ccc/work/cont003/gen2224/gen2224/spack/var/spack/environments/gysela-deisa-irene-skl-draft/.spack-env/view/lib/python3.9/site-packages/distributed/worker.py", line 2878, in gather_dep
    response = await get_data_from_worker(
  File "/ccc/work/cont003/gen2224/gen2224/spack/var/spack/environments/gysela-deisa-irene-skl-draft/.spack-env/view/lib/python3.9/site-packages/distributed/worker.py", line 4143, in get_data_from_worker
    return await retry_operation(_get_data, operation="get_data_from_worker")
  File "/ccc/work/cont003/gen2224/gen2224/spack/var/spack/environments/gysela-deisa-irene-skl-draft/.spack-env/view/lib/python3.9/site-packages/distributed/utils_comm.py", line 366, in retry_operation
    return await retry(
  File "/ccc/work/cont003/gen2224/gen2224/spack/var/spack/environments/gysela-deisa-irene-skl-draft/.spack-env/view/lib/python3.9/site-packages/distributed/utils_comm.py", line 351, in retry
    return await coro()
  File "/ccc/work/cont003/gen2224/gen2224/spack/var/spack/environments/gysela-deisa-irene-skl-draft/.spack-env/view/lib/python3.9/site-packages/distributed/worker.py", line 4120, in _get_data
    comm = await rpc.connect(worker)
  File "/ccc/work/cont003/gen2224/gen2224/spack/var/spack/environments/gysela-deisa-irene-skl-draft/.spack-env/view/lib/python3.9/site-packages/distributed/worker.py", line 4143, in get_data_from_worker
    return await retry_operation(_get_data, operation="get_data_from_worker")
  File "/ccc/work/cont003/gen2224/gen2224/spack/var/spack/environments/gysela-deisa-irene-skl-draft/.spack-env/view/lib/python3.9/site-packages/distributed/utils_comm.py", line 366, in retry_operation
    return await retry(
  File "/ccc/work/cont003/gen2224/gen2224/spack/var/spack/environments/gysela-deisa-irene-skl-draft/.spack-env/view/lib/python3.9/site-packages/distributed/utils_comm.py", line 351, in retry
    return await coro()
  File "/ccc/work/cont003/gen2224/gen2224/spack/var/spack/environments/gysela-deisa-irene-skl-draft/.spack-env/view/lib/python3.9/site-packages/distributed/worker.py", line 4120, in _get_data
    comm = await rpc.connect(worker)
  File "/ccc/work/cont003/gen2224/gen2224/spack/var/spack/environments/gysela-deisa-irene-skl-draft/.spack-env/view/lib/python3.9/site-packages/distributed/core.py", line 1081, in connect
    raise exc
  File "/ccc/work/cont003/gen2224/gen2224/spack/var/spack/environments/gysela-deisa-irene-skl-draft/.spack-env/view/lib/python3.9/site-packages/distributed/core.py", line 1065, in connect
    comm = await fut
  File "/ccc/work/cont003/gen2224/gen2224/spack/var/spack/environments/gysela-deisa-irene-skl-draft/.spack-env/view/lib/python3.9/site-packages/distributed/comm/core.py", line 324, in connect
    raise OSError(
OSError: Timed out during handshake while connecting to tcp://172.21.3.81:45638 after 30 s
  File "/ccc/work/cont003/gen2224/gen2224/spack/var/spack/environments/gysela-deisa-irene-skl-draft/.spack-env/view/lib/python3.9/site-packages/distributed/core.py", line 1081, in connect
    raise exc
  File "/ccc/work/cont003/gen2224/gen2224/spack/var/spack/environments/gysela-deisa-irene-skl-draft/.spack-env/view/lib/python3.9/site-packages/distributed/core.py", line 1065, in connect
    comm = await fut
  File "/ccc/work/cont003/gen2224/gen2224/spack/var/spack/environments/gysela-deisa-irene-skl-draft/.spack-env/view/lib/python3.9/site-packages/distributed/comm/core.py", line 324, in connect
    raise OSError(
OSError: Timed out during handshake while connecting to tcp://172.21.3.81:45638 after 30 s
distributed.worker - ERROR - Worker stream died during communication: tcp://172.21.3.82:33688
Traceback (most recent call last):
  File "/ccc/work/cont003/gen2224/gen2224/spack/var/spack/environments/gysela-deisa-irene-skl-draft/.spack-env/view/lib/python3.9/site-packages/distributed/comm/tcp.py", line 205, in read
    frames_nbytes = await stream.read_bytes(fmt_size)
asyncio.exceptions.CancelledError

During handling of the above exception, another exception occurred:

Traceback (most recent call last):
  File "/ccc/work/cont003/gen2224/gen2224/spack/var/spack/environments/gysela-deisa-irene-skl-draft/.spack-env/._view/whcr3wyhzgorszy3rfxsphyebtvfpqzk/lib/python3.9/asyncio/tasks.py", line 490, in wait_for
    return fut.result()
asyncio.exceptions.CancelledError

The above exception was the direct cause of the following exception:

Traceback (most recent call last):
  File "/ccc/work/cont003/gen2224/gen2224/spack/var/spack/environments/gysela-deisa-irene-skl-draft/.spack-env/view/lib/python3.9/site-packages/distributed/comm/core.py", line 319, in connect
    handshake = await asyncio.wait_for(comm.read(), time_left())
  File "/ccc/work/cont003/gen2224/gen2224/spack/var/spack/environments/gysela-deisa-irene-skl-draft/.spack-env/._view/whcr3wyhzgorszy3rfxsphyebtvfpqzk/lib/python3.9/asyncio/tasks.py", line 492, in wait_for
    raise exceptions.TimeoutError() from exc
asyncio.exceptions.TimeoutError

The above exception was the direct cause of the following exception:

Traceback (most recent call last):
  File "/ccc/work/cont003/gen2224/gen2224/spack/var/spack/environments/gysela-deisa-irene-skl-draft/.spack-env/view/lib/python3.9/site-packages/distributed/worker.py", line 2878, in gather_dep
    response = await get_data_from_worker(
  File "/ccc/work/cont003/gen2224/gen2224/spack/var/spack/environments/gysela-deisa-irene-skl-draft/.spack-env/view/lib/python3.9/site-packages/distributed/worker.py", line 4143, in get_data_from_worker
    return await retry_operation(_get_data, operation="get_data_from_worker")
  File "/ccc/work/cont003/gen2224/gen2224/spack/var/spack/environments/gysela-deisa-irene-skl-draft/.spack-env/view/lib/python3.9/site-packages/distributed/utils_comm.py", line 366, in retry_operation
    return await retry(
  File "/ccc/work/cont003/gen2224/gen2224/spack/var/spack/environments/gysela-deisa-irene-skl-draft/.spack-env/view/lib/python3.9/site-packages/distributed/utils_comm.py", line 351, in retry
    return await coro()
  File "/ccc/work/cont003/gen2224/gen2224/spack/var/spack/environments/gysela-deisa-irene-skl-draft/.spack-env/view/lib/python3.9/site-packages/distributed/worker.py", line 4120, in _get_data
    comm = await rpc.connect(worker)
distributed.worker - ERROR - Worker stream died during communication: tcp://172.21.3.82:33688
Traceback (most recent call last):
  File "/ccc/work/cont003/gen2224/gen2224/spack/var/spack/environments/gysela-deisa-irene-skl-draft/.spack-env/view/lib/python3.9/site-packages/distributed/comm/tcp.py", line 205, in read
    frames_nbytes = await stream.read_bytes(fmt_size)
asyncio.exceptions.CancelledError

During handling of the above exception, another exception occurred:

Traceback (most recent call last):
  File "/ccc/work/cont003/gen2224/gen2224/spack/var/spack/environments/gysela-deisa-irene-skl-draft/.spack-env/._view/whcr3wyhzgorszy3rfxsphyebtvfpqzk/lib/python3.9/asyncio/tasks.py", line 490, in wait_for
    return fut.result()
asyncio.exceptions.CancelledError

The above exception was the direct cause of the following exception:

Traceback (most recent call last):
distributed.worker - ERROR - Worker stream died during communication: tcp://172.21.3.82:33688
Traceback (most recent call last):
  File "/ccc/work/cont003/gen2224/gen2224/spack/var/spack/environments/gysela-deisa-irene-skl-draft/.spack-env/view/lib/python3.9/site-packages/distributed/comm/tcp.py", line 205, in read
    frames_nbytes = await stream.read_bytes(fmt_size)
asyncio.exceptions.CancelledError

During handling of the above exception, another exception occurred:

Traceback (most recent call last):
  File "/ccc/work/cont003/gen2224/gen2224/spack/var/spack/environments/gysela-deisa-irene-skl-draft/.spack-env/._view/whcr3wyhzgorszy3rfxsphyebtvfpqzk/lib/python3.9/asyncio/tasks.py", line 490, in wait_for
    return fut.result()
asyncio.exceptions.CancelledError

The above exception was the direct cause of the following exception:

Traceback (most recent call last):
distributed.worker - ERROR - Worker stream died during communication: tcp://172.21.3.82:33688
Traceback (most recent call last):
  File "/ccc/work/cont003/gen2224/gen2224/spack/var/spack/environments/gysela-deisa-irene-skl-draft/.spack-env/view/lib/python3.9/site-packages/distributed/comm/tcp.py", line 205, in read
    frames_nbytes = await stream.read_bytes(fmt_size)
asyncio.exceptions.CancelledError

During handling of the above exception, another exception occurred:

Traceback (most recent call last):
  File "/ccc/work/cont003/gen2224/gen2224/spack/var/spack/environments/gysela-deisa-irene-skl-draft/.spack-env/._view/whcr3wyhzgorszy3rfxsphyebtvfpqzk/lib/python3.9/asyncio/tasks.py", line 490, in wait_for
    return fut.result()
asyncio.exceptions.CancelledError

The above exception was the direct cause of the following exception:

Traceback (most recent call last):
  File "/ccc/work/cont003/gen2224/gen2224/spack/var/spack/environments/gysela-deisa-irene-skl-draft/.spack-env/view/lib/python3.9/site-packages/distributed/core.py", line 1081, in connect
    raise exc
  File "/ccc/work/cont003/gen2224/gen2224/spack/var/spack/environments/gysela-deisa-irene-skl-draft/.spack-env/view/lib/python3.9/site-packages/distributed/core.py", line 1065, in connect
    comm = await fut
  File "/ccc/work/cont003/gen2224/gen2224/spack/var/spack/environments/gysela-deisa-irene-skl-draft/.spack-env/view/lib/python3.9/site-packages/distributed/comm/core.py", line 324, in connect
    raise OSError(
OSError: Timed out during handshake while connecting to tcp://172.21.3.82:33688 after 30 s
  File "/ccc/work/cont003/gen2224/gen2224/spack/var/spack/environments/gysela-deisa-irene-skl-draft/.spack-env/view/lib/python3.9/site-packages/distributed/comm/core.py", line 319, in connect
    handshake = await asyncio.wait_for(comm.read(), time_left())
  File "/ccc/work/cont003/gen2224/gen2224/spack/var/spack/environments/gysela-deisa-irene-skl-draft/.spack-env/._view/whcr3wyhzgorszy3rfxsphyebtvfpqzk/lib/python3.9/asyncio/tasks.py", line 492, in wait_for
    raise exceptions.TimeoutError() from exc
asyncio.exceptions.TimeoutError

The above exception was the direct cause of the following exception:

Traceback (most recent call last):
  File "/ccc/work/cont003/gen2224/gen2224/spack/var/spack/environments/gysela-deisa-irene-skl-draft/.spack-env/view/lib/python3.9/site-packages/distributed/worker.py", line 2878, in gather_dep
    response = await get_data_from_worker(
  File "/ccc/work/cont003/gen2224/gen2224/spack/var/spack/environments/gysela-deisa-irene-skl-draft/.spack-env/view/lib/python3.9/site-packages/distributed/comm/core.py", line 319, in connect
    handshake = await asyncio.wait_for(comm.read(), time_left())
  File "/ccc/work/cont003/gen2224/gen2224/spack/var/spack/environments/gysela-deisa-irene-skl-draft/.spack-env/._view/whcr3wyhzgorszy3rfxsphyebtvfpqzk/lib/python3.9/asyncio/tasks.py", line 492, in wait_for
    raise exceptions.TimeoutError() from exc
asyncio.exceptions.TimeoutError

The above exception was the direct cause of the following exception:

Traceback (most recent call last):
  File "/ccc/work/cont003/gen2224/gen2224/spack/var/spack/environments/gysela-deisa-irene-skl-draft/.spack-env/view/lib/python3.9/site-packages/distributed/worker.py", line 2878, in gather_dep
    response = await get_data_from_worker(
  File "/ccc/work/cont003/gen2224/gen2224/spack/var/spack/environments/gysela-deisa-irene-skl-draft/.spack-env/view/lib/python3.9/site-packages/distributed/comm/core.py", line 319, in connect
    handshake = await asyncio.wait_for(comm.read(), time_left())
  File "/ccc/work/cont003/gen2224/gen2224/spack/var/spack/environments/gysela-deisa-irene-skl-draft/.spack-env/._view/whcr3wyhzgorszy3rfxsphyebtvfpqzk/lib/python3.9/asyncio/tasks.py", line 492, in wait_for
    raise exceptions.TimeoutError() from exc
asyncio.exceptions.TimeoutError

The above exception was the direct cause of the following exception:

Traceback (most recent call last):
  File "/ccc/work/cont003/gen2224/gen2224/spack/var/spack/environments/gysela-deisa-irene-skl-draft/.spack-env/view/lib/python3.9/site-packages/distributed/worker.py", line 2878, in gather_dep
    response = await get_data_from_worker(
distributed.worker - ERROR - Worker stream died during communication: tcp://172.21.3.82:33688
Traceback (most recent call last):
  File "/ccc/work/cont003/gen2224/gen2224/spack/var/spack/environments/gysela-deisa-irene-skl-draft/.spack-env/view/lib/python3.9/site-packages/distributed/comm/tcp.py", line 205, in read
    frames_nbytes = await stream.read_bytes(fmt_size)
asyncio.exceptions.CancelledError

During handling of the above exception, another exception occurred:

Traceback (most recent call last):
  File "/ccc/work/cont003/gen2224/gen2224/spack/var/spack/environments/gysela-deisa-irene-skl-draft/.spack-env/._view/whcr3wyhzgorszy3rfxsphyebtvfpqzk/lib/python3.9/asyncio/tasks.py", line 490, in wait_for
    return fut.result()
asyncio.exceptions.CancelledError

The above exception was the direct cause of the following exception:

Traceback (most recent call last):
  File "/ccc/work/cont003/gen2224/gen2224/spack/var/spack/environments/gysela-deisa-irene-skl-draft/.spack-env/view/lib/python3.9/site-packages/distributed/worker.py", line 4143, in get_data_from_worker
    return await retry_operation(_get_data, operation="get_data_from_worker")
  File "/ccc/work/cont003/gen2224/gen2224/spack/var/spack/environments/gysela-deisa-irene-skl-draft/.spack-env/view/lib/python3.9/site-packages/distributed/utils_comm.py", line 366, in retry_operation
    return await retry(
  File "/ccc/work/cont003/gen2224/gen2224/spack/var/spack/environments/gysela-deisa-irene-skl-draft/.spack-env/view/lib/python3.9/site-packages/distributed/utils_comm.py", line 351, in retry
    return await coro()
  File "/ccc/work/cont003/gen2224/gen2224/spack/var/spack/environments/gysela-deisa-irene-skl-draft/.spack-env/view/lib/python3.9/site-packages/distributed/worker.py", line 4120, in _get_data
    comm = await rpc.connect(worker)
  File "/ccc/work/cont003/gen2224/gen2224/spack/var/spack/environments/gysela-deisa-irene-skl-draft/.spack-env/view/lib/python3.9/site-packages/distributed/worker.py", line 4143, in get_data_from_worker
    return await retry_operation(_get_data, operation="get_data_from_worker")
  File "/ccc/work/cont003/gen2224/gen2224/spack/var/spack/environments/gysela-deisa-irene-skl-draft/.spack-env/view/lib/python3.9/site-packages/distributed/utils_comm.py", line 366, in retry_operation
    return await retry(
  File "/ccc/work/cont003/gen2224/gen2224/spack/var/spack/environments/gysela-deisa-irene-skl-draft/.spack-env/view/lib/python3.9/site-packages/distributed/utils_comm.py", line 351, in retry
    return await coro()
  File "/ccc/work/cont003/gen2224/gen2224/spack/var/spack/environments/gysela-deisa-irene-skl-draft/.spack-env/view/lib/python3.9/site-packages/distributed/worker.py", line 4120, in _get_data
    comm = await rpc.connect(worker)
  File "/ccc/work/cont003/gen2224/gen2224/spack/var/spack/environments/gysela-deisa-irene-skl-draft/.spack-env/view/lib/python3.9/site-packages/distributed/worker.py", line 4143, in get_data_from_worker
    return await retry_operation(_get_data, operation="get_data_from_worker")
  File "/ccc/work/cont003/gen2224/gen2224/spack/var/spack/environments/gysela-deisa-irene-skl-draft/.spack-env/view/lib/python3.9/site-packages/distributed/utils_comm.py", line 366, in retry_operation
    return await retry(
  File "/ccc/work/cont003/gen2224/gen2224/spack/var/spack/environments/gysela-deisa-irene-skl-draft/.spack-env/view/lib/python3.9/site-packages/distributed/utils_comm.py", line 351, in retry
    return await coro()
  File "/ccc/work/cont003/gen2224/gen2224/spack/var/spack/environments/gysela-deisa-irene-skl-draft/.spack-env/view/lib/python3.9/site-packages/distributed/worker.py", line 4120, in _get_data
    comm = await rpc.connect(worker)
  File "/ccc/work/cont003/gen2224/gen2224/spack/var/spack/environments/gysela-deisa-irene-skl-draft/.spack-env/view/lib/python3.9/site-packages/distributed/comm/core.py", line 319, in connect
    handshake = await asyncio.wait_for(comm.read(), time_left())
  File "/ccc/work/cont003/gen2224/gen2224/spack/var/spack/environments/gysela-deisa-irene-skl-draft/.spack-env/._view/whcr3wyhzgorszy3rfxsphyebtvfpqzk/lib/python3.9/asyncio/tasks.py", line 492, in wait_for
    raise exceptions.TimeoutError() from exc
asyncio.exceptions.TimeoutError

The above exception was the direct cause of the following exception:

Traceback (most recent call last):
  File "/ccc/work/cont003/gen2224/gen2224/spack/var/spack/environments/gysela-deisa-irene-skl-draft/.spack-env/view/lib/python3.9/site-packages/distributed/worker.py", line 2878, in gather_dep
    response = await get_data_from_worker(
  File "/ccc/work/cont003/gen2224/gen2224/spack/var/spack/environments/gysela-deisa-irene-skl-draft/.spack-env/view/lib/python3.9/site-packages/distributed/core.py", line 1081, in connect
    raise exc
  File "/ccc/work/cont003/gen2224/gen2224/spack/var/spack/environments/gysela-deisa-irene-skl-draft/.spack-env/view/lib/python3.9/site-packages/distributed/core.py", line 1065, in connect
    comm = await fut
  File "/ccc/work/cont003/gen2224/gen2224/spack/var/spack/environments/gysela-deisa-irene-skl-draft/.spack-env/view/lib/python3.9/site-packages/distributed/comm/core.py", line 324, in connect
    raise OSError(
OSError: Timed out during handshake while connecting to tcp://172.21.3.82:33688 after 30 s
  File "/ccc/work/cont003/gen2224/gen2224/spack/var/spack/environments/gysela-deisa-irene-skl-draft/.spack-env/view/lib/python3.9/site-packages/distributed/core.py", line 1081, in connect
    raise exc
  File "/ccc/work/cont003/gen2224/gen2224/spack/var/spack/environments/gysela-deisa-irene-skl-draft/.spack-env/view/lib/python3.9/site-packages/distributed/core.py", line 1065, in connect
    comm = await fut
  File "/ccc/work/cont003/gen2224/gen2224/spack/var/spack/environments/gysela-deisa-irene-skl-draft/.spack-env/view/lib/python3.9/site-packages/distributed/comm/core.py", line 324, in connect
    raise OSError(
OSError: Timed out during handshake while connecting to tcp://172.21.3.82:33688 after 30 s
  File "/ccc/work/cont003/gen2224/gen2224/spack/var/spack/environments/gysela-deisa-irene-skl-draft/.spack-env/view/lib/python3.9/site-packages/distributed/core.py", line 1081, in connect
    raise exc
  File "/ccc/work/cont003/gen2224/gen2224/spack/var/spack/environments/gysela-deisa-irene-skl-draft/.spack-env/view/lib/python3.9/site-packages/distributed/core.py", line 1065, in connect
    comm = await fut
  File "/ccc/work/cont003/gen2224/gen2224/spack/var/spack/environments/gysela-deisa-irene-skl-draft/.spack-env/view/lib/python3.9/site-packages/distributed/comm/core.py", line 324, in connect
    raise OSError(
OSError: Timed out during handshake while connecting to tcp://172.21.3.82:33688 after 30 s
  File "/ccc/work/cont003/gen2224/gen2224/spack/var/spack/environments/gysela-deisa-irene-skl-draft/.spack-env/view/lib/python3.9/site-packages/distributed/worker.py", line 4143, in get_data_from_worker
    return await retry_operation(_get_data, operation="get_data_from_worker")
  File "/ccc/work/cont003/gen2224/gen2224/spack/var/spack/environments/gysela-deisa-irene-skl-draft/.spack-env/view/lib/python3.9/site-packages/distributed/utils_comm.py", line 366, in retry_operation
    return await retry(
  File "/ccc/work/cont003/gen2224/gen2224/spack/var/spack/environments/gysela-deisa-irene-skl-draft/.spack-env/view/lib/python3.9/site-packages/distributed/utils_comm.py", line 351, in retry
    return await coro()
  File "/ccc/work/cont003/gen2224/gen2224/spack/var/spack/environments/gysela-deisa-irene-skl-draft/.spack-env/view/lib/python3.9/site-packages/distributed/worker.py", line 4120, in _get_data
    comm = await rpc.connect(worker)
distributed.worker - ERROR - Worker stream died during communication: tcp://172.21.3.82:33688
Traceback (most recent call last):
  File "/ccc/work/cont003/gen2224/gen2224/spack/var/spack/environments/gysela-deisa-irene-skl-draft/.spack-env/view/lib/python3.9/site-packages/distributed/comm/tcp.py", line 205, in read
    frames_nbytes = await stream.read_bytes(fmt_size)
asyncio.exceptions.CancelledError

During handling of the above exception, another exception occurred:

Traceback (most recent call last):
  File "/ccc/work/cont003/gen2224/gen2224/spack/var/spack/environments/gysela-deisa-irene-skl-draft/.spack-env/._view/whcr3wyhzgorszy3rfxsphyebtvfpqzk/lib/python3.9/asyncio/tasks.py", line 490, in wait_for
    return fut.result()
asyncio.exceptions.CancelledError

The above exception was the direct cause of the following exception:

Traceback (most recent call last):
distributed.worker - ERROR - Worker stream died during communication: tcp://172.21.3.82:33688
Traceback (most recent call last):
  File "/ccc/work/cont003/gen2224/gen2224/spack/var/spack/environments/gysela-deisa-irene-skl-draft/.spack-env/view/lib/python3.9/site-packages/distributed/comm/tcp.py", line 205, in read
    frames_nbytes = await stream.read_bytes(fmt_size)
asyncio.exceptions.CancelledError

During handling of the above exception, another exception occurred:

Traceback (most recent call last):
  File "/ccc/work/cont003/gen2224/gen2224/spack/var/spack/environments/gysela-deisa-irene-skl-draft/.spack-env/._view/whcr3wyhzgorszy3rfxsphyebtvfpqzk/lib/python3.9/asyncio/tasks.py", line 490, in wait_for
    return fut.result()
asyncio.exceptions.CancelledError

The above exception was the direct cause of the following exception:

Traceback (most recent call last):
  File "/ccc/work/cont003/gen2224/gen2224/spack/var/spack/environments/gysela-deisa-irene-skl-draft/.spack-env/view/lib/python3.9/site-packages/distributed/core.py", line 1081, in connect
    raise exc
  File "/ccc/work/cont003/gen2224/gen2224/spack/var/spack/environments/gysela-deisa-irene-skl-draft/.spack-env/view/lib/python3.9/site-packages/distributed/core.py", line 1065, in connect
    comm = await fut
  File "/ccc/work/cont003/gen2224/gen2224/spack/var/spack/environments/gysela-deisa-irene-skl-draft/.spack-env/view/lib/python3.9/site-packages/distributed/comm/core.py", line 324, in connect
    raise OSError(
OSError: Timed out during handshake while connecting to tcp://172.21.3.82:33688 after 30 s
  File "/ccc/work/cont003/gen2224/gen2224/spack/var/spack/environments/gysela-deisa-irene-skl-draft/.spack-env/view/lib/python3.9/site-packages/distributed/comm/core.py", line 319, in connect
    handshake = await asyncio.wait_for(comm.read(), time_left())
  File "/ccc/work/cont003/gen2224/gen2224/spack/var/spack/environments/gysela-deisa-irene-skl-draft/.spack-env/._view/whcr3wyhzgorszy3rfxsphyebtvfpqzk/lib/python3.9/asyncio/tasks.py", line 492, in wait_for
    raise exceptions.TimeoutError() from exc
asyncio.exceptions.TimeoutError

The above exception was the direct cause of the following exception:

Traceback (most recent call last):
  File "/ccc/work/cont003/gen2224/gen2224/spack/var/spack/environments/gysela-deisa-irene-skl-draft/.spack-env/view/lib/python3.9/site-packages/distributed/worker.py", line 2878, in gather_dep
    response = await get_data_from_worker(
  File "/ccc/work/cont003/gen2224/gen2224/spack/var/spack/environments/gysela-deisa-irene-skl-draft/.spack-env/view/lib/python3.9/site-packages/distributed/comm/core.py", line 319, in connect
    handshake = await asyncio.wait_for(comm.read(), time_left())
  File "/ccc/work/cont003/gen2224/gen2224/spack/var/spack/environments/gysela-deisa-irene-skl-draft/.spack-env/._view/whcr3wyhzgorszy3rfxsphyebtvfpqzk/lib/python3.9/asyncio/tasks.py", line 492, in wait_for
    raise exceptions.TimeoutError() from exc
asyncio.exceptions.TimeoutError

The above exception was the direct cause of the following exception:

Traceback (most recent call last):
  File "/ccc/work/cont003/gen2224/gen2224/spack/var/spack/environments/gysela-deisa-irene-skl-draft/.spack-env/view/lib/python3.9/site-packages/distributed/worker.py", line 2878, in gather_dep
    response = await get_data_from_worker(
  File "/ccc/work/cont003/gen2224/gen2224/spack/var/spack/environments/gysela-deisa-irene-skl-draft/.spack-env/view/lib/python3.9/site-packages/distributed/worker.py", line 4143, in get_data_from_worker
    return await retry_operation(_get_data, operation="get_data_from_worker")
  File "/ccc/work/cont003/gen2224/gen2224/spack/var/spack/environments/gysela-deisa-irene-skl-draft/.spack-env/view/lib/python3.9/site-packages/distributed/utils_comm.py", line 366, in retry_operation
    return await retry(
  File "/ccc/work/cont003/gen2224/gen2224/spack/var/spack/environments/gysela-deisa-irene-skl-draft/.spack-env/view/lib/python3.9/site-packages/distributed/utils_comm.py", line 351, in retry
    return await coro()
  File "/ccc/work/cont003/gen2224/gen2224/spack/var/spack/environments/gysela-deisa-irene-skl-draft/.spack-env/view/lib/python3.9/site-packages/distributed/worker.py", line 4120, in _get_data
    comm = await rpc.connect(worker)
  File "/ccc/work/cont003/gen2224/gen2224/spack/var/spack/environments/gysela-deisa-irene-skl-draft/.spack-env/view/lib/python3.9/site-packages/distributed/worker.py", line 4143, in get_data_from_worker
    return await retry_operation(_get_data, operation="get_data_from_worker")
  File "/ccc/work/cont003/gen2224/gen2224/spack/var/spack/environments/gysela-deisa-irene-skl-draft/.spack-env/view/lib/python3.9/site-packages/distributed/utils_comm.py", line 366, in retry_operation
    return await retry(
  File "/ccc/work/cont003/gen2224/gen2224/spack/var/spack/environments/gysela-deisa-irene-skl-draft/.spack-env/view/lib/python3.9/site-packages/distributed/utils_comm.py", line 351, in retry
    return await coro()
  File "/ccc/work/cont003/gen2224/gen2224/spack/var/spack/environments/gysela-deisa-irene-skl-draft/.spack-env/view/lib/python3.9/site-packages/distributed/worker.py", line 4120, in _get_data
    comm = await rpc.connect(worker)
  File "/ccc/work/cont003/gen2224/gen2224/spack/var/spack/environments/gysela-deisa-irene-skl-draft/.spack-env/view/lib/python3.9/site-packages/distributed/core.py", line 1081, in connect
    raise exc
  File "/ccc/work/cont003/gen2224/gen2224/spack/var/spack/environments/gysela-deisa-irene-skl-draft/.spack-env/view/lib/python3.9/site-packages/distributed/core.py", line 1065, in connect
    comm = await fut
  File "/ccc/work/cont003/gen2224/gen2224/spack/var/spack/environments/gysela-deisa-irene-skl-draft/.spack-env/view/lib/python3.9/site-packages/distributed/comm/core.py", line 324, in connect
    raise OSError(
OSError: Timed out during handshake while connecting to tcp://172.21.3.82:33688 after 30 s
  File "/ccc/work/cont003/gen2224/gen2224/spack/var/spack/environments/gysela-deisa-irene-skl-draft/.spack-env/view/lib/python3.9/site-packages/distributed/core.py", line 1081, in connect
    raise exc
  File "/ccc/work/cont003/gen2224/gen2224/spack/var/spack/environments/gysela-deisa-irene-skl-draft/.spack-env/view/lib/python3.9/site-packages/distributed/core.py", line 1065, in connect
    comm = await fut
  File "/ccc/work/cont003/gen2224/gen2224/spack/var/spack/environments/gysela-deisa-irene-skl-draft/.spack-env/view/lib/python3.9/site-packages/distributed/comm/core.py", line 324, in connect
    raise OSError(
OSError: Timed out during handshake while connecting to tcp://172.21.3.82:33688 after 30 s
distributed.core - INFO - Event loop was unresponsive in Worker for 79.95s.  This is often caused by long-running GIL-holding functions or moving large chunks of data. This can cause timeouts and instability.
distributed.worker - ERROR - 'array-original-7bdd4b5a4ab7535fc06a874b6ebec639'
Traceback (most recent call last):
  File "/ccc/work/cont003/gen2224/gen2224/spack/var/spack/environments/gysela-deisa-irene-skl-draft/.spack-env/view/lib/python3.9/site-packages/distributed/worker.py", line 2885, in gather_dep
    self._update_metrics_received_data(
  File "/ccc/work/cont003/gen2224/gen2224/spack/var/spack/environments/gysela-deisa-irene-skl-draft/.spack-env/view/lib/python3.9/site-packages/distributed/worker.py", line 2782, in _update_metrics_received_data
    total_bytes = sum(self.tasks[key].get_nbytes() for key in data)
  File "/ccc/work/cont003/gen2224/gen2224/spack/var/spack/environments/gysela-deisa-irene-skl-draft/.spack-env/view/lib/python3.9/site-packages/distributed/worker.py", line 2782, in <genexpr>
    total_bytes = sum(self.tasks[key].get_nbytes() for key in data)
KeyError: 'array-original-7bdd4b5a4ab7535fc06a874b6ebec639'
distributed.worker - ERROR - 'array-original-7bdd4b5a4ab7535fc06a874b6ebec639'
Traceback (most recent call last):
  File "/ccc/work/cont003/gen2224/gen2224/spack/var/spack/environments/gysela-deisa-irene-skl-draft/.spack-env/view/lib/python3.9/site-packages/distributed/worker.py", line 2885, in gather_dep
    self._update_metrics_received_data(
  File "/ccc/work/cont003/gen2224/gen2224/spack/var/spack/environments/gysela-deisa-irene-skl-draft/.spack-env/view/lib/python3.9/site-packages/distributed/worker.py", line 2782, in _update_metrics_received_data
    total_bytes = sum(self.tasks[key].get_nbytes() for key in data)
  File "/ccc/work/cont003/gen2224/gen2224/spack/var/spack/environments/gysela-deisa-irene-skl-draft/.spack-env/view/lib/python3.9/site-packages/distributed/worker.py", line 2782, in <genexpr>
    total_bytes = sum(self.tasks[key].get_nbytes() for key in data)
KeyError: 'array-original-7bdd4b5a4ab7535fc06a874b6ebec639'
distributed.worker - ERROR - 'array-original-7bdd4b5a4ab7535fc06a874b6ebec639'
Traceback (most recent call last):
  File "/ccc/work/cont003/gen2224/gen2224/spack/var/spack/environments/gysela-deisa-irene-skl-draft/.spack-env/view/lib/python3.9/site-packages/distributed/worker.py", line 2885, in gather_dep
    self._update_metrics_received_data(
  File "/ccc/work/cont003/gen2224/gen2224/spack/var/spack/environments/gysela-deisa-irene-skl-draft/.spack-env/view/lib/python3.9/site-packages/distributed/worker.py", line 2782, in _update_metrics_received_data
    total_bytes = sum(self.tasks[key].get_nbytes() for key in data)
  File "/ccc/work/cont003/gen2224/gen2224/spack/var/spack/environments/gysela-deisa-irene-skl-draft/.spack-env/view/lib/python3.9/site-packages/distributed/worker.py", line 2782, in <genexpr>
    total_bytes = sum(self.tasks[key].get_nbytes() for key in data)
KeyError: 'array-original-7bdd4b5a4ab7535fc06a874b6ebec639'
distributed.utils - ERROR - 'array-original-7bdd4b5a4ab7535fc06a874b6ebec639'
Traceback (most recent call last):
  File "/ccc/work/cont003/gen2224/gen2224/spack/var/spack/environments/gysela-deisa-irene-skl-draft/.spack-env/view/lib/python3.9/site-packages/distributed/worker.py", line 2885, in gather_dep
    self._update_metrics_received_data(
  File "/ccc/work/cont003/gen2224/gen2224/spack/var/spack/environments/gysela-deisa-irene-skl-draft/.spack-env/view/lib/python3.9/site-packages/distributed/worker.py", line 2782, in _update_metrics_received_data
    total_bytes = sum(self.tasks[key].get_nbytes() for key in data)
  File "/ccc/work/cont003/gen2224/gen2224/spack/var/spack/environments/gysela-deisa-irene-skl-draft/.spack-env/view/lib/python3.9/site-packages/distributed/worker.py", line 2782, in <genexpr>
    total_bytes = sum(self.tasks[key].get_nbytes() for key in data)
KeyError: 'array-original-7bdd4b5a4ab7535fc06a874b6ebec639'

During handling of the above exception, another exception occurred:

Traceback (most recent call last):
  File "/ccc/work/cont003/gen2224/gen2224/spack/var/spack/environments/gysela-deisa-irene-skl-draft/.spack-env/view/lib/python3.9/site-packages/distributed/worker.py", line 2915, in gather_dep
    ts = self.tasks[k]
KeyError: 'array-original-7bdd4b5a4ab7535fc06a874b6ebec639'

During handling of the above exception, another exception occurred:

Traceback (most recent call last):
  File "/ccc/work/cont003/gen2224/gen2224/spack/var/spack/environments/gysela-deisa-irene-skl-draft/.spack-env/view/lib/python3.9/site-packages/distributed/utils.py", line 684, in log_errors
    yield
  File "/ccc/work/cont003/gen2224/gen2224/spack/var/spack/environments/gysela-deisa-irene-skl-draft/.spack-env/view/lib/python3.9/site-packages/distributed/worker.py", line 2929, in gather_dep
    ts = self.tasks[d]
KeyError: 'array-original-7bdd4b5a4ab7535fc06a874b6ebec639'
distributed.utils - ERROR - 'array-original-7bdd4b5a4ab7535fc06a874b6ebec639'
Traceback (most recent call last):
  File "/ccc/work/cont003/gen2224/gen2224/spack/var/spack/environments/gysela-deisa-irene-skl-draft/.spack-env/view/lib/python3.9/site-packages/distributed/worker.py", line 2885, in gather_dep
    self._update_metrics_received_data(
  File "/ccc/work/cont003/gen2224/gen2224/spack/var/spack/environments/gysela-deisa-irene-skl-draft/.spack-env/view/lib/python3.9/site-packages/distributed/worker.py", line 2782, in _update_metrics_received_data
    total_bytes = sum(self.tasks[key].get_nbytes() for key in data)
  File "/ccc/work/cont003/gen2224/gen2224/spack/var/spack/environments/gysela-deisa-irene-skl-draft/.spack-env/view/lib/python3.9/site-packages/distributed/worker.py", line 2782, in <genexpr>
    total_bytes = sum(self.tasks[key].get_nbytes() for key in data)
KeyError: 'array-original-7bdd4b5a4ab7535fc06a874b6ebec639'

During handling of the above exception, another exception occurred:

distributed.utils - ERROR - 'array-original-7bdd4b5a4ab7535fc06a874b6ebec639'
Traceback (most recent call last):
  File "/ccc/work/cont003/gen2224/gen2224/spack/var/spack/environments/gysela-deisa-irene-skl-draft/.spack-env/view/lib/python3.9/site-packages/distributed/worker.py", line 2885, in gather_dep
    self._update_metrics_received_data(
  File "/ccc/work/cont003/gen2224/gen2224/spack/var/spack/environments/gysela-deisa-irene-skl-draft/.spack-env/view/lib/python3.9/site-packages/distributed/worker.py", line 2782, in _update_metrics_received_data
    total_bytes = sum(self.tasks[key].get_nbytes() for key in data)
  File "/ccc/work/cont003/gen2224/gen2224/spack/var/spack/environments/gysela-deisa-irene-skl-draft/.spack-env/view/lib/python3.9/site-packages/distributed/worker.py", line 2782, in <genexpr>
    total_bytes = sum(self.tasks[key].get_nbytes() for key in data)
KeyError: 'array-original-7bdd4b5a4ab7535fc06a874b6ebec639'

During handling of the above exception, another exception occurred:

Traceback (most recent call last):
  File "/ccc/work/cont003/gen2224/gen2224/spack/var/spack/environments/gysela-deisa-irene-skl-draft/.spack-env/view/lib/python3.9/site-packages/distributed/worker.py", line 2915, in gather_dep
    ts = self.tasks[k]
KeyError: 'array-original-7bdd4b5a4ab7535fc06a874b6ebec639'

During handling of the above exception, another exception occurred:

Traceback (most recent call last):
  File "/ccc/work/cont003/gen2224/gen2224/spack/var/spack/environments/gysela-deisa-irene-skl-draft/.spack-env/view/lib/python3.9/site-packages/distributed/utils.py", line 684, in log_errors
    yield
  File "/ccc/work/cont003/gen2224/gen2224/spack/var/spack/environments/gysela-deisa-irene-skl-draft/.spack-env/view/lib/python3.9/site-packages/distributed/worker.py", line 2929, in gather_dep
    ts = self.tasks[d]
KeyError: 'array-original-7bdd4b5a4ab7535fc06a874b6ebec639'
Traceback (most recent call last):
  File "/ccc/work/cont003/gen2224/gen2224/spack/var/spack/environments/gysela-deisa-irene-skl-draft/.spack-env/view/lib/python3.9/site-packages/distributed/worker.py", line 2915, in gather_dep
    ts = self.tasks[k]
KeyError: 'array-original-7bdd4b5a4ab7535fc06a874b6ebec639'

During handling of the above exception, another exception occurred:

Traceback (most recent call last):
  File "/ccc/work/cont003/gen2224/gen2224/spack/var/spack/environments/gysela-deisa-irene-skl-draft/.spack-env/view/lib/python3.9/site-packages/distributed/utils.py", line 684, in log_errors
    yield
  File "/ccc/work/cont003/gen2224/gen2224/spack/var/spack/environments/gysela-deisa-irene-skl-draft/.spack-env/view/lib/python3.9/site-packages/distributed/worker.py", line 2929, in gather_dep
    ts = self.tasks[d]
KeyError: 'array-original-7bdd4b5a4ab7535fc06a874b6ebec639'
tornado.application - ERROR - Exception in callback functools.partial(<bound method IOLoop._discard_future_result of <tornado.platform.asyncio.AsyncIOLoop object at 0x2b2a3daeb7f0>>, <Task finished name='Task-1648' coro=<Worker.gather_dep() done, defined at /ccc/work/cont003/gen2224/gen2224/spack/var/spack/environments/gysela-deisa-irene-skl-draft/.spack-env/view/lib/python3.9/site-packages/distributed/worker.py:2823> exception=KeyError('array-original-7bdd4b5a4ab7535fc06a874b6ebec639')>)
Traceback (most recent call last):
  File "/ccc/work/cont003/gen2224/gen2224/spack/var/spack/environments/gysela-deisa-irene-skl-draft/.spack-env/view/lib/python3.9/site-packages/distributed/worker.py", line 2885, in gather_dep
    self._update_metrics_received_data(
  File "/ccc/work/cont003/gen2224/gen2224/spack/var/spack/environments/gysela-deisa-irene-skl-draft/.spack-env/view/lib/python3.9/site-packages/distributed/worker.py", line 2782, in _update_metrics_received_data
    total_bytes = sum(self.tasks[key].get_nbytes() for key in data)
  File "/ccc/work/cont003/gen2224/gen2224/spack/var/spack/environments/gysela-deisa-irene-skl-draft/.spack-env/view/lib/python3.9/site-packages/distributed/worker.py", line 2782, in <genexpr>
    total_bytes = sum(self.tasks[key].get_nbytes() for key in data)
KeyError: 'array-original-7bdd4b5a4ab7535fc06a874b6ebec639'

During handling of the above exception, another exception occurred:

Traceback (most recent call last):
  File "/ccc/work/cont003/gen2224/gen2224/spack/var/spack/environments/gysela-deisa-irene-skl-draft/.spack-env/view/lib/python3.9/site-packages/distributed/worker.py", line 2915, in gather_dep
    ts = self.tasks[k]
KeyError: 'array-original-7bdd4b5a4ab7535fc06a874b6ebec639'

During handling of the above exception, another exception occurred:

Traceback (most recent call last):
  File "/ccc/work/cont003/gen2224/gen2224/spack/var/spack/environments/gysela-deisa-irene-skl-draft/.spack-env/view/lib/python3.9/site-packages/tornado/ioloop.py", line 741, in _run_callback
    ret = callback()
  File "/ccc/work/cont003/gen2224/gen2224/spack/var/spack/environments/gysela-deisa-irene-skl-draft/.spack-env/view/lib/python3.9/site-packages/tornado/ioloop.py", line 765, in _discard_future_result
    future.result()
  File "/ccc/work/cont003/gen2224/gen2224/spack/var/spack/environments/gysela-deisa-irene-skl-draft/.spack-env/view/lib/python3.9/site-packages/distributed/worker.py", line 2929, in gather_dep
    ts = self.tasks[d]
KeyError: 'array-original-7bdd4b5a4ab7535fc06a874b6ebec639'
tornado.application - ERROR - Exception in callback functools.partial(<bound method IOLoop._discard_future_result of <tornado.platform.asyncio.AsyncIOLoop object at 0x2b6a17fc77f0>>, <Task finished name='Task-1617' coro=<Worker.gather_dep() done, defined at /ccc/work/cont003/gen2224/gen2224/spack/var/spack/environments/gysela-deisa-irene-skl-draft/.spack-env/view/lib/python3.9/site-packages/distributed/worker.py:2823> exception=KeyError('array-original-7bdd4b5a4ab7535fc06a874b6ebec639')>)
Traceback (most recent call last):
  File "/ccc/work/cont003/gen2224/gen2224/spack/var/spack/environments/gysela-deisa-irene-skl-draft/.spack-env/view/lib/python3.9/site-packages/distributed/worker.py", line 2885, in gather_dep
    self._update_metrics_received_data(
  File "/ccc/work/cont003/gen2224/gen2224/spack/var/spack/environments/gysela-deisa-irene-skl-draft/.spack-env/view/lib/python3.9/site-packages/distributed/worker.py", line 2782, in _update_metrics_received_data
    total_bytes = sum(self.tasks[key].get_nbytes() for key in data)
  File "/ccc/work/cont003/gen2224/gen2224/spack/var/spack/environments/gysela-deisa-irene-skl-draft/.spack-env/view/lib/python3.9/site-packages/distributed/worker.py", line 2782, in <genexpr>
    total_bytes = sum(self.tasks[key].get_nbytes() for key in data)
KeyError: 'array-original-7bdd4b5a4ab7535fc06a874b6ebec639'

During handling of the above exception, another exception occurred:

Traceback (most recent call last):
  File "/ccc/work/cont003/gen2224/gen2224/spack/var/spack/environments/gysela-deisa-irene-skl-draft/.spack-env/view/lib/python3.9/site-packages/distributed/worker.py", line 2915, in gather_dep
    ts = self.tasks[k]
KeyError: 'array-original-7bdd4b5a4ab7535fc06a874b6ebec639'

During handling of the above exception, another exception occurred:

Traceback (most recent call last):
  File "/ccc/work/cont003/gen2224/gen2224/spack/var/spack/environments/gysela-deisa-irene-skl-draft/.spack-env/view/lib/python3.9/site-packages/tornado/ioloop.py", line 741, in _run_callback
    ret = callback()
  File "/ccc/work/cont003/gen2224/gen2224/spack/var/spack/environments/gysela-deisa-irene-skl-draft/.spack-env/view/lib/python3.9/site-packages/tornado/ioloop.py", line 765, in _discard_future_result
    future.result()
  File "/ccc/work/cont003/gen2224/gen2224/spack/var/spack/environments/gysela-deisa-irene-skl-draft/.spack-env/view/lib/python3.9/site-packages/distributed/worker.py", line 2929, in gather_dep
    ts = self.tasks[d]
KeyError: 'array-original-7bdd4b5a4ab7535fc06a874b6ebec639'
tornado.application - ERROR - Exception in callback functools.partial(<bound method IOLoop._discard_future_result of <tornado.platform.asyncio.AsyncIOLoop object at 0x2aea47fa9820>>, <Task finished name='Task-1653' coro=<Worker.gather_dep() done, defined at /ccc/work/cont003/gen2224/gen2224/spack/var/spack/environments/gysela-deisa-irene-skl-draft/.spack-env/view/lib/python3.9/site-packages/distributed/worker.py:2823> exception=KeyError('array-original-7bdd4b5a4ab7535fc06a874b6ebec639')>)
Traceback (most recent call last):
  File "/ccc/work/cont003/gen2224/gen2224/spack/var/spack/environments/gysela-deisa-irene-skl-draft/.spack-env/view/lib/python3.9/site-packages/distributed/worker.py", line 2885, in gather_dep
    self._update_metrics_received_data(
  File "/ccc/work/cont003/gen2224/gen2224/spack/var/spack/environments/gysela-deisa-irene-skl-draft/.spack-env/view/lib/python3.9/site-packages/distributed/worker.py", line 2782, in _update_metrics_received_data
    total_bytes = sum(self.tasks[key].get_nbytes() for key in data)
  File "/ccc/work/cont003/gen2224/gen2224/spack/var/spack/environments/gysela-deisa-irene-skl-draft/.spack-env/view/lib/python3.9/site-packages/distributed/worker.py", line 2782, in <genexpr>
    total_bytes = sum(self.tasks[key].get_nbytes() for key in data)
KeyError: 'array-original-7bdd4b5a4ab7535fc06a874b6ebec639'

During handling of the above exception, another exception occurred:

Traceback (most recent call last):
  File "/ccc/work/cont003/gen2224/gen2224/spack/var/spack/environments/gysela-deisa-irene-skl-draft/.spack-env/view/lib/python3.9/site-packages/distributed/worker.py", line 2915, in gather_dep
    ts = self.tasks[k]
KeyError: 'array-original-7bdd4b5a4ab7535fc06a874b6ebec639'

During handling of the above exception, another exception occurred:

Traceback (most recent call last):
  File "/ccc/work/cont003/gen2224/gen2224/spack/var/spack/environments/gysela-deisa-irene-skl-draft/.spack-env/view/lib/python3.9/site-packages/tornado/ioloop.py", line 741, in _run_callback
    ret = callback()
  File "/ccc/work/cont003/gen2224/gen2224/spack/var/spack/environments/gysela-deisa-irene-skl-draft/.spack-env/view/lib/python3.9/site-packages/tornado/ioloop.py", line 765, in _discard_future_result
    future.result()
  File "/ccc/work/cont003/gen2224/gen2224/spack/var/spack/environments/gysela-deisa-irene-skl-draft/.spack-env/view/lib/python3.9/site-packages/distributed/worker.py", line 2929, in gather_dep
    ts = self.tasks[d]
KeyError: 'array-original-7bdd4b5a4ab7535fc06a874b6ebec639'
distributed.comm.tcp - INFO - Connection from tcp://172.21.3.86:49134 closed before handshake completed
distributed.comm.tcp - INFO - Connection from tcp://172.21.3.86:49136 closed before handshake completed
distributed.comm.tcp - INFO - Connection from tcp://172.21.3.87:49436 closed before handshake completed
distributed.comm.tcp - INFO - Connection from tcp://172.21.3.74:38716 closed before handshake completed
distributed.comm.tcp - INFO - Connection from tcp://172.21.3.88:48022 closed before handshake completed
distributed.comm.tcp - INFO - Connection from tcp://172.21.3.88:48024 closed before handshake completed
distributed.core - INFO - Event loop was unresponsive in Worker for 68.80s.  This is often caused by long-running GIL-holding functions or moving large chunks of data. This can cause timeouts and instability.
distributed.utils_perf - INFO - full garbage collection released 1.25 GiB from 80 reference cycles (threshold: 9.54 MiB)
distributed.comm.tcp - INFO - Connection from tcp://172.21.3.86:40832 closed before handshake completed
distributed.comm.tcp - INFO - Connection from tcp://172.21.3.86:40834 closed before handshake completed
distributed.worker - ERROR - Worker stream died during communication: tcp://172.21.3.82:37680
Traceback (most recent call last):
  File "/ccc/work/cont003/gen2224/gen2224/spack/var/spack/environments/gysela-deisa-irene-skl-draft/.spack-env/view/lib/python3.9/site-packages/distributed/comm/tcp.py", line 205, in read
    frames_nbytes = await stream.read_bytes(fmt_size)
asyncio.exceptions.CancelledError

During handling of the above exception, another exception occurred:

Traceback (most recent call last):
  File "/ccc/work/cont003/gen2224/gen2224/spack/var/spack/environments/gysela-deisa-irene-skl-draft/.spack-env/._view/whcr3wyhzgorszy3rfxsphyebtvfpqzk/lib/python3.9/asyncio/tasks.py", line 490, in wait_for
    return fut.result()
asyncio.exceptions.CancelledError

The above exception was the direct cause of the following exception:

Traceback (most recent call last):
  File "/ccc/work/cont003/gen2224/gen2224/spack/var/spack/environments/gysela-deisa-irene-skl-draft/.spack-env/view/lib/python3.9/site-packages/distributed/comm/core.py", line 319, in connect
    handshake = await asyncio.wait_for(comm.read(), time_left())
  File "/ccc/work/cont003/gen2224/gen2224/spack/var/spack/environments/gysela-deisa-irene-skl-draft/.spack-env/._view/whcr3wyhzgorszy3rfxsphyebtvfpqzk/lib/python3.9/asyncio/tasks.py", line 492, in wait_for
    raise exceptions.TimeoutError() from exc
asyncio.exceptions.TimeoutError

The above exception was the direct cause of the following exception:

Traceback (most recent call last):
  File "/ccc/work/cont003/gen2224/gen2224/spack/var/spack/environments/gysela-deisa-irene-skl-draft/.spack-env/view/lib/python3.9/site-packages/distributed/worker.py", line 2878, in gather_dep
    response = await get_data_from_worker(
  File "/ccc/work/cont003/gen2224/gen2224/spack/var/spack/environments/gysela-deisa-irene-skl-draft/.spack-env/view/lib/python3.9/site-packages/distributed/worker.py", line 4143, in get_data_from_worker
    return await retry_operation(_get_data, operation="get_data_from_worker")
  File "/ccc/work/cont003/gen2224/gen2224/spack/var/spack/environments/gysela-deisa-irene-skl-draft/.spack-env/view/lib/python3.9/site-packages/distributed/utils_comm.py", line 366, in retry_operation
    return await retry(
  File "/ccc/work/cont003/gen2224/gen2224/spack/var/spack/environments/gysela-deisa-irene-skl-draft/.spack-env/view/lib/python3.9/site-packages/distributed/utils_comm.py", line 351, in retry
    return await coro()
  File "/ccc/work/cont003/gen2224/gen2224/spack/var/spack/environments/gysela-deisa-irene-skl-draft/.spack-env/view/lib/python3.9/site-packages/distributed/worker.py", line 4120, in _get_data
    comm = await rpc.connect(worker)
  File "/ccc/work/cont003/gen2224/gen2224/spack/var/spack/environments/gysela-deisa-irene-skl-draft/.spack-env/view/lib/python3.9/site-packages/distributed/core.py", line 1081, in connect
    raise exc
  File "/ccc/work/cont003/gen2224/gen2224/spack/var/spack/environments/gysela-deisa-irene-skl-draft/.spack-env/view/lib/python3.9/site-packages/distributed/core.py", line 1065, in connect
    comm = await fut
  File "/ccc/work/cont003/gen2224/gen2224/spack/var/spack/environments/gysela-deisa-irene-skl-draft/.spack-env/view/lib/python3.9/site-packages/distributed/comm/core.py", line 324, in connect
    raise OSError(
OSError: Timed out during handshake while connecting to tcp://172.21.3.82:37680 after 30 s
distributed.worker - ERROR - Worker stream died during communication: tcp://172.21.3.82:37680
Traceback (most recent call last):
  File "/ccc/work/cont003/gen2224/gen2224/spack/var/spack/environments/gysela-deisa-irene-skl-draft/.spack-env/view/lib/python3.9/site-packages/distributed/comm/tcp.py", line 205, in read
    frames_nbytes = await stream.read_bytes(fmt_size)
asyncio.exceptions.CancelledError

During handling of the above exception, another exception occurred:

Traceback (most recent call last):
  File "/ccc/work/cont003/gen2224/gen2224/spack/var/spack/environments/gysela-deisa-irene-skl-draft/.spack-env/._view/whcr3wyhzgorszy3rfxsphyebtvfpqzk/lib/python3.9/asyncio/tasks.py", line 490, in wait_for
    return fut.result()
asyncio.exceptions.CancelledError

The above exception was the direct cause of the following exception:

Traceback (most recent call last):
  File "/ccc/work/cont003/gen2224/gen2224/spack/var/spack/environments/gysela-deisa-irene-skl-draft/.spack-env/view/lib/python3.9/site-packages/distributed/comm/core.py", line 319, in connect
    handshake = await asyncio.wait_for(comm.read(), time_left())
  File "/ccc/work/cont003/gen2224/gen2224/spack/var/spack/environments/gysela-deisa-irene-skl-draft/.spack-env/._view/whcr3wyhzgorszy3rfxsphyebtvfpqzk/lib/python3.9/asyncio/tasks.py", line 492, in wait_for
    raise exceptions.TimeoutError() from exc
asyncio.exceptions.TimeoutError

The above exception was the direct cause of the following exception:

Traceback (most recent call last):
  File "/ccc/work/cont003/gen2224/gen2224/spack/var/spack/environments/gysela-deisa-irene-skl-draft/.spack-env/view/lib/python3.9/site-packages/distributed/worker.py", line 2878, in gather_dep
    response = await get_data_from_worker(
  File "/ccc/work/cont003/gen2224/gen2224/spack/var/spack/environments/gysela-deisa-irene-skl-draft/.spack-env/view/lib/python3.9/site-packages/distributed/worker.py", line 4143, in get_data_from_worker
    return await retry_operation(_get_data, operation="get_data_from_worker")
  File "/ccc/work/cont003/gen2224/gen2224/spack/var/spack/environments/gysela-deisa-irene-skl-draft/.spack-env/view/lib/python3.9/site-packages/distributed/utils_comm.py", line 366, in retry_operation
    return await retry(
  File "/ccc/work/cont003/gen2224/gen2224/spack/var/spack/environments/gysela-deisa-irene-skl-draft/.spack-env/view/lib/python3.9/site-packages/distributed/utils_comm.py", line 351, in retry
    return await coro()
  File "/ccc/work/cont003/gen2224/gen2224/spack/var/spack/environments/gysela-deisa-irene-skl-draft/.spack-env/view/lib/python3.9/site-packages/distributed/worker.py", line 4120, in _get_data
    comm = await rpc.connect(worker)
  File "/ccc/work/cont003/gen2224/gen2224/spack/var/spack/environments/gysela-deisa-irene-skl-draft/.spack-env/view/lib/python3.9/site-packages/distributed/core.py", line 1081, in connect
    raise exc
  File "/ccc/work/cont003/gen2224/gen2224/spack/var/spack/environments/gysela-deisa-irene-skl-draft/.spack-env/view/lib/python3.9/site-packages/distributed/core.py", line 1065, in connect
    comm = await fut
  File "/ccc/work/cont003/gen2224/gen2224/spack/var/spack/environments/gysela-deisa-irene-skl-draft/.spack-env/view/lib/python3.9/site-packages/distributed/comm/core.py", line 324, in connect
    raise OSError(
OSError: Timed out during handshake while connecting to tcp://172.21.3.82:37680 after 30 s
distributed.worker - ERROR - Worker stream died during communication: tcp://172.21.3.82:37680
Traceback (most recent call last):
  File "/ccc/work/cont003/gen2224/gen2224/spack/var/spack/environments/gysela-deisa-irene-skl-draft/.spack-env/view/lib/python3.9/site-packages/distributed/comm/tcp.py", line 205, in read
    frames_nbytes = await stream.read_bytes(fmt_size)
asyncio.exceptions.CancelledError

During handling of the above exception, another exception occurred:

Traceback (most recent call last):
  File "/ccc/work/cont003/gen2224/gen2224/spack/var/spack/environments/gysela-deisa-irene-skl-draft/.spack-env/._view/whcr3wyhzgorszy3rfxsphyebtvfpqzk/lib/python3.9/asyncio/tasks.py", line 490, in wait_for
    return fut.result()
asyncio.exceptions.CancelledError

The above exception was the direct cause of the following exception:

Traceback (most recent call last):
  File "/ccc/work/cont003/gen2224/gen2224/spack/var/spack/environments/gysela-deisa-irene-skl-draft/.spack-env/view/lib/python3.9/site-packages/distributed/comm/core.py", line 319, in connect
    handshake = await asyncio.wait_for(comm.read(), time_left())
  File "/ccc/work/cont003/gen2224/gen2224/spack/var/spack/environments/gysela-deisa-irene-skl-draft/.spack-env/._view/whcr3wyhzgorszy3rfxsphyebtvfpqzk/lib/python3.9/asyncio/tasks.py", line 492, in wait_for
    raise exceptions.TimeoutError() from exc
asyncio.exceptions.TimeoutError

The above exception was the direct cause of the following exception:

Traceback (most recent call last):
  File "/ccc/work/cont003/gen2224/gen2224/spack/var/spack/environments/gysela-deisa-irene-skl-draft/.spack-env/view/lib/python3.9/site-packages/distributed/worker.py", line 2878, in gather_dep
    response = await get_data_from_worker(
  File "/ccc/work/cont003/gen2224/gen2224/spack/var/spack/environments/gysela-deisa-irene-skl-draft/.spack-env/view/lib/python3.9/site-packages/distributed/worker.py", line 4143, in get_data_from_worker
    return await retry_operation(_get_data, operation="get_data_from_worker")
  File "/ccc/work/cont003/gen2224/gen2224/spack/var/spack/environments/gysela-deisa-irene-skl-draft/.spack-env/view/lib/python3.9/site-packages/distributed/utils_comm.py", line 366, in retry_operation
    return await retry(
  File "/ccc/work/cont003/gen2224/gen2224/spack/var/spack/environments/gysela-deisa-irene-skl-draft/.spack-env/view/lib/python3.9/site-packages/distributed/utils_comm.py", line 351, in retry
    return await coro()
  File "/ccc/work/cont003/gen2224/gen2224/spack/var/spack/environments/gysela-deisa-irene-skl-draft/.spack-env/view/lib/python3.9/site-packages/distributed/worker.py", line 4120, in _get_data
    comm = await rpc.connect(worker)
  File "/ccc/work/cont003/gen2224/gen2224/spack/var/spack/environments/gysela-deisa-irene-skl-draft/.spack-env/view/lib/python3.9/site-packages/distributed/core.py", line 1081, in connect
    raise exc
  File "/ccc/work/cont003/gen2224/gen2224/spack/var/spack/environments/gysela-deisa-irene-skl-draft/.spack-env/view/lib/python3.9/site-packages/distributed/core.py", line 1065, in connect
    comm = await fut
  File "/ccc/work/cont003/gen2224/gen2224/spack/var/spack/environments/gysela-deisa-irene-skl-draft/.spack-env/view/lib/python3.9/site-packages/distributed/comm/core.py", line 324, in connect
    raise OSError(
OSError: Timed out during handshake while connecting to tcp://172.21.3.82:37680 after 30 s
distributed.worker - ERROR - Worker stream died during communication: tcp://172.21.3.82:37680
Traceback (most recent call last):
  File "/ccc/work/cont003/gen2224/gen2224/spack/var/spack/environments/gysela-deisa-irene-skl-draft/.spack-env/view/lib/python3.9/site-packages/distributed/comm/tcp.py", line 205, in read
    frames_nbytes = await stream.read_bytes(fmt_size)
asyncio.exceptions.CancelledError

During handling of the above exception, another exception occurred:

Traceback (most recent call last):
  File "/ccc/work/cont003/gen2224/gen2224/spack/var/spack/environments/gysela-deisa-irene-skl-draft/.spack-env/._view/whcr3wyhzgorszy3rfxsphyebtvfpqzk/lib/python3.9/asyncio/tasks.py", line 490, in wait_for
    return fut.result()
asyncio.exceptions.CancelledError

The above exception was the direct cause of the following exception:

Traceback (most recent call last):
  File "/ccc/work/cont003/gen2224/gen2224/spack/var/spack/environments/gysela-deisa-irene-skl-draft/.spack-env/view/lib/python3.9/site-packages/distributed/comm/core.py", line 319, in connect
    handshake = await asyncio.wait_for(comm.read(), time_left())
  File "/ccc/work/cont003/gen2224/gen2224/spack/var/spack/environments/gysela-deisa-irene-skl-draft/.spack-env/._view/whcr3wyhzgorszy3rfxsphyebtvfpqzk/lib/python3.9/asyncio/tasks.py", line 492, in wait_for
    raise exceptions.TimeoutError() from exc
asyncio.exceptions.TimeoutError

The above exception was the direct cause of the following exception:

Traceback (most recent call last):
  File "/ccc/work/cont003/gen2224/gen2224/spack/var/spack/environments/gysela-deisa-irene-skl-draft/.spack-env/view/lib/python3.9/site-packages/distributed/worker.py", line 2878, in gather_dep
    response = await get_data_from_worker(
  File "/ccc/work/cont003/gen2224/gen2224/spack/var/spack/environments/gysela-deisa-irene-skl-draft/.spack-env/view/lib/python3.9/site-packages/distributed/worker.py", line 4143, in get_data_from_worker
    return await retry_operation(_get_data, operation="get_data_from_worker")
  File "/ccc/work/cont003/gen2224/gen2224/spack/var/spack/environments/gysela-deisa-irene-skl-draft/.spack-env/view/lib/python3.9/site-packages/distributed/utils_comm.py", line 366, in retry_operation
    return await retry(
  File "/ccc/work/cont003/gen2224/gen2224/spack/var/spack/environments/gysela-deisa-irene-skl-draft/.spack-env/view/lib/python3.9/site-packages/distributed/utils_comm.py", line 351, in retry
    return await coro()
  File "/ccc/work/cont003/gen2224/gen2224/spack/var/spack/environments/gysela-deisa-irene-skl-draft/.spack-env/view/lib/python3.9/site-packages/distributed/worker.py", line 4120, in _get_data
    comm = await rpc.connect(worker)
  File "/ccc/work/cont003/gen2224/gen2224/spack/var/spack/environments/gysela-deisa-irene-skl-draft/.spack-env/view/lib/python3.9/site-packages/distributed/core.py", line 1081, in connect
    raise exc
  File "/ccc/work/cont003/gen2224/gen2224/spack/var/spack/environments/gysela-deisa-irene-skl-draft/.spack-env/view/lib/python3.9/site-packages/distributed/core.py", line 1065, in connect
    comm = await fut
  File "/ccc/work/cont003/gen2224/gen2224/spack/var/spack/environments/gysela-deisa-irene-skl-draft/.spack-env/view/lib/python3.9/site-packages/distributed/comm/core.py", line 324, in connect
    raise OSError(
OSError: Timed out during handshake while connecting to tcp://172.21.3.82:37680 after 30 s
distributed.core - INFO - Event loop was unresponsive in Worker for 21.29s.  This is often caused by long-running GIL-holding functions or moving large chunks of data. This can cause timeouts and instability.
distributed.core - INFO - Event loop was unresponsive in Worker for 27.50s.  This is often caused by long-running GIL-holding functions or moving large chunks of data. This can cause timeouts and instability.
distributed.core - INFO - Event loop was unresponsive in Worker for 62.20s.  This is often caused by long-running GIL-holding functions or moving large chunks of data. This can cause timeouts and instability.
distributed.comm.tcp - INFO - Connection from tcp://172.21.3.82:40426 closed before handshake completed
distributed.comm.tcp - INFO - Connection from tcp://172.21.3.87:49438 closed before handshake completed
distributed.core - INFO - Event loop was unresponsive in Worker for 44.95s.  This is often caused by long-running GIL-holding functions or moving large chunks of data. This can cause timeouts and instability.
distributed.comm.tcp - INFO - Connection from tcp://172.21.3.87:36384 closed before handshake completed
distributed.comm.tcp - INFO - Connection from tcp://172.21.3.74:36908 closed before handshake completed
distributed.comm.tcp - INFO - Connection from tcp://172.21.3.88:60640 closed before handshake completed
distributed.comm.tcp - INFO - Connection from tcp://172.21.3.88:60642 closed before handshake completed
distributed.comm.tcp - INFO - Connection from tcp://172.21.3.87:36386 closed before handshake completed
distributed.utils - ERROR - 'array-original-7bdd4b5a4ab7535fc06a874b6ebec639'
Traceback (most recent call last):
  File "/ccc/work/cont003/gen2224/gen2224/spack/var/spack/environments/gysela-deisa-irene-skl-draft/.spack-env/view/lib/python3.9/site-packages/distributed/utils.py", line 684, in log_errors
    yield
  File "/ccc/work/cont003/gen2224/gen2224/spack/var/spack/environments/gysela-deisa-irene-skl-draft/.spack-env/view/lib/python3.9/site-packages/distributed/worker.py", line 2929, in gather_dep
    ts = self.tasks[d]
KeyError: 'array-original-7bdd4b5a4ab7535fc06a874b6ebec639'
tornado.application - ERROR - Exception in callback functools.partial(<bound method IOLoop._discard_future_result of <tornado.platform.asyncio.AsyncIOLoop object at 0x2b97fd016850>>, <Task finished name='Task-1724' coro=<Worker.gather_dep() done, defined at /ccc/work/cont003/gen2224/gen2224/spack/var/spack/environments/gysela-deisa-irene-skl-draft/.spack-env/view/lib/python3.9/site-packages/distributed/worker.py:2823> exception=KeyError('array-original-7bdd4b5a4ab7535fc06a874b6ebec639')>)
Traceback (most recent call last):
  File "/ccc/work/cont003/gen2224/gen2224/spack/var/spack/environments/gysela-deisa-irene-skl-draft/.spack-env/view/lib/python3.9/site-packages/tornado/ioloop.py", line 741, in _run_callback
    ret = callback()
  File "/ccc/work/cont003/gen2224/gen2224/spack/var/spack/environments/gysela-deisa-irene-skl-draft/.spack-env/view/lib/python3.9/site-packages/tornado/ioloop.py", line 765, in _discard_future_result
    future.result()
  File "/ccc/work/cont003/gen2224/gen2224/spack/var/spack/environments/gysela-deisa-irene-skl-draft/.spack-env/view/lib/python3.9/site-packages/distributed/worker.py", line 2929, in gather_dep
    ts = self.tasks[d]
KeyError: 'array-original-7bdd4b5a4ab7535fc06a874b6ebec639'
distributed.core - INFO - Event loop was unresponsive in Worker for 38.55s.  This is often caused by long-running GIL-holding functions or moving large chunks of data. This can cause timeouts and instability.
distributed.core - INFO - Event loop was unresponsive in Worker for 69.03s.  This is often caused by long-running GIL-holding functions or moving large chunks of data. This can cause timeouts and instability.
distributed.comm.tcp - INFO - Connection from tcp://172.21.3.87:54368 closed before handshake completed
distributed.comm.tcp - INFO - Connection from tcp://172.21.3.88:39338 closed before handshake completed
distributed.comm.tcp - INFO - Connection from tcp://172.21.3.74:50828 closed before handshake completed
distributed.comm.tcp - INFO - Connection from tcp://172.21.3.88:39340 closed before handshake completed
distributed.core - INFO - Event loop was unresponsive in Worker for 6.23s.  This is often caused by long-running GIL-holding functions or moving large chunks of data. This can cause timeouts and instability.
distributed.core - INFO - Event loop was unresponsive in Worker for 6.59s.  This is often caused by long-running GIL-holding functions or moving large chunks of data. This can cause timeouts and instability.
distributed.worker - INFO - Stopping worker at tcp://172.21.3.74:45382
distributed.worker - INFO - Stopping worker at tcp://172.21.3.79:36113
distributed.worker - INFO - Stopping worker at tcp://172.21.3.80:41498
distributed.worker - INFO - Stopping worker at tcp://172.21.3.79:45306
distributed.worker - INFO - Stopping worker at tcp://172.21.3.80:35493
distributed.worker - INFO - Stopping worker at tcp://172.21.3.87:36481
distributed.worker - INFO - Stopping worker at tcp://172.21.3.81:32795
distributed.worker - INFO - Stopping worker at tcp://172.21.3.82:33688
distributed.worker - INFO - Stopping worker at tcp://172.21.3.86:35653
distributed.worker - INFO - Stopping worker at tcp://172.21.3.81:45638
distributed.worker - INFO - Stopping worker at tcp://172.21.3.87:41603
distributed.worker - INFO - Stopping worker at tcp://172.21.3.82:37680
distributed.worker - INFO - Stopping worker at tcp://172.21.3.86:42319
distributed.worker - INFO - Stopping worker at tcp://172.21.3.88:36990
distributed.worker - INFO - Stopping worker at tcp://172.21.3.88:40705
distributed.worker - INFO - Stopping worker at tcp://172.21.3.74:43859
distributed.nanny - INFO -         Start Nanny at: 'tcp://172.21.3.81:33294'
distributed.nanny - INFO -         Start Nanny at: 'tcp://172.21.3.86:35268'
distributed.nanny - INFO -         Start Nanny at: 'tcp://172.21.3.86:38537'
distributed.nanny - INFO -         Start Nanny at: 'tcp://172.21.3.74:37182'
distributed.nanny - INFO -         Start Nanny at: 'tcp://172.21.3.88:43943'
distributed.nanny - INFO -         Start Nanny at: 'tcp://172.21.3.74:34731'
distributed.nanny - INFO -         Start Nanny at: 'tcp://172.21.3.88:33651'
distributed.nanny - INFO -         Start Nanny at: 'tcp://172.21.3.81:39657'
distributed.nanny - INFO -         Start Nanny at: 'tcp://172.21.3.87:44380'
distributed.nanny - INFO -         Start Nanny at: 'tcp://172.21.3.87:38987'
distributed.nanny - INFO -         Start Nanny at: 'tcp://172.21.3.80:43197'
distributed.nanny - INFO -         Start Nanny at: 'tcp://172.21.3.80:37033'
distributed.nanny - INFO -         Start Nanny at: 'tcp://172.21.3.82:42704'
distributed.nanny - INFO -         Start Nanny at: 'tcp://172.21.3.82:43788'
distributed.nanny - INFO -         Start Nanny at: 'tcp://172.21.3.79:44849'
distributed.nanny - INFO -         Start Nanny at: 'tcp://172.21.3.79:34380'
distributed.nanny - INFO - Worker closed
distributed.nanny - INFO - Worker closed
distributed.nanny - INFO - Worker closed
distributed.nanny - INFO - Worker closed
distributed.nanny - INFO - Worker closed
distributed.nanny - INFO - Worker closed
distributed.nanny - INFO - Worker closed
distributed.nanny - INFO - Worker closed
distributed.nanny - INFO - Worker closed
distributed.nanny - INFO - Worker closed
distributed.nanny - INFO - Worker closed
distributed.nanny - INFO - Worker closed
distributed.nanny - INFO - Worker closed
distributed.nanny - INFO - Worker closed
distributed.nanny - INFO - Worker closed
distributed.nanny - INFO - Worker closed
distributed.nanny - INFO - Closing Nanny at 'tcp://172.21.3.86:35268'
distributed.dask_worker - INFO - End worker
distributed.nanny - INFO - Closing Nanny at 'tcp://172.21.3.74:34731'
distributed.nanny - INFO - Closing Nanny at 'tcp://172.21.3.88:33651'
distributed.dask_worker - INFO - End worker
distributed.nanny - INFO - Closing Nanny at 'tcp://172.21.3.87:38987'
distributed.dask_worker - INFO - End worker
distributed.dask_worker - INFO - End worker
distributed.nanny - INFO - Closing Nanny at 'tcp://172.21.3.81:33294'
distributed.nanny - INFO - Closing Nanny at 'tcp://172.21.3.74:37182'
distributed.dask_worker - INFO - End worker
distributed.dask_worker - INFO - End worker
distributed.nanny - INFO - Closing Nanny at 'tcp://172.21.3.87:44380'
distributed.dask_worker - INFO - End worker
distributed.nanny - INFO - Closing Nanny at 'tcp://172.21.3.86:38537'
distributed.dask_worker - INFO - End worker
distributed.nanny - INFO - Closing Nanny at 'tcp://172.21.3.88:43943'
distributed.dask_worker - INFO - End worker
distributed.nanny - INFO - Closing Nanny at 'tcp://172.21.3.82:42704'
distributed.dask_worker - INFO - End worker
distributed.nanny - INFO - Closing Nanny at 'tcp://172.21.3.80:37033'
distributed.dask_worker - INFO - End worker
distributed.nanny - INFO - Closing Nanny at 'tcp://172.21.3.79:34380'
distributed.dask_worker - INFO - End worker
distributed.nanny - INFO - Closing Nanny at 'tcp://172.21.3.80:43197'
distributed.dask_worker - INFO - End worker
distributed.nanny - INFO - Closing Nanny at 'tcp://172.21.3.81:39657'
distributed.dask_worker - INFO - End worker
distributed.nanny - INFO - Closing Nanny at 'tcp://172.21.3.79:44849'
distributed.dask_worker - INFO - End worker
distributed.nanny - INFO - Closing Nanny at 'tcp://172.21.3.82:43788'
distributed.dask_worker - INFO - End worker
