distributed.nanny - INFO -         Start Nanny at: 'tcp://172.21.6.170:39725'
distributed.nanny - INFO -         Start Nanny at: 'tcp://172.21.6.167:34988'
distributed.nanny - INFO -         Start Nanny at: 'tcp://172.21.6.171:45033'
distributed.nanny - INFO -         Start Nanny at: 'tcp://172.21.6.169:40994'
distributed.nanny - INFO -         Start Nanny at: 'tcp://172.21.6.169:34678'
distributed.nanny - INFO -         Start Nanny at: 'tcp://172.21.6.170:46296'
distributed.nanny - INFO -         Start Nanny at: 'tcp://172.21.6.167:35171'
distributed.nanny - INFO -         Start Nanny at: 'tcp://172.21.6.171:41394'
distributed.nanny - INFO -         Start Nanny at: 'tcp://172.21.8.207:33131'
distributed.nanny - INFO -         Start Nanny at: 'tcp://172.21.10.168:44924'
distributed.nanny - INFO -         Start Nanny at: 'tcp://172.21.8.207:45698'
distributed.nanny - INFO -         Start Nanny at: 'tcp://172.21.10.168:33738'
distributed.nanny - INFO -         Start Nanny at: 'tcp://172.21.2.253:43273'
distributed.nanny - INFO -         Start Nanny at: 'tcp://172.21.2.253:39710'
distributed.nanny - INFO -         Start Nanny at: 'tcp://172.21.7.155:38421'
distributed.nanny - INFO -         Start Nanny at: 'tcp://172.21.7.155:44022'
distributed.worker - INFO -       Start worker at:   tcp://172.21.6.171:43075
distributed.worker - INFO -          Listening to:   tcp://172.21.6.171:43075
distributed.worker - INFO -       Start worker at:   tcp://172.21.6.171:42111
distributed.worker - INFO -          dashboard at:         172.21.6.171:45008
distributed.worker - INFO -          Listening to:   tcp://172.21.6.171:42111
distributed.worker - INFO - Waiting to connect to:    tcp://172.21.1.144:8786
distributed.worker - INFO -          dashboard at:         172.21.6.171:39399
distributed.worker - INFO - -------------------------------------------------
distributed.worker - INFO - Waiting to connect to:    tcp://172.21.1.144:8786
distributed.worker - INFO -               Threads:                         24
distributed.worker - INFO - -------------------------------------------------
distributed.worker - INFO -                Memory:                 172.73 GiB
distributed.worker - INFO -               Threads:                         24
distributed.worker - INFO -       Local Directory: /tmp/dask-worker-space/worker-l8p9jq1x
distributed.worker - INFO -                Memory:                 172.73 GiB
distributed.worker - INFO -       Local Directory: /tmp/dask-worker-space/worker-4tgus274
distributed.worker - INFO - -------------------------------------------------
distributed.worker - INFO - -------------------------------------------------
distributed.worker - INFO -       Start worker at:   tcp://172.21.6.167:39784
distributed.worker - INFO -          Listening to:   tcp://172.21.6.167:39784
distributed.worker - INFO -          dashboard at:         172.21.6.167:40816
distributed.worker - INFO - Waiting to connect to:    tcp://172.21.1.144:8786
distributed.worker - INFO - -------------------------------------------------
distributed.worker - INFO -               Threads:                         24
distributed.worker - INFO -                Memory:                 172.73 GiB
distributed.worker - INFO -       Local Directory: /tmp/dask-worker-space/worker-g8c5t3nm
distributed.worker - INFO - -------------------------------------------------
distributed.worker - INFO -       Start worker at:   tcp://172.21.6.170:43319
distributed.worker - INFO -       Start worker at:   tcp://172.21.6.170:36855
distributed.worker - INFO -          Listening to:   tcp://172.21.6.170:43319
distributed.worker - INFO -          dashboard at:         172.21.6.170:45673
distributed.worker - INFO -          Listening to:   tcp://172.21.6.170:36855
distributed.worker - INFO -       Start worker at:   tcp://172.21.6.167:35094
distributed.worker - INFO - Waiting to connect to:    tcp://172.21.1.144:8786
distributed.worker - INFO -          dashboard at:         172.21.6.170:46031
distributed.worker - INFO - Waiting to connect to:    tcp://172.21.1.144:8786
distributed.worker - INFO -          Listening to:   tcp://172.21.6.167:35094
distributed.worker - INFO - -------------------------------------------------
distributed.worker - INFO -          dashboard at:         172.21.6.167:44121
distributed.worker - INFO - Waiting to connect to:    tcp://172.21.1.144:8786
distributed.worker - INFO - -------------------------------------------------
distributed.worker - INFO - -------------------------------------------------
distributed.worker - INFO -               Threads:                         24
distributed.worker - INFO -               Threads:                         24
distributed.worker - INFO -               Threads:                         24
distributed.worker - INFO -                Memory:                 172.73 GiB
distributed.worker - INFO -                Memory:                 172.73 GiB
distributed.worker - INFO -       Local Directory: /tmp/dask-worker-space/worker-v2fvvb9_
distributed.worker - INFO -       Local Directory: /tmp/dask-worker-space/worker-g3vjbpch
distributed.worker - INFO - -------------------------------------------------
distributed.worker - INFO - -------------------------------------------------
distributed.worker - INFO -       Start worker at:   tcp://172.21.6.169:35439
distributed.worker - INFO -                Memory:                 172.73 GiB
distributed.worker - INFO -       Local Directory: /tmp/dask-worker-space/worker-_evzk7uf
distributed.worker - INFO - -------------------------------------------------
distributed.worker - INFO -          Listening to:   tcp://172.21.6.169:35439
distributed.worker - INFO -          dashboard at:         172.21.6.169:37151
distributed.worker - INFO - Waiting to connect to:    tcp://172.21.1.144:8786
distributed.worker - INFO - -------------------------------------------------
distributed.worker - INFO -               Threads:                         24
distributed.worker - INFO -                Memory:                 172.73 GiB
distributed.worker - INFO -       Local Directory: /tmp/dask-worker-space/worker-89bxhzxb
distributed.worker - INFO -       Start worker at:   tcp://172.21.6.169:35588
distributed.worker - INFO - -------------------------------------------------
distributed.worker - INFO -          Listening to:   tcp://172.21.6.169:35588
distributed.worker - INFO -          dashboard at:         172.21.6.169:39963
distributed.worker - INFO - Waiting to connect to:    tcp://172.21.1.144:8786
distributed.worker - INFO - -------------------------------------------------
distributed.worker - INFO -               Threads:                         24
distributed.worker - INFO -                Memory:                 172.73 GiB
distributed.worker - INFO -       Local Directory: /tmp/dask-worker-space/worker-r1prno7b
distributed.worker - INFO - -------------------------------------------------
distributed.worker - INFO -         Registered to:    tcp://172.21.1.144:8786
distributed.worker - INFO - -------------------------------------------------
distributed.core - INFO - Starting established connection
distributed.worker - INFO -         Registered to:    tcp://172.21.1.144:8786
distributed.worker - INFO - -------------------------------------------------
distributed.core - INFO - Starting established connection
distributed.worker - INFO -         Registered to:    tcp://172.21.1.144:8786
distributed.worker - INFO - -------------------------------------------------
distributed.core - INFO - Starting established connection
distributed.worker - INFO -         Registered to:    tcp://172.21.1.144:8786
distributed.worker - INFO - -------------------------------------------------
distributed.core - INFO - Starting established connection
distributed.worker - INFO -         Registered to:    tcp://172.21.1.144:8786
distributed.worker - INFO - -------------------------------------------------
distributed.core - INFO - Starting established connection
distributed.worker - INFO -         Registered to:    tcp://172.21.1.144:8786
distributed.worker - INFO - -------------------------------------------------
distributed.core - INFO - Starting established connection
distributed.worker - INFO -         Registered to:    tcp://172.21.1.144:8786
distributed.worker - INFO - -------------------------------------------------
distributed.core - INFO - Starting established connection
distributed.worker - INFO -         Registered to:    tcp://172.21.1.144:8786
distributed.worker - INFO - -------------------------------------------------
distributed.core - INFO - Starting established connection
distributed.worker - INFO -       Start worker at:   tcp://172.21.8.207:44983
distributed.worker - INFO -          Listening to:   tcp://172.21.8.207:44983
distributed.worker - INFO -          dashboard at:         172.21.8.207:42799
distributed.worker - INFO -       Start worker at:  tcp://172.21.10.168:37139
distributed.worker - INFO - Waiting to connect to:    tcp://172.21.1.144:8786
distributed.worker - INFO - -------------------------------------------------
distributed.worker - INFO -               Threads:                         24
distributed.worker - INFO -       Start worker at:   tcp://172.21.8.207:37278
distributed.worker - INFO -          Listening to:  tcp://172.21.10.168:37139
distributed.worker - INFO -                Memory:                 172.73 GiB
distributed.worker - INFO -          dashboard at:        172.21.10.168:39621
distributed.worker - INFO -       Local Directory: /tmp/dask-worker-space/worker-sxu9ciln
distributed.worker - INFO - Waiting to connect to:    tcp://172.21.1.144:8786
distributed.worker - INFO -          Listening to:   tcp://172.21.8.207:37278
distributed.worker - INFO - -------------------------------------------------
distributed.worker - INFO -          dashboard at:         172.21.8.207:46261
distributed.worker - INFO -       Start worker at:  tcp://172.21.10.168:46741
distributed.worker - INFO - -------------------------------------------------
distributed.worker - INFO -               Threads:                         24
distributed.worker - INFO - Waiting to connect to:    tcp://172.21.1.144:8786
distributed.worker - INFO -          Listening to:  tcp://172.21.10.168:46741
distributed.worker - INFO - -------------------------------------------------
distributed.worker - INFO -                Memory:                 172.73 GiB
distributed.worker - INFO -               Threads:                         24
distributed.worker - INFO -          dashboard at:        172.21.10.168:44327
distributed.worker - INFO -                Memory:                 172.73 GiB
distributed.worker - INFO -       Local Directory: /tmp/dask-worker-space/worker-q8u3i4tx
distributed.worker - INFO -       Local Directory: /tmp/dask-worker-space/worker-t2x931fd
distributed.worker - INFO - Waiting to connect to:    tcp://172.21.1.144:8786
distributed.worker - INFO - -------------------------------------------------
distributed.worker - INFO - -------------------------------------------------
distributed.worker - INFO - -------------------------------------------------
distributed.worker - INFO -               Threads:                         24
distributed.worker - INFO -                Memory:                 172.73 GiB
distributed.worker - INFO -       Local Directory: /tmp/dask-worker-space/worker-uyg6c8to
distributed.worker - INFO - -------------------------------------------------
distributed.worker - INFO -         Registered to:    tcp://172.21.1.144:8786
distributed.worker - INFO - -------------------------------------------------
distributed.core - INFO - Starting established connection
distributed.worker - INFO -         Registered to:    tcp://172.21.1.144:8786
distributed.worker - INFO - -------------------------------------------------
distributed.core - INFO - Starting established connection
distributed.worker - INFO -         Registered to:    tcp://172.21.1.144:8786
distributed.worker - INFO - -------------------------------------------------
distributed.core - INFO - Starting established connection
distributed.worker - INFO -         Registered to:    tcp://172.21.1.144:8786
distributed.worker - INFO - -------------------------------------------------
distributed.core - INFO - Starting established connection
distributed.worker - INFO -       Start worker at:   tcp://172.21.2.253:39862
distributed.worker - INFO -          Listening to:   tcp://172.21.2.253:39862
distributed.worker - INFO -          dashboard at:         172.21.2.253:37259
distributed.worker - INFO - Waiting to connect to:    tcp://172.21.1.144:8786
distributed.worker - INFO -       Start worker at:   tcp://172.21.2.253:38331
distributed.worker - INFO - -------------------------------------------------
distributed.worker - INFO -          Listening to:   tcp://172.21.2.253:38331
distributed.worker - INFO -               Threads:                         24
distributed.worker - INFO -          dashboard at:         172.21.2.253:40716
distributed.worker - INFO -                Memory:                 172.73 GiB
distributed.worker - INFO -       Local Directory: /tmp/dask-worker-space/worker-s69c874e
distributed.worker - INFO - Waiting to connect to:    tcp://172.21.1.144:8786
distributed.worker - INFO - -------------------------------------------------
distributed.worker - INFO -               Threads:                         24
distributed.worker - INFO - -------------------------------------------------
distributed.worker - INFO -                Memory:                 172.73 GiB
distributed.worker - INFO -       Local Directory: /tmp/dask-worker-space/worker-v8qordxg
distributed.worker - INFO - -------------------------------------------------
distributed.worker - INFO -         Registered to:    tcp://172.21.1.144:8786
distributed.worker - INFO - -------------------------------------------------
distributed.core - INFO - Starting established connection
distributed.worker - INFO -         Registered to:    tcp://172.21.1.144:8786
distributed.worker - INFO - -------------------------------------------------
distributed.core - INFO - Starting established connection
distributed.worker - INFO -       Start worker at:   tcp://172.21.7.155:40508
distributed.worker - INFO -          Listening to:   tcp://172.21.7.155:40508
distributed.worker - INFO -          dashboard at:         172.21.7.155:44151
distributed.worker - INFO - Waiting to connect to:    tcp://172.21.1.144:8786
distributed.worker - INFO - -------------------------------------------------
distributed.worker - INFO -               Threads:                         24
distributed.worker - INFO -                Memory:                 172.73 GiB
distributed.worker - INFO -       Start worker at:   tcp://172.21.7.155:35480
distributed.worker - INFO -       Local Directory: /tmp/dask-worker-space/worker-04uu55eo
distributed.worker - INFO -          Listening to:   tcp://172.21.7.155:35480
distributed.worker - INFO - -------------------------------------------------
distributed.worker - INFO -          dashboard at:         172.21.7.155:38202
distributed.worker - INFO - Waiting to connect to:    tcp://172.21.1.144:8786
distributed.worker - INFO - -------------------------------------------------
distributed.worker - INFO -               Threads:                         24
distributed.worker - INFO -                Memory:                 172.73 GiB
distributed.worker - INFO -       Local Directory: /tmp/dask-worker-space/worker-0ggu_chz
distributed.worker - INFO - -------------------------------------------------
distributed.worker - INFO -         Registered to:    tcp://172.21.1.144:8786
distributed.worker - INFO - -------------------------------------------------
distributed.core - INFO - Starting established connection
distributed.worker - INFO -         Registered to:    tcp://172.21.1.144:8786
distributed.worker - INFO - -------------------------------------------------
distributed.core - INFO - Starting established connection
distributed.worker - ERROR - Worker stream died during communication: tcp://172.21.6.170:43319
Traceback (most recent call last):
  File "/ccc/work/cont003/gen2224/gen2224/spack/var/spack/environments/gysela-deisa-irene-skl-draft/.spack-env/view/lib/python3.9/site-packages/distributed/comm/tcp.py", line 205, in read
    frames_nbytes = await stream.read_bytes(fmt_size)
asyncio.exceptions.CancelledError

During handling of the above exception, another exception occurred:

Traceback (most recent call last):
  File "/ccc/work/cont003/gen2224/gen2224/spack/var/spack/environments/gysela-deisa-irene-skl-draft/.spack-env/._view/whcr3wyhzgorszy3rfxsphyebtvfpqzk/lib/python3.9/asyncio/tasks.py", line 490, in wait_for
    return fut.result()
asyncio.exceptions.CancelledError

The above exception was the direct cause of the following exception:

Traceback (most recent call last):
  File "/ccc/work/cont003/gen2224/gen2224/spack/var/spack/environments/gysela-deisa-irene-skl-draft/.spack-env/view/lib/python3.9/site-packages/distributed/comm/core.py", line 319, in connect
    handshake = await asyncio.wait_for(comm.read(), time_left())
  File "/ccc/work/cont003/gen2224/gen2224/spack/var/spack/environments/gysela-deisa-irene-skl-draft/.spack-env/._view/whcr3wyhzgorszy3rfxsphyebtvfpqzk/lib/python3.9/asyncio/tasks.py", line 492, in wait_for
    raise exceptions.TimeoutError() from exc
asyncio.exceptions.TimeoutError

The above exception was the direct cause of the following exception:

Traceback (most recent call last):
  File "/ccc/work/cont003/gen2224/gen2224/spack/var/spack/environments/gysela-deisa-irene-skl-draft/.spack-env/view/lib/python3.9/site-packages/distributed/worker.py", line 2878, in gather_dep
    response = await get_data_from_worker(
  File "/ccc/work/cont003/gen2224/gen2224/spack/var/spack/environments/gysela-deisa-irene-skl-draft/.spack-env/view/lib/python3.9/site-packages/distributed/worker.py", line 4143, in get_data_from_worker
    return await retry_operation(_get_data, operation="get_data_from_worker")
  File "/ccc/work/cont003/gen2224/gen2224/spack/var/spack/environments/gysela-deisa-irene-skl-draft/.spack-env/view/lib/python3.9/site-packages/distributed/utils_comm.py", line 366, in retry_operation
    return await retry(
  File "/ccc/work/cont003/gen2224/gen2224/spack/var/spack/environments/gysela-deisa-irene-skl-draft/.spack-env/view/lib/python3.9/site-packages/distributed/utils_comm.py", line 351, in retry
    return await coro()
  File "/ccc/work/cont003/gen2224/gen2224/spack/var/spack/environments/gysela-deisa-irene-skl-draft/.spack-env/view/lib/python3.9/site-packages/distributed/worker.py", line 4120, in _get_data
    comm = await rpc.connect(worker)
  File "/ccc/work/cont003/gen2224/gen2224/spack/var/spack/environments/gysela-deisa-irene-skl-draft/.spack-env/view/lib/python3.9/site-packages/distributed/core.py", line 1081, in connect
    raise exc
  File "/ccc/work/cont003/gen2224/gen2224/spack/var/spack/environments/gysela-deisa-irene-skl-draft/.spack-env/view/lib/python3.9/site-packages/distributed/core.py", line 1065, in connect
    comm = await fut
  File "/ccc/work/cont003/gen2224/gen2224/spack/var/spack/environments/gysela-deisa-irene-skl-draft/.spack-env/view/lib/python3.9/site-packages/distributed/comm/core.py", line 324, in connect
    raise OSError(
OSError: Timed out during handshake while connecting to tcp://172.21.6.170:43319 after 30 s
distributed.worker - ERROR - Worker stream died during communication: tcp://172.21.6.170:43319
Traceback (most recent call last):
  File "/ccc/work/cont003/gen2224/gen2224/spack/var/spack/environments/gysela-deisa-irene-skl-draft/.spack-env/view/lib/python3.9/site-packages/distributed/comm/tcp.py", line 205, in read
    frames_nbytes = await stream.read_bytes(fmt_size)
asyncio.exceptions.CancelledError

During handling of the above exception, another exception occurred:

Traceback (most recent call last):
  File "/ccc/work/cont003/gen2224/gen2224/spack/var/spack/environments/gysela-deisa-irene-skl-draft/.spack-env/._view/whcr3wyhzgorszy3rfxsphyebtvfpqzk/lib/python3.9/asyncio/tasks.py", line 490, in wait_for
    return fut.result()
asyncio.exceptions.CancelledError

The above exception was the direct cause of the following exception:

Traceback (most recent call last):
  File "/ccc/work/cont003/gen2224/gen2224/spack/var/spack/environments/gysela-deisa-irene-skl-draft/.spack-env/view/lib/python3.9/site-packages/distributed/comm/core.py", line 319, in connect
    handshake = await asyncio.wait_for(comm.read(), time_left())
  File "/ccc/work/cont003/gen2224/gen2224/spack/var/spack/environments/gysela-deisa-irene-skl-draft/.spack-env/._view/whcr3wyhzgorszy3rfxsphyebtvfpqzk/lib/python3.9/asyncio/tasks.py", line 492, in wait_for
    raise exceptions.TimeoutError() from exc
asyncio.exceptions.TimeoutError

The above exception was the direct cause of the following exception:

Traceback (most recent call last):
  File "/ccc/work/cont003/gen2224/gen2224/spack/var/spack/environments/gysela-deisa-irene-skl-draft/.spack-env/view/lib/python3.9/site-packages/distributed/worker.py", line 2878, in gather_dep
    response = await get_data_from_worker(
  File "/ccc/work/cont003/gen2224/gen2224/spack/var/spack/environments/gysela-deisa-irene-skl-draft/.spack-env/view/lib/python3.9/site-packages/distributed/worker.py", line 4143, in get_data_from_worker
    return await retry_operation(_get_data, operation="get_data_from_worker")
  File "/ccc/work/cont003/gen2224/gen2224/spack/var/spack/environments/gysela-deisa-irene-skl-draft/.spack-env/view/lib/python3.9/site-packages/distributed/utils_comm.py", line 366, in retry_operation
    return await retry(
  File "/ccc/work/cont003/gen2224/gen2224/spack/var/spack/environments/gysela-deisa-irene-skl-draft/.spack-env/view/lib/python3.9/site-packages/distributed/utils_comm.py", line 351, in retry
    return await coro()
  File "/ccc/work/cont003/gen2224/gen2224/spack/var/spack/environments/gysela-deisa-irene-skl-draft/.spack-env/view/lib/python3.9/site-packages/distributed/worker.py", line 4120, in _get_data
    comm = await rpc.connect(worker)
  File "/ccc/work/cont003/gen2224/gen2224/spack/var/spack/environments/gysela-deisa-irene-skl-draft/.spack-env/view/lib/python3.9/site-packages/distributed/core.py", line 1081, in connect
    raise exc
  File "/ccc/work/cont003/gen2224/gen2224/spack/var/spack/environments/gysela-deisa-irene-skl-draft/.spack-env/view/lib/python3.9/site-packages/distributed/core.py", line 1065, in connect
    comm = await fut
  File "/ccc/work/cont003/gen2224/gen2224/spack/var/spack/environments/gysela-deisa-irene-skl-draft/.spack-env/view/lib/python3.9/site-packages/distributed/comm/core.py", line 324, in connect
    raise OSError(
OSError: Timed out during handshake while connecting to tcp://172.21.6.170:43319 after 30 s
distributed.worker - ERROR - Worker stream died during communication: tcp://172.21.6.170:43319
Traceback (most recent call last):
  File "/ccc/work/cont003/gen2224/gen2224/spack/var/spack/environments/gysela-deisa-irene-skl-draft/.spack-env/view/lib/python3.9/site-packages/distributed/comm/tcp.py", line 205, in read
    frames_nbytes = await stream.read_bytes(fmt_size)
asyncio.exceptions.CancelledError

During handling of the above exception, another exception occurred:

Traceback (most recent call last):
  File "/ccc/work/cont003/gen2224/gen2224/spack/var/spack/environments/gysela-deisa-irene-skl-draft/.spack-env/._view/whcr3wyhzgorszy3rfxsphyebtvfpqzk/lib/python3.9/asyncio/tasks.py", line 490, in wait_for
    return fut.result()
asyncio.exceptions.CancelledError

The above exception was the direct cause of the following exception:

Traceback (most recent call last):
  File "/ccc/work/cont003/gen2224/gen2224/spack/var/spack/environments/gysela-deisa-irene-skl-draft/.spack-env/view/lib/python3.9/site-packages/distributed/comm/core.py", line 319, in connect
    handshake = await asyncio.wait_for(comm.read(), time_left())
  File "/ccc/work/cont003/gen2224/gen2224/spack/var/spack/environments/gysela-deisa-irene-skl-draft/.spack-env/._view/whcr3wyhzgorszy3rfxsphyebtvfpqzk/lib/python3.9/asyncio/tasks.py", line 492, in wait_for
    raise exceptions.TimeoutError() from exc
asyncio.exceptions.TimeoutError

The above exception was the direct cause of the following exception:

Traceback (most recent call last):
  File "/ccc/work/cont003/gen2224/gen2224/spack/var/spack/environments/gysela-deisa-irene-skl-draft/.spack-env/view/lib/python3.9/site-packages/distributed/worker.py", line 2878, in gather_dep
    response = await get_data_from_worker(
  File "/ccc/work/cont003/gen2224/gen2224/spack/var/spack/environments/gysela-deisa-irene-skl-draft/.spack-env/view/lib/python3.9/site-packages/distributed/worker.py", line 4143, in get_data_from_worker
    return await retry_operation(_get_data, operation="get_data_from_worker")
  File "/ccc/work/cont003/gen2224/gen2224/spack/var/spack/environments/gysela-deisa-irene-skl-draft/.spack-env/view/lib/python3.9/site-packages/distributed/utils_comm.py", line 366, in retry_operation
    return await retry(
  File "/ccc/work/cont003/gen2224/gen2224/spack/var/spack/environments/gysela-deisa-irene-skl-draft/.spack-env/view/lib/python3.9/site-packages/distributed/utils_comm.py", line 351, in retry
    return await coro()
  File "/ccc/work/cont003/gen2224/gen2224/spack/var/spack/environments/gysela-deisa-irene-skl-draft/.spack-env/view/lib/python3.9/site-packages/distributed/worker.py", line 4120, in _get_data
    comm = await rpc.connect(worker)
  File "/ccc/work/cont003/gen2224/gen2224/spack/var/spack/environments/gysela-deisa-irene-skl-draft/.spack-env/view/lib/python3.9/site-packages/distributed/core.py", line 1081, in connect
    raise exc
  File "/ccc/work/cont003/gen2224/gen2224/spack/var/spack/environments/gysela-deisa-irene-skl-draft/.spack-env/view/lib/python3.9/site-packages/distributed/core.py", line 1065, in connect
    comm = await fut
  File "/ccc/work/cont003/gen2224/gen2224/spack/var/spack/environments/gysela-deisa-irene-skl-draft/.spack-env/view/lib/python3.9/site-packages/distributed/comm/core.py", line 324, in connect
    raise OSError(
OSError: Timed out during handshake while connecting to tcp://172.21.6.170:43319 after 30 s
distributed.worker - ERROR - Worker stream died during communication: tcp://172.21.6.170:43319
Traceback (most recent call last):
  File "/ccc/work/cont003/gen2224/gen2224/spack/var/spack/environments/gysela-deisa-irene-skl-draft/.spack-env/view/lib/python3.9/site-packages/distributed/comm/tcp.py", line 205, in read
    frames_nbytes = await stream.read_bytes(fmt_size)
asyncio.exceptions.CancelledError

During handling of the above exception, another exception occurred:

Traceback (most recent call last):
  File "/ccc/work/cont003/gen2224/gen2224/spack/var/spack/environments/gysela-deisa-irene-skl-draft/.spack-env/._view/whcr3wyhzgorszy3rfxsphyebtvfpqzk/lib/python3.9/asyncio/tasks.py", line 490, in wait_for
    return fut.result()
asyncio.exceptions.CancelledError

The above exception was the direct cause of the following exception:

Traceback (most recent call last):
  File "/ccc/work/cont003/gen2224/gen2224/spack/var/spack/environments/gysela-deisa-irene-skl-draft/.spack-env/view/lib/python3.9/site-packages/distributed/comm/core.py", line 319, in connect
    handshake = await asyncio.wait_for(comm.read(), time_left())
  File "/ccc/work/cont003/gen2224/gen2224/spack/var/spack/environments/gysela-deisa-irene-skl-draft/.spack-env/._view/whcr3wyhzgorszy3rfxsphyebtvfpqzk/lib/python3.9/asyncio/tasks.py", line 492, in wait_for
    raise exceptions.TimeoutError() from exc
asyncio.exceptions.TimeoutError

The above exception was the direct cause of the following exception:

Traceback (most recent call last):
  File "/ccc/work/cont003/gen2224/gen2224/spack/var/spack/environments/gysela-deisa-irene-skl-draft/.spack-env/view/lib/python3.9/site-packages/distributed/worker.py", line 2878, in gather_dep
    response = await get_data_from_worker(
  File "/ccc/work/cont003/gen2224/gen2224/spack/var/spack/environments/gysela-deisa-irene-skl-draft/.spack-env/view/lib/python3.9/site-packages/distributed/worker.py", line 4143, in get_data_from_worker
    return await retry_operation(_get_data, operation="get_data_from_worker")
  File "/ccc/work/cont003/gen2224/gen2224/spack/var/spack/environments/gysela-deisa-irene-skl-draft/.spack-env/view/lib/python3.9/site-packages/distributed/utils_comm.py", line 366, in retry_operation
    return await retry(
  File "/ccc/work/cont003/gen2224/gen2224/spack/var/spack/environments/gysela-deisa-irene-skl-draft/.spack-env/view/lib/python3.9/site-packages/distributed/utils_comm.py", line 351, in retry
    return await coro()
  File "/ccc/work/cont003/gen2224/gen2224/spack/var/spack/environments/gysela-deisa-irene-skl-draft/.spack-env/view/lib/python3.9/site-packages/distributed/worker.py", line 4120, in _get_data
    comm = await rpc.connect(worker)
  File "/ccc/work/cont003/gen2224/gen2224/spack/var/spack/environments/gysela-deisa-irene-skl-draft/.spack-env/view/lib/python3.9/site-packages/distributed/core.py", line 1081, in connect
    raise exc
  File "/ccc/work/cont003/gen2224/gen2224/spack/var/spack/environments/gysela-deisa-irene-skl-draft/.spack-env/view/lib/python3.9/site-packages/distributed/core.py", line 1065, in connect
    comm = await fut
  File "/ccc/work/cont003/gen2224/gen2224/spack/var/spack/environments/gysela-deisa-irene-skl-draft/.spack-env/view/lib/python3.9/site-packages/distributed/comm/core.py", line 324, in connect
    raise OSError(
OSError: Timed out during handshake while connecting to tcp://172.21.6.170:43319 after 30 s
distributed.worker - ERROR - Worker stream died during communication: tcp://172.21.6.170:43319
Traceback (most recent call last):
  File "/ccc/work/cont003/gen2224/gen2224/spack/var/spack/environments/gysela-deisa-irene-skl-draft/.spack-env/view/lib/python3.9/site-packages/distributed/comm/tcp.py", line 205, in read
    frames_nbytes = await stream.read_bytes(fmt_size)
asyncio.exceptions.CancelledError

During handling of the above exception, another exception occurred:

Traceback (most recent call last):
  File "/ccc/work/cont003/gen2224/gen2224/spack/var/spack/environments/gysela-deisa-irene-skl-draft/.spack-env/._view/whcr3wyhzgorszy3rfxsphyebtvfpqzk/lib/python3.9/asyncio/tasks.py", line 490, in wait_for
    return fut.result()
asyncio.exceptions.CancelledError

The above exception was the direct cause of the following exception:

Traceback (most recent call last):
  File "/ccc/work/cont003/gen2224/gen2224/spack/var/spack/environments/gysela-deisa-irene-skl-draft/.spack-env/view/lib/python3.9/site-packages/distributed/comm/core.py", line 319, in connect
    handshake = await asyncio.wait_for(comm.read(), time_left())
  File "/ccc/work/cont003/gen2224/gen2224/spack/var/spack/environments/gysela-deisa-irene-skl-draft/.spack-env/._view/whcr3wyhzgorszy3rfxsphyebtvfpqzk/lib/python3.9/asyncio/tasks.py", line 492, in wait_for
    raise exceptions.TimeoutError() from exc
asyncio.exceptions.TimeoutError

The above exception was the direct cause of the following exception:

Traceback (most recent call last):
  File "/ccc/work/cont003/gen2224/gen2224/spack/var/spack/environments/gysela-deisa-irene-skl-draft/.spack-env/view/lib/python3.9/site-packages/distributed/worker.py", line 2878, in gather_dep
    response = await get_data_from_worker(
  File "/ccc/work/cont003/gen2224/gen2224/spack/var/spack/environments/gysela-deisa-irene-skl-draft/.spack-env/view/lib/python3.9/site-packages/distributed/worker.py", line 4143, in get_data_from_worker
    return await retry_operation(_get_data, operation="get_data_from_worker")
  File "/ccc/work/cont003/gen2224/gen2224/spack/var/spack/environments/gysela-deisa-irene-skl-draft/.spack-env/view/lib/python3.9/site-packages/distributed/utils_comm.py", line 366, in retry_operation
    return await retry(
  File "/ccc/work/cont003/gen2224/gen2224/spack/var/spack/environments/gysela-deisa-irene-skl-draft/.spack-env/view/lib/python3.9/site-packages/distributed/utils_comm.py", line 351, in retry
    return await coro()
  File "/ccc/work/cont003/gen2224/gen2224/spack/var/spack/environments/gysela-deisa-irene-skl-draft/.spack-env/view/lib/python3.9/site-packages/distributed/worker.py", line 4120, in _get_data
    comm = await rpc.connect(worker)
  File "/ccc/work/cont003/gen2224/gen2224/spack/var/spack/environments/gysela-deisa-irene-skl-draft/.spack-env/view/lib/python3.9/site-packages/distributed/core.py", line 1081, in connect
    raise exc
  File "/ccc/work/cont003/gen2224/gen2224/spack/var/spack/environments/gysela-deisa-irene-skl-draft/.spack-env/view/lib/python3.9/site-packages/distributed/core.py", line 1065, in connect
    comm = await fut
  File "/ccc/work/cont003/gen2224/gen2224/spack/var/spack/environments/gysela-deisa-irene-skl-draft/.spack-env/view/lib/python3.9/site-packages/distributed/comm/core.py", line 324, in connect
    raise OSError(
OSError: Timed out during handshake while connecting to tcp://172.21.6.170:43319 after 30 s
distributed.worker - ERROR - Worker stream died during communication: tcp://172.21.6.170:43319
Traceback (most recent call last):
  File "/ccc/work/cont003/gen2224/gen2224/spack/var/spack/environments/gysela-deisa-irene-skl-draft/.spack-env/view/lib/python3.9/site-packages/distributed/comm/tcp.py", line 205, in read
    frames_nbytes = await stream.read_bytes(fmt_size)
asyncio.exceptions.CancelledError

During handling of the above exception, another exception occurred:

Traceback (most recent call last):
  File "/ccc/work/cont003/gen2224/gen2224/spack/var/spack/environments/gysela-deisa-irene-skl-draft/.spack-env/._view/whcr3wyhzgorszy3rfxsphyebtvfpqzk/lib/python3.9/asyncio/tasks.py", line 490, in wait_for
    return fut.result()
asyncio.exceptions.CancelledError

The above exception was the direct cause of the following exception:

Traceback (most recent call last):
  File "/ccc/work/cont003/gen2224/gen2224/spack/var/spack/environments/gysela-deisa-irene-skl-draft/.spack-env/view/lib/python3.9/site-packages/distributed/comm/core.py", line 319, in connect
    handshake = await asyncio.wait_for(comm.read(), time_left())
  File "/ccc/work/cont003/gen2224/gen2224/spack/var/spack/environments/gysela-deisa-irene-skl-draft/.spack-env/._view/whcr3wyhzgorszy3rfxsphyebtvfpqzk/lib/python3.9/asyncio/tasks.py", line 492, in wait_for
    raise exceptions.TimeoutError() from exc
asyncio.exceptions.TimeoutError

The above exception was the direct cause of the following exception:

Traceback (most recent call last):
  File "/ccc/work/cont003/gen2224/gen2224/spack/var/spack/environments/gysela-deisa-irene-skl-draft/.spack-env/view/lib/python3.9/site-packages/distributed/worker.py", line 2878, in gather_dep
    response = await get_data_from_worker(
  File "/ccc/work/cont003/gen2224/gen2224/spack/var/spack/environments/gysela-deisa-irene-skl-draft/.spack-env/view/lib/python3.9/site-packages/distributed/worker.py", line 4143, in get_data_from_worker
    return await retry_operation(_get_data, operation="get_data_from_worker")
  File "/ccc/work/cont003/gen2224/gen2224/spack/var/spack/environments/gysela-deisa-irene-skl-draft/.spack-env/view/lib/python3.9/site-packages/distributed/utils_comm.py", line 366, in retry_operation
    return await retry(
  File "/ccc/work/cont003/gen2224/gen2224/spack/var/spack/environments/gysela-deisa-irene-skl-draft/.spack-env/view/lib/python3.9/site-packages/distributed/utils_comm.py", line 351, in retry
    return await coro()
  File "/ccc/work/cont003/gen2224/gen2224/spack/var/spack/environments/gysela-deisa-irene-skl-draft/.spack-env/view/lib/python3.9/site-packages/distributed/worker.py", line 4120, in _get_data
    comm = await rpc.connect(worker)
  File "/ccc/work/cont003/gen2224/gen2224/spack/var/spack/environments/gysela-deisa-irene-skl-draft/.spack-env/view/lib/python3.9/site-packages/distributed/core.py", line 1081, in connect
    raise exc
  File "/ccc/work/cont003/gen2224/gen2224/spack/var/spack/environments/gysela-deisa-irene-skl-draft/.spack-env/view/lib/python3.9/site-packages/distributed/core.py", line 1065, in connect
    comm = await fut
  File "/ccc/work/cont003/gen2224/gen2224/spack/var/spack/environments/gysela-deisa-irene-skl-draft/.spack-env/view/lib/python3.9/site-packages/distributed/comm/core.py", line 324, in connect
    raise OSError(
OSError: Timed out during handshake while connecting to tcp://172.21.6.170:43319 after 30 s
distributed.worker - ERROR - Worker stream died during communication: tcp://172.21.6.170:43319
Traceback (most recent call last):
  File "/ccc/work/cont003/gen2224/gen2224/spack/var/spack/environments/gysela-deisa-irene-skl-draft/.spack-env/view/lib/python3.9/site-packages/distributed/comm/tcp.py", line 205, in read
    frames_nbytes = await stream.read_bytes(fmt_size)
asyncio.exceptions.CancelledError

During handling of the above exception, another exception occurred:

Traceback (most recent call last):
  File "/ccc/work/cont003/gen2224/gen2224/spack/var/spack/environments/gysela-deisa-irene-skl-draft/.spack-env/._view/whcr3wyhzgorszy3rfxsphyebtvfpqzk/lib/python3.9/asyncio/tasks.py", line 490, in wait_for
    return fut.result()
asyncio.exceptions.CancelledError

The above exception was the direct cause of the following exception:

Traceback (most recent call last):
  File "/ccc/work/cont003/gen2224/gen2224/spack/var/spack/environments/gysela-deisa-irene-skl-draft/.spack-env/view/lib/python3.9/site-packages/distributed/comm/core.py", line 319, in connect
    handshake = await asyncio.wait_for(comm.read(), time_left())
  File "/ccc/work/cont003/gen2224/gen2224/spack/var/spack/environments/gysela-deisa-irene-skl-draft/.spack-env/._view/whcr3wyhzgorszy3rfxsphyebtvfpqzk/lib/python3.9/asyncio/tasks.py", line 492, in wait_for
    raise exceptions.TimeoutError() from exc
asyncio.exceptions.TimeoutError

The above exception was the direct cause of the following exception:

Traceback (most recent call last):
  File "/ccc/work/cont003/gen2224/gen2224/spack/var/spack/environments/gysela-deisa-irene-skl-draft/.spack-env/view/lib/python3.9/site-packages/distributed/worker.py", line 2878, in gather_dep
    response = await get_data_from_worker(
  File "/ccc/work/cont003/gen2224/gen2224/spack/var/spack/environments/gysela-deisa-irene-skl-draft/.spack-env/view/lib/python3.9/site-packages/distributed/worker.py", line 4143, in get_data_from_worker
    return await retry_operation(_get_data, operation="get_data_from_worker")
  File "/ccc/work/cont003/gen2224/gen2224/spack/var/spack/environments/gysela-deisa-irene-skl-draft/.spack-env/view/lib/python3.9/site-packages/distributed/utils_comm.py", line 366, in retry_operation
    return await retry(
  File "/ccc/work/cont003/gen2224/gen2224/spack/var/spack/environments/gysela-deisa-irene-skl-draft/.spack-env/view/lib/python3.9/site-packages/distributed/utils_comm.py", line 351, in retry
    return await coro()
  File "/ccc/work/cont003/gen2224/gen2224/spack/var/spack/environments/gysela-deisa-irene-skl-draft/.spack-env/view/lib/python3.9/site-packages/distributed/worker.py", line 4120, in _get_data
    comm = await rpc.connect(worker)
  File "/ccc/work/cont003/gen2224/gen2224/spack/var/spack/environments/gysela-deisa-irene-skl-draft/.spack-env/view/lib/python3.9/site-packages/distributed/core.py", line 1081, in connect
    raise exc
  File "/ccc/work/cont003/gen2224/gen2224/spack/var/spack/environments/gysela-deisa-irene-skl-draft/.spack-env/view/lib/python3.9/site-packages/distributed/core.py", line 1065, in connect
    comm = await fut
  File "/ccc/work/cont003/gen2224/gen2224/spack/var/spack/environments/gysela-deisa-irene-skl-draft/.spack-env/view/lib/python3.9/site-packages/distributed/comm/core.py", line 324, in connect
    raise OSError(
OSError: Timed out during handshake while connecting to tcp://172.21.6.170:43319 after 30 s
distributed.worker - ERROR - Worker stream died during communication: tcp://172.21.6.170:43319
Traceback (most recent call last):
  File "/ccc/work/cont003/gen2224/gen2224/spack/var/spack/environments/gysela-deisa-irene-skl-draft/.spack-env/view/lib/python3.9/site-packages/distributed/comm/tcp.py", line 205, in read
    frames_nbytes = await stream.read_bytes(fmt_size)
asyncio.exceptions.CancelledError

During handling of the above exception, another exception occurred:

Traceback (most recent call last):
  File "/ccc/work/cont003/gen2224/gen2224/spack/var/spack/environments/gysela-deisa-irene-skl-draft/.spack-env/._view/whcr3wyhzgorszy3rfxsphyebtvfpqzk/lib/python3.9/asyncio/tasks.py", line 490, in wait_for
    return fut.result()
asyncio.exceptions.CancelledError

The above exception was the direct cause of the following exception:

Traceback (most recent call last):
  File "/ccc/work/cont003/gen2224/gen2224/spack/var/spack/environments/gysela-deisa-irene-skl-draft/.spack-env/view/lib/python3.9/site-packages/distributed/comm/core.py", line 319, in connect
    handshake = await asyncio.wait_for(comm.read(), time_left())
  File "/ccc/work/cont003/gen2224/gen2224/spack/var/spack/environments/gysela-deisa-irene-skl-draft/.spack-env/._view/whcr3wyhzgorszy3rfxsphyebtvfpqzk/lib/python3.9/asyncio/tasks.py", line 492, in wait_for
    raise exceptions.TimeoutError() from exc
asyncio.exceptions.TimeoutError

The above exception was the direct cause of the following exception:

Traceback (most recent call last):
  File "/ccc/work/cont003/gen2224/gen2224/spack/var/spack/environments/gysela-deisa-irene-skl-draft/.spack-env/view/lib/python3.9/site-packages/distributed/worker.py", line 2878, in gather_dep
    response = await get_data_from_worker(
  File "/ccc/work/cont003/gen2224/gen2224/spack/var/spack/environments/gysela-deisa-irene-skl-draft/.spack-env/view/lib/python3.9/site-packages/distributed/worker.py", line 4143, in get_data_from_worker
    return await retry_operation(_get_data, operation="get_data_from_worker")
  File "/ccc/work/cont003/gen2224/gen2224/spack/var/spack/environments/gysela-deisa-irene-skl-draft/.spack-env/view/lib/python3.9/site-packages/distributed/utils_comm.py", line 366, in retry_operation
    return await retry(
  File "/ccc/work/cont003/gen2224/gen2224/spack/var/spack/environments/gysela-deisa-irene-skl-draft/.spack-env/view/lib/python3.9/site-packages/distributed/utils_comm.py", line 351, in retry
    return await coro()
  File "/ccc/work/cont003/gen2224/gen2224/spack/var/spack/environments/gysela-deisa-irene-skl-draft/.spack-env/view/lib/python3.9/site-packages/distributed/worker.py", line 4120, in _get_data
    comm = await rpc.connect(worker)
  File "/ccc/work/cont003/gen2224/gen2224/spack/var/spack/environments/gysela-deisa-irene-skl-draft/.spack-env/view/lib/python3.9/site-packages/distributed/core.py", line 1081, in connect
    raise exc
  File "/ccc/work/cont003/gen2224/gen2224/spack/var/spack/environments/gysela-deisa-irene-skl-draft/.spack-env/view/lib/python3.9/site-packages/distributed/core.py", line 1065, in connect
    comm = await fut
  File "/ccc/work/cont003/gen2224/gen2224/spack/var/spack/environments/gysela-deisa-irene-skl-draft/.spack-env/view/lib/python3.9/site-packages/distributed/comm/core.py", line 324, in connect
    raise OSError(
OSError: Timed out during handshake while connecting to tcp://172.21.6.170:43319 after 30 s
distributed.worker - ERROR - Worker stream died during communication: tcp://172.21.6.170:43319
Traceback (most recent call last):
  File "/ccc/work/cont003/gen2224/gen2224/spack/var/spack/environments/gysela-deisa-irene-skl-draft/.spack-env/view/lib/python3.9/site-packages/distributed/comm/tcp.py", line 205, in read
    frames_nbytes = await stream.read_bytes(fmt_size)
asyncio.exceptions.CancelledError

During handling of the above exception, another exception occurred:

Traceback (most recent call last):
  File "/ccc/work/cont003/gen2224/gen2224/spack/var/spack/environments/gysela-deisa-irene-skl-draft/.spack-env/._view/whcr3wyhzgorszy3rfxsphyebtvfpqzk/lib/python3.9/asyncio/tasks.py", line 490, in wait_for
    return fut.result()
asyncio.exceptions.CancelledError

The above exception was the direct cause of the following exception:

Traceback (most recent call last):
  File "/ccc/work/cont003/gen2224/gen2224/spack/var/spack/environments/gysela-deisa-irene-skl-draft/.spack-env/view/lib/python3.9/site-packages/distributed/comm/core.py", line 319, in connect
    handshake = await asyncio.wait_for(comm.read(), time_left())
  File "/ccc/work/cont003/gen2224/gen2224/spack/var/spack/environments/gysela-deisa-irene-skl-draft/.spack-env/._view/whcr3wyhzgorszy3rfxsphyebtvfpqzk/lib/python3.9/asyncio/tasks.py", line 492, in wait_for
    raise exceptions.TimeoutError() from exc
asyncio.exceptions.TimeoutError

The above exception was the direct cause of the following exception:

Traceback (most recent call last):
  File "/ccc/work/cont003/gen2224/gen2224/spack/var/spack/environments/gysela-deisa-irene-skl-draft/.spack-env/view/lib/python3.9/site-packages/distributed/worker.py", line 2878, in gather_dep
    response = await get_data_from_worker(
  File "/ccc/work/cont003/gen2224/gen2224/spack/var/spack/environments/gysela-deisa-irene-skl-draft/.spack-env/view/lib/python3.9/site-packages/distributed/worker.py", line 4143, in get_data_from_worker
    return await retry_operation(_get_data, operation="get_data_from_worker")
  File "/ccc/work/cont003/gen2224/gen2224/spack/var/spack/environments/gysela-deisa-irene-skl-draft/.spack-env/view/lib/python3.9/site-packages/distributed/utils_comm.py", line 366, in retry_operation
    return await retry(
  File "/ccc/work/cont003/gen2224/gen2224/spack/var/spack/environments/gysela-deisa-irene-skl-draft/.spack-env/view/lib/python3.9/site-packages/distributed/utils_comm.py", line 351, in retry
    return await coro()
  File "/ccc/work/cont003/gen2224/gen2224/spack/var/spack/environments/gysela-deisa-irene-skl-draft/.spack-env/view/lib/python3.9/site-packages/distributed/worker.py", line 4120, in _get_data
    comm = await rpc.connect(worker)
  File "/ccc/work/cont003/gen2224/gen2224/spack/var/spack/environments/gysela-deisa-irene-skl-draft/.spack-env/view/lib/python3.9/site-packages/distributed/core.py", line 1081, in connect
    raise exc
  File "/ccc/work/cont003/gen2224/gen2224/spack/var/spack/environments/gysela-deisa-irene-skl-draft/.spack-env/view/lib/python3.9/site-packages/distributed/core.py", line 1065, in connect
    comm = await fut
  File "/ccc/work/cont003/gen2224/gen2224/spack/var/spack/environments/gysela-deisa-irene-skl-draft/.spack-env/view/lib/python3.9/site-packages/distributed/comm/core.py", line 324, in connect
    raise OSError(
OSError: Timed out during handshake while connecting to tcp://172.21.6.170:43319 after 30 s
distributed.utils - ERROR - 'array-original-9c77429c3ba4831a17ca74bb7c0d0dbc'
Traceback (most recent call last):
  File "/ccc/work/cont003/gen2224/gen2224/spack/var/spack/environments/gysela-deisa-irene-skl-draft/.spack-env/view/lib/python3.9/site-packages/distributed/utils.py", line 684, in log_errors
    yield
  File "/ccc/work/cont003/gen2224/gen2224/spack/var/spack/environments/gysela-deisa-irene-skl-draft/.spack-env/view/lib/python3.9/site-packages/distributed/worker.py", line 2929, in gather_dep
    ts = self.tasks[d]
KeyError: 'array-original-9c77429c3ba4831a17ca74bb7c0d0dbc'
tornado.application - ERROR - Exception in callback functools.partial(<bound method IOLoop._discard_future_result of <tornado.platform.asyncio.AsyncIOLoop object at 0x2b7d96533850>>, <Task finished name='Task-12741' coro=<Worker.gather_dep() done, defined at /ccc/work/cont003/gen2224/gen2224/spack/var/spack/environments/gysela-deisa-irene-skl-draft/.spack-env/view/lib/python3.9/site-packages/distributed/worker.py:2823> exception=KeyError('array-original-9c77429c3ba4831a17ca74bb7c0d0dbc')>)
Traceback (most recent call last):
  File "/ccc/work/cont003/gen2224/gen2224/spack/var/spack/environments/gysela-deisa-irene-skl-draft/.spack-env/view/lib/python3.9/site-packages/tornado/ioloop.py", line 741, in _run_callback
    ret = callback()
  File "/ccc/work/cont003/gen2224/gen2224/spack/var/spack/environments/gysela-deisa-irene-skl-draft/.spack-env/view/lib/python3.9/site-packages/tornado/ioloop.py", line 765, in _discard_future_result
    future.result()
  File "/ccc/work/cont003/gen2224/gen2224/spack/var/spack/environments/gysela-deisa-irene-skl-draft/.spack-env/view/lib/python3.9/site-packages/distributed/worker.py", line 2929, in gather_dep
    ts = self.tasks[d]
KeyError: 'array-original-9c77429c3ba4831a17ca74bb7c0d0dbc'
distributed.worker - ERROR - Worker stream died during communication: tcp://172.21.2.253:38331
Traceback (most recent call last):
  File "/ccc/work/cont003/gen2224/gen2224/spack/var/spack/environments/gysela-deisa-irene-skl-draft/.spack-env/view/lib/python3.9/site-packages/distributed/comm/tcp.py", line 205, in read
    frames_nbytes = await stream.read_bytes(fmt_size)
asyncio.exceptions.CancelledError

During handling of the above exception, another exception occurred:

Traceback (most recent call last):
  File "/ccc/work/cont003/gen2224/gen2224/spack/var/spack/environments/gysela-deisa-irene-skl-draft/.spack-env/._view/whcr3wyhzgorszy3rfxsphyebtvfpqzk/lib/python3.9/asyncio/tasks.py", line 490, in wait_for
    return fut.result()
asyncio.exceptions.CancelledError

The above exception was the direct cause of the following exception:

Traceback (most recent call last):
  File "/ccc/work/cont003/gen2224/gen2224/spack/var/spack/environments/gysela-deisa-irene-skl-draft/.spack-env/view/lib/python3.9/site-packages/distributed/comm/core.py", line 319, in connect
    handshake = await asyncio.wait_for(comm.read(), time_left())
  File "/ccc/work/cont003/gen2224/gen2224/spack/var/spack/environments/gysela-deisa-irene-skl-draft/.spack-env/._view/whcr3wyhzgorszy3rfxsphyebtvfpqzk/lib/python3.9/asyncio/tasks.py", line 492, in wait_for
    raise exceptions.TimeoutError() from exc
asyncio.exceptions.TimeoutError

The above exception was the direct cause of the following exception:

Traceback (most recent call last):
  File "/ccc/work/cont003/gen2224/gen2224/spack/var/spack/environments/gysela-deisa-irene-skl-draft/.spack-env/view/lib/python3.9/site-packages/distributed/worker.py", line 2878, in gather_dep
    response = await get_data_from_worker(
  File "/ccc/work/cont003/gen2224/gen2224/spack/var/spack/environments/gysela-deisa-irene-skl-draft/.spack-env/view/lib/python3.9/site-packages/distributed/worker.py", line 4143, in get_data_from_worker
    return await retry_operation(_get_data, operation="get_data_from_worker")
  File "/ccc/work/cont003/gen2224/gen2224/spack/var/spack/environments/gysela-deisa-irene-skl-draft/.spack-env/view/lib/python3.9/site-packages/distributed/utils_comm.py", line 366, in retry_operation
    return await retry(
  File "/ccc/work/cont003/gen2224/gen2224/spack/var/spack/environments/gysela-deisa-irene-skl-draft/.spack-env/view/lib/python3.9/site-packages/distributed/utils_comm.py", line 351, in retry
    return await coro()
  File "/ccc/work/cont003/gen2224/gen2224/spack/var/spack/environments/gysela-deisa-irene-skl-draft/.spack-env/view/lib/python3.9/site-packages/distributed/worker.py", line 4120, in _get_data
    comm = await rpc.connect(worker)
  File "/ccc/work/cont003/gen2224/gen2224/spack/var/spack/environments/gysela-deisa-irene-skl-draft/.spack-env/view/lib/python3.9/site-packages/distributed/core.py", line 1081, in connect
    raise exc
  File "/ccc/work/cont003/gen2224/gen2224/spack/var/spack/environments/gysela-deisa-irene-skl-draft/.spack-env/view/lib/python3.9/site-packages/distributed/core.py", line 1065, in connect
    comm = await fut
  File "/ccc/work/cont003/gen2224/gen2224/spack/var/spack/environments/gysela-deisa-irene-skl-draft/.spack-env/view/lib/python3.9/site-packages/distributed/comm/core.py", line 324, in connect
    raise OSError(
OSError: Timed out during handshake while connecting to tcp://172.21.2.253:38331 after 30 s
distributed.worker - ERROR - Worker stream died during communication: tcp://172.21.2.253:38331
Traceback (most recent call last):
  File "/ccc/work/cont003/gen2224/gen2224/spack/var/spack/environments/gysela-deisa-irene-skl-draft/.spack-env/view/lib/python3.9/site-packages/distributed/comm/tcp.py", line 205, in read
    frames_nbytes = await stream.read_bytes(fmt_size)
asyncio.exceptions.CancelledError

During handling of the above exception, another exception occurred:

Traceback (most recent call last):
  File "/ccc/work/cont003/gen2224/gen2224/spack/var/spack/environments/gysela-deisa-irene-skl-draft/.spack-env/._view/whcr3wyhzgorszy3rfxsphyebtvfpqzk/lib/python3.9/asyncio/tasks.py", line 490, in wait_for
    return fut.result()
asyncio.exceptions.CancelledError

The above exception was the direct cause of the following exception:

Traceback (most recent call last):
  File "/ccc/work/cont003/gen2224/gen2224/spack/var/spack/environments/gysela-deisa-irene-skl-draft/.spack-env/view/lib/python3.9/site-packages/distributed/comm/core.py", line 319, in connect
    handshake = await asyncio.wait_for(comm.read(), time_left())
  File "/ccc/work/cont003/gen2224/gen2224/spack/var/spack/environments/gysela-deisa-irene-skl-draft/.spack-env/._view/whcr3wyhzgorszy3rfxsphyebtvfpqzk/lib/python3.9/asyncio/tasks.py", line 492, in wait_for
    raise exceptions.TimeoutError() from exc
asyncio.exceptions.TimeoutError

The above exception was the direct cause of the following exception:

Traceback (most recent call last):
  File "/ccc/work/cont003/gen2224/gen2224/spack/var/spack/environments/gysela-deisa-irene-skl-draft/.spack-env/view/lib/python3.9/site-packages/distributed/worker.py", line 2878, in gather_dep
    response = await get_data_from_worker(
distributed.worker - ERROR - Worker stream died during communication: tcp://172.21.2.253:38331
Traceback (most recent call last):
  File "/ccc/work/cont003/gen2224/gen2224/spack/var/spack/environments/gysela-deisa-irene-skl-draft/.spack-env/view/lib/python3.9/site-packages/distributed/comm/tcp.py", line 205, in read
    frames_nbytes = await stream.read_bytes(fmt_size)
asyncio.exceptions.CancelledError

During handling of the above exception, another exception occurred:

Traceback (most recent call last):
  File "/ccc/work/cont003/gen2224/gen2224/spack/var/spack/environments/gysela-deisa-irene-skl-draft/.spack-env/._view/whcr3wyhzgorszy3rfxsphyebtvfpqzk/lib/python3.9/asyncio/tasks.py", line 490, in wait_for
    return fut.result()
asyncio.exceptions.CancelledError

The above exception was the direct cause of the following exception:

Traceback (most recent call last):
  File "/ccc/work/cont003/gen2224/gen2224/spack/var/spack/environments/gysela-deisa-irene-skl-draft/.spack-env/view/lib/python3.9/site-packages/distributed/worker.py", line 4143, in get_data_from_worker
    return await retry_operation(_get_data, operation="get_data_from_worker")
  File "/ccc/work/cont003/gen2224/gen2224/spack/var/spack/environments/gysela-deisa-irene-skl-draft/.spack-env/view/lib/python3.9/site-packages/distributed/utils_comm.py", line 366, in retry_operation
    return await retry(
  File "/ccc/work/cont003/gen2224/gen2224/spack/var/spack/environments/gysela-deisa-irene-skl-draft/.spack-env/view/lib/python3.9/site-packages/distributed/utils_comm.py", line 351, in retry
    return await coro()
  File "/ccc/work/cont003/gen2224/gen2224/spack/var/spack/environments/gysela-deisa-irene-skl-draft/.spack-env/view/lib/python3.9/site-packages/distributed/worker.py", line 4120, in _get_data
    comm = await rpc.connect(worker)
  File "/ccc/work/cont003/gen2224/gen2224/spack/var/spack/environments/gysela-deisa-irene-skl-draft/.spack-env/view/lib/python3.9/site-packages/distributed/core.py", line 1081, in connect
    raise exc
  File "/ccc/work/cont003/gen2224/gen2224/spack/var/spack/environments/gysela-deisa-irene-skl-draft/.spack-env/view/lib/python3.9/site-packages/distributed/core.py", line 1065, in connect
    comm = await fut
  File "/ccc/work/cont003/gen2224/gen2224/spack/var/spack/environments/gysela-deisa-irene-skl-draft/.spack-env/view/lib/python3.9/site-packages/distributed/comm/core.py", line 324, in connect
    raise OSError(
OSError: Timed out during handshake while connecting to tcp://172.21.2.253:38331 after 30 s
  File "/ccc/work/cont003/gen2224/gen2224/spack/var/spack/environments/gysela-deisa-irene-skl-draft/.spack-env/view/lib/python3.9/site-packages/distributed/comm/core.py", line 319, in connect
    handshake = await asyncio.wait_for(comm.read(), time_left())
  File "/ccc/work/cont003/gen2224/gen2224/spack/var/spack/environments/gysela-deisa-irene-skl-draft/.spack-env/._view/whcr3wyhzgorszy3rfxsphyebtvfpqzk/lib/python3.9/asyncio/tasks.py", line 492, in wait_for
    raise exceptions.TimeoutError() from exc
asyncio.exceptions.TimeoutError

The above exception was the direct cause of the following exception:

Traceback (most recent call last):
  File "/ccc/work/cont003/gen2224/gen2224/spack/var/spack/environments/gysela-deisa-irene-skl-draft/.spack-env/view/lib/python3.9/site-packages/distributed/worker.py", line 2878, in gather_dep
    response = await get_data_from_worker(
  File "/ccc/work/cont003/gen2224/gen2224/spack/var/spack/environments/gysela-deisa-irene-skl-draft/.spack-env/view/lib/python3.9/site-packages/distributed/worker.py", line 4143, in get_data_from_worker
    return await retry_operation(_get_data, operation="get_data_from_worker")
  File "/ccc/work/cont003/gen2224/gen2224/spack/var/spack/environments/gysela-deisa-irene-skl-draft/.spack-env/view/lib/python3.9/site-packages/distributed/utils_comm.py", line 366, in retry_operation
    return await retry(
  File "/ccc/work/cont003/gen2224/gen2224/spack/var/spack/environments/gysela-deisa-irene-skl-draft/.spack-env/view/lib/python3.9/site-packages/distributed/utils_comm.py", line 351, in retry
    return await coro()
  File "/ccc/work/cont003/gen2224/gen2224/spack/var/spack/environments/gysela-deisa-irene-skl-draft/.spack-env/view/lib/python3.9/site-packages/distributed/worker.py", line 4120, in _get_data
    comm = await rpc.connect(worker)
distributed.worker - ERROR - Worker stream died during communication: tcp://172.21.2.253:38331
Traceback (most recent call last):
  File "/ccc/work/cont003/gen2224/gen2224/spack/var/spack/environments/gysela-deisa-irene-skl-draft/.spack-env/view/lib/python3.9/site-packages/distributed/comm/tcp.py", line 205, in read
    frames_nbytes = await stream.read_bytes(fmt_size)
asyncio.exceptions.CancelledError

During handling of the above exception, another exception occurred:

Traceback (most recent call last):
  File "/ccc/work/cont003/gen2224/gen2224/spack/var/spack/environments/gysela-deisa-irene-skl-draft/.spack-env/._view/whcr3wyhzgorszy3rfxsphyebtvfpqzk/lib/python3.9/asyncio/tasks.py", line 490, in wait_for
    return fut.result()
asyncio.exceptions.CancelledError

The above exception was the direct cause of the following exception:

Traceback (most recent call last):
  File "/ccc/work/cont003/gen2224/gen2224/spack/var/spack/environments/gysela-deisa-irene-skl-draft/.spack-env/view/lib/python3.9/site-packages/distributed/core.py", line 1081, in connect
    raise exc
  File "/ccc/work/cont003/gen2224/gen2224/spack/var/spack/environments/gysela-deisa-irene-skl-draft/.spack-env/view/lib/python3.9/site-packages/distributed/core.py", line 1065, in connect
    comm = await fut
  File "/ccc/work/cont003/gen2224/gen2224/spack/var/spack/environments/gysela-deisa-irene-skl-draft/.spack-env/view/lib/python3.9/site-packages/distributed/comm/core.py", line 324, in connect
    raise OSError(
OSError: Timed out during handshake while connecting to tcp://172.21.2.253:38331 after 30 s
distributed.worker - ERROR - Worker stream died during communication: tcp://172.21.2.253:38331
Traceback (most recent call last):
  File "/ccc/work/cont003/gen2224/gen2224/spack/var/spack/environments/gysela-deisa-irene-skl-draft/.spack-env/view/lib/python3.9/site-packages/distributed/comm/tcp.py", line 205, in read
    frames_nbytes = await stream.read_bytes(fmt_size)
asyncio.exceptions.CancelledError

During handling of the above exception, another exception occurred:

Traceback (most recent call last):
  File "/ccc/work/cont003/gen2224/gen2224/spack/var/spack/environments/gysela-deisa-irene-skl-draft/.spack-env/._view/whcr3wyhzgorszy3rfxsphyebtvfpqzk/lib/python3.9/asyncio/tasks.py", line 490, in wait_for
    return fut.result()
asyncio.exceptions.CancelledError

The above exception was the direct cause of the following exception:

Traceback (most recent call last):
  File "/ccc/work/cont003/gen2224/gen2224/spack/var/spack/environments/gysela-deisa-irene-skl-draft/.spack-env/view/lib/python3.9/site-packages/distributed/comm/core.py", line 319, in connect
    handshake = await asyncio.wait_for(comm.read(), time_left())
  File "/ccc/work/cont003/gen2224/gen2224/spack/var/spack/environments/gysela-deisa-irene-skl-draft/.spack-env/._view/whcr3wyhzgorszy3rfxsphyebtvfpqzk/lib/python3.9/asyncio/tasks.py", line 492, in wait_for
    raise exceptions.TimeoutError() from exc
asyncio.exceptions.TimeoutError

The above exception was the direct cause of the following exception:

Traceback (most recent call last):
  File "/ccc/work/cont003/gen2224/gen2224/spack/var/spack/environments/gysela-deisa-irene-skl-draft/.spack-env/view/lib/python3.9/site-packages/distributed/worker.py", line 2878, in gather_dep
    response = await get_data_from_worker(
  File "/ccc/work/cont003/gen2224/gen2224/spack/var/spack/environments/gysela-deisa-irene-skl-draft/.spack-env/view/lib/python3.9/site-packages/distributed/comm/core.py", line 319, in connect
    handshake = await asyncio.wait_for(comm.read(), time_left())
  File "/ccc/work/cont003/gen2224/gen2224/spack/var/spack/environments/gysela-deisa-irene-skl-draft/.spack-env/._view/whcr3wyhzgorszy3rfxsphyebtvfpqzk/lib/python3.9/asyncio/tasks.py", line 492, in wait_for
    raise exceptions.TimeoutError() from exc
asyncio.exceptions.TimeoutError

The above exception was the direct cause of the following exception:

Traceback (most recent call last):
  File "/ccc/work/cont003/gen2224/gen2224/spack/var/spack/environments/gysela-deisa-irene-skl-draft/.spack-env/view/lib/python3.9/site-packages/distributed/worker.py", line 2878, in gather_dep
    response = await get_data_from_worker(
  File "/ccc/work/cont003/gen2224/gen2224/spack/var/spack/environments/gysela-deisa-irene-skl-draft/.spack-env/view/lib/python3.9/site-packages/distributed/worker.py", line 4143, in get_data_from_worker
    return await retry_operation(_get_data, operation="get_data_from_worker")
  File "/ccc/work/cont003/gen2224/gen2224/spack/var/spack/environments/gysela-deisa-irene-skl-draft/.spack-env/view/lib/python3.9/site-packages/distributed/utils_comm.py", line 366, in retry_operation
    return await retry(
  File "/ccc/work/cont003/gen2224/gen2224/spack/var/spack/environments/gysela-deisa-irene-skl-draft/.spack-env/view/lib/python3.9/site-packages/distributed/utils_comm.py", line 351, in retry
    return await coro()
  File "/ccc/work/cont003/gen2224/gen2224/spack/var/spack/environments/gysela-deisa-irene-skl-draft/.spack-env/view/lib/python3.9/site-packages/distributed/worker.py", line 4120, in _get_data
    comm = await rpc.connect(worker)
  File "/ccc/work/cont003/gen2224/gen2224/spack/var/spack/environments/gysela-deisa-irene-skl-draft/.spack-env/view/lib/python3.9/site-packages/distributed/worker.py", line 4143, in get_data_from_worker
    return await retry_operation(_get_data, operation="get_data_from_worker")
  File "/ccc/work/cont003/gen2224/gen2224/spack/var/spack/environments/gysela-deisa-irene-skl-draft/.spack-env/view/lib/python3.9/site-packages/distributed/utils_comm.py", line 366, in retry_operation
    return await retry(
  File "/ccc/work/cont003/gen2224/gen2224/spack/var/spack/environments/gysela-deisa-irene-skl-draft/.spack-env/view/lib/python3.9/site-packages/distributed/utils_comm.py", line 351, in retry
    return await coro()
  File "/ccc/work/cont003/gen2224/gen2224/spack/var/spack/environments/gysela-deisa-irene-skl-draft/.spack-env/view/lib/python3.9/site-packages/distributed/worker.py", line 4120, in _get_data
    comm = await rpc.connect(worker)
  File "/ccc/work/cont003/gen2224/gen2224/spack/var/spack/environments/gysela-deisa-irene-skl-draft/.spack-env/view/lib/python3.9/site-packages/distributed/core.py", line 1081, in connect
    raise exc
  File "/ccc/work/cont003/gen2224/gen2224/spack/var/spack/environments/gysela-deisa-irene-skl-draft/.spack-env/view/lib/python3.9/site-packages/distributed/core.py", line 1065, in connect
    comm = await fut
  File "/ccc/work/cont003/gen2224/gen2224/spack/var/spack/environments/gysela-deisa-irene-skl-draft/.spack-env/view/lib/python3.9/site-packages/distributed/comm/core.py", line 324, in connect
    raise OSError(
OSError: Timed out during handshake while connecting to tcp://172.21.2.253:38331 after 30 s
  File "/ccc/work/cont003/gen2224/gen2224/spack/var/spack/environments/gysela-deisa-irene-skl-draft/.spack-env/view/lib/python3.9/site-packages/distributed/core.py", line 1081, in connect
    raise exc
  File "/ccc/work/cont003/gen2224/gen2224/spack/var/spack/environments/gysela-deisa-irene-skl-draft/.spack-env/view/lib/python3.9/site-packages/distributed/core.py", line 1065, in connect
    comm = await fut
  File "/ccc/work/cont003/gen2224/gen2224/spack/var/spack/environments/gysela-deisa-irene-skl-draft/.spack-env/view/lib/python3.9/site-packages/distributed/comm/core.py", line 324, in connect
    raise OSError(
OSError: Timed out during handshake while connecting to tcp://172.21.2.253:38331 after 30 s
distributed.worker - ERROR - Worker stream died during communication: tcp://172.21.2.253:38331
Traceback (most recent call last):
  File "/ccc/work/cont003/gen2224/gen2224/spack/var/spack/environments/gysela-deisa-irene-skl-draft/.spack-env/view/lib/python3.9/site-packages/distributed/comm/tcp.py", line 205, in read
    frames_nbytes = await stream.read_bytes(fmt_size)
asyncio.exceptions.CancelledError

During handling of the above exception, another exception occurred:

Traceback (most recent call last):
  File "/ccc/work/cont003/gen2224/gen2224/spack/var/spack/environments/gysela-deisa-irene-skl-draft/.spack-env/._view/whcr3wyhzgorszy3rfxsphyebtvfpqzk/lib/python3.9/asyncio/tasks.py", line 490, in wait_for
    return fut.result()
asyncio.exceptions.CancelledError

The above exception was the direct cause of the following exception:

Traceback (most recent call last):
  File "/ccc/work/cont003/gen2224/gen2224/spack/var/spack/environments/gysela-deisa-irene-skl-draft/.spack-env/view/lib/python3.9/site-packages/distributed/comm/core.py", line 319, in connect
    handshake = await asyncio.wait_for(comm.read(), time_left())
  File "/ccc/work/cont003/gen2224/gen2224/spack/var/spack/environments/gysela-deisa-irene-skl-draft/.spack-env/._view/whcr3wyhzgorszy3rfxsphyebtvfpqzk/lib/python3.9/asyncio/tasks.py", line 492, in wait_for
    raise exceptions.TimeoutError() from exc
asyncio.exceptions.TimeoutError

The above exception was the direct cause of the following exception:

Traceback (most recent call last):
  File "/ccc/work/cont003/gen2224/gen2224/spack/var/spack/environments/gysela-deisa-irene-skl-draft/.spack-env/view/lib/python3.9/site-packages/distributed/worker.py", line 2878, in gather_dep
    response = await get_data_from_worker(
  File "/ccc/work/cont003/gen2224/gen2224/spack/var/spack/environments/gysela-deisa-irene-skl-draft/.spack-env/view/lib/python3.9/site-packages/distributed/worker.py", line 4143, in get_data_from_worker
    return await retry_operation(_get_data, operation="get_data_from_worker")
  File "/ccc/work/cont003/gen2224/gen2224/spack/var/spack/environments/gysela-deisa-irene-skl-draft/.spack-env/view/lib/python3.9/site-packages/distributed/utils_comm.py", line 366, in retry_operation
    return await retry(
  File "/ccc/work/cont003/gen2224/gen2224/spack/var/spack/environments/gysela-deisa-irene-skl-draft/.spack-env/view/lib/python3.9/site-packages/distributed/utils_comm.py", line 351, in retry
    return await coro()
  File "/ccc/work/cont003/gen2224/gen2224/spack/var/spack/environments/gysela-deisa-irene-skl-draft/.spack-env/view/lib/python3.9/site-packages/distributed/worker.py", line 4120, in _get_data
    comm = await rpc.connect(worker)
  File "/ccc/work/cont003/gen2224/gen2224/spack/var/spack/environments/gysela-deisa-irene-skl-draft/.spack-env/view/lib/python3.9/site-packages/distributed/core.py", line 1081, in connect
    raise exc
  File "/ccc/work/cont003/gen2224/gen2224/spack/var/spack/environments/gysela-deisa-irene-skl-draft/.spack-env/view/lib/python3.9/site-packages/distributed/core.py", line 1065, in connect
    comm = await fut
  File "/ccc/work/cont003/gen2224/gen2224/spack/var/spack/environments/gysela-deisa-irene-skl-draft/.spack-env/view/lib/python3.9/site-packages/distributed/comm/core.py", line 324, in connect
    raise OSError(
OSError: Timed out during handshake while connecting to tcp://172.21.2.253:38331 after 30 s
distributed.worker - ERROR - Worker stream died during communication: tcp://172.21.2.253:38331
Traceback (most recent call last):
  File "/ccc/work/cont003/gen2224/gen2224/spack/var/spack/environments/gysela-deisa-irene-skl-draft/.spack-env/view/lib/python3.9/site-packages/distributed/comm/tcp.py", line 205, in read
    frames_nbytes = await stream.read_bytes(fmt_size)
asyncio.exceptions.CancelledError

During handling of the above exception, another exception occurred:

Traceback (most recent call last):
  File "/ccc/work/cont003/gen2224/gen2224/spack/var/spack/environments/gysela-deisa-irene-skl-draft/.spack-env/._view/whcr3wyhzgorszy3rfxsphyebtvfpqzk/lib/python3.9/asyncio/tasks.py", line 490, in wait_for
    return fut.result()
asyncio.exceptions.CancelledError

The above exception was the direct cause of the following exception:

Traceback (most recent call last):
  File "/ccc/work/cont003/gen2224/gen2224/spack/var/spack/environments/gysela-deisa-irene-skl-draft/.spack-env/view/lib/python3.9/site-packages/distributed/comm/core.py", line 319, in connect
    handshake = await asyncio.wait_for(comm.read(), time_left())
  File "/ccc/work/cont003/gen2224/gen2224/spack/var/spack/environments/gysela-deisa-irene-skl-draft/.spack-env/._view/whcr3wyhzgorszy3rfxsphyebtvfpqzk/lib/python3.9/asyncio/tasks.py", line 492, in wait_for
    raise exceptions.TimeoutError() from exc
asyncio.exceptions.TimeoutError

The above exception was the direct cause of the following exception:

Traceback (most recent call last):
  File "/ccc/work/cont003/gen2224/gen2224/spack/var/spack/environments/gysela-deisa-irene-skl-draft/.spack-env/view/lib/python3.9/site-packages/distributed/worker.py", line 2878, in gather_dep
    response = await get_data_from_worker(
  File "/ccc/work/cont003/gen2224/gen2224/spack/var/spack/environments/gysela-deisa-irene-skl-draft/.spack-env/view/lib/python3.9/site-packages/distributed/worker.py", line 4143, in get_data_from_worker
    return await retry_operation(_get_data, operation="get_data_from_worker")
  File "/ccc/work/cont003/gen2224/gen2224/spack/var/spack/environments/gysela-deisa-irene-skl-draft/.spack-env/view/lib/python3.9/site-packages/distributed/utils_comm.py", line 366, in retry_operation
    return await retry(
  File "/ccc/work/cont003/gen2224/gen2224/spack/var/spack/environments/gysela-deisa-irene-skl-draft/.spack-env/view/lib/python3.9/site-packages/distributed/utils_comm.py", line 351, in retry
    return await coro()
  File "/ccc/work/cont003/gen2224/gen2224/spack/var/spack/environments/gysela-deisa-irene-skl-draft/.spack-env/view/lib/python3.9/site-packages/distributed/worker.py", line 4120, in _get_data
    comm = await rpc.connect(worker)
  File "/ccc/work/cont003/gen2224/gen2224/spack/var/spack/environments/gysela-deisa-irene-skl-draft/.spack-env/view/lib/python3.9/site-packages/distributed/core.py", line 1081, in connect
    raise exc
  File "/ccc/work/cont003/gen2224/gen2224/spack/var/spack/environments/gysela-deisa-irene-skl-draft/.spack-env/view/lib/python3.9/site-packages/distributed/core.py", line 1065, in connect
    comm = await fut
  File "/ccc/work/cont003/gen2224/gen2224/spack/var/spack/environments/gysela-deisa-irene-skl-draft/.spack-env/view/lib/python3.9/site-packages/distributed/comm/core.py", line 324, in connect
    raise OSError(
OSError: Timed out during handshake while connecting to tcp://172.21.2.253:38331 after 30 s
distributed.worker - ERROR - Worker stream died during communication: tcp://172.21.2.253:38331
Traceback (most recent call last):
  File "/ccc/work/cont003/gen2224/gen2224/spack/var/spack/environments/gysela-deisa-irene-skl-draft/.spack-env/view/lib/python3.9/site-packages/distributed/comm/tcp.py", line 205, in read
    frames_nbytes = await stream.read_bytes(fmt_size)
asyncio.exceptions.CancelledError

During handling of the above exception, another exception occurred:

Traceback (most recent call last):
  File "/ccc/work/cont003/gen2224/gen2224/spack/var/spack/environments/gysela-deisa-irene-skl-draft/.spack-env/._view/whcr3wyhzgorszy3rfxsphyebtvfpqzk/lib/python3.9/asyncio/tasks.py", line 490, in wait_for
    return fut.result()
asyncio.exceptions.CancelledError

The above exception was the direct cause of the following exception:

Traceback (most recent call last):
  File "/ccc/work/cont003/gen2224/gen2224/spack/var/spack/environments/gysela-deisa-irene-skl-draft/.spack-env/view/lib/python3.9/site-packages/distributed/comm/core.py", line 319, in connect
    handshake = await asyncio.wait_for(comm.read(), time_left())
  File "/ccc/work/cont003/gen2224/gen2224/spack/var/spack/environments/gysela-deisa-irene-skl-draft/.spack-env/._view/whcr3wyhzgorszy3rfxsphyebtvfpqzk/lib/python3.9/asyncio/tasks.py", line 492, in wait_for
    raise exceptions.TimeoutError() from exc
asyncio.exceptions.TimeoutError

The above exception was the direct cause of the following exception:

Traceback (most recent call last):
  File "/ccc/work/cont003/gen2224/gen2224/spack/var/spack/environments/gysela-deisa-irene-skl-draft/.spack-env/view/lib/python3.9/site-packages/distributed/worker.py", line 2878, in gather_dep
    response = await get_data_from_worker(
  File "/ccc/work/cont003/gen2224/gen2224/spack/var/spack/environments/gysela-deisa-irene-skl-draft/.spack-env/view/lib/python3.9/site-packages/distributed/worker.py", line 4143, in get_data_from_worker
    return await retry_operation(_get_data, operation="get_data_from_worker")
  File "/ccc/work/cont003/gen2224/gen2224/spack/var/spack/environments/gysela-deisa-irene-skl-draft/.spack-env/view/lib/python3.9/site-packages/distributed/utils_comm.py", line 366, in retry_operation
    return await retry(
  File "/ccc/work/cont003/gen2224/gen2224/spack/var/spack/environments/gysela-deisa-irene-skl-draft/.spack-env/view/lib/python3.9/site-packages/distributed/utils_comm.py", line 351, in retry
    return await coro()
  File "/ccc/work/cont003/gen2224/gen2224/spack/var/spack/environments/gysela-deisa-irene-skl-draft/.spack-env/view/lib/python3.9/site-packages/distributed/worker.py", line 4120, in _get_data
    comm = await rpc.connect(worker)
  File "/ccc/work/cont003/gen2224/gen2224/spack/var/spack/environments/gysela-deisa-irene-skl-draft/.spack-env/view/lib/python3.9/site-packages/distributed/core.py", line 1081, in connect
    raise exc
  File "/ccc/work/cont003/gen2224/gen2224/spack/var/spack/environments/gysela-deisa-irene-skl-draft/.spack-env/view/lib/python3.9/site-packages/distributed/core.py", line 1065, in connect
    comm = await fut
  File "/ccc/work/cont003/gen2224/gen2224/spack/var/spack/environments/gysela-deisa-irene-skl-draft/.spack-env/view/lib/python3.9/site-packages/distributed/comm/core.py", line 324, in connect
    raise OSError(
OSError: Timed out during handshake while connecting to tcp://172.21.2.253:38331 after 30 s
distributed.worker - ERROR - Worker stream died during communication: tcp://172.21.2.253:38331
Traceback (most recent call last):
  File "/ccc/work/cont003/gen2224/gen2224/spack/var/spack/environments/gysela-deisa-irene-skl-draft/.spack-env/view/lib/python3.9/site-packages/distributed/comm/tcp.py", line 205, in read
    frames_nbytes = await stream.read_bytes(fmt_size)
asyncio.exceptions.CancelledError

During handling of the above exception, another exception occurred:

Traceback (most recent call last):
  File "/ccc/work/cont003/gen2224/gen2224/spack/var/spack/environments/gysela-deisa-irene-skl-draft/.spack-env/._view/whcr3wyhzgorszy3rfxsphyebtvfpqzk/lib/python3.9/asyncio/tasks.py", line 490, in wait_for
    return fut.result()
asyncio.exceptions.CancelledError

The above exception was the direct cause of the following exception:

Traceback (most recent call last):
  File "/ccc/work/cont003/gen2224/gen2224/spack/var/spack/environments/gysela-deisa-irene-skl-draft/.spack-env/view/lib/python3.9/site-packages/distributed/comm/core.py", line 319, in connect
    handshake = await asyncio.wait_for(comm.read(), time_left())
  File "/ccc/work/cont003/gen2224/gen2224/spack/var/spack/environments/gysela-deisa-irene-skl-draft/.spack-env/._view/whcr3wyhzgorszy3rfxsphyebtvfpqzk/lib/python3.9/asyncio/tasks.py", line 492, in wait_for
    raise exceptions.TimeoutError() from exc
asyncio.exceptions.TimeoutError

The above exception was the direct cause of the following exception:

Traceback (most recent call last):
  File "/ccc/work/cont003/gen2224/gen2224/spack/var/spack/environments/gysela-deisa-irene-skl-draft/.spack-env/view/lib/python3.9/site-packages/distributed/worker.py", line 2878, in gather_dep
    response = await get_data_from_worker(
  File "/ccc/work/cont003/gen2224/gen2224/spack/var/spack/environments/gysela-deisa-irene-skl-draft/.spack-env/view/lib/python3.9/site-packages/distributed/worker.py", line 4143, in get_data_from_worker
    return await retry_operation(_get_data, operation="get_data_from_worker")
  File "/ccc/work/cont003/gen2224/gen2224/spack/var/spack/environments/gysela-deisa-irene-skl-draft/.spack-env/view/lib/python3.9/site-packages/distributed/utils_comm.py", line 366, in retry_operation
    return await retry(
  File "/ccc/work/cont003/gen2224/gen2224/spack/var/spack/environments/gysela-deisa-irene-skl-draft/.spack-env/view/lib/python3.9/site-packages/distributed/utils_comm.py", line 351, in retry
    return await coro()
  File "/ccc/work/cont003/gen2224/gen2224/spack/var/spack/environments/gysela-deisa-irene-skl-draft/.spack-env/view/lib/python3.9/site-packages/distributed/worker.py", line 4120, in _get_data
    comm = await rpc.connect(worker)
  File "/ccc/work/cont003/gen2224/gen2224/spack/var/spack/environments/gysela-deisa-irene-skl-draft/.spack-env/view/lib/python3.9/site-packages/distributed/core.py", line 1081, in connect
    raise exc
  File "/ccc/work/cont003/gen2224/gen2224/spack/var/spack/environments/gysela-deisa-irene-skl-draft/.spack-env/view/lib/python3.9/site-packages/distributed/core.py", line 1065, in connect
    comm = await fut
  File "/ccc/work/cont003/gen2224/gen2224/spack/var/spack/environments/gysela-deisa-irene-skl-draft/.spack-env/view/lib/python3.9/site-packages/distributed/comm/core.py", line 324, in connect
    raise OSError(
OSError: Timed out during handshake while connecting to tcp://172.21.2.253:38331 after 30 s
distributed.worker - ERROR - Worker stream died during communication: tcp://172.21.8.207:37278
Traceback (most recent call last):
  File "/ccc/work/cont003/gen2224/gen2224/spack/var/spack/environments/gysela-deisa-irene-skl-draft/.spack-env/view/lib/python3.9/site-packages/distributed/comm/tcp.py", line 205, in read
    frames_nbytes = await stream.read_bytes(fmt_size)
asyncio.exceptions.CancelledError

During handling of the above exception, another exception occurred:

Traceback (most recent call last):
  File "/ccc/work/cont003/gen2224/gen2224/spack/var/spack/environments/gysela-deisa-irene-skl-draft/.spack-env/._view/whcr3wyhzgorszy3rfxsphyebtvfpqzk/lib/python3.9/asyncio/tasks.py", line 490, in wait_for
    return fut.result()
asyncio.exceptions.CancelledError

The above exception was the direct cause of the following exception:

Traceback (most recent call last):
  File "/ccc/work/cont003/gen2224/gen2224/spack/var/spack/environments/gysela-deisa-irene-skl-draft/.spack-env/view/lib/python3.9/site-packages/distributed/comm/core.py", line 319, in connect
    handshake = await asyncio.wait_for(comm.read(), time_left())
  File "/ccc/work/cont003/gen2224/gen2224/spack/var/spack/environments/gysela-deisa-irene-skl-draft/.spack-env/._view/whcr3wyhzgorszy3rfxsphyebtvfpqzk/lib/python3.9/asyncio/tasks.py", line 492, in wait_for
    raise exceptions.TimeoutError() from exc
asyncio.exceptions.TimeoutError

The above exception was the direct cause of the following exception:

Traceback (most recent call last):
  File "/ccc/work/cont003/gen2224/gen2224/spack/var/spack/environments/gysela-deisa-irene-skl-draft/.spack-env/view/lib/python3.9/site-packages/distributed/worker.py", line 2878, in gather_dep
    response = await get_data_from_worker(
  File "/ccc/work/cont003/gen2224/gen2224/spack/var/spack/environments/gysela-deisa-irene-skl-draft/.spack-env/view/lib/python3.9/site-packages/distributed/worker.py", line 4143, in get_data_from_worker
    return await retry_operation(_get_data, operation="get_data_from_worker")
  File "/ccc/work/cont003/gen2224/gen2224/spack/var/spack/environments/gysela-deisa-irene-skl-draft/.spack-env/view/lib/python3.9/site-packages/distributed/utils_comm.py", line 366, in retry_operation
    return await retry(
  File "/ccc/work/cont003/gen2224/gen2224/spack/var/spack/environments/gysela-deisa-irene-skl-draft/.spack-env/view/lib/python3.9/site-packages/distributed/utils_comm.py", line 351, in retry
    return await coro()
  File "/ccc/work/cont003/gen2224/gen2224/spack/var/spack/environments/gysela-deisa-irene-skl-draft/.spack-env/view/lib/python3.9/site-packages/distributed/worker.py", line 4120, in _get_data
    comm = await rpc.connect(worker)
  File "/ccc/work/cont003/gen2224/gen2224/spack/var/spack/environments/gysela-deisa-irene-skl-draft/.spack-env/view/lib/python3.9/site-packages/distributed/core.py", line 1081, in connect
    raise exc
  File "/ccc/work/cont003/gen2224/gen2224/spack/var/spack/environments/gysela-deisa-irene-skl-draft/.spack-env/view/lib/python3.9/site-packages/distributed/core.py", line 1065, in connect
    comm = await fut
  File "/ccc/work/cont003/gen2224/gen2224/spack/var/spack/environments/gysela-deisa-irene-skl-draft/.spack-env/view/lib/python3.9/site-packages/distributed/comm/core.py", line 324, in connect
    raise OSError(
OSError: Timed out during handshake while connecting to tcp://172.21.8.207:37278 after 30 s
distributed.worker - ERROR - Worker stream died during communication: tcp://172.21.8.207:37278
Traceback (most recent call last):
  File "/ccc/work/cont003/gen2224/gen2224/spack/var/spack/environments/gysela-deisa-irene-skl-draft/.spack-env/view/lib/python3.9/site-packages/distributed/comm/tcp.py", line 205, in read
    frames_nbytes = await stream.read_bytes(fmt_size)
asyncio.exceptions.CancelledError

During handling of the above exception, another exception occurred:

Traceback (most recent call last):
  File "/ccc/work/cont003/gen2224/gen2224/spack/var/spack/environments/gysela-deisa-irene-skl-draft/.spack-env/._view/whcr3wyhzgorszy3rfxsphyebtvfpqzk/lib/python3.9/asyncio/tasks.py", line 490, in wait_for
    return fut.result()
asyncio.exceptions.CancelledError

The above exception was the direct cause of the following exception:

Traceback (most recent call last):
  File "/ccc/work/cont003/gen2224/gen2224/spack/var/spack/environments/gysela-deisa-irene-skl-draft/.spack-env/view/lib/python3.9/site-packages/distributed/comm/core.py", line 319, in connect
    handshake = await asyncio.wait_for(comm.read(), time_left())
  File "/ccc/work/cont003/gen2224/gen2224/spack/var/spack/environments/gysela-deisa-irene-skl-draft/.spack-env/._view/whcr3wyhzgorszy3rfxsphyebtvfpqzk/lib/python3.9/asyncio/tasks.py", line 492, in wait_for
    raise exceptions.TimeoutError() from exc
asyncio.exceptions.TimeoutError

The above exception was the direct cause of the following exception:

Traceback (most recent call last):
  File "/ccc/work/cont003/gen2224/gen2224/spack/var/spack/environments/gysela-deisa-irene-skl-draft/.spack-env/view/lib/python3.9/site-packages/distributed/worker.py", line 2878, in gather_dep
    response = await get_data_from_worker(
  File "/ccc/work/cont003/gen2224/gen2224/spack/var/spack/environments/gysela-deisa-irene-skl-draft/.spack-env/view/lib/python3.9/site-packages/distributed/worker.py", line 4143, in get_data_from_worker
    return await retry_operation(_get_data, operation="get_data_from_worker")
  File "/ccc/work/cont003/gen2224/gen2224/spack/var/spack/environments/gysela-deisa-irene-skl-draft/.spack-env/view/lib/python3.9/site-packages/distributed/utils_comm.py", line 366, in retry_operation
    return await retry(
  File "/ccc/work/cont003/gen2224/gen2224/spack/var/spack/environments/gysela-deisa-irene-skl-draft/.spack-env/view/lib/python3.9/site-packages/distributed/utils_comm.py", line 351, in retry
    return await coro()
  File "/ccc/work/cont003/gen2224/gen2224/spack/var/spack/environments/gysela-deisa-irene-skl-draft/.spack-env/view/lib/python3.9/site-packages/distributed/worker.py", line 4120, in _get_data
    comm = await rpc.connect(worker)
  File "/ccc/work/cont003/gen2224/gen2224/spack/var/spack/environments/gysela-deisa-irene-skl-draft/.spack-env/view/lib/python3.9/site-packages/distributed/core.py", line 1081, in connect
    raise exc
  File "/ccc/work/cont003/gen2224/gen2224/spack/var/spack/environments/gysela-deisa-irene-skl-draft/.spack-env/view/lib/python3.9/site-packages/distributed/core.py", line 1065, in connect
    comm = await fut
  File "/ccc/work/cont003/gen2224/gen2224/spack/var/spack/environments/gysela-deisa-irene-skl-draft/.spack-env/view/lib/python3.9/site-packages/distributed/comm/core.py", line 324, in connect
    raise OSError(
OSError: Timed out during handshake while connecting to tcp://172.21.8.207:37278 after 30 s
distributed.worker - ERROR - Worker stream died during communication: tcp://172.21.8.207:37278
Traceback (most recent call last):
  File "/ccc/work/cont003/gen2224/gen2224/spack/var/spack/environments/gysela-deisa-irene-skl-draft/.spack-env/view/lib/python3.9/site-packages/distributed/comm/tcp.py", line 205, in read
    frames_nbytes = await stream.read_bytes(fmt_size)
asyncio.exceptions.CancelledError

During handling of the above exception, another exception occurred:

Traceback (most recent call last):
  File "/ccc/work/cont003/gen2224/gen2224/spack/var/spack/environments/gysela-deisa-irene-skl-draft/.spack-env/._view/whcr3wyhzgorszy3rfxsphyebtvfpqzk/lib/python3.9/asyncio/tasks.py", line 490, in wait_for
    return fut.result()
asyncio.exceptions.CancelledError

The above exception was the direct cause of the following exception:

Traceback (most recent call last):
  File "/ccc/work/cont003/gen2224/gen2224/spack/var/spack/environments/gysela-deisa-irene-skl-draft/.spack-env/view/lib/python3.9/site-packages/distributed/comm/core.py", line 319, in connect
    handshake = await asyncio.wait_for(comm.read(), time_left())
  File "/ccc/work/cont003/gen2224/gen2224/spack/var/spack/environments/gysela-deisa-irene-skl-draft/.spack-env/._view/whcr3wyhzgorszy3rfxsphyebtvfpqzk/lib/python3.9/asyncio/tasks.py", line 492, in wait_for
    raise exceptions.TimeoutError() from exc
asyncio.exceptions.TimeoutError

The above exception was the direct cause of the following exception:

Traceback (most recent call last):
  File "/ccc/work/cont003/gen2224/gen2224/spack/var/spack/environments/gysela-deisa-irene-skl-draft/.spack-env/view/lib/python3.9/site-packages/distributed/worker.py", line 2878, in gather_dep
    response = await get_data_from_worker(
  File "/ccc/work/cont003/gen2224/gen2224/spack/var/spack/environments/gysela-deisa-irene-skl-draft/.spack-env/view/lib/python3.9/site-packages/distributed/worker.py", line 4143, in get_data_from_worker
    return await retry_operation(_get_data, operation="get_data_from_worker")
  File "/ccc/work/cont003/gen2224/gen2224/spack/var/spack/environments/gysela-deisa-irene-skl-draft/.spack-env/view/lib/python3.9/site-packages/distributed/utils_comm.py", line 366, in retry_operation
    return await retry(
  File "/ccc/work/cont003/gen2224/gen2224/spack/var/spack/environments/gysela-deisa-irene-skl-draft/.spack-env/view/lib/python3.9/site-packages/distributed/utils_comm.py", line 351, in retry
    return await coro()
  File "/ccc/work/cont003/gen2224/gen2224/spack/var/spack/environments/gysela-deisa-irene-skl-draft/.spack-env/view/lib/python3.9/site-packages/distributed/worker.py", line 4120, in _get_data
    comm = await rpc.connect(worker)
  File "/ccc/work/cont003/gen2224/gen2224/spack/var/spack/environments/gysela-deisa-irene-skl-draft/.spack-env/view/lib/python3.9/site-packages/distributed/core.py", line 1081, in connect
    raise exc
  File "/ccc/work/cont003/gen2224/gen2224/spack/var/spack/environments/gysela-deisa-irene-skl-draft/.spack-env/view/lib/python3.9/site-packages/distributed/core.py", line 1065, in connect
    comm = await fut
  File "/ccc/work/cont003/gen2224/gen2224/spack/var/spack/environments/gysela-deisa-irene-skl-draft/.spack-env/view/lib/python3.9/site-packages/distributed/comm/core.py", line 324, in connect
    raise OSError(
OSError: Timed out during handshake while connecting to tcp://172.21.8.207:37278 after 30 s
distributed.worker - ERROR - Worker stream died during communication: tcp://172.21.8.207:37278
Traceback (most recent call last):
  File "/ccc/work/cont003/gen2224/gen2224/spack/var/spack/environments/gysela-deisa-irene-skl-draft/.spack-env/view/lib/python3.9/site-packages/distributed/comm/tcp.py", line 205, in read
    frames_nbytes = await stream.read_bytes(fmt_size)
asyncio.exceptions.CancelledError

During handling of the above exception, another exception occurred:

Traceback (most recent call last):
  File "/ccc/work/cont003/gen2224/gen2224/spack/var/spack/environments/gysela-deisa-irene-skl-draft/.spack-env/._view/whcr3wyhzgorszy3rfxsphyebtvfpqzk/lib/python3.9/asyncio/tasks.py", line 490, in wait_for
    return fut.result()
asyncio.exceptions.CancelledError

The above exception was the direct cause of the following exception:

Traceback (most recent call last):
  File "/ccc/work/cont003/gen2224/gen2224/spack/var/spack/environments/gysela-deisa-irene-skl-draft/.spack-env/view/lib/python3.9/site-packages/distributed/comm/core.py", line 319, in connect
    handshake = await asyncio.wait_for(comm.read(), time_left())
  File "/ccc/work/cont003/gen2224/gen2224/spack/var/spack/environments/gysela-deisa-irene-skl-draft/.spack-env/._view/whcr3wyhzgorszy3rfxsphyebtvfpqzk/lib/python3.9/asyncio/tasks.py", line 492, in wait_for
    raise exceptions.TimeoutError() from exc
asyncio.exceptions.TimeoutError

The above exception was the direct cause of the following exception:

Traceback (most recent call last):
  File "/ccc/work/cont003/gen2224/gen2224/spack/var/spack/environments/gysela-deisa-irene-skl-draft/.spack-env/view/lib/python3.9/site-packages/distributed/worker.py", line 2878, in gather_dep
    response = await get_data_from_worker(
  File "/ccc/work/cont003/gen2224/gen2224/spack/var/spack/environments/gysela-deisa-irene-skl-draft/.spack-env/view/lib/python3.9/site-packages/distributed/worker.py", line 4143, in get_data_from_worker
    return await retry_operation(_get_data, operation="get_data_from_worker")
  File "/ccc/work/cont003/gen2224/gen2224/spack/var/spack/environments/gysela-deisa-irene-skl-draft/.spack-env/view/lib/python3.9/site-packages/distributed/utils_comm.py", line 366, in retry_operation
    return await retry(
  File "/ccc/work/cont003/gen2224/gen2224/spack/var/spack/environments/gysela-deisa-irene-skl-draft/.spack-env/view/lib/python3.9/site-packages/distributed/utils_comm.py", line 351, in retry
    return await coro()
  File "/ccc/work/cont003/gen2224/gen2224/spack/var/spack/environments/gysela-deisa-irene-skl-draft/.spack-env/view/lib/python3.9/site-packages/distributed/worker.py", line 4120, in _get_data
    comm = await rpc.connect(worker)
  File "/ccc/work/cont003/gen2224/gen2224/spack/var/spack/environments/gysela-deisa-irene-skl-draft/.spack-env/view/lib/python3.9/site-packages/distributed/core.py", line 1081, in connect
    raise exc
  File "/ccc/work/cont003/gen2224/gen2224/spack/var/spack/environments/gysela-deisa-irene-skl-draft/.spack-env/view/lib/python3.9/site-packages/distributed/core.py", line 1065, in connect
    comm = await fut
  File "/ccc/work/cont003/gen2224/gen2224/spack/var/spack/environments/gysela-deisa-irene-skl-draft/.spack-env/view/lib/python3.9/site-packages/distributed/comm/core.py", line 324, in connect
    raise OSError(
OSError: Timed out during handshake while connecting to tcp://172.21.8.207:37278 after 30 s
distributed.worker - ERROR - Worker stream died during communication: tcp://172.21.8.207:37278
Traceback (most recent call last):
  File "/ccc/work/cont003/gen2224/gen2224/spack/var/spack/environments/gysela-deisa-irene-skl-draft/.spack-env/view/lib/python3.9/site-packages/distributed/comm/tcp.py", line 205, in read
    frames_nbytes = await stream.read_bytes(fmt_size)
asyncio.exceptions.CancelledError

During handling of the above exception, another exception occurred:

Traceback (most recent call last):
  File "/ccc/work/cont003/gen2224/gen2224/spack/var/spack/environments/gysela-deisa-irene-skl-draft/.spack-env/._view/whcr3wyhzgorszy3rfxsphyebtvfpqzk/lib/python3.9/asyncio/tasks.py", line 490, in wait_for
    return fut.result()
asyncio.exceptions.CancelledError

The above exception was the direct cause of the following exception:

Traceback (most recent call last):
  File "/ccc/work/cont003/gen2224/gen2224/spack/var/spack/environments/gysela-deisa-irene-skl-draft/.spack-env/view/lib/python3.9/site-packages/distributed/comm/core.py", line 319, in connect
    handshake = await asyncio.wait_for(comm.read(), time_left())
  File "/ccc/work/cont003/gen2224/gen2224/spack/var/spack/environments/gysela-deisa-irene-skl-draft/.spack-env/._view/whcr3wyhzgorszy3rfxsphyebtvfpqzk/lib/python3.9/asyncio/tasks.py", line 492, in wait_for
    raise exceptions.TimeoutError() from exc
asyncio.exceptions.TimeoutError

The above exception was the direct cause of the following exception:

Traceback (most recent call last):
  File "/ccc/work/cont003/gen2224/gen2224/spack/var/spack/environments/gysela-deisa-irene-skl-draft/.spack-env/view/lib/python3.9/site-packages/distributed/worker.py", line 2878, in gather_dep
    response = await get_data_from_worker(
  File "/ccc/work/cont003/gen2224/gen2224/spack/var/spack/environments/gysela-deisa-irene-skl-draft/.spack-env/view/lib/python3.9/site-packages/distributed/worker.py", line 4143, in get_data_from_worker
    return await retry_operation(_get_data, operation="get_data_from_worker")
  File "/ccc/work/cont003/gen2224/gen2224/spack/var/spack/environments/gysela-deisa-irene-skl-draft/.spack-env/view/lib/python3.9/site-packages/distributed/utils_comm.py", line 366, in retry_operation
    return await retry(
  File "/ccc/work/cont003/gen2224/gen2224/spack/var/spack/environments/gysela-deisa-irene-skl-draft/.spack-env/view/lib/python3.9/site-packages/distributed/utils_comm.py", line 351, in retry
    return await coro()
  File "/ccc/work/cont003/gen2224/gen2224/spack/var/spack/environments/gysela-deisa-irene-skl-draft/.spack-env/view/lib/python3.9/site-packages/distributed/worker.py", line 4120, in _get_data
    comm = await rpc.connect(worker)
  File "/ccc/work/cont003/gen2224/gen2224/spack/var/spack/environments/gysela-deisa-irene-skl-draft/.spack-env/view/lib/python3.9/site-packages/distributed/core.py", line 1081, in connect
    raise exc
  File "/ccc/work/cont003/gen2224/gen2224/spack/var/spack/environments/gysela-deisa-irene-skl-draft/.spack-env/view/lib/python3.9/site-packages/distributed/core.py", line 1065, in connect
    comm = await fut
  File "/ccc/work/cont003/gen2224/gen2224/spack/var/spack/environments/gysela-deisa-irene-skl-draft/.spack-env/view/lib/python3.9/site-packages/distributed/comm/core.py", line 324, in connect
    raise OSError(
OSError: Timed out during handshake while connecting to tcp://172.21.8.207:37278 after 30 s
distributed.worker - ERROR - Worker stream died during communication: tcp://172.21.6.171:42111
Traceback (most recent call last):
  File "/ccc/work/cont003/gen2224/gen2224/spack/var/spack/environments/gysela-deisa-irene-skl-draft/.spack-env/view/lib/python3.9/site-packages/distributed/comm/tcp.py", line 205, in read
    frames_nbytes = await stream.read_bytes(fmt_size)
asyncio.exceptions.CancelledError

During handling of the above exception, another exception occurred:

Traceback (most recent call last):
  File "/ccc/work/cont003/gen2224/gen2224/spack/var/spack/environments/gysela-deisa-irene-skl-draft/.spack-env/._view/whcr3wyhzgorszy3rfxsphyebtvfpqzk/lib/python3.9/asyncio/tasks.py", line 490, in wait_for
    return fut.result()
asyncio.exceptions.CancelledError

The above exception was the direct cause of the following exception:

Traceback (most recent call last):
  File "/ccc/work/cont003/gen2224/gen2224/spack/var/spack/environments/gysela-deisa-irene-skl-draft/.spack-env/view/lib/python3.9/site-packages/distributed/comm/core.py", line 319, in connect
    handshake = await asyncio.wait_for(comm.read(), time_left())
  File "/ccc/work/cont003/gen2224/gen2224/spack/var/spack/environments/gysela-deisa-irene-skl-draft/.spack-env/._view/whcr3wyhzgorszy3rfxsphyebtvfpqzk/lib/python3.9/asyncio/tasks.py", line 492, in wait_for
    raise exceptions.TimeoutError() from exc
asyncio.exceptions.TimeoutError

The above exception was the direct cause of the following exception:

Traceback (most recent call last):
  File "/ccc/work/cont003/gen2224/gen2224/spack/var/spack/environments/gysela-deisa-irene-skl-draft/.spack-env/view/lib/python3.9/site-packages/distributed/worker.py", line 2878, in gather_dep
    response = await get_data_from_worker(
  File "/ccc/work/cont003/gen2224/gen2224/spack/var/spack/environments/gysela-deisa-irene-skl-draft/.spack-env/view/lib/python3.9/site-packages/distributed/worker.py", line 4143, in get_data_from_worker
    return await retry_operation(_get_data, operation="get_data_from_worker")
  File "/ccc/work/cont003/gen2224/gen2224/spack/var/spack/environments/gysela-deisa-irene-skl-draft/.spack-env/view/lib/python3.9/site-packages/distributed/utils_comm.py", line 366, in retry_operation
    return await retry(
  File "/ccc/work/cont003/gen2224/gen2224/spack/var/spack/environments/gysela-deisa-irene-skl-draft/.spack-env/view/lib/python3.9/site-packages/distributed/utils_comm.py", line 351, in retry
    return await coro()
  File "/ccc/work/cont003/gen2224/gen2224/spack/var/spack/environments/gysela-deisa-irene-skl-draft/.spack-env/view/lib/python3.9/site-packages/distributed/worker.py", line 4120, in _get_data
    comm = await rpc.connect(worker)
  File "/ccc/work/cont003/gen2224/gen2224/spack/var/spack/environments/gysela-deisa-irene-skl-draft/.spack-env/view/lib/python3.9/site-packages/distributed/core.py", line 1081, in connect
    raise exc
  File "/ccc/work/cont003/gen2224/gen2224/spack/var/spack/environments/gysela-deisa-irene-skl-draft/.spack-env/view/lib/python3.9/site-packages/distributed/core.py", line 1065, in connect
    comm = await fut
  File "/ccc/work/cont003/gen2224/gen2224/spack/var/spack/environments/gysela-deisa-irene-skl-draft/.spack-env/view/lib/python3.9/site-packages/distributed/comm/core.py", line 324, in connect
    raise OSError(
OSError: Timed out during handshake while connecting to tcp://172.21.6.171:42111 after 30 s
distributed.core - INFO - Event loop was unresponsive in Worker for 280.87s.  This is often caused by long-running GIL-holding functions or moving large chunks of data. This can cause timeouts and instability.
distributed.comm.tcp - INFO - Connection from tcp://172.21.10.168:33132 closed before handshake completed
distributed.comm.tcp - INFO - Connection from tcp://172.21.6.171:48408 closed before handshake completed
distributed.comm.tcp - INFO - Connection from tcp://172.21.6.171:48410 closed before handshake completed
distributed.comm.tcp - INFO - Connection from tcp://172.21.2.253:42418 closed before handshake completed
distributed.comm.tcp - INFO - Connection from tcp://172.21.8.207:42150 closed before handshake completed
distributed.comm.tcp - INFO - Connection from tcp://172.21.2.253:42420 closed before handshake completed
distributed.comm.tcp - INFO - Connection from tcp://172.21.8.207:42152 closed before handshake completed
distributed.comm.tcp - INFO - Connection from tcp://172.21.6.169:37630 closed before handshake completed
distributed.comm.tcp - INFO - Connection from tcp://172.21.6.169:37632 closed before handshake completed
distributed.worker - ERROR - Worker stream died during communication: tcp://172.21.2.253:38331
Traceback (most recent call last):
  File "/ccc/work/cont003/gen2224/gen2224/spack/var/spack/environments/gysela-deisa-irene-skl-draft/.spack-env/view/lib/python3.9/site-packages/distributed/comm/tcp.py", line 205, in read
    frames_nbytes = await stream.read_bytes(fmt_size)
asyncio.exceptions.CancelledError

During handling of the above exception, another exception occurred:

Traceback (most recent call last):
  File "/ccc/work/cont003/gen2224/gen2224/spack/var/spack/environments/gysela-deisa-irene-skl-draft/.spack-env/._view/whcr3wyhzgorszy3rfxsphyebtvfpqzk/lib/python3.9/asyncio/tasks.py", line 490, in wait_for
    return fut.result()
asyncio.exceptions.CancelledError

The above exception was the direct cause of the following exception:

Traceback (most recent call last):
  File "/ccc/work/cont003/gen2224/gen2224/spack/var/spack/environments/gysela-deisa-irene-skl-draft/.spack-env/view/lib/python3.9/site-packages/distributed/comm/core.py", line 319, in connect
    handshake = await asyncio.wait_for(comm.read(), time_left())
  File "/ccc/work/cont003/gen2224/gen2224/spack/var/spack/environments/gysela-deisa-irene-skl-draft/.spack-env/._view/whcr3wyhzgorszy3rfxsphyebtvfpqzk/lib/python3.9/asyncio/tasks.py", line 492, in wait_for
    raise exceptions.TimeoutError() from exc
asyncio.exceptions.TimeoutError

The above exception was the direct cause of the following exception:

Traceback (most recent call last):
  File "/ccc/work/cont003/gen2224/gen2224/spack/var/spack/environments/gysela-deisa-irene-skl-draft/.spack-env/view/lib/python3.9/site-packages/distributed/worker.py", line 2878, in gather_dep
    response = await get_data_from_worker(
  File "/ccc/work/cont003/gen2224/gen2224/spack/var/spack/environments/gysela-deisa-irene-skl-draft/.spack-env/view/lib/python3.9/site-packages/distributed/worker.py", line 4143, in get_data_from_worker
    return await retry_operation(_get_data, operation="get_data_from_worker")
  File "/ccc/work/cont003/gen2224/gen2224/spack/var/spack/environments/gysela-deisa-irene-skl-draft/.spack-env/view/lib/python3.9/site-packages/distributed/utils_comm.py", line 366, in retry_operation
    return await retry(
  File "/ccc/work/cont003/gen2224/gen2224/spack/var/spack/environments/gysela-deisa-irene-skl-draft/.spack-env/view/lib/python3.9/site-packages/distributed/utils_comm.py", line 351, in retry
    return await coro()
  File "/ccc/work/cont003/gen2224/gen2224/spack/var/spack/environments/gysela-deisa-irene-skl-draft/.spack-env/view/lib/python3.9/site-packages/distributed/worker.py", line 4120, in _get_data
    comm = await rpc.connect(worker)
  File "/ccc/work/cont003/gen2224/gen2224/spack/var/spack/environments/gysela-deisa-irene-skl-draft/.spack-env/view/lib/python3.9/site-packages/distributed/core.py", line 1081, in connect
    raise exc
  File "/ccc/work/cont003/gen2224/gen2224/spack/var/spack/environments/gysela-deisa-irene-skl-draft/.spack-env/view/lib/python3.9/site-packages/distributed/core.py", line 1065, in connect
    comm = await fut
  File "/ccc/work/cont003/gen2224/gen2224/spack/var/spack/environments/gysela-deisa-irene-skl-draft/.spack-env/view/lib/python3.9/site-packages/distributed/comm/core.py", line 324, in connect
    raise OSError(
OSError: Timed out during handshake while connecting to tcp://172.21.2.253:38331 after 30 s
distributed.worker - ERROR - Worker stream died during communication: tcp://172.21.8.207:37278
Traceback (most recent call last):
  File "/ccc/work/cont003/gen2224/gen2224/spack/var/spack/environments/gysela-deisa-irene-skl-draft/.spack-env/view/lib/python3.9/site-packages/distributed/comm/tcp.py", line 205, in read
    frames_nbytes = await stream.read_bytes(fmt_size)
asyncio.exceptions.CancelledError

During handling of the above exception, another exception occurred:

Traceback (most recent call last):
  File "/ccc/work/cont003/gen2224/gen2224/spack/var/spack/environments/gysela-deisa-irene-skl-draft/.spack-env/._view/whcr3wyhzgorszy3rfxsphyebtvfpqzk/lib/python3.9/asyncio/tasks.py", line 490, in wait_for
    return fut.result()
asyncio.exceptions.CancelledError

The above exception was the direct cause of the following exception:

Traceback (most recent call last):
  File "/ccc/work/cont003/gen2224/gen2224/spack/var/spack/environments/gysela-deisa-irene-skl-draft/.spack-env/view/lib/python3.9/site-packages/distributed/comm/core.py", line 319, in connect
    handshake = await asyncio.wait_for(comm.read(), time_left())
  File "/ccc/work/cont003/gen2224/gen2224/spack/var/spack/environments/gysela-deisa-irene-skl-draft/.spack-env/._view/whcr3wyhzgorszy3rfxsphyebtvfpqzk/lib/python3.9/asyncio/tasks.py", line 492, in wait_for
    raise exceptions.TimeoutError() from exc
asyncio.exceptions.TimeoutError

The above exception was the direct cause of the following exception:

Traceback (most recent call last):
  File "/ccc/work/cont003/gen2224/gen2224/spack/var/spack/environments/gysela-deisa-irene-skl-draft/.spack-env/view/lib/python3.9/site-packages/distributed/worker.py", line 2878, in gather_dep
    response = await get_data_from_worker(
  File "/ccc/work/cont003/gen2224/gen2224/spack/var/spack/environments/gysela-deisa-irene-skl-draft/.spack-env/view/lib/python3.9/site-packages/distributed/worker.py", line 4143, in get_data_from_worker
    return await retry_operation(_get_data, operation="get_data_from_worker")
  File "/ccc/work/cont003/gen2224/gen2224/spack/var/spack/environments/gysela-deisa-irene-skl-draft/.spack-env/view/lib/python3.9/site-packages/distributed/utils_comm.py", line 366, in retry_operation
    return await retry(
  File "/ccc/work/cont003/gen2224/gen2224/spack/var/spack/environments/gysela-deisa-irene-skl-draft/.spack-env/view/lib/python3.9/site-packages/distributed/utils_comm.py", line 351, in retry
    return await coro()
  File "/ccc/work/cont003/gen2224/gen2224/spack/var/spack/environments/gysela-deisa-irene-skl-draft/.spack-env/view/lib/python3.9/site-packages/distributed/worker.py", line 4120, in _get_data
    comm = await rpc.connect(worker)
  File "/ccc/work/cont003/gen2224/gen2224/spack/var/spack/environments/gysela-deisa-irene-skl-draft/.spack-env/view/lib/python3.9/site-packages/distributed/core.py", line 1081, in connect
    raise exc
  File "/ccc/work/cont003/gen2224/gen2224/spack/var/spack/environments/gysela-deisa-irene-skl-draft/.spack-env/view/lib/python3.9/site-packages/distributed/core.py", line 1065, in connect
    comm = await fut
  File "/ccc/work/cont003/gen2224/gen2224/spack/var/spack/environments/gysela-deisa-irene-skl-draft/.spack-env/view/lib/python3.9/site-packages/distributed/comm/core.py", line 324, in connect
    raise OSError(
OSError: Timed out during handshake while connecting to tcp://172.21.8.207:37278 after 30 s
distributed.worker - ERROR - Worker stream died during communication: tcp://172.21.6.171:42111
Traceback (most recent call last):
  File "/ccc/work/cont003/gen2224/gen2224/spack/var/spack/environments/gysela-deisa-irene-skl-draft/.spack-env/view/lib/python3.9/site-packages/distributed/comm/tcp.py", line 205, in read
    frames_nbytes = await stream.read_bytes(fmt_size)
asyncio.exceptions.CancelledError

During handling of the above exception, another exception occurred:

Traceback (most recent call last):
  File "/ccc/work/cont003/gen2224/gen2224/spack/var/spack/environments/gysela-deisa-irene-skl-draft/.spack-env/._view/whcr3wyhzgorszy3rfxsphyebtvfpqzk/lib/python3.9/asyncio/tasks.py", line 490, in wait_for
    return fut.result()
asyncio.exceptions.CancelledError

The above exception was the direct cause of the following exception:

Traceback (most recent call last):
  File "/ccc/work/cont003/gen2224/gen2224/spack/var/spack/environments/gysela-deisa-irene-skl-draft/.spack-env/view/lib/python3.9/site-packages/distributed/comm/core.py", line 319, in connect
    handshake = await asyncio.wait_for(comm.read(), time_left())
  File "/ccc/work/cont003/gen2224/gen2224/spack/var/spack/environments/gysela-deisa-irene-skl-draft/.spack-env/._view/whcr3wyhzgorszy3rfxsphyebtvfpqzk/lib/python3.9/asyncio/tasks.py", line 492, in wait_for
    raise exceptions.TimeoutError() from exc
asyncio.exceptions.TimeoutError

The above exception was the direct cause of the following exception:

Traceback (most recent call last):
  File "/ccc/work/cont003/gen2224/gen2224/spack/var/spack/environments/gysela-deisa-irene-skl-draft/.spack-env/view/lib/python3.9/site-packages/distributed/worker.py", line 2878, in gather_dep
    response = await get_data_from_worker(
  File "/ccc/work/cont003/gen2224/gen2224/spack/var/spack/environments/gysela-deisa-irene-skl-draft/.spack-env/view/lib/python3.9/site-packages/distributed/worker.py", line 4143, in get_data_from_worker
    return await retry_operation(_get_data, operation="get_data_from_worker")
  File "/ccc/work/cont003/gen2224/gen2224/spack/var/spack/environments/gysela-deisa-irene-skl-draft/.spack-env/view/lib/python3.9/site-packages/distributed/utils_comm.py", line 366, in retry_operation
    return await retry(
  File "/ccc/work/cont003/gen2224/gen2224/spack/var/spack/environments/gysela-deisa-irene-skl-draft/.spack-env/view/lib/python3.9/site-packages/distributed/utils_comm.py", line 351, in retry
    return await coro()
  File "/ccc/work/cont003/gen2224/gen2224/spack/var/spack/environments/gysela-deisa-irene-skl-draft/.spack-env/view/lib/python3.9/site-packages/distributed/worker.py", line 4120, in _get_data
    comm = await rpc.connect(worker)
  File "/ccc/work/cont003/gen2224/gen2224/spack/var/spack/environments/gysela-deisa-irene-skl-draft/.spack-env/view/lib/python3.9/site-packages/distributed/core.py", line 1081, in connect
    raise exc
  File "/ccc/work/cont003/gen2224/gen2224/spack/var/spack/environments/gysela-deisa-irene-skl-draft/.spack-env/view/lib/python3.9/site-packages/distributed/core.py", line 1065, in connect
    comm = await fut
  File "/ccc/work/cont003/gen2224/gen2224/spack/var/spack/environments/gysela-deisa-irene-skl-draft/.spack-env/view/lib/python3.9/site-packages/distributed/comm/core.py", line 324, in connect
    raise OSError(
OSError: Timed out during handshake while connecting to tcp://172.21.6.171:42111 after 30 s
distributed.worker - ERROR - Worker stream died during communication: tcp://172.21.6.167:39784
Traceback (most recent call last):
  File "/ccc/work/cont003/gen2224/gen2224/spack/var/spack/environments/gysela-deisa-irene-skl-draft/.spack-env/view/lib/python3.9/site-packages/distributed/comm/tcp.py", line 205, in read
    frames_nbytes = await stream.read_bytes(fmt_size)
asyncio.exceptions.CancelledError

During handling of the above exception, another exception occurred:

Traceback (most recent call last):
  File "/ccc/work/cont003/gen2224/gen2224/spack/var/spack/environments/gysela-deisa-irene-skl-draft/.spack-env/._view/whcr3wyhzgorszy3rfxsphyebtvfpqzk/lib/python3.9/asyncio/tasks.py", line 490, in wait_for
    return fut.result()
asyncio.exceptions.CancelledError

The above exception was the direct cause of the following exception:

Traceback (most recent call last):
  File "/ccc/work/cont003/gen2224/gen2224/spack/var/spack/environments/gysela-deisa-irene-skl-draft/.spack-env/view/lib/python3.9/site-packages/distributed/comm/core.py", line 319, in connect
    handshake = await asyncio.wait_for(comm.read(), time_left())
  File "/ccc/work/cont003/gen2224/gen2224/spack/var/spack/environments/gysela-deisa-irene-skl-draft/.spack-env/._view/whcr3wyhzgorszy3rfxsphyebtvfpqzk/lib/python3.9/asyncio/tasks.py", line 492, in wait_for
    raise exceptions.TimeoutError() from exc
asyncio.exceptions.TimeoutError

The above exception was the direct cause of the following exception:

Traceback (most recent call last):
  File "/ccc/work/cont003/gen2224/gen2224/spack/var/spack/environments/gysela-deisa-irene-skl-draft/.spack-env/view/lib/python3.9/site-packages/distributed/worker.py", line 2878, in gather_dep
    response = await get_data_from_worker(
  File "/ccc/work/cont003/gen2224/gen2224/spack/var/spack/environments/gysela-deisa-irene-skl-draft/.spack-env/view/lib/python3.9/site-packages/distributed/worker.py", line 4143, in get_data_from_worker
    return await retry_operation(_get_data, operation="get_data_from_worker")
  File "/ccc/work/cont003/gen2224/gen2224/spack/var/spack/environments/gysela-deisa-irene-skl-draft/.spack-env/view/lib/python3.9/site-packages/distributed/utils_comm.py", line 366, in retry_operation
    return await retry(
  File "/ccc/work/cont003/gen2224/gen2224/spack/var/spack/environments/gysela-deisa-irene-skl-draft/.spack-env/view/lib/python3.9/site-packages/distributed/utils_comm.py", line 351, in retry
    return await coro()
  File "/ccc/work/cont003/gen2224/gen2224/spack/var/spack/environments/gysela-deisa-irene-skl-draft/.spack-env/view/lib/python3.9/site-packages/distributed/worker.py", line 4120, in _get_data
    comm = await rpc.connect(worker)
  File "/ccc/work/cont003/gen2224/gen2224/spack/var/spack/environments/gysela-deisa-irene-skl-draft/.spack-env/view/lib/python3.9/site-packages/distributed/core.py", line 1081, in connect
    raise exc
  File "/ccc/work/cont003/gen2224/gen2224/spack/var/spack/environments/gysela-deisa-irene-skl-draft/.spack-env/view/lib/python3.9/site-packages/distributed/core.py", line 1065, in connect
    comm = await fut
  File "/ccc/work/cont003/gen2224/gen2224/spack/var/spack/environments/gysela-deisa-irene-skl-draft/.spack-env/view/lib/python3.9/site-packages/distributed/comm/core.py", line 324, in connect
    raise OSError(
OSError: Timed out during handshake while connecting to tcp://172.21.6.167:39784 after 30 s
distributed.core - INFO - Event loop was unresponsive in Worker for 321.63s.  This is often caused by long-running GIL-holding functions or moving large chunks of data. This can cause timeouts and instability.
distributed.comm.tcp - INFO - Connection from tcp://172.21.6.169:45858 closed before handshake completed
distributed.comm.tcp - INFO - Connection from tcp://172.21.6.169:45856 closed before handshake completed
distributed.comm.tcp - INFO - Connection from tcp://172.21.6.171:44388 closed before handshake completed
distributed.comm.tcp - INFO - Connection from tcp://172.21.6.171:44386 closed before handshake completed
distributed.comm.tcp - INFO - Connection from tcp://172.21.7.155:43396 closed before handshake completed
distributed.comm.tcp - INFO - Connection from tcp://172.21.8.207:45958 closed before handshake completed
distributed.comm.tcp - INFO - Connection from tcp://172.21.8.207:45960 closed before handshake completed
distributed.comm.tcp - INFO - Connection from tcp://172.21.10.168:48746 closed before handshake completed
distributed.comm.tcp - INFO - Connection from tcp://172.21.7.155:43398 closed before handshake completed
distributed.comm.tcp - INFO - Connection from tcp://172.21.6.170:55480 closed before handshake completed
distributed.core - INFO - Event loop was unresponsive in Worker for 244.99s.  This is often caused by long-running GIL-holding functions or moving large chunks of data. This can cause timeouts and instability.
distributed.comm.tcp - INFO - Connection from tcp://172.21.6.170:53862 closed before handshake completed
distributed.core - INFO - Event loop was unresponsive in Worker for 334.13s.  This is often caused by long-running GIL-holding functions or moving large chunks of data. This can cause timeouts and instability.
distributed.comm.tcp - INFO - Connection from tcp://172.21.6.170:41186 closed before handshake completed
distributed.comm.tcp - INFO - Connection from tcp://172.21.6.169:34734 closed before handshake completed
distributed.comm.tcp - INFO - Connection from tcp://172.21.6.169:34736 closed before handshake completed
distributed.comm.tcp - INFO - Connection from tcp://172.21.6.171:52990 closed before handshake completed
distributed.comm.tcp - INFO - Connection from tcp://172.21.6.171:52992 closed before handshake completed
distributed.comm.tcp - INFO - Connection from tcp://172.21.6.170:41224 closed before handshake completed
distributed.core - INFO - Event loop was unresponsive in Worker for 361.34s.  This is often caused by long-running GIL-holding functions or moving large chunks of data. This can cause timeouts and instability.
distributed.comm.tcp - INFO - Connection from tcp://172.21.6.171:41548 closed before handshake completed
distributed.comm.tcp - INFO - Connection from tcp://172.21.6.170:53148 closed before handshake completed
distributed.worker - ERROR - Worker stream died during communication: tcp://172.21.10.168:46741
Traceback (most recent call last):
  File "/ccc/work/cont003/gen2224/gen2224/spack/var/spack/environments/gysela-deisa-irene-skl-draft/.spack-env/view/lib/python3.9/site-packages/distributed/comm/tcp.py", line 205, in read
    frames_nbytes = await stream.read_bytes(fmt_size)
asyncio.exceptions.CancelledError

During handling of the above exception, another exception occurred:

Traceback (most recent call last):
  File "/ccc/work/cont003/gen2224/gen2224/spack/var/spack/environments/gysela-deisa-irene-skl-draft/.spack-env/._view/whcr3wyhzgorszy3rfxsphyebtvfpqzk/lib/python3.9/asyncio/tasks.py", line 490, in wait_for
    return fut.result()
asyncio.exceptions.CancelledError

The above exception was the direct cause of the following exception:

Traceback (most recent call last):
  File "/ccc/work/cont003/gen2224/gen2224/spack/var/spack/environments/gysela-deisa-irene-skl-draft/.spack-env/view/lib/python3.9/site-packages/distributed/comm/core.py", line 319, in connect
    handshake = await asyncio.wait_for(comm.read(), time_left())
  File "/ccc/work/cont003/gen2224/gen2224/spack/var/spack/environments/gysela-deisa-irene-skl-draft/.spack-env/._view/whcr3wyhzgorszy3rfxsphyebtvfpqzk/lib/python3.9/asyncio/tasks.py", line 492, in wait_for
    raise exceptions.TimeoutError() from exc
asyncio.exceptions.TimeoutError

The above exception was the direct cause of the following exception:

Traceback (most recent call last):
  File "/ccc/work/cont003/gen2224/gen2224/spack/var/spack/environments/gysela-deisa-irene-skl-draft/.spack-env/view/lib/python3.9/site-packages/distributed/worker.py", line 2878, in gather_dep
    response = await get_data_from_worker(
  File "/ccc/work/cont003/gen2224/gen2224/spack/var/spack/environments/gysela-deisa-irene-skl-draft/.spack-env/view/lib/python3.9/site-packages/distributed/worker.py", line 4143, in get_data_from_worker
    return await retry_operation(_get_data, operation="get_data_from_worker")
  File "/ccc/work/cont003/gen2224/gen2224/spack/var/spack/environments/gysela-deisa-irene-skl-draft/.spack-env/view/lib/python3.9/site-packages/distributed/utils_comm.py", line 366, in retry_operation
    return await retry(
  File "/ccc/work/cont003/gen2224/gen2224/spack/var/spack/environments/gysela-deisa-irene-skl-draft/.spack-env/view/lib/python3.9/site-packages/distributed/utils_comm.py", line 351, in retry
    return await coro()
  File "/ccc/work/cont003/gen2224/gen2224/spack/var/spack/environments/gysela-deisa-irene-skl-draft/.spack-env/view/lib/python3.9/site-packages/distributed/worker.py", line 4120, in _get_data
    comm = await rpc.connect(worker)
  File "/ccc/work/cont003/gen2224/gen2224/spack/var/spack/environments/gysela-deisa-irene-skl-draft/.spack-env/view/lib/python3.9/site-packages/distributed/core.py", line 1081, in connect
    raise exc
  File "/ccc/work/cont003/gen2224/gen2224/spack/var/spack/environments/gysela-deisa-irene-skl-draft/.spack-env/view/lib/python3.9/site-packages/distributed/core.py", line 1065, in connect
    comm = await fut
  File "/ccc/work/cont003/gen2224/gen2224/spack/var/spack/environments/gysela-deisa-irene-skl-draft/.spack-env/view/lib/python3.9/site-packages/distributed/comm/core.py", line 324, in connect
    raise OSError(
OSError: Timed out during handshake while connecting to tcp://172.21.10.168:46741 after 30 s
distributed.worker - ERROR - Worker stream died during communication: tcp://172.21.10.168:46741
Traceback (most recent call last):
  File "/ccc/work/cont003/gen2224/gen2224/spack/var/spack/environments/gysela-deisa-irene-skl-draft/.spack-env/view/lib/python3.9/site-packages/distributed/comm/tcp.py", line 205, in read
    frames_nbytes = await stream.read_bytes(fmt_size)
asyncio.exceptions.CancelledError

During handling of the above exception, another exception occurred:

Traceback (most recent call last):
  File "/ccc/work/cont003/gen2224/gen2224/spack/var/spack/environments/gysela-deisa-irene-skl-draft/.spack-env/._view/whcr3wyhzgorszy3rfxsphyebtvfpqzk/lib/python3.9/asyncio/tasks.py", line 490, in wait_for
    return fut.result()
asyncio.exceptions.CancelledError

The above exception was the direct cause of the following exception:

Traceback (most recent call last):
  File "/ccc/work/cont003/gen2224/gen2224/spack/var/spack/environments/gysela-deisa-irene-skl-draft/.spack-env/view/lib/python3.9/site-packages/distributed/comm/core.py", line 319, in connect
    handshake = await asyncio.wait_for(comm.read(), time_left())
  File "/ccc/work/cont003/gen2224/gen2224/spack/var/spack/environments/gysela-deisa-irene-skl-draft/.spack-env/._view/whcr3wyhzgorszy3rfxsphyebtvfpqzk/lib/python3.9/asyncio/tasks.py", line 492, in wait_for
    raise exceptions.TimeoutError() from exc
asyncio.exceptions.TimeoutError

The above exception was the direct cause of the following exception:

Traceback (most recent call last):
  File "/ccc/work/cont003/gen2224/gen2224/spack/var/spack/environments/gysela-deisa-irene-skl-draft/.spack-env/view/lib/python3.9/site-packages/distributed/worker.py", line 2878, in gather_dep
    response = await get_data_from_worker(
  File "/ccc/work/cont003/gen2224/gen2224/spack/var/spack/environments/gysela-deisa-irene-skl-draft/.spack-env/view/lib/python3.9/site-packages/distributed/worker.py", line 4143, in get_data_from_worker
    return await retry_operation(_get_data, operation="get_data_from_worker")
  File "/ccc/work/cont003/gen2224/gen2224/spack/var/spack/environments/gysela-deisa-irene-skl-draft/.spack-env/view/lib/python3.9/site-packages/distributed/utils_comm.py", line 366, in retry_operation
    return await retry(
  File "/ccc/work/cont003/gen2224/gen2224/spack/var/spack/environments/gysela-deisa-irene-skl-draft/.spack-env/view/lib/python3.9/site-packages/distributed/utils_comm.py", line 351, in retry
    return await coro()
  File "/ccc/work/cont003/gen2224/gen2224/spack/var/spack/environments/gysela-deisa-irene-skl-draft/.spack-env/view/lib/python3.9/site-packages/distributed/worker.py", line 4120, in _get_data
    comm = await rpc.connect(worker)
  File "/ccc/work/cont003/gen2224/gen2224/spack/var/spack/environments/gysela-deisa-irene-skl-draft/.spack-env/view/lib/python3.9/site-packages/distributed/core.py", line 1081, in connect
    raise exc
  File "/ccc/work/cont003/gen2224/gen2224/spack/var/spack/environments/gysela-deisa-irene-skl-draft/.spack-env/view/lib/python3.9/site-packages/distributed/core.py", line 1065, in connect
    comm = await fut
  File "/ccc/work/cont003/gen2224/gen2224/spack/var/spack/environments/gysela-deisa-irene-skl-draft/.spack-env/view/lib/python3.9/site-packages/distributed/comm/core.py", line 324, in connect
    raise OSError(
OSError: Timed out during handshake while connecting to tcp://172.21.10.168:46741 after 30 s
distributed.core - INFO - Event loop was unresponsive in Worker for 299.29s.  This is often caused by long-running GIL-holding functions or moving large chunks of data. This can cause timeouts and instability.
distributed.core - INFO - Event loop was unresponsive in Worker for 341.82s.  This is often caused by long-running GIL-holding functions or moving large chunks of data. This can cause timeouts and instability.
distributed.worker - ERROR - Worker stream died during communication: tcp://172.21.10.168:46741
Traceback (most recent call last):
  File "/ccc/work/cont003/gen2224/gen2224/spack/var/spack/environments/gysela-deisa-irene-skl-draft/.spack-env/view/lib/python3.9/site-packages/distributed/comm/tcp.py", line 205, in read
    frames_nbytes = await stream.read_bytes(fmt_size)
asyncio.exceptions.CancelledError

During handling of the above exception, another exception occurred:

Traceback (most recent call last):
  File "/ccc/work/cont003/gen2224/gen2224/spack/var/spack/environments/gysela-deisa-irene-skl-draft/.spack-env/._view/whcr3wyhzgorszy3rfxsphyebtvfpqzk/lib/python3.9/asyncio/tasks.py", line 490, in wait_for
    return fut.result()
asyncio.exceptions.CancelledError

The above exception was the direct cause of the following exception:

Traceback (most recent call last):
  File "/ccc/work/cont003/gen2224/gen2224/spack/var/spack/environments/gysela-deisa-irene-skl-draft/.spack-env/view/lib/python3.9/site-packages/distributed/comm/core.py", line 319, in connect
    handshake = await asyncio.wait_for(comm.read(), time_left())
  File "/ccc/work/cont003/gen2224/gen2224/spack/var/spack/environments/gysela-deisa-irene-skl-draft/.spack-env/._view/whcr3wyhzgorszy3rfxsphyebtvfpqzk/lib/python3.9/asyncio/tasks.py", line 492, in wait_for
    raise exceptions.TimeoutError() from exc
asyncio.exceptions.TimeoutError

The above exception was the direct cause of the following exception:

Traceback (most recent call last):
  File "/ccc/work/cont003/gen2224/gen2224/spack/var/spack/environments/gysela-deisa-irene-skl-draft/.spack-env/view/lib/python3.9/site-packages/distributed/worker.py", line 2878, in gather_dep
    response = await get_data_from_worker(
  File "/ccc/work/cont003/gen2224/gen2224/spack/var/spack/environments/gysela-deisa-irene-skl-draft/.spack-env/view/lib/python3.9/site-packages/distributed/worker.py", line 4143, in get_data_from_worker
    return await retry_operation(_get_data, operation="get_data_from_worker")
  File "/ccc/work/cont003/gen2224/gen2224/spack/var/spack/environments/gysela-deisa-irene-skl-draft/.spack-env/view/lib/python3.9/site-packages/distributed/utils_comm.py", line 366, in retry_operation
    return await retry(
  File "/ccc/work/cont003/gen2224/gen2224/spack/var/spack/environments/gysela-deisa-irene-skl-draft/.spack-env/view/lib/python3.9/site-packages/distributed/utils_comm.py", line 351, in retry
    return await coro()
  File "/ccc/work/cont003/gen2224/gen2224/spack/var/spack/environments/gysela-deisa-irene-skl-draft/.spack-env/view/lib/python3.9/site-packages/distributed/worker.py", line 4120, in _get_data
    comm = await rpc.connect(worker)
  File "/ccc/work/cont003/gen2224/gen2224/spack/var/spack/environments/gysela-deisa-irene-skl-draft/.spack-env/view/lib/python3.9/site-packages/distributed/core.py", line 1081, in connect
    raise exc
  File "/ccc/work/cont003/gen2224/gen2224/spack/var/spack/environments/gysela-deisa-irene-skl-draft/.spack-env/view/lib/python3.9/site-packages/distributed/core.py", line 1065, in connect
    comm = await fut
  File "/ccc/work/cont003/gen2224/gen2224/spack/var/spack/environments/gysela-deisa-irene-skl-draft/.spack-env/view/lib/python3.9/site-packages/distributed/comm/core.py", line 324, in connect
    raise OSError(
OSError: Timed out during handshake while connecting to tcp://172.21.10.168:46741 after 30 s
distributed.worker - ERROR - Worker stream died during communication: tcp://172.21.10.168:46741
Traceback (most recent call last):
  File "/ccc/work/cont003/gen2224/gen2224/spack/var/spack/environments/gysela-deisa-irene-skl-draft/.spack-env/view/lib/python3.9/site-packages/distributed/comm/tcp.py", line 205, in read
    frames_nbytes = await stream.read_bytes(fmt_size)
asyncio.exceptions.CancelledError

During handling of the above exception, another exception occurred:

Traceback (most recent call last):
  File "/ccc/work/cont003/gen2224/gen2224/spack/var/spack/environments/gysela-deisa-irene-skl-draft/.spack-env/._view/whcr3wyhzgorszy3rfxsphyebtvfpqzk/lib/python3.9/asyncio/tasks.py", line 490, in wait_for
    return fut.result()
asyncio.exceptions.CancelledError

The above exception was the direct cause of the following exception:

Traceback (most recent call last):
  File "/ccc/work/cont003/gen2224/gen2224/spack/var/spack/environments/gysela-deisa-irene-skl-draft/.spack-env/view/lib/python3.9/site-packages/distributed/comm/core.py", line 319, in connect
    handshake = await asyncio.wait_for(comm.read(), time_left())
  File "/ccc/work/cont003/gen2224/gen2224/spack/var/spack/environments/gysela-deisa-irene-skl-draft/.spack-env/._view/whcr3wyhzgorszy3rfxsphyebtvfpqzk/lib/python3.9/asyncio/tasks.py", line 492, in wait_for
    raise exceptions.TimeoutError() from exc
asyncio.exceptions.TimeoutError

The above exception was the direct cause of the following exception:

Traceback (most recent call last):
  File "/ccc/work/cont003/gen2224/gen2224/spack/var/spack/environments/gysela-deisa-irene-skl-draft/.spack-env/view/lib/python3.9/site-packages/distributed/worker.py", line 2878, in gather_dep
    response = await get_data_from_worker(
  File "/ccc/work/cont003/gen2224/gen2224/spack/var/spack/environments/gysela-deisa-irene-skl-draft/.spack-env/view/lib/python3.9/site-packages/distributed/worker.py", line 4143, in get_data_from_worker
    return await retry_operation(_get_data, operation="get_data_from_worker")
  File "/ccc/work/cont003/gen2224/gen2224/spack/var/spack/environments/gysela-deisa-irene-skl-draft/.spack-env/view/lib/python3.9/site-packages/distributed/utils_comm.py", line 366, in retry_operation
    return await retry(
  File "/ccc/work/cont003/gen2224/gen2224/spack/var/spack/environments/gysela-deisa-irene-skl-draft/.spack-env/view/lib/python3.9/site-packages/distributed/utils_comm.py", line 351, in retry
    return await coro()
  File "/ccc/work/cont003/gen2224/gen2224/spack/var/spack/environments/gysela-deisa-irene-skl-draft/.spack-env/view/lib/python3.9/site-packages/distributed/worker.py", line 4120, in _get_data
    comm = await rpc.connect(worker)
  File "/ccc/work/cont003/gen2224/gen2224/spack/var/spack/environments/gysela-deisa-irene-skl-draft/.spack-env/view/lib/python3.9/site-packages/distributed/core.py", line 1081, in connect
    raise exc
  File "/ccc/work/cont003/gen2224/gen2224/spack/var/spack/environments/gysela-deisa-irene-skl-draft/.spack-env/view/lib/python3.9/site-packages/distributed/core.py", line 1065, in connect
    comm = await fut
  File "/ccc/work/cont003/gen2224/gen2224/spack/var/spack/environments/gysela-deisa-irene-skl-draft/.spack-env/view/lib/python3.9/site-packages/distributed/comm/core.py", line 324, in connect
    raise OSError(
OSError: Timed out during handshake while connecting to tcp://172.21.10.168:46741 after 30 s
distributed.core - INFO - Event loop was unresponsive in Worker for 371.08s.  This is often caused by long-running GIL-holding functions or moving large chunks of data. This can cause timeouts and instability.
distributed.comm.tcp - INFO - Connection from tcp://172.21.10.168:59534 closed before handshake completed
distributed.comm.tcp - INFO - Connection from tcp://172.21.10.168:59540 closed before handshake completed
distributed.comm.tcp - INFO - Connection from tcp://172.21.6.167:59484 closed before handshake completed
distributed.comm.tcp - INFO - Connection from tcp://172.21.6.167:59508 closed before handshake completed
distributed.core - INFO - Event loop was unresponsive in Worker for 382.35s.  This is often caused by long-running GIL-holding functions or moving large chunks of data. This can cause timeouts and instability.
distributed.core - INFO - Event loop was unresponsive in Worker for 350.11s.  This is often caused by long-running GIL-holding functions or moving large chunks of data. This can cause timeouts and instability.
distributed.core - INFO - Event loop was unresponsive in Worker for 427.58s.  This is often caused by long-running GIL-holding functions or moving large chunks of data. This can cause timeouts and instability.
distributed.worker - ERROR - Worker stream died during communication: tcp://172.21.6.171:42111
Traceback (most recent call last):
  File "/ccc/work/cont003/gen2224/gen2224/spack/var/spack/environments/gysela-deisa-irene-skl-draft/.spack-env/view/lib/python3.9/site-packages/distributed/comm/tcp.py", line 205, in read
    frames_nbytes = await stream.read_bytes(fmt_size)
asyncio.exceptions.CancelledError

During handling of the above exception, another exception occurred:

Traceback (most recent call last):
  File "/ccc/work/cont003/gen2224/gen2224/spack/var/spack/environments/gysela-deisa-irene-skl-draft/.spack-env/._view/whcr3wyhzgorszy3rfxsphyebtvfpqzk/lib/python3.9/asyncio/tasks.py", line 490, in wait_for
    return fut.result()
asyncio.exceptions.CancelledError

The above exception was the direct cause of the following exception:

Traceback (most recent call last):
  File "/ccc/work/cont003/gen2224/gen2224/spack/var/spack/environments/gysela-deisa-irene-skl-draft/.spack-env/view/lib/python3.9/site-packages/distributed/comm/core.py", line 319, in connect
    handshake = await asyncio.wait_for(comm.read(), time_left())
  File "/ccc/work/cont003/gen2224/gen2224/spack/var/spack/environments/gysela-deisa-irene-skl-draft/.spack-env/._view/whcr3wyhzgorszy3rfxsphyebtvfpqzk/lib/python3.9/asyncio/tasks.py", line 492, in wait_for
    raise exceptions.TimeoutError() from exc
asyncio.exceptions.TimeoutError

The above exception was the direct cause of the following exception:

Traceback (most recent call last):
  File "/ccc/work/cont003/gen2224/gen2224/spack/var/spack/environments/gysela-deisa-irene-skl-draft/.spack-env/view/lib/python3.9/site-packages/distributed/worker.py", line 2878, in gather_dep
    response = await get_data_from_worker(
  File "/ccc/work/cont003/gen2224/gen2224/spack/var/spack/environments/gysela-deisa-irene-skl-draft/.spack-env/view/lib/python3.9/site-packages/distributed/worker.py", line 4143, in get_data_from_worker
    return await retry_operation(_get_data, operation="get_data_from_worker")
  File "/ccc/work/cont003/gen2224/gen2224/spack/var/spack/environments/gysela-deisa-irene-skl-draft/.spack-env/view/lib/python3.9/site-packages/distributed/utils_comm.py", line 366, in retry_operation
    return await retry(
  File "/ccc/work/cont003/gen2224/gen2224/spack/var/spack/environments/gysela-deisa-irene-skl-draft/.spack-env/view/lib/python3.9/site-packages/distributed/utils_comm.py", line 351, in retry
    return await coro()
  File "/ccc/work/cont003/gen2224/gen2224/spack/var/spack/environments/gysela-deisa-irene-skl-draft/.spack-env/view/lib/python3.9/site-packages/distributed/worker.py", line 4120, in _get_data
    comm = await rpc.connect(worker)
  File "/ccc/work/cont003/gen2224/gen2224/spack/var/spack/environments/gysela-deisa-irene-skl-draft/.spack-env/view/lib/python3.9/site-packages/distributed/core.py", line 1081, in connect
    raise exc
  File "/ccc/work/cont003/gen2224/gen2224/spack/var/spack/environments/gysela-deisa-irene-skl-draft/.spack-env/view/lib/python3.9/site-packages/distributed/core.py", line 1065, in connect
    comm = await fut
  File "/ccc/work/cont003/gen2224/gen2224/spack/var/spack/environments/gysela-deisa-irene-skl-draft/.spack-env/view/lib/python3.9/site-packages/distributed/comm/core.py", line 324, in connect
    raise OSError(
OSError: Timed out during handshake while connecting to tcp://172.21.6.171:42111 after 30 s
distributed.worker - ERROR - Worker stream died during communication: tcp://172.21.6.171:42111
Traceback (most recent call last):
  File "/ccc/work/cont003/gen2224/gen2224/spack/var/spack/environments/gysela-deisa-irene-skl-draft/.spack-env/view/lib/python3.9/site-packages/distributed/comm/tcp.py", line 205, in read
    frames_nbytes = await stream.read_bytes(fmt_size)
asyncio.exceptions.CancelledError

During handling of the above exception, another exception occurred:

Traceback (most recent call last):
  File "/ccc/work/cont003/gen2224/gen2224/spack/var/spack/environments/gysela-deisa-irene-skl-draft/.spack-env/._view/whcr3wyhzgorszy3rfxsphyebtvfpqzk/lib/python3.9/asyncio/tasks.py", line 490, in wait_for
    return fut.result()
asyncio.exceptions.CancelledError

The above exception was the direct cause of the following exception:

Traceback (most recent call last):
  File "/ccc/work/cont003/gen2224/gen2224/spack/var/spack/environments/gysela-deisa-irene-skl-draft/.spack-env/view/lib/python3.9/site-packages/distributed/comm/core.py", line 319, in connect
    handshake = await asyncio.wait_for(comm.read(), time_left())
  File "/ccc/work/cont003/gen2224/gen2224/spack/var/spack/environments/gysela-deisa-irene-skl-draft/.spack-env/._view/whcr3wyhzgorszy3rfxsphyebtvfpqzk/lib/python3.9/asyncio/tasks.py", line 492, in wait_for
    raise exceptions.TimeoutError() from exc
asyncio.exceptions.TimeoutError

The above exception was the direct cause of the following exception:

Traceback (most recent call last):
  File "/ccc/work/cont003/gen2224/gen2224/spack/var/spack/environments/gysela-deisa-irene-skl-draft/.spack-env/view/lib/python3.9/site-packages/distributed/worker.py", line 2878, in gather_dep
    response = await get_data_from_worker(
  File "/ccc/work/cont003/gen2224/gen2224/spack/var/spack/environments/gysela-deisa-irene-skl-draft/.spack-env/view/lib/python3.9/site-packages/distributed/worker.py", line 4143, in get_data_from_worker
    return await retry_operation(_get_data, operation="get_data_from_worker")
  File "/ccc/work/cont003/gen2224/gen2224/spack/var/spack/environments/gysela-deisa-irene-skl-draft/.spack-env/view/lib/python3.9/site-packages/distributed/utils_comm.py", line 366, in retry_operation
    return await retry(
  File "/ccc/work/cont003/gen2224/gen2224/spack/var/spack/environments/gysela-deisa-irene-skl-draft/.spack-env/view/lib/python3.9/site-packages/distributed/utils_comm.py", line 351, in retry
    return await coro()
  File "/ccc/work/cont003/gen2224/gen2224/spack/var/spack/environments/gysela-deisa-irene-skl-draft/.spack-env/view/lib/python3.9/site-packages/distributed/worker.py", line 4120, in _get_data
    comm = await rpc.connect(worker)
  File "/ccc/work/cont003/gen2224/gen2224/spack/var/spack/environments/gysela-deisa-irene-skl-draft/.spack-env/view/lib/python3.9/site-packages/distributed/core.py", line 1081, in connect
    raise exc
  File "/ccc/work/cont003/gen2224/gen2224/spack/var/spack/environments/gysela-deisa-irene-skl-draft/.spack-env/view/lib/python3.9/site-packages/distributed/core.py", line 1065, in connect
    comm = await fut
  File "/ccc/work/cont003/gen2224/gen2224/spack/var/spack/environments/gysela-deisa-irene-skl-draft/.spack-env/view/lib/python3.9/site-packages/distributed/comm/core.py", line 324, in connect
    raise OSError(
OSError: Timed out during handshake while connecting to tcp://172.21.6.171:42111 after 30 s
distributed.worker - ERROR - Worker stream died during communication: tcp://172.21.6.171:42111
Traceback (most recent call last):
  File "/ccc/work/cont003/gen2224/gen2224/spack/var/spack/environments/gysela-deisa-irene-skl-draft/.spack-env/view/lib/python3.9/site-packages/distributed/comm/tcp.py", line 205, in read
    frames_nbytes = await stream.read_bytes(fmt_size)
asyncio.exceptions.CancelledError

During handling of the above exception, another exception occurred:

Traceback (most recent call last):
  File "/ccc/work/cont003/gen2224/gen2224/spack/var/spack/environments/gysela-deisa-irene-skl-draft/.spack-env/._view/whcr3wyhzgorszy3rfxsphyebtvfpqzk/lib/python3.9/asyncio/tasks.py", line 490, in wait_for
    return fut.result()
asyncio.exceptions.CancelledError

The above exception was the direct cause of the following exception:

Traceback (most recent call last):
  File "/ccc/work/cont003/gen2224/gen2224/spack/var/spack/environments/gysela-deisa-irene-skl-draft/.spack-env/view/lib/python3.9/site-packages/distributed/comm/core.py", line 319, in connect
    handshake = await asyncio.wait_for(comm.read(), time_left())
  File "/ccc/work/cont003/gen2224/gen2224/spack/var/spack/environments/gysela-deisa-irene-skl-draft/.spack-env/._view/whcr3wyhzgorszy3rfxsphyebtvfpqzk/lib/python3.9/asyncio/tasks.py", line 492, in wait_for
    raise exceptions.TimeoutError() from exc
asyncio.exceptions.TimeoutError

The above exception was the direct cause of the following exception:

Traceback (most recent call last):
  File "/ccc/work/cont003/gen2224/gen2224/spack/var/spack/environments/gysela-deisa-irene-skl-draft/.spack-env/view/lib/python3.9/site-packages/distributed/worker.py", line 2878, in gather_dep
    response = await get_data_from_worker(
  File "/ccc/work/cont003/gen2224/gen2224/spack/var/spack/environments/gysela-deisa-irene-skl-draft/.spack-env/view/lib/python3.9/site-packages/distributed/worker.py", line 4143, in get_data_from_worker
    return await retry_operation(_get_data, operation="get_data_from_worker")
  File "/ccc/work/cont003/gen2224/gen2224/spack/var/spack/environments/gysela-deisa-irene-skl-draft/.spack-env/view/lib/python3.9/site-packages/distributed/utils_comm.py", line 366, in retry_operation
    return await retry(
  File "/ccc/work/cont003/gen2224/gen2224/spack/var/spack/environments/gysela-deisa-irene-skl-draft/.spack-env/view/lib/python3.9/site-packages/distributed/utils_comm.py", line 351, in retry
    return await coro()
  File "/ccc/work/cont003/gen2224/gen2224/spack/var/spack/environments/gysela-deisa-irene-skl-draft/.spack-env/view/lib/python3.9/site-packages/distributed/worker.py", line 4120, in _get_data
    comm = await rpc.connect(worker)
  File "/ccc/work/cont003/gen2224/gen2224/spack/var/spack/environments/gysela-deisa-irene-skl-draft/.spack-env/view/lib/python3.9/site-packages/distributed/core.py", line 1081, in connect
    raise exc
  File "/ccc/work/cont003/gen2224/gen2224/spack/var/spack/environments/gysela-deisa-irene-skl-draft/.spack-env/view/lib/python3.9/site-packages/distributed/core.py", line 1065, in connect
    comm = await fut
  File "/ccc/work/cont003/gen2224/gen2224/spack/var/spack/environments/gysela-deisa-irene-skl-draft/.spack-env/view/lib/python3.9/site-packages/distributed/comm/core.py", line 324, in connect
    raise OSError(
OSError: Timed out during handshake while connecting to tcp://172.21.6.171:42111 after 30 s
distributed.worker - ERROR - Worker stream died during communication: tcp://172.21.6.171:42111
Traceback (most recent call last):
  File "/ccc/work/cont003/gen2224/gen2224/spack/var/spack/environments/gysela-deisa-irene-skl-draft/.spack-env/view/lib/python3.9/site-packages/distributed/comm/tcp.py", line 205, in read
    frames_nbytes = await stream.read_bytes(fmt_size)
asyncio.exceptions.CancelledError

During handling of the above exception, another exception occurred:

Traceback (most recent call last):
  File "/ccc/work/cont003/gen2224/gen2224/spack/var/spack/environments/gysela-deisa-irene-skl-draft/.spack-env/._view/whcr3wyhzgorszy3rfxsphyebtvfpqzk/lib/python3.9/asyncio/tasks.py", line 490, in wait_for
    return fut.result()
asyncio.exceptions.CancelledError

The above exception was the direct cause of the following exception:

Traceback (most recent call last):
  File "/ccc/work/cont003/gen2224/gen2224/spack/var/spack/environments/gysela-deisa-irene-skl-draft/.spack-env/view/lib/python3.9/site-packages/distributed/comm/core.py", line 319, in connect
    handshake = await asyncio.wait_for(comm.read(), time_left())
  File "/ccc/work/cont003/gen2224/gen2224/spack/var/spack/environments/gysela-deisa-irene-skl-draft/.spack-env/._view/whcr3wyhzgorszy3rfxsphyebtvfpqzk/lib/python3.9/asyncio/tasks.py", line 492, in wait_for
    raise exceptions.TimeoutError() from exc
asyncio.exceptions.TimeoutError

The above exception was the direct cause of the following exception:

Traceback (most recent call last):
  File "/ccc/work/cont003/gen2224/gen2224/spack/var/spack/environments/gysela-deisa-irene-skl-draft/.spack-env/view/lib/python3.9/site-packages/distributed/worker.py", line 2878, in gather_dep
    response = await get_data_from_worker(
  File "/ccc/work/cont003/gen2224/gen2224/spack/var/spack/environments/gysela-deisa-irene-skl-draft/.spack-env/view/lib/python3.9/site-packages/distributed/worker.py", line 4143, in get_data_from_worker
    return await retry_operation(_get_data, operation="get_data_from_worker")
  File "/ccc/work/cont003/gen2224/gen2224/spack/var/spack/environments/gysela-deisa-irene-skl-draft/.spack-env/view/lib/python3.9/site-packages/distributed/utils_comm.py", line 366, in retry_operation
    return await retry(
  File "/ccc/work/cont003/gen2224/gen2224/spack/var/spack/environments/gysela-deisa-irene-skl-draft/.spack-env/view/lib/python3.9/site-packages/distributed/utils_comm.py", line 351, in retry
    return await coro()
  File "/ccc/work/cont003/gen2224/gen2224/spack/var/spack/environments/gysela-deisa-irene-skl-draft/.spack-env/view/lib/python3.9/site-packages/distributed/worker.py", line 4120, in _get_data
    comm = await rpc.connect(worker)
  File "/ccc/work/cont003/gen2224/gen2224/spack/var/spack/environments/gysela-deisa-irene-skl-draft/.spack-env/view/lib/python3.9/site-packages/distributed/core.py", line 1081, in connect
    raise exc
  File "/ccc/work/cont003/gen2224/gen2224/spack/var/spack/environments/gysela-deisa-irene-skl-draft/.spack-env/view/lib/python3.9/site-packages/distributed/core.py", line 1065, in connect
    comm = await fut
  File "/ccc/work/cont003/gen2224/gen2224/spack/var/spack/environments/gysela-deisa-irene-skl-draft/.spack-env/view/lib/python3.9/site-packages/distributed/comm/core.py", line 324, in connect
    raise OSError(
OSError: Timed out during handshake while connecting to tcp://172.21.6.171:42111 after 30 s
distributed.worker - ERROR - Worker stream died during communication: tcp://172.21.6.171:42111
Traceback (most recent call last):
  File "/ccc/work/cont003/gen2224/gen2224/spack/var/spack/environments/gysela-deisa-irene-skl-draft/.spack-env/view/lib/python3.9/site-packages/distributed/comm/tcp.py", line 205, in read
    frames_nbytes = await stream.read_bytes(fmt_size)
asyncio.exceptions.CancelledError

During handling of the above exception, another exception occurred:

Traceback (most recent call last):
  File "/ccc/work/cont003/gen2224/gen2224/spack/var/spack/environments/gysela-deisa-irene-skl-draft/.spack-env/._view/whcr3wyhzgorszy3rfxsphyebtvfpqzk/lib/python3.9/asyncio/tasks.py", line 490, in wait_for
    return fut.result()
asyncio.exceptions.CancelledError

The above exception was the direct cause of the following exception:

Traceback (most recent call last):
  File "/ccc/work/cont003/gen2224/gen2224/spack/var/spack/environments/gysela-deisa-irene-skl-draft/.spack-env/view/lib/python3.9/site-packages/distributed/comm/core.py", line 319, in connect
    handshake = await asyncio.wait_for(comm.read(), time_left())
  File "/ccc/work/cont003/gen2224/gen2224/spack/var/spack/environments/gysela-deisa-irene-skl-draft/.spack-env/._view/whcr3wyhzgorszy3rfxsphyebtvfpqzk/lib/python3.9/asyncio/tasks.py", line 492, in wait_for
    raise exceptions.TimeoutError() from exc
asyncio.exceptions.TimeoutError

The above exception was the direct cause of the following exception:

Traceback (most recent call last):
  File "/ccc/work/cont003/gen2224/gen2224/spack/var/spack/environments/gysela-deisa-irene-skl-draft/.spack-env/view/lib/python3.9/site-packages/distributed/worker.py", line 2878, in gather_dep
    response = await get_data_from_worker(
  File "/ccc/work/cont003/gen2224/gen2224/spack/var/spack/environments/gysela-deisa-irene-skl-draft/.spack-env/view/lib/python3.9/site-packages/distributed/worker.py", line 4143, in get_data_from_worker
    return await retry_operation(_get_data, operation="get_data_from_worker")
  File "/ccc/work/cont003/gen2224/gen2224/spack/var/spack/environments/gysela-deisa-irene-skl-draft/.spack-env/view/lib/python3.9/site-packages/distributed/utils_comm.py", line 366, in retry_operation
    return await retry(
  File "/ccc/work/cont003/gen2224/gen2224/spack/var/spack/environments/gysela-deisa-irene-skl-draft/.spack-env/view/lib/python3.9/site-packages/distributed/utils_comm.py", line 351, in retry
    return await coro()
  File "/ccc/work/cont003/gen2224/gen2224/spack/var/spack/environments/gysela-deisa-irene-skl-draft/.spack-env/view/lib/python3.9/site-packages/distributed/worker.py", line 4120, in _get_data
    comm = await rpc.connect(worker)
  File "/ccc/work/cont003/gen2224/gen2224/spack/var/spack/environments/gysela-deisa-irene-skl-draft/.spack-env/view/lib/python3.9/site-packages/distributed/core.py", line 1081, in connect
    raise exc
  File "/ccc/work/cont003/gen2224/gen2224/spack/var/spack/environments/gysela-deisa-irene-skl-draft/.spack-env/view/lib/python3.9/site-packages/distributed/core.py", line 1065, in connect
    comm = await fut
  File "/ccc/work/cont003/gen2224/gen2224/spack/var/spack/environments/gysela-deisa-irene-skl-draft/.spack-env/view/lib/python3.9/site-packages/distributed/comm/core.py", line 324, in connect
    raise OSError(
OSError: Timed out during handshake while connecting to tcp://172.21.6.171:42111 after 30 s
distributed.core - INFO - Event loop was unresponsive in Worker for 212.91s.  This is often caused by long-running GIL-holding functions or moving large chunks of data. This can cause timeouts and instability.
distributed.worker - ERROR - Worker stream died during communication: tcp://172.21.6.171:42111
Traceback (most recent call last):
  File "/ccc/work/cont003/gen2224/gen2224/spack/var/spack/environments/gysela-deisa-irene-skl-draft/.spack-env/view/lib/python3.9/site-packages/distributed/comm/tcp.py", line 205, in read
    frames_nbytes = await stream.read_bytes(fmt_size)
asyncio.exceptions.CancelledError

During handling of the above exception, another exception occurred:

Traceback (most recent call last):
  File "/ccc/work/cont003/gen2224/gen2224/spack/var/spack/environments/gysela-deisa-irene-skl-draft/.spack-env/._view/whcr3wyhzgorszy3rfxsphyebtvfpqzk/lib/python3.9/asyncio/tasks.py", line 490, in wait_for
    return fut.result()
asyncio.exceptions.CancelledError

The above exception was the direct cause of the following exception:

Traceback (most recent call last):
  File "/ccc/work/cont003/gen2224/gen2224/spack/var/spack/environments/gysela-deisa-irene-skl-draft/.spack-env/view/lib/python3.9/site-packages/distributed/comm/core.py", line 319, in connect
    handshake = await asyncio.wait_for(comm.read(), time_left())
  File "/ccc/work/cont003/gen2224/gen2224/spack/var/spack/environments/gysela-deisa-irene-skl-draft/.spack-env/._view/whcr3wyhzgorszy3rfxsphyebtvfpqzk/lib/python3.9/asyncio/tasks.py", line 492, in wait_for
    raise exceptions.TimeoutError() from exc
asyncio.exceptions.TimeoutError

The above exception was the direct cause of the following exception:

Traceback (most recent call last):
  File "/ccc/work/cont003/gen2224/gen2224/spack/var/spack/environments/gysela-deisa-irene-skl-draft/.spack-env/view/lib/python3.9/site-packages/distributed/worker.py", line 2878, in gather_dep
    response = await get_data_from_worker(
  File "/ccc/work/cont003/gen2224/gen2224/spack/var/spack/environments/gysela-deisa-irene-skl-draft/.spack-env/view/lib/python3.9/site-packages/distributed/worker.py", line 4143, in get_data_from_worker
    return await retry_operation(_get_data, operation="get_data_from_worker")
  File "/ccc/work/cont003/gen2224/gen2224/spack/var/spack/environments/gysela-deisa-irene-skl-draft/.spack-env/view/lib/python3.9/site-packages/distributed/utils_comm.py", line 366, in retry_operation
    return await retry(
  File "/ccc/work/cont003/gen2224/gen2224/spack/var/spack/environments/gysela-deisa-irene-skl-draft/.spack-env/view/lib/python3.9/site-packages/distributed/utils_comm.py", line 351, in retry
    return await coro()
  File "/ccc/work/cont003/gen2224/gen2224/spack/var/spack/environments/gysela-deisa-irene-skl-draft/.spack-env/view/lib/python3.9/site-packages/distributed/worker.py", line 4120, in _get_data
    comm = await rpc.connect(worker)
  File "/ccc/work/cont003/gen2224/gen2224/spack/var/spack/environments/gysela-deisa-irene-skl-draft/.spack-env/view/lib/python3.9/site-packages/distributed/core.py", line 1081, in connect
    raise exc
  File "/ccc/work/cont003/gen2224/gen2224/spack/var/spack/environments/gysela-deisa-irene-skl-draft/.spack-env/view/lib/python3.9/site-packages/distributed/core.py", line 1065, in connect
    comm = await fut
  File "/ccc/work/cont003/gen2224/gen2224/spack/var/spack/environments/gysela-deisa-irene-skl-draft/.spack-env/view/lib/python3.9/site-packages/distributed/comm/core.py", line 324, in connect
    raise OSError(
OSError: Timed out during handshake while connecting to tcp://172.21.6.171:42111 after 30 s
distributed.core - INFO - Event loop was unresponsive in Worker for 134.62s.  This is often caused by long-running GIL-holding functions or moving large chunks of data. This can cause timeouts and instability.
distributed.comm.tcp - INFO - Connection from tcp://172.21.7.155:35898 closed before handshake completed
distributed.comm.tcp - INFO - Connection from tcp://172.21.7.155:35918 closed before handshake completed
distributed.comm.tcp - INFO - Connection from tcp://172.21.7.155:35924 closed before handshake completed
distributed.comm.tcp - INFO - Connection from tcp://172.21.7.155:35930 closed before handshake completed
distributed.comm.tcp - INFO - Connection from tcp://172.21.10.168:46022 closed before handshake completed
distributed.comm.tcp - INFO - Connection from tcp://172.21.7.155:35954 closed before handshake completed
distributed.worker - INFO - Stopping worker at tcp://172.21.10.168:46741
distributed.worker - INFO - Stopping worker at tcp://172.21.10.168:37139
distributed.worker - INFO - Stopping worker at tcp://172.21.6.167:35094
distributed.worker - INFO - Stopping worker at tcp://172.21.6.170:43319
distributed.worker - INFO - Stopping worker at tcp://172.21.6.167:39784
distributed.worker - INFO - Stopping worker at tcp://172.21.6.171:43075
distributed.worker - INFO - Stopping worker at tcp://172.21.6.170:36855
distributed.worker - INFO - Stopping worker at tcp://172.21.6.169:35439
distributed.worker - INFO - Stopping worker at tcp://172.21.6.171:42111
distributed.worker - INFO - Stopping worker at tcp://172.21.7.155:40508
distributed.worker - INFO - Stopping worker at tcp://172.21.8.207:37278
distributed.worker - INFO - Stopping worker at tcp://172.21.7.155:35480
distributed.worker - INFO - Stopping worker at tcp://172.21.2.253:38331
distributed.worker - INFO - Stopping worker at tcp://172.21.6.169:35588
distributed.worker - INFO - Stopping worker at tcp://172.21.2.253:39862
distributed.worker - INFO - Stopping worker at tcp://172.21.8.207:44983
distributed.nanny - INFO -         Start Nanny at: 'tcp://172.21.6.171:41394'
distributed.nanny - INFO -         Start Nanny at: 'tcp://172.21.6.171:45033'
distributed.nanny - INFO -         Start Nanny at: 'tcp://172.21.7.155:38421'
distributed.nanny - INFO -         Start Nanny at: 'tcp://172.21.7.155:44022'
distributed.nanny - INFO -         Start Nanny at: 'tcp://172.21.10.168:33738'
distributed.nanny - INFO -         Start Nanny at: 'tcp://172.21.10.168:44924'
distributed.nanny - INFO -         Start Nanny at: 'tcp://172.21.8.207:45698'
distributed.nanny - INFO -         Start Nanny at: 'tcp://172.21.8.207:33131'
distributed.nanny - INFO -         Start Nanny at: 'tcp://172.21.6.169:34678'
distributed.nanny - INFO -         Start Nanny at: 'tcp://172.21.6.169:40994'
distributed.nanny - INFO -         Start Nanny at: 'tcp://172.21.6.167:35171'
distributed.nanny - INFO -         Start Nanny at: 'tcp://172.21.6.167:34988'
distributed.nanny - INFO -         Start Nanny at: 'tcp://172.21.6.170:46296'
distributed.nanny - INFO -         Start Nanny at: 'tcp://172.21.6.170:39725'
distributed.nanny - INFO -         Start Nanny at: 'tcp://172.21.2.253:43273'
distributed.nanny - INFO -         Start Nanny at: 'tcp://172.21.2.253:39710'
distributed.nanny - INFO - Worker closed
distributed.nanny - INFO - Worker closed
distributed.nanny - INFO - Worker closed
distributed.nanny - INFO - Worker closed
distributed.nanny - INFO - Worker closed
distributed.nanny - INFO - Worker closed
distributed.nanny - INFO - Worker closed
distributed.nanny - INFO - Worker closed
distributed.nanny - INFO - Worker closed
distributed.nanny - INFO - Worker closed
distributed.nanny - INFO - Worker closed
distributed.nanny - INFO - Worker closed
distributed.nanny - INFO - Worker closed
distributed.nanny - INFO - Worker closed
distributed.nanny - INFO - Worker closed
distributed.nanny - INFO - Worker closed
distributed.nanny - INFO - Closing Nanny at 'tcp://172.21.6.169:40994'
distributed.dask_worker - INFO - End worker
distributed.nanny - INFO - Closing Nanny at 'tcp://172.21.2.253:39710'
distributed.dask_worker - INFO - End worker
distributed.nanny - INFO - Closing Nanny at 'tcp://172.21.6.170:46296'
distributed.dask_worker - INFO - End worker
distributed.nanny - INFO - Closing Nanny at 'tcp://172.21.10.168:33738'
distributed.dask_worker - INFO - End worker
distributed.nanny - INFO - Closing Nanny at 'tcp://172.21.7.155:44022'
distributed.dask_worker - INFO - End worker
distributed.nanny - INFO - Closing Nanny at 'tcp://172.21.6.171:41394'
distributed.dask_worker - INFO - End worker
distributed.nanny - INFO - Closing Nanny at 'tcp://172.21.8.207:33131'
distributed.nanny - INFO - Closing Nanny at 'tcp://172.21.6.169:34678'
distributed.dask_worker - INFO - End worker
distributed.dask_worker - INFO - End worker
distributed.nanny - INFO - Closing Nanny at 'tcp://172.21.6.170:39725'
distributed.dask_worker - INFO - End worker
distributed.nanny - INFO - Closing Nanny at 'tcp://172.21.7.155:38421'
distributed.dask_worker - INFO - End worker
distributed.nanny - INFO - Closing Nanny at 'tcp://172.21.2.253:43273'
distributed.dask_worker - INFO - End worker
distributed.nanny - INFO - Closing Nanny at 'tcp://172.21.8.207:45698'
distributed.nanny - INFO - Closing Nanny at 'tcp://172.21.10.168:44924'
distributed.dask_worker - INFO - End worker
distributed.dask_worker - INFO - End worker
distributed.nanny - INFO - Closing Nanny at 'tcp://172.21.6.171:45033'
distributed.dask_worker - INFO - End worker
distributed.nanny - INFO - Closing Nanny at 'tcp://172.21.6.167:34988'
distributed.dask_worker - INFO - End worker
distributed.nanny - INFO - Closing Nanny at 'tcp://172.21.6.167:35171'
distributed.dask_worker - INFO - End worker
